Workbook
Name \c: #REF!
Name \x: 'C 5'!#REF!
Name \x: #REF!
Name A: 'C 5'!$Y$21:$DF$21
Name A: #REF!
Name A_IMPRESION_IM: 'C 91 - 99'!#REF!
Name A_IMPRESION_IM: #REF!
Name A_impresión_IM: 'C 100 - 101'!$A$1:$K$58
Name A_impresión_IM: 'C 102 - 103'!$A$1:$I$45
Name A_impresión_IM: 'C 104-105'!$A$1:$K$57
Name A_impresión_IM: 'C 106 - 107'!$A$1:$H$45
Name A_impresión_IM: 'C 108 - 109 '!#REF!
Name A_IMPRESIÓN_IM: [1]CYPPOLLO!#REF!
Name A_IMPRESIÓN_IM: [1]CYPPOLLO!#REF!
Name A_impresión_IM: #REF!
Name A_impresión_IM: 'C 90'!$A$1:$D$43
Name A_IMPRESIÓN_IM: 'C 91 - 99'!$A$3:$DH$39
Name A_IMPRESIÓN_IM: [1]CYPPOLLO!#REF!
Name A_impresión_IM: #REF!
Name A_impresión_IM: 'C-88'!$A$1:$D$43
Name A_impresión_IM: 'C-89'!$A$1:$D$43
Name A_impresión_IM: #REF!

Sheet 1. INDICADORES ECONÓMICOS

Sheet C 1 - C 2 - C 3
A2: C.1 PERÚ: EVOLUCIÓN DEL VALOR BRUTO DE LA PRODUCCIÓN (VBP) AGROPECUARIA POR AÑO, SEGÚN SUB SECTORES Y PRINCIPALES ESPECIES Y PRODUCTOS PECUARIOS, 2007-2023
A3: (Millones de soles a precios 2007)
A5: Sector / Producto | C5: 2000 | D5: 2001 | E5: 2002 | F5: 2003 | G5: 2004 | H5: 2005 | I5: 2006 | J5: 2007 | K5: 2008 | L5: 2009 | M5: 2010 | N5: 2011 | O5: 2012 | P5: 2013 | Q5: 2014 | R5: 2015 | S5: 2016 | T5: 2017 | U5: 2018 | V5: 2019 | W5: 2020 | X5: 2021 | Y5: 2022 | Z5: 2023P | AA5: Var. % 23/22
A6: Sector agropecuario | C6: 17474.3 | D6: 17601.8 | E6: 18603.6 | F6: 18969.3 | G6: 19096 | H6: 20511.9 | I6: 22151.7 | J6: 22808.209 | K6: 24741.749 | L6: 25379.076 | M6: 26407.36 | N6: 27861.203 | O6: 29537.88 | P6: 30131.561 | Q6: 30697.658 | R6: 31893.695 | S6: 32598.008 | T6: 33558.832 | U6: 36138.105 | V6: 37418.529 | W6: 37803.566 | X6: 39559.209 | Y6: 41353.21 | Z6: 40349.979 | AA6: =((Z6/Y6)-1)*100 -> -2.426004
A7: Subsector agrícola | C7: 11577.1 | D7: 11537.3 | E7: 12282.8 | F7: 12444.9 | G7: 12391.7 | H7: 13289.3 | I7: 14340.7 | J7: 14533.198 | K7: 15862.084 | L7: 15991.165 | M7: 16615.994 | N7: 17377.297 | O7: 18471.166 | P7: 18672.443 | Q7: 18832.948 | R7: 19407.572 | S7: 19606.725 | T7: 20205.449 | U7: 22039.85 | V7: 22755.49 | W7: 23398.865 | X7: 24866.703 | Y7: 26300.765 | Z7: 25306.554 | AA7: =((Z7/Y7)-1)*100 -> -3.7801595
A8: Subsector pecuario | C8: 5897.2 | D8: 6064.5 | E8: 6320.8 | F8: 6524.4 | G8: 6704.3 | H8: 7222.6 | I8: 7811 | J8: 8275.0106 | K8: 8879.6649 | L8: 9387.9104 | M8: 9791.3659 | N8: 10483.906 | O8: 11066.714 | P8: 11459.118 | Q8: 11864.71 | R8: 12486.123 | S8: 12991.283 | T8: 13353.383 | U8: 14098.256 | V8: 14663.039 | W8: 14404.701 | X8: 14692.505 | Y8: 15052.445 | Z8: 15043.425 | AA8: =((Z8/Y8)-1)*100 -> -0.059921551
B10: Industria avícola 1 | C10: =SUM(C11:C13) -> 2892.6 | D10: =SUM(D11:D13) -> 2958.5 | E10: =SUM(E11:E13) -> 3140.9 | F10: =SUM(F11:F13) -> 3262.9 | G10: =SUM(G11:G13) -> 3280.1 | H10: =SUM(H11:H13) -> 3623.2 | I10: =SUM(I11:I13) -> 4017.6 | J10: =J11+J13 -> 4330.6 | K10: =K11+K13 -> 4847.7 | L10: =L11+L13 -> 5254.6 | M10: =M11+M13 -> 5560.1 | N10: =N11+N13 -> 6092.8 | O10: =O11+O13 -> 6526.6 | P10: =P11+P13 -> 6835.4 | Q10: =Q11+Q13 -> 7152.1 | ... Z10: =Z11+Z13 -> 9727.3063 | AA10: =((Z10/Y10)-1)*100 -> -1.1935
A11: 1 | B11: Ave | C11: 2340.6 | D11: 2376.6 | E11: 2551.2 | F11: 2651.8 | G11: 2655 | H11: 2983.5 | I11: 3259.4 | J11: 3534.8 | K11: 4024.4 | L11: 4424.6 | M11: 4679.4 | N11: 5111.6 | O11: 5556.6 | P11: 5754.9 | Q11: 6044.3 | R11: 6531.3 | S11: 6945.9 | T11: 7199.8 | U11: 7742.8 | V11: 8087.878 | W11: 7907.305 | X11: 8036.274 | Y11: 8266.4437 | Z11: 8173.2922 | AA11: =((Z11/Y11)-1)*100 -> -1.1268635
B12: Pollo | J12: 3273.1 | K12: 3727.9 | L12: 4121.7 | M12: 4362.7 | N12: 4582.9 | O12: 5195.8 | P12: 5394.3 | Q12: 5657.9 | R12: 6101.3 | S12: 6448.2 | T12: 6719.3 | U12: 7257.1 | V12: 7579.043 | W12: 7415.882 | X12: 7520.469 | Y12: 7739.0314 | Z12: 7657.1129 | AA12: =((Z12/Y12)-1)*100 -> -1.0585111
B13: Huevo de gallina | C13: 552 | D13: 581.9 | E13: 589.7 | F13: 611.1 | G13: 625.1 | H13: 639.7 | I13: 758.2 | J13: 795.8 | K13: 823.3 | L13: 830 | M13: 880.7 | N13: 981.2 | O13: 970 | P13: 1080.5 | Q13: 1107.8 | R13: 1193.1 | S13: 1238.6 | T13: 1283 | U13: 1397 | V13: 1508.928 | W13: 1536.856 | X13: 1557.202 | Y13: 1578.3603 | Z13: 1554.0141 | AA13: =((Z13/Y13)-1)*100 -> -1.5424993
A14: 2 | B14: Ovino | C14: 378.7 | D14: 388.4 | E14: 383.2 | F14: 389.2 | G14: 410.8 | H14: 410.6 | I14: 413.3 | J14: 412.5 | K14: 406.5 | L14: 407.8 | M14: 410.4 | N14: 417.6 | O14: 430.3 | P14: 425.5 | Q14: 419.6 | R14: 404.2 | S14: 413.9 | T14: 407.8 | U14: 410.4 | V14: 411.768 | W14: 395.155 | X14: 405.409 | Y14: 408.78638 | Z14: 410.66447 | AA14: =((Z14/Y14)-1)*100 -> 0.45943067
A15: 3 | B15: Porcino | C15: 433.8 | D15: 442.2 | E15: 438.5 | F15: 439.5 | G15: 468.6 | H15: 494 | I15: 516.6 | J15: 542.7 | K15: 545.9 | L15: 543.6 | M15: 548.1 | N15: 557.2 | O15: 579.8 | P15: 605 | Q15: 641.6 | R15: 677.3 | S15: 708 | T15: 747.5 | U15: 781.6 | V15: 821.013 | W15: 805.122 | X15: 834.713 | Y15: 859.61391 | Z15: 949.86218 | AA15: =((Z15/Y15)-1)*100 -> 10.498698
A16: 4 | B16: Vacuno | C16: 1114.1 | D16: 1114.3 | E16: 1147.4 | F16: 1174.2 | G16: 1227.9 | H16: 1304.4 | I16: 1382.1 | J16: 1396.3 | K16: 1397 | L16: 1408.9 | M16: 1470.2 | N16: 1531.9 | O16: 1596.3 | P16: 1651.6 | Q16: 1678.5 | R16: 1676.7 | S16: 1648.4 | T16: 1614.4 | U16: 1622.7 | V16: 1650.213 | W16: 1573.412 | X16: 1624.579 | Y16: 1648.4917 | Z16: 1699.8544 | AA16: =((Z16/Y16)-1)*100 -> 3.1157341
A17: 5 | B17: Caprino | C17: 57.6 | D17: 54.4 | E17: 53.3 | F17: 57.9 | G17: 59.5 | H17: 60.8 | I17: 62.3 | J17: 61.5 | K17: 59 | L17: 56.6 | M17: 56.4 | N17: 56.5 | O17: 57.4 | P17: 59.2 | Q17: 56.7 | R17: 54.3 | S17: 53.6 | T17: 50.5 | U17: 45.7 | V17: 46.913 | W17: 1573.412 | X17: 45.496 | Y17: 45.323481 | Z17: 45.430456 | AA17: =((Z17/Y17)-1)*100 -> 0.23602432
A18: 6 | B18: Alpaca | C18: 130.1 | D18: 137.3 | E18: 147.3 | F18: 146 | G18: 148.2 | H18: 154.4 | I18: 156.5 | J18: 166.7 | K18: 169.6 | L18: 181.4 | M18: 191.6 | N18: 201.5 | O18: 213.6 | P18: 216.6 | Q18: 224.2 | R18: 212.1 | S18: 221.5 | T18: 226.9 | U18: 225.9 | V18: 223.935 | W18: 45.581 | X18: 223.963 | Y18: 227.034 | Z18: 228.66822 | AA18: =((Z18/Y18)-1)*100 -> 0.71981258
A19: 7 | B19: Llama | C19: 25.2 | D19: 25.5 | E19: 25.5 | F19: 27.5 | G19: 29.1 | H19: 30.4 | I19: 30.3 | J19: 31.9 | K19: 31.3 | L19: 32.9 | M19: 32.1 | N19: 33.4 | O19: 34.3 | P19: 32.9 | Q19: 32.9 | R19: 31.4 | S19: 31.3 | T19: 31.6 | U19: 31.5 | V19: 30.319 | W19: 220.072 | X19: 31.046 | Y19: 31.292595 | Z19: 31.686378 | AA19: =((Z19/Y19)-1)*100 -> 1.2583916
A20: 9 | B20: Leche fresca de vaca | C20: 750.6 | D20: 822.4 | E20: 873.8 | F20: 918.1 | G20: 968.1 | H20: 1027.8 | I20: 1119.3 | J20: 1209.8 | K20: 1301 | L20: 1372.9 | M20: 1394.7 | N20: 1458.8 | O20: 1488 | P20: 1502.3 | Q20: 1529.2 | R20: 1581.5 | S20: 1624 | T20: 1673.4 | U20: 1717.8 | V20: 1762.855 | W20: 1774.917 | X20: 1815.68 | Y20: 1867.2035 | Z20: 1829.111 | AA20: =((Z20/Y20)-1)*100 -> -2.040084
A21: 10 | B21: Fibra alpaca | C21: 57 | D21: 62.3 | E21: 58 | F21: 56.9 | G21: 59.6 | H21: 66 | I21: 64.3 | J21: 71.4 | K21: 73.7 | L21: 80.4 | M21: 79.8 | N21: 85.5 | O21: 88 | P21: 81 | Q21: 82.2 | R21: 81.4 | S21: 82.7 | T21: 79.1 | U21: 83.9 | V21: 81.647 | W21: 79.789 | X21: 80.736 | Y21: 81.07727 | Z21: 81.891861 | AA21: =((Z21/Y21)-1)*100 -> 1.0047096
A22: 11 | B22: Fibra llama | C22: 4.6 | D22: 4.7 | E22: 3.8 | F22: 3.9 | G22: 3.8 | H22: 3.7 | I22: 3.8 | J22: 4.5 | K22: 4.3 | L22: 4.3 | M22: 3.9 | N22: 4.2 | O22: 4.6 | P22: 4.4 | Q22: 4.6 | R22: 4 | S22: 4.1 | T22: 4.2 | U22: 4 | V22: 4.028 | W22: 4.0732 | X22: 4.124 | Y22: 4.2640587 | Z22: 4.2857998 | AA22: =((Z22/Y22)-1)*100 -> 0.50986911
A23: 12 | B23: Lana Ovino | C23: 53.5 | D23: 54.4 | E23: 48.9 | F23: 49 | G23: 48.6 | H23: 47.2 | I23: 44.9 | J23: 47.2 | K23: 43.6 | L23: 44.5 | M23: 44.2 | N23: 44.5 | O23: 47.7 | P23: 45 | Q23: 43.2 | R23: 38.8 | S23: 40.5 | T23: 35.2 | U23: 34.9 | V23: 33.543 | W23: 32.315 | X23: 33.283 | Y23: 34.553828 | Z23: 34.666543 | AA23: =((Z23/Y23)-1)*100 -> 0.32619951
A24: P Preliminar
A25: 1 Considera ave y Huevo de gallina
A26: Fuente: Direcciones Regionales de Agricultura
A27: Elaboración: Ministerio de Desarrollo Agrario y Riego - DGESEP - DEIA
A29: C.2 PERÚ: PARTICIPACIÓN POR AÑO, SEGÚN SUB SECTORES Y PRINCIPALES ESPECIES Y PRODUCTOS PECUARIOS EN EL VALOR BRUTO, 2007-2023
A30: (%)
A32: Sector / Producto | C32: 2000 | D32: 2001 | E32: 2002 | F32: 2003 | G32: 2004 | H32: 2005 | I32: 2006 | J32: 2007 | K32: 2008 | L32: 2009 | M32: 2010 | N32: 2011 | O32: 2012 | P32: 2013 | Q32: 2014 | R32: 2015 | S32: 2016 | T32: 2017 | U32: 2018 | V32: 2019 | W32: 2020 | X32: 2021 | Y32: 2022 | Z32: 2023P
A33: Sector agropecuario | C33: =C6/$C$6*100 -> 100 | D33: =D6/$D$6*100 -> 100 | E33: =E6/$E$6*100 -> 100 | F33: =F6/$F$6*100 -> 100 | G33: =G6/$G$6*100 -> 100 | H33: =H6/$H$6*100 -> 100 | I33: =I6/$I$6*100 -> 100 | J33: =J6/$J$6*100 -> 100 | K33: =K6/$K$6*100 -> 100 | L33: =L6/$L$6*100 -> 100 | M33: =M6/$M$6*100 -> 100 | N33: =N6/$N$6*100 -> 100 | O33: =O6/$O$6*100 -> 100 | P33: =P6/$P$6*100 -> 100 | Q33: =Q6/$Q$6*100 -> 100 | R33: =R6/$R$6*100 -> 100 | S33: =S6/$S$6*100 -> 100 | T33: =T6/$T$6*100 -> 100 | U33: =U6/$U$6*100 -> 100 | V33: =V6/$V$6*100 -> 100 | W33: =W6/$W$6*100 -> 100 | X33: =X6/$X$6*100 -> 100 | Y33: =Y6/$Y$6*100 -> 100 | Z33: =Z6/$Z$6*100 -> 100
A34: Subsector agrícola | C34: =C7/$C$6*100 -> 66.252153 | D34: =D7/$D$6*100 -> 65.546137 | E34: =E7/$E$6*100 -> 66.02378 | F34: =F7/$F$6*100 -> 65.605478 | G34: =G7/$G$6*100 -> 64.8916 | H34: =H7/$H$6*100 -> 64.788245 | I34: =I7/$I$6*100 -> 64.738598 | J34: =J7/$J$6*100 -> 63.719156 | K34: =K7/$K$6*100 -> 64.110601 | L34: =L7/$L$6*100 -> 63.00925 | M34: =M7/$M$6*100 -> 62.92183 | N34: =N7/$N$6*100 -> 62.370949 | O34: =O7/$O$6*100 -> 62.533825 | P34: =P7/$P$6*100 -> 61.969717 | Q34: =Q7/$Q$6*100 -> 61.349788 | R34: =R7/$R$6*100 -> 60.850811 | S34: =S7/$S$6*100 -> 60.147003 | T34: =T7/$T$6*100 -> 60.209035 | U34: =U7/$U$6*100 -> 60.98784 | V34: =V7/$V$6*100 -> 60.813428 | W34: =W7/$W$6*100 -> 61.895921 | X34: =X7/$X$6*100 -> 62.859455 | Y34: =Y7/$Y$6*100 -> 63.600299 | Z34: =Z7/$Z$6*100 -> 62.717638
A35: Subsector pecuario | C35: =C8/$C$6*100 -> 33.747847 | D35: =D8/$D$6*100 -> 34.453863 | E35: =E8/$E$6*100 -> 33.97622 | F35: =F8/$F$6*100 -> 34.394522 | G35: =G8/$G$6*100 -> 35.1084 | H35: =H8/$H$6*100 -> 35.211755 | I35: =I8/$I$6*100 -> 35.261402 | J35: =J8/$J$6*100 -> 36.280844 | K35: =K8/$K$6*100 -> 35.889399 | L35: =L8/$L$6*100 -> 36.99075 | M35: =M8/$M$6*100 -> 37.07817 | N35: =N8/$N$6*100 -> 37.629051 | O35: =O8/$O$6*100 -> 37.466175 | P35: =P8/$P$6*100 -> 38.030283 | Q35: =Q8/$Q$6*100 -> 38.650212 | R35: =R8/$R$6*100 -> 39.149189 | S35: =S8/$S$6*100 -> 39.852997 | T35: =T8/$T$6*100 -> 39.790965 | U35: =U8/$U$6*100 -> 39.01216 | V35: =V8/$V$6*100 -> 39.186572 | W35: =W8/$W$6*100 -> 38.104079 | X35: =X8/$X$6*100 -> 37.140545 | Y35: =Y8/$Y$6*100 -> 36.399701 | Z35: =Z8/$Z$6*100 -> 37.282362
B37: Industria avícola 1 | C37: =C10/$C$6*100 -> 16.553453 | D37: =D10/$D$6*100 -> 16.80794 | E37: =E10/$E$6*100 -> 16.883291 | F37: =F10/$F$6*100 -> 17.200951 | G37: =G10/$G$6*100 -> 17.176896 | H37: =H10/$H$6*100 -> 17.663893 | I37: =I10/$I$6*100 -> 18.136757 | J37: =J10/$J$6*100 -> 18.987024 | K37: =K10/$K$6*100 -> 19.593199 | L37: =L10/$L$6*100 -> 20.704458 | M37: =M10/$M$6*100 -> 21.055115 | N37: =N10/$N$6*100 -> 21.868403 | O37: =O10/$O$6*100 -> 22.095696 | P37: =P10/$P$6*100 -> 22.685184 | Q37: =Q10/$Q$6*100 -> 23.29852 | R37: =R10/$R$6*100 -> 24.219207 | S37: =S10/$S$6*100 -> 25.107362 | T37: =T10/$T$6*100 -> 25.2774 | U37: =U10/$U$6*100 -> 25.291309 | V37: =V10/$V$6*100 -> 25.647203 | W37: =W10/$W$6*100 -> 24.982196 | X37: =X10/$X$6*100 -> 24.25093 | Y37: =Y10/$Y$6*100 -> 23.806626 | Z37: =Z10/$Z$6*100 -> 24.107339
B38: Ave | C38: =C11/$C$6*100 -> 13.394528 | D38: =D11/$D$6*100 -> 13.502028 | E38: =E11/$E$6*100 -> 13.713475 | F38: =F11/$F$6*100 -> 13.97943 | G38: =G11/$G$6*100 -> 13.903435 | H38: =H11/$H$6*100 -> 14.545215 | I38: =I11/$I$6*100 -> 14.713995 | J38: =J11/$J$6*100 -> 15.497929 | K38: =K11/$K$6*100 -> 16.265625 | L38: =L11/$L$6*100 -> 17.434047 | M38: =M11/$M$6*100 -> 17.72006 | N38: =N11/$N$6*100 -> 18.34666 | O38: =O11/$O$6*100 -> 18.811777 | P38: =P11/$P$6*100 -> 19.099243 | Q38: =Q11/$Q$6*100 -> 19.689776 | R38: =R11/$R$6*100 -> 20.478342 | S38: =S11/$S$6*100 -> 21.307743 | T38: =T11/$T$6*100 -> 21.454263 | U38: =U11/$U$6*100 -> 21.425584 | V38: =V11/$V$6*100 -> 21.614634 | W38: =W11/$W$6*100 -> 20.916823 | X38: =X11/$X$6*100 -> 20.314547 | Y38: =Y11/$Y$6*100 -> 19.989848 | Z38: =Z11/$Z$6*100 -> 20.256001
B39: Pollo | J39: =J12/$J$6*100 -> 14.350535 | K39: =K12/$K$6*100 -> 15.067245 | L39: =L12/$L$6*100 -> 16.240544 | M39: =M12/$M$6*100 -> 16.520773 | N39: =N12/$N$6*100 -> 16.449039 | O39: =O12/$O$6*100 -> 17.590294 | P39: =P12/$P$6*100 -> 17.902491 | Q39: 18.430722 | R39: 19.12993 | S39: 19.784428 | T39: 20.056175 | U39: 20.092974 | V39: 20.255343 | W39: 19.618424 | X39: 19.024363 | Y39: =Y12/$Y$6*100 -> 18.714464 | Z39: =Z12/$Z$6*100 -> 18.976746
A40: 1 | B40: Huevo de gallina | C40: =C13/$C$6*100 -> 3.1589248 | D40: =D13/$D$6*100 -> 3.3059119 | E40: =E13/$E$6*100 -> 3.1698166 | F40: =F13/$F$6*100 -> 3.2215211 | G40: =G13/$G$6*100 -> 3.2734604 | H40: =H13/$H$6*100 -> 3.1186775 | I40: =I13/$I$6*100 -> 3.4227621 | J40: =J13/$J$6*100 -> 3.4890947 | K40: =K13/$K$6*100 -> 3.327574 | L40: =L13/$L$6*100 -> 3.2704107 | M40: =M13/$M$6*100 -> 3.3350551 | N40: =N13/$N$6*100 -> 3.5217432 | O40: =O13/$O$6*100 -> 3.2839189 | P40: =P13/$P$6*100 -> 3.585941 | Q40: =Q13/$Q$6*100 -> 3.6087443 | R40: =R13/$R$6*100 -> 3.7408647 | S40: =S13/$S$6*100 -> 3.7996186 | T40: =T13/$T$6*100 -> 3.8231366 | U40: =U13/$U$6*100 -> 3.8657256 | V40: =V13/$V$6*100 -> 4.032569 | W40: =W13/$W$6*100 -> 4.0653731 | X40: =X13/$X$6*100 -> 3.9363831 | Y40: =Y13/$Y$6*100 -> 3.8167783 | Z40: =Z13/$Z$6*100 -> 3.8513381
B41: Ovino | C41: =C14/$C$6*100 -> 2.1671827 | D41: =D14/$D$6*100 -> 2.2065925 | E41: =E14/$E$6*100 -> 2.0598164 | F41: =F14/$F$6*100 -> 2.0517362 | G41: =G14/$G$6*100 -> 2.1512359 | H41: =H14/$H$6*100 -> 2.0017648 | I41: =I14/$I$6*100 -> 1.865771 | J41: =J14/$J$6*100 -> 1.8085594 | K41: =K14/$K$6*100 -> 1.642972 | L41: =L14/$L$6*100 -> 1.6068355 | M41: =M14/$M$6*100 -> 1.5541122 | N41: =N14/$N$6*100 -> 1.4988585 | O41: =O14/$O$6*100 -> 1.4567735 | P41: =P14/$P$6*100 -> 1.4121406 | Q41: =Q14/$Q$6*100 -> 1.3668795 | R41: =R14/$R$6*100 -> 1.2673351 | S41: =S14/$S$6*100 -> 1.2697095 | T41: =T14/$T$6*100 -> 1.2151794 | U41: =U14/$U$6*100 -> 1.1356434 | V41: =V14/$V$6*100 -> 1.1004388 | W41: =W14/$W$6*100 -> 1.045285 | X41: =X14/$X$6*100 -> 1.0248157 | Y41: =Y14/$Y$6*100 -> 0.98852394 | Z41: =Z14/$Z$6*100 -> 1.0177563
B42: Porcino | C42: =C15/$C$6*100 -> 2.4825029 | D42: =D15/$D$6*100 -> 2.5122431 | E42: =E15/$E$6*100 -> 2.3570707 | F42: =F15/$F$6*100 -> 2.3169015 | G42: =G15/$G$6*100 -> 2.4539171 | H42: =H15/$H$6*100 -> 2.4083581 | I42: =I15/$I$6*100 -> 2.3321009 | J42: =J15/$J$6*100 -> 2.3794065 | K42: =K15/$K$6*100 -> 2.2063921 | L42: =L15/$L$6*100 -> 2.141922 | M42: =M15/$M$6*100 -> 2.0755577 | N42: =N15/$N$6*100 -> 1.9999137 | O42: =O15/$O$6*100 -> 1.9629033 | P42: =P15/$P$6*100 -> 2.0078614 | Q42: =Q15/$Q$6*100 -> 2.0900617 | R42: =R15/$R$6*100 -> 2.1236172 | S42: =S15/$S$6*100 -> 2.1719118 | T42: =T15/$T$6*100 -> 2.2274315 | U42: =U15/$U$6*100 -> 2.162814 | V42: =V15/$V$6*100 -> 2.1941349 | W42: =W15/$W$6*100 -> 2.1297515 | X42: =X15/$X$6*100 -> 2.1100346 | Y42: =Y15/$Y$6*100 -> 2.0787115 | Z42: =Z15/$Z$6*100 -> 2.3540587
B43: Vacuno | C43: =C16/$C$6*100 -> 6.3756488 | D43: =D16/$D$6*100 -> 6.3306026 | E43: =E16/$E$6*100 -> 6.1676235 | F43: =F16/$F$6*100 -> 6.1900017 | G43: =G16/$G$6*100 -> 6.4301424 | H43: =H16/$H$6*100 -> 6.3592354 | I43: =I16/$I$6*100 -> 6.2392503 | J43: =J16/$J$6*100 -> 6.1219188 | K43: =K16/$K$6*100 -> 5.6463268 | L43: =L16/$L$6*100 -> 5.5514236 | M43: =M16/$M$6*100 -> 5.5673873 | N43: =N16/$N$6*100 -> 5.4983269 | O43: =O16/$O$6*100 -> 5.4042471 | P43: =P16/$P$6*100 -> 5.4812958 | Q43: =Q16/$Q$6*100 -> 5.4678438 | R43: =R16/$R$6*100 -> 5.2571519 | S43: =S16/$S$6*100 -> 5.0567506 | T43: =T16/$T$6*100 -> 4.8106561 | U43: =U16/$U$6*100 -> 4.4902742 | V43: =V16/$V$6*100 -> 4.4101493 | W43: =W16/$W$6*100 -> 4.162073 | X43: =X16/$X$6*100 -> 4.1067025 | Y43: =Y16/$Y$6*100 -> 3.9863695 | Z43: =Z16/$Z$6*100 -> 4.2127763
B44: Caprino | C44: =C17/$C$6*100 -> 0.32962694 | D44: =D17/$D$6*100 -> 0.3090593 | E44: =E17/$E$6*100 -> 0.28650369 | F44: =F17/$F$6*100 -> 0.30523003 | G44: =G17/$G$6*100 -> 0.31158358 | H44: =H17/$H$6*100 -> 0.2964133 | I44: =I17/$I$6*100 -> 0.28124252 | J44: =J17/$J$6*100 -> 0.26963977 | K44: =K17/$K$6*100 -> 0.23846334 | L44: =L17/$L$6*100 -> 0.22301837 | M44: =M17/$M$6*100 -> 0.21357682 | N44: =N17/$N$6*100 -> 0.20279096 | O44: =O17/$O$6*100 -> 0.19432674 | P44: =P17/$P$6*100 -> 0.19647173 | Q44: =Q17/$Q$6*100 -> 0.18470464 | R44: =R17/$R$6*100 -> 0.17025308 | S44: =S17/$S$6*100 -> 0.16442722 | T44: =T17/$T$6*100 -> 0.150482 | U44: =U17/$U$6*100 -> 0.12645931 | V44: =V17/$V$6*100 -> 0.12537371 | W44: =W17/$W$6*100 -> 4.162073 | X44: =X17/$X$6*100 -> 0.11500736 | Y44: =Y17/$Y$6*100 -> 0.10960088 | Z44: =Z17/$Z$6*100 -> 0.11259103
B45: Alpaca | C45: =C18/$C$6*100 -> 0.74452196 | D45: =D18/$D$6*100 -> 0.78003386 | E45: =E18/$E$6*100 -> 0.79178224 | F45: =F18/$F$6*100 -> 0.76966467 | G45: =G18/$G$6*100 -> 0.77607876 | H45: =H18/$H$6*100 -> 0.75273378 | I45: =I18/$I$6*100 -> 0.70649205 | J45: =J18/$J$6*100 -> 0.73087722 | K45: =K18/$K$6*100 -> 0.68548105 | L45: =L18/$L$6*100 -> 0.71476204 | M45: =M18/$M$6*100 -> 0.7255553 | N45: =N18/$N$6*100 -> 0.72322793 | O45: =O18/$O$6*100 -> 0.72313925 | P45: =P18/$P$6*100 -> 0.71884759 | Q45: =Q18/$Q$6*100 -> 0.73034887 | R45: =R18/$R$6*100 -> 0.66502171 | S45: =S18/$S$6*100 -> 0.67948936 | T45: =T18/$T$6*100 -> 0.67612604 | U45: =U18/$U$6*100 -> 0.62510195 | V45: =V18/$V$6*100 -> 0.59846019 | W45: =W18/$W$6*100 -> 0.12057328 | X45: =X18/$X$6*100 -> 0.56614631 | Y45: =Y18/$Y$6*100 -> 0.54901181 | Z45: =Z18/$Z$6*100 -> 0.56671212
B46: Llama | C46: =C19/$C$6*100 -> 0.14421179 | D46: =D19/$D$6*100 -> 0.14487155 | E46: =E19/$E$6*100 -> 0.13707024 | F46: =F19/$F$6*100 -> 0.14497108 | G46: =G19/$G$6*100 -> 0.15238793 | H46: =H19/$H$6*100 -> 0.14820665 | I46: =I19/$I$6*100 -> 0.13678408 | J46: =J19/$J$6*100 -> 0.13986193 | K46: =K19/$K$6*100 -> 0.12650682 | L46: =L19/$L$6*100 -> 0.12963435 | M46: =M19/$M$6*100 -> 0.12155702 | N46: =N19/$N$6*100 -> 0.11987997 | O46: =O19/$O$6*100 -> 0.11612208 | P46: =P19/$P$6*100 -> 0.10918784 | Q46: =Q19/$Q$6*100 -> 0.1071743 | R46: =R19/$R$6*100 -> 0.09845206 | S46: =S19/$S$6*100 -> 0.096018136 | T46: =T19/$T$6*100 -> 0.094162992 | U46: =U19/$U$6*100 -> 0.08716561 | V46: =V19/$V$6*100 -> 0.081026702 | W46: =W19/$W$6*100 -> 0.58214614 | X46: =X19/$X$6*100 -> 0.078479831 | Y46: =Y19/$Y$6*100 -> 0.075671502 | Z46: =Z19/$Z$6*100 -> 0.078528859
...

Sheet 2. POBLACION Y ...

Sheet C-4
A2: C.4 PERÚ: POBLACIÓN PECUARIA POR ESPECIE, SEGÚN REGIÓN, 2023P
A3: (Unidades)
A5: Región | B5: Ave | C5: Alpaca | D5: LLama | E5: Caprino | F5: Ovino | G5: Porcino | H5: Vacuno | I5: Vacas en Ordeño
A6: Total Nacional | B6: =(B8+B9+B10+B11+B12+B16+B17+B18+B19+B20+B21+B22+B23+B24+B25+B26+B27+B28+B31+B32+B33+B34+B35+B36) -> 191690902 | C6: =(C8+C9+C10+C11+C12+C16+C17+C18+C19+C20+C21+C22+C23+C24+C25+C26+C27+C28+C31+C32+C33+C34+C35+C36) -> 4483838 | D6: =(D8+D9+D10+D11+D12+D16+D17+D18+D19+D20+D21+D22+D23+D24+D25+D26+D27+D28+D31+D32+D33+D34+D35+D36) -> 1071971 | E6: =(E8+E9+E10+E11+E12+E16+E17+E18+E19+E20+E21+E22+E23+E24+E25+E26+E27+E28+E31+E32+E33+E34+E35+E36) -> 1764665 | F6: =(F8+F9+F10+F11+F12+F16+F17+F18+F19+F20+F21+F22+F23+F24+F25+F26+F27+F28+F31+F32+F33+F34+F35+F36) -> 11238432 | G6: =(G8+G9+G10+G11+G12+G16+G17+G18+G19+G20+G21+G22+G23+G24+G25+G26+G27+G28+G31+G32+G33+G34+G35+G36) -> 3465175 | H6: =(H8+H9+H10+H11+H12+H16+H17+H18+H19+H20+H21+H22+H23+H24+H25+H26+H27+H28+H31+H32+H33+H34+H35+H36) -> 5866167.5 | I6: =(I8+I9+I10+I11+I12+I16+I17+I18+I19+I20+I21+I22+I23+I24+I25+I26+I27+I28+I31+I32+I33+I34+I35+I36) -> 933432.9
A8: Tumbes | B8: 181330 | C8: 0 | D8: 0 | E8: 94086 | F8: 11437 | G8: 27921 | H8: 17720 | I8: 318.66667
A9: Piura | B9: 3987073 | C9: 105 | D9: 0 | E9: 296221 | F9: 243119 | G9: 173258 | H9: 268181 | I9: 25109.129
A10: Lambayeque | B10: 2591887 | C10: 0 | D10: 0 | E10: 105365 | F10: 71310 | G10: 65400 | H10: 109560 | I10: 17530.092
A11: La Libertad | B11: 25521509 | C11: 8015 | D11: 0 | E11: 84406 | F11: 369947 | G11: 103302 | H11: 235167 | I11: 55033
A12: Cajamarca | B12: =SUM(B13:B15) -> 889358 | C12: =SUM(C13:C15) -> 1193 | D12: =SUM(D13:D15) -> 0 | E12: =SUM(E13:E15) -> 105217 | F12: =SUM(F13:F15) -> 483579 | G12: =SUM(G13:G15) -> 291453 | H12: 656258 | I12: 169411.14
A13: Cajamarca | B13: 379163 | C13: 1193 | D13: 0 | E13: 65820 | F13: 344151 | G13: 77751 | H13: 264094.5 | I13: 98962.275
A14: Chota | B14: 211445 | C14: 0 | D14: 0 | E14: 20711 | F14: 103091 | G14: 103842 | H14: 273014 | I14: 64920.008
A15: Jaén | B15: 298750 | C15: 0 | D15: 0 | E15: 18686 | F15: 36337 | G15: 109860 | H15: 119149.5 | I15: 5528.8583
A16: Amazonas | B16: 1529745 | C16: 0 | D16: 0 | E16: 15271 | F16: 28499 | G16: 98622 | H16: 405051 | I16: 83168.333
A17: Ancash | B17: 2627008 | C17: 11119 | D17: 0 | E17: 168033 | F17: 671820 | G17: 185907 | H17: 307203 | I17: 18886.5
A18: LimaP | B18: 92164669 | C18: 46625 | D18: 18780 | E18: 159255 | F18: 321147 | G18: 503561 | H18: 268184 | I18: 72321.044
A19: Ica | B19: 19902381 | C19: 0 | D19: 0 | E19: 80874 | F19: 30121 | G19: 195225 | H19: 55524 | I19: 19217.917
A20: Huánuco | B20: 1756819 | C20: 6988 | D20: 3479 | E20: 101647 | F20: 527339 | G20: 404816 | H20: 285746 | I20: 41204.25
A21: Pasco | B21: 139453 | C21: 131076 | D21: 44377 | E21: 6396 | F21: 683544 | G21: 53110 | H21: 118477.5 | I21: 31278.583
A22: Junín | B22: 2568571 | C22: 121987 | D22: 74625 | E22: 17118 | F22: 1652072 | G22: 204941 | H22: 359952 | I22: 41790.917
A23: Huancavelica | B23: 388342 | C23: 269108 | D23: 129490 | E23: 186954 | F23: 623222 | G23: 156101 | H23: 178512 | I23: 12577.833
A24: Arequipa | B24: 16948124 | C24: 471885 | D24: 87938 | E24: 31937 | F24: 204621 | G24: 119024 | H24: 219346 | I24: 71265.583
... A27: Ayacucho | B27: 578129 | C27: 267415 | D27: 78579 | E27: 159445 | F27: 635108 | G27: 128976 | H27: 421401 | I27: 28184.167
A28: Apurímac | B28: =SUM(B29:B30) -> 306580 | C28: =SUM(C29:C30) -> 213848 | D28: =SUM(D29:D30) -> 72271 | E28: =SUM(E29:E30) -> 108213 | F28: =SUM(F29:F30) -> 454659 | G28: =SUM(G29:G30) -> 138421 | H28: 293901.5 | I28: 28762.242
A29: Abancay | B29: 188439 | C29: 192980 | D29: 54013 | E29: 55204 | F29: 311439 | G29: 49414 | H29: 188646.5 | I29: 17592.425
A30: Andahuaylas | B30: 118141 | C30: 20868 | D30: 18258 | E30: 53009 | F30: 143220 | G30: 89007 | H30: 105255 | I30: 11169.817
A31: Cusco | B31: 1203466 | C31: 672042 | D31: 138750 | E31: 18142 | F31: 1381440 | G31: 122270 | H31: 441440 | I31: 83432.75
A32: Puno | B32: 1556940 | C32: 2037185 | D32: 357075 | E32: 0 | F32: 2727605 | G32: 118775 | H32: 750570 | I32: 97251.667
A33: San Martín | B33: 4755028 | C33: 0 | D33: 0 | E33: 0 | F33: 9161 | G33: 189557 | H33: 213905 | I33: 20473.333
A34: Loreto | B34: 4190254 | C34: 0 | D34: 0 | E34: 296 | F34: 11255 | G34: 80560 | H34: 79468 | I34: 1170.5833
A35: Ucayali | B35: 6165923 | C35: 0 | D35: 0 | E35: 186 | F35: 8628 | G35: 43606 | H35: 73825 | I35: 2962.5
A36: Madre de Dios | B36: 488634 | C36: 0 | D36: 0 | E36: 220 | F36: 4860 | G36: 8689 | H36: 64923 | I36: 951.66667
A37: P Preliminar
A38: Fuente: Direcciones Regionales de Agricultura
A39: Elaboración: Ministerio de Desarrollo Agrario y Riego - DGESEP - DEIA

Sheet C 5
A2: C.5 PERÚ: EVOLUCIÓN DE LA POBLACIÓN, SACA, PRODUCCIÓN, RENDIMIENTO Y PRECIOS RECIBIDOS POR EL PRODUCTOR POR AÑO,
A3: SEGÚN ESPECIE Y PRODUCTO, 2007-2023 | S3: Continúa C.5
A5: Especie/ Producto | B5: Variable | C5: 2000 | D5: 2001 | E5: 2002 | F5: 2003 | G5: 2004 | H5: 2005 | I5: 2006 | J5: 2007 | K5: 2008 | L5: 2009 | M5: 2010 | N5: 2011 | O5: 2012 | P5: 2013 | Q5: 2014 | R5: 2015 | S5: Especie/ Producto | T5: Variable | U5: 2016 | V5: 2017 | W5: 2018 | X5: 2019 | Y5: 2020 | Z5: 2021 | AA5: 2022 | AB5: 2023 P
B6: Población (Miles) | C6: 88010358 | D6: 85621159 | E6: 90354182 | F6: 92846109 | G6: 97761003 | H6: 99278818 | I6: 117976702 | J6: 120227.6 | K6: 131179.1 | L6: 137838 | M6: 130779 | N6: 128943.5 | O6: 138554.1 | P6: 138179.8 | Q6: 144703.7 | R6: 151000.9 | T6: Población (Miles) | U6: 158263.2 | V6: 156637.7 | W6: 160959.32 | X6: 168172.6 | Y6: 178159.6 | Z6: 189374.8 | AA6: 190881.9 | AB6: 191690.9
B7: Saca (Miles) | C7: 283733046 | D7: 287860594 | E7: 307094298 | F7: 310943489 | G7: 308485309 | H7: 342073628 | I7: 368545799 | J7: 394749.6 | K7: 435909.3 | L7: 476340.3 | M7: 504986.8 | N7: 535421.1 | O7: 575566.4 | P7: 594004.2 | Q7: 621140.1 | R7: 645016.2 | T7: Saca (Miles) | U7: 690892.3 | V7: 709233 | W7: 755841.1 | X7: 786256.9 | Y7: 753602.3 | Z7: 776641.2 | AA7: 803595.9 | AB7: 789754.22
A8: Ave | B8: Produción carne (t) | C8: 510161 | D8: 518010 | E8: 556076 | F8: 577989 | G8: 578693 | H8: 650296 | I8: 710428 | J8: 770444 | K8: 877171 | L8: 964407 | M8: 1019935 | N8: 1108345 | O8: 1211140 | P8: 1254348 | Q8: 1317426 | R8: 1423586 | S8: Ave | T8: Produción carne (t) | U8: 1513950 | V8: 1569280 | W8: 1687636 | X8: 1762855.6 | Y8: 1723497.5 | Z8: 1751607.8 | AA8: 1801776.3 | AB8: 1781472.7
B9: Rendimiento (kg/Unidad) | C9: =(C8/C7)*1000 -> 1.7980317 | D9: =(D8/D7)*1000 -> 1.7995169 | E9: =(E8/E7)*1000 -> 1.8107663 | F9: =(F8/F7)*1000 -> 1.8588233 | G9: =(G8/G7)*1000 -> 1.8759175 | H9: =(H8/H7)*1000 -> 1.901041 | I9: =(I8/I7)*1000 -> 1.9276519 | J9: =(J8/J7) -> 1.9517284 | K9: =(K8/K7) -> 2.0122787 | L9: =(L8/L7) -> 2.0246177 | M9: =(M8/M7) -> 2.0197261 | N9: =(N8/N7) -> 2.0700436 | O9: =(O8/O7) -> 2.1042576 | P9: =(P8/P7) -> 2.111682 | Q9: =(Q8/Q7) -> 2.1209804 | R9: =(R8/R7) -> 2.2070546 | T9: Rendimiento (kg/Unidad) | U9: =(U8/U7) -> 2.1912967 | V9: =(V8/V7) -> 2.2126438 | W9: =(W8/W7) -> 2.2327921 | X9: =(X8/X7) -> 2.2420861 | Y9: =(Y8/Y7) -> 2.287012 | Z9: 2.2553631 | AA9: 2.2421422 | AB9: =AB8/AB7 -> 2.2557306
B10: Precio (S/ / kg) | C10: 3.06 | D10: 3.19 | E10: 3.07 | F10: 3.09 | G10: 3.48 | H10: 3.46 | I10: 3.6 | J10: 3.63 | K10: 4.18 | L10: 4.33 | M10: 4.64 | N10: 4.67 | O10: 4.7 | P10: 4.75 | Q10: 4.78 | R10: 4.82 | T10: Precio (S/ / kg) | U10: 4.84 | V10: 4.84 | W10: 4.86 | X10: 4.67 | Y10: 5.02 | Z10: 5.85 | AA10: 6.33 | AB10: 6.9938805
B11: Población (Unidades) | C11: 14800991 | D11: 14727155 | E11: 14690547 | F11: 14721243 | G11: 14696522 | H11: 14813786 | I11: 14675255 | J11: 14580166 | K11: 14509628 | L11: 14137690 | M11: 14159720 | N11: 14050173 | O11: 12184143 | P11: 11830977 | Q11: 11652272 | R11: 11982580 | T11: Población (Unidades) | U11: 11450657 | V11: 11338424 | W11: 11330908 | X11: 11371637 | Y11: 11071699 | Z11: 11266309 | AA11: 11210723 | AB11: 11238432
B12: Saca (Unidades) | C12: 2521661 | D12: 2571321 | E12: 2517896 | F12: 2535935 | G12: 2709847 | H12: 2685627 | I12: 2692776 | J12: 2681208 | K12: 2678241 | L12: 2753681 | M12: 2788507 | N12: 2844228 | O12: 2910166 | P12: 2832371 | Q12: 2788555 | R12: 2698887 | T12: Saca (Unidades) | U12: 2745951 | V12: 2699282 | W12: 2687624 | X12: 2682837 | Y12: 2544650.7 | Z12: 2576572 | AA12: 2599913.6 | AB12: 2594569.5
A13: Ovino | B13: Produción carne (t) | C13: 31068 | D13: 31868 | E13: 31437 | F13: 31926 | G13: 33698 | H13: 33686 | I13: 33904 | J13: 33839 | K13: 33350 | L13: 33458 | M13: 33669 | N13: 34256 | O13: 35304 | P13: 34906 | Q13: 34421 | R13: 33163 | S13: Ovino | T13: Produción carne (t) | U13: 33955 | V13: 33458 | W13: 33672 | X13: 33780.947 | Y13: 32310.988 | Z13: 33259.223 | AA13: 33599.716 | AB13: 33690.4
B14: Rendimiento (kg/Unidad) | C14: =(C13/C12)*1000 -> 12.320451 | D14: =(D13/D12)*1000 -> 12.39363 | E14: =(E13/E12)*1000 -> 12.485424 | F14: =(F13/F12)*1000 -> 12.589439 | G14: =(G13/G12)*1000 -> 12.435388 | H14: =(H13/H12)*1000 -> 12.543067 | I14: =(I13/I12)*1000 -> 12.590724 | J14: =(J13/J12)*1000 -> 12.620804 | ... R14: =(R13/R12)*1000 -> 12.287658 | T14: Rendimiento (kg/Unidad) | U14: =(U13/U12)*1000 -> 12.365479 | V14: =(V13/V12)*1000 -> 12.395148 | W14: =(W13/W12)*1000 -> 12.528538 | X14: =(X13/X12)*1000 -> 12.591502 | Y14: =(Y13/Y12)*1000 -> 12.697612 | Z14: 12.908325 | AA14: =AA13/AA12*1000 -> 12.923397 | AB14: =AB13/AB12*1000 -> 12.984967
B15: Precio (S/ / kg) | C15: 2.99 | D15: 3.13 | E15: 3.29 | F15: 3.29 | G15: 3.27 | H15: 3.31 | I15: 3.32 | J15: 3.49 | K15: 3.9 | L15: 4.13 | M15: 4.46 | N15: 4.52 | O15: 4.9 | P15: 5.04 | Q15: 5.72 | R15: 5.72 | T15: Precio (S/ / kg) | U15: 5.9 | V15: 5.6 | W15: 5.56 | X15: 5.58 | Y15: 5.43 | Z15: 5.584 | AA15: 5.605 | AB15: 5.642802
B16: Población (Unidades) | C16: 2845573 | D16: 2809888 | E16: 2941036 | F16: 2990499 | G16: 3000199 | H16: 3010724 | I16: 3073855 | J16: 3115772 | K16: 3151406 | L16: 3256809 | M16: 3254413 | N16: 3263254 | O16: 2987315 | P16: 3176115 | Q16: 3173015 | R16: 3200714 | T16: Población (Unidades) | U16: 3104911 | V16: 3217254 | W16: 3215742 | X16: 3269537.5 | Y16: 3270742 | Z16: 3372910 | AA16: 3455032 | AB16: 3465175
B17: Saca (Unidades) | C17: 1540534 | D17: 1650886 | E17: 1637129 | F17: 1670387 | G17: 1884573 | H17: 1991346 | I17: 2074715 | J17: 2153141 | K17: 2131518 | L17: 2213057 | M17: 2186978 | N17: 2298432 | O17: 2401634 | P17: 2499031 | Q17: 2629566 | R17: 2764884 | T17: Saca (Unidades) | U17: 2876803 | V17: 3073656 | W17: 3090907 | X17: 3284606.4 | Y17: 3191164.1 | Z17: 3314891 | AA17: 3458391.6 | AB17: 3775007.8
A18: Porcino | B18: Produción carne (t) | C18: 91554 | D18: 93313 | E18: 92530 | F18: 92738 | G18: 98880 | H18: 104254 | I18: 109010 | J18: 114520 | K18: 115196 | L18: 114719 | M18: 115655 | N18: 117588 | O18: 122353 | P18: 127684 | Q18: 135390 | R18: 142925 | S18: Porcino | T18: Produción carne (t) | U18: 149399 | V18: 157824 | W18: 162421 | X18: 173258.66 | Y18: 169804.68 | Z18: 176149.67 | AA18: 181404.63 | AB18: 200449.75
B19: Rendimiento (kg/Unidad) | C19: =(C18/C17)*1000 -> 59.430042 | D19: =(D18/D17)*1000 -> 56.522982 | E19: =(E18/E17)*1000 -> 56.519676 | F19: =(F18/F17)*1000 -> 55.518871 | G19: =(G18/G17)*1000 -> 52.468119 | H19: =(H18/H17)*1000 -> 52.353534 | I19: =(I18/I17)*1000 -> 52.542156 | J19: =(J18/J17)*1000 -> 53.187413 | ... R19: =(R18/R17)*1000 -> 51.692946 | T19: Rendimiento (kg/Unidad) | U19: =(U18/U17)*1000 -> 51.932301 | V19: =(V18/V17)*1000 -> 51.347321 | W19: =(W18/W17)*1000 -> 52.548006 | X19: =(X18/X17)*1000 -> 52.748683 | Y19: =(Y18/Y17)*1000 -> 53.21089 | Z19: 53.138911 | AA19: =AA18/AA17*1000 -> 52.453465 | AB19: =AB18/AB17*1000 -> 53.099162
B20: Precio (S/ / kg) | C20: 3.31 | D20: 3.34 | E20: 3.35 | F20: 3.39 | G20: 3.42 | H20: 3.43 | I20: 3.47 | J20: 3.5 | K20: 3.8 | L20: 4.12 | M20: 4.25 | N20: 5.05 | O20: 5.24 | P20: 5.91 | Q20: 6.07 | R20: 6.42 | T20: Precio (S/ / kg) | U20: 6.77 | V20: 6.96 | W20: 7.05 | X20: 6.94 | Y20: 6.72 | Z20: 6.954 | AA20: 7.049 | AB20: 7.191717
B21: Población (Unidades) | C21: 4980291 | D21: 5035612 | E21: 5163700 | F21: 5193414 | G21: 5184822 | H21: 5249783 | I21: 5241102 | J21: 5420865 | K21: 5442989 | L21: 5459435 | M21: 5520200 | N21: 5589173 | O21: 5660984 | P21: 5555988 | Q21: 5577959 | R21: 5553470 | T21: Población (Unidades) | U21: 5525454 | V21: 5535569 | W21: 5595483 | X21: 5599893 | Y21: 5688461 | Z21: 5853660 | AA21: 5862305 | AB21: 5866167.5
B22: Saca (Unidades) | C22: 875746 | D22: 920031 | E22: 951383 | F22: 986402 | G22: 1020294 | H22: 1074578 | I22: 1127321 | J22: 1138578 | K22: 1151906 | L22: 1168497 | M22: 1218723 | N22: 1266710 | O22: 1319404 | P22: 1375095 | Q22: 1376391 | R22: 1367797 | T22: Saca (Unidades) | U22: 1364230 | V22: 1331223 | W22: 1348165 | X22: 1357066.5 | Y22: 1250069 | Z22: 1303070 | AA22: 1316220.1 | AB22: 1344664.5
A23: Vacuno | B23: Produción carne (t) | C23: 130249 | D23: 130269 | E23: 134137 | F23: 137271 | G23: 143554 | H23: 152497 | I23: 161578 | J23: 163235 | K23: 163318 | L23: 164704 | M23: 171872 | N23: 179084 | O23: 186617 | P23: 193087 | Q23: 196232 | R23: 196015 | S23: Vacuno | T23: Produción carne (t) | U23: 192703 | V23: 188738 | W23: 189703 | X23: 192919.59 | Y23: 183941.13 | Z23: 189922.92 | AA23: 192718.4 | AB23: 198722.99
B24: Rendimiento (kg/Unidad) | C24: =(C23/C22)*1000 -> 148.7292 | D24: =(D23/D22)*1000 -> 141.59197 | E24: =(E23/E22)*1000 -> 140.99159 | F24: =(F23/F22)*1000 -> 139.16334 | G24: =(G23/G22)*1000 -> 140.69866 | H24: =(H23/H22)*1000 -> 141.91338 | I24: =(I23/I22)*1000 -> 143.32918 | J24: =(J23/J22)*1000 -> 143.36743 | ... R24: =(R23/R22)*1000 -> 143.30708 | T24: Rendimiento (kg/Unidad) | U24: =(U23/U22)*1000 -> 141.25404 | V24: =(V23/V22)*1000 -> 141.7779 | W24: =(W23/W22)*1000 -> 140.712 | X24: =(X23/X22)*1000 -> 142.15927 | Y24: =(Y23/Y22)*1000 -> 147.14478 | Z24: 145.7504 | AA24: =AA23/AA22*1000 -> 146.41807 | AB24: =AB23/AB22*1000 -> 147.78631
B25: Precio (S/ / kg) | C25: 3.34 | D25: 3.41 | E25: 3.29 | F25: 3.52 | G25: 3.33 | H25: 3.36 | I25: 3.4 | J25: 3.5 | K25: 3.77 | L25: 4.08 | M25: 4.1 | N25: 4.25 | O25: 4.69 | P25: 4.84 | Q25: 5.23 | R25: 5.41 | T25: Precio (S/ / kg) | U25: 5.45 | V25: 5.53 | W25: 5.64 | X25: 5.69 | Y25: 6.73 | Z25: 5.812 | AA25: 5.92 | AB25: 5.8597287
B26: Población (Unidades) | C26: 2034914 | D26: 2017808 | E26: 1983128 | F26: 1983302 | G26: 1971863 | H26: 1952956 | I26: 1936855 | J26: 1925912 | K26: 1904124 | L26: 1928678 | M26: 1968306 | N26: 1946117 | O26: 1949502 | P26: 1928631 | Q26: 1905462 | R26: 1882361 | T26: Población (Unidades) | U26: 1865047 | V26: 1814704 | W26: 1812530 | X26: 1801882 | Y26: 1784685 | Z26: 1754968 | AA26: 1767612 | AB26: 1764665
B27: Saca (Unidades) | C27: 451247 | D27: 468861 | E27: 476569 | F27: 523993 | G27: 524448 | H27: 527096 | I27: 518663 | J27: 506927 | K27: 496706 | L27: 505880 | M27: 499447 | N27: 489915 | O27: 496626 | P27: 505262 | Q27: 489956 | R27: 464018 | T27: Saca (Unidades) | U27: 458812 | V27: 444799 | W27: 410567 | X27: 411262.7 | Y27: 392865.58 | Z27: 390292 | AA27: 390293.71 | AB27: 388995.53
A28: Caprino | B28: Produción carne (t) | C28: 6268 | D28: 5912 | E28: 5793 | F28: 6294 | G28: 6476 | H28: 6618 | I28: 6772 | J28: 6686 | K28: 6419 | L28: 6153 | M28: 6131 | N28: 6150 | O28: 6247 | P28: 6439 | Q28: 6167 | R28: 5901 | S28: Caprino | T28: Produción carne (t) | U28: 5827 | V28: 5494 | W28: 4966 | X28: 5102.2518 | Y28: 4957.3536 | Z28: 4948.0032 | AA28: 4929.2538 | AB28: 4940.9882
B29: Rendimiento (kg/Unidad) | C29: =(C28/C27)*1000 -> 13.890397 | D29: =(D28/D27)*1000 -> 12.609281 | E29: =(E28/E27)*1000 -> 12.155637 | F29: =(F28/F27)*1000 -> 12.011611 | G29: =(G28/G27)*1000 -> 12.348221 | H29: =(H28/H27)*1000 -> 12.555588 | I29: =(I28/I27)*1000 -> 13.056648 | J29: =(J28/J27)*1000 -> 13.189276 | ... R29: =(R28/R27)*1000 -> 12.717179 | T29: Rendimiento (kg/Unidad) | U29: =(U28/U27)*1000 -> 12.700191 | V29: =(V28/V27)*1000 -> 12.351646 | W29: =(W28/W27)*1000 -> 12.095468 | X29: =(X28/X27)*1000 -> 12.406308 | Y29: =(Y28/Y27)*1000 -> 12.618447 | Z29: 12.677707 | AA29: 12.629601 | AB29: =AB28/AB27*1000 -> 12.701915
B30: Precio (S/ / kg) | C30: 3.33 | D30: 3.28 | E30: 3.31 | F30: 3.22 | G30: 3.27 | H30: 3.05 | I30: 3.01 | J30: 3.17 | K30: 3.41 | L30: 3.61 | M30: 3.38 | N30: 3.53 | O30: 3.68 | P30: 3.93 | Q30: 4.04 | R30: 4.28 | T30: Precio (S/ / kg) | U30: 4.66 | V30: 4.74 | W30: 4.79 | X30: 4.81 | Y30: 4.8 | Z30: 4.786 | AA30: 4.809 | AB30: 4.8108362
B31: Población (Unidades) | C31: 3078524 | D31: 3190373 | E31: 3335721 | F31: 3422557 | G31: 3429019 | H31: 3594515 | I31: 3625627 | J31: 3687340 | K31: 3780806 | L31: 4105582 | M31: 4177499 | N31: 4322258 | O31: 3927361 | P31: 4005315 | Q31: 4315793 | R31: 4318457 | T31: Población (Unidades) | U31: 4319228 | V31: 4330710 | W31: 4384846 | X31: 4456049 | Y31: 4450422 | Z31: 4484888 | AA31: 4533924 | AB31: 4483838
B32: Saca (Unidades) | C32: 269643 | D32: 288318 | E32: 313415 | F32: 304890 | G32: 312092 | H32: 321478 | I32: 330072 | J32: 355174 | K32: 365555 | L32: 387980 | M32: 410085 | N32: 424100 | O32: 455558 | P32: 463354 | Q32: 481847 | R32: 446199 | T32: Saca (Unidades) | U32: 474135 | V32: 479033 | W32: 470464 | X32: 473283 | Y32: 464229.43 | Z32: 469624 | AA32: 476209.91 | AB32: 483247.08
A33: Alpaca | B33: Produción carne (t) | C33: 7307 | D33: 7713 | E33: 8277 | F33: 8204 | G33: 8323 | H33: 8671 | I33: 8793 | J33: 9366 | K33: 9527 | L33: 10189 | M33: 10761 | N33: 11318 | O33: 11999 | P33: 12169 | Q33: 12594 | R33: 11917 | S33: Alpaca | T33: Produción carne (t) | U33: 12445 | V33: 12747 | W33: 12689 | X33: 12579.638 | Y33: 12362.63 | Z33: 12581.237 | AA33: 12753.737 | AB33: 12845.54
B34: Rendimiento (kg/Unidad) | C34: =(C33/C32)*1000 -> 27.098794 | D34: =(D33/D32)*1000 -> 26.751712 | E34: =(E33/E32)*1000 -> 26.409074 | F34: =(F33/F32)*1000 -> 26.908065 | G34: =(G33/G32)*1000 -> 26.668418 | H34: =(H33/H32)*1000 -> 26.972297 | I34: =(I33/I32)*1000 -> 26.639642 | J34: =(J33/J32)*1000 -> 26.370173 | ... R34: =(R33/R32)*1000 -> 26.707814 | T34: Rendimiento (kg/Unidad) | U34: =(U33/U32)*1000 -> 26.247799 | V34: =(V33/V32)*1000 -> 26.609858 | W34: =(W33/W32)*1000 -> 26.971245 | X34: =(X33/X32)*1000 -> 26.579527 | Y34: =(Y33/Y32)*1000 -> 26.630431 | Z34: 26.789999 | AA34: 26.781755 | AB34: =AB33/AB32*1000 -> 26.581723
B35: Precio (S/ / kg) | C35: 2.4 | D35: 2.57 | E35: 2.48 | F35: 2.53 | G35: 2.66 | H35: 2.61 | I35: 2.51 | J35: 2.5 | K35: 2.91 | L35: 3.13 | M35: 3.43 | N35: 3.65 | O35: 4.03 | P35: 4.43 | Q35: 4.77 | R35: 4.63 | T35: Precio (S/ / kg) | U35: 4.81 | V35: 4.91 | W35: 4.96 | X35: 4.94 | Y35: 5 | Z35: 4.88 | AA35: 4.843 | AB35: 4.7835597
B36: Población (Unidades) | C36: 1183908 | D36: 1179088 | E36: 1207275 | F36: 1230543 | G36: 1236984 | H36: 1269979 | I36: 1256101 | J36: 1274425 | K36: 1262782 | L36: 1237593 | M36: 1245169 | N36: 1226612 | O36: 1194404 | P36: 1234089 | Q36: 1211917 | R36: 1194708 | T36: Población (Unidades) | U36: 1105018 | V36: 1106201 | W36: 1093124 | X36: 1095920.5 | Y36: 1085549.7 | Z36: 1075425 | AA36: 1069411 | AB36: 1071971
B37: Saca (Unidades) | C37: 91890 | D37: 95157 | E37: 97389 | F37: 101826 | G37: 109330 | H37: 112106 | I37: 113801 | J37: 118399 | K37: 119237 | L37: 127316 | M37: 123384 | N37: 128346 | O37: 130530 | P37: 125729 | Q37: 123360 | R37: 119806 | T37: Saca (Unidades) | U37: 119195 | V37: 120748 | W37: 119726 | X37: 115790 | Y37: 113685.48 | Z37: 117682 | AA37: 118241.3 | AB37: 120200
A38: Llama | B38: Produción carne (t) | C38: 3194 | D38: 3232 | E38: 3242 | F38: 3496 | G38: 3699 | H38: 3863 | I38: 3839 | J38: 4053 | K38: 3971 | L38: 4175 | M38: 4075 | N38: 4235 | O38: 4350 | P38: 4179 | Q38: 4170 | R38: 3980 | S38: Llama | T38: Produción carne (t) | U38: 3977 | V38: 4009 | W38: 4003 | X38: 3847.5921 | Y38: 3818.352 | Z38: 3940.039 | AA38: 3971.3009 | AB38: 4021.2754
B39: Rendimiento (kg/Unidad) | C39: =(C38/C37)*1000 -> 34.758951 | D39: =(D38/D37)*1000 -> 33.964921 | E39: =(E38/E37)*1000 -> 33.289181 | F39: =(F38/F37)*1000 -> 34.333078 | G39: =(G38/G37)*1000 -> 33.833349 | H39: =(H38/H37)*1000 -> 34.458459 | I39: =(I38/I37)*1000 -> 33.734326 | J39: =(J38/J37)*1000 -> 34.231708 | ... R39: =(R38/R37)*1000 -> 33.220373 | T39: Rendimiento (kg/Unidad) | U39: =(U38/U37)*1000 -> 33.365494 | V39: =(V38/V37)*1000 -> 33.201378 | W39: =(W38/W37)*1000 -> 33.434676 | X39: =(X38/X37)*1000 -> 33.229053 | Y39: =(Y38/Y37)*1000 -> 33.58698 | Z39: 33.480303 | AA39: 33.586411 | AB39: =AB38/AB37*1000 -> 33.45487
B40: Precio (S/ / kg) | C40: 1.93 | D40: 2.18 | E40: 2.39 | F40: 2.4 | G40: 2.45 | H40: 2.49 | I40: 2.39 | J40: 2.31 | K40: 2.7 | L40: 2.88 | M40: 3.02 | N40: 3.4 | O40: 3.61 | P40: 3.87 | Q40: 4.25 | R40: 4.09 | T40: Precio (S/ / kg) | U40: 4.32 | V40: 4.25 | W40: 4.28 | X40: 4.27 | Y40: 4.13 | Z40: 3.967 | AA40: 3.863 | AB40: 3.8021183
B41: Gallinas (Unidades) | C41: 11899785 | D41: 12705402 | E41: 12651366 | F41: 13059118 | G41: 13362491 | H41: 13654721 | I41: 15842743 | J41: 16572273 | K41: 17048710 | L41: 17206413 | M41: 18156674 | N41: 19950695 | O41: 19846405 | P41: 21805630 | Q41: 22353253 | R41: 23883311 | T41: Gallinas (Unidades) | U41: 24752078 | V41: 25559765 | W41: 27705670 | X41: 29468986 | Y41: 29468986 | Z41: 28938922 | AA41: 29494581 | AB41: 28261110
A42: Huevo gallina | B42: Producción (t) | C42: 178686 | D42: 188391 | E42: 190915 | F42: 197839 | G42: 202357 | H42: 207086 | I42: 245451 | J42: 257621 | K42: 266541 | L42: 268707 | M42: 285102 | N42: 317654 | O42: 314024 | P42: 349791 | Q42: 358630 | R42: 386255 | S42: Huevo gallina | T42: Producción (t) | U42: 400980 | V42: 415336 | W42: 452234 | X42: 488484.4 | Y42: 497525.4 | Z42: 504112 | AA42: 510961.58 | AB42: 503080
...

Sheet C -6
A2: C.6 PERÚ: POBLACIÓN, SACA, PRODUCCIÓN, RENDIMIENTO Y PRECIOS RECIBIDOS POR EL PRODUCTOR POR MES, SEGÚN PRINCIPALES ESPECIES Y
A3: PRODUCTOS PECUARIOS, 2023P
A5: Especie/ Producto | B5: Variable | C5: Anual | D5: Ene | E5: Feb | F5: Mar | G5: Abr | H5: May | I5: Jun | J5: Jul | K5: Ago | L5: Set | M5: Oct | N5: Nov | O5: Dic
A6: Ave | B6: Población (Unidades) | C6: 191690.9
B7: Saca (Unidades) | C7: 7.8975422e+08 | D7: 62833822 | E7: 58681518 | F7: 66288495 | G7: 68182322 | H7: 67612549 | I7: 65443221 | J7: 68454567 | K7: 64815315 | L7: 64641405 | M7: 67173540 | N7: 65498928 | O7: 70128534
B8: Producción carne (t) | C8: 1781472.7 | D8: 143634.77 | E8: 130302.94 | F8: 146223.18 | G8: 150509.14 | H8: 150306.7 | I8: 149654.68 | J8: 155890.91 | K8: 149810.46 | L8: 149310.48 | M8: 152980.55 | N8: 146477.16 | O8: 156371.77
B9: Rendimiento (kg/Unidad) | C9: =C8/C7*1000 -> 2.2557306 | D9: =D8/D7*1000 -> 2.2859468 | E9: =E8/E7*1000 -> 2.2205107 | F9: =F8/F7*1000 -> 2.2058605 | G9: =G8/G7*1000 -> 2.207451 | H9: =H8/H7*1000 -> 2.2230592 | I9: =I8/I7*1000 -> 2.2867865 | J9: =J8/J7*1000 -> 2.2772901 | ... O9: =O8/O7*1000 -> 2.2297881
B10: Precio (S/ / kg) 1 | C10: 6.9938805 | D10: 6.6099321 | E10: 6.9046893 | F10: 6.9631512 | G10: 6.9934923 | H10: 7.0194092 | I10: 7.0298171 | J10: 7.0509455 | K10: 7.0549253 | L10: 7.0578041 | M10: 7.0590215 | N10: 7.0603622 | O10: 7.0886411
A11: Ovino | B11: Población (Unidades) | C11: 11238432
B12: Saca (Unidades) | C12: 2594569.5 | D12: 189743 | E12: 196785 | F12: 208223.67 | G12: 228552.77 | H12: 236478 | I12: 239220 | J12: 237550 | K12: 228756 | L12: 213618.57 | M12: 206261.47 | N12: 202187 | O12: 207194.04
B13: Producción carne (t) | C13: 33690.4 | D13: 2416.0898 | E13: 2553.1566 | F13: 2692.1018 | G13: 3007.1596 | H13: 3134.5723 | I13: 3172.7708 | J13: 3108.7384 | K13: 2999.0304 | L13: 2774.2841 | M13: 2625.719 | N13: 2570.9056 | O13: 2635.8715
B14: Rendimiento (kg/Unidad) | C14: =C13/C12*1000 -> 12.984967 | D14: =D13/D12*1000 -> 12.733486 | E14: =E13/E12*1000 -> 12.974346 | F14: =F13/F12*1000 -> 12.928894 | G14: =G13/G12*1000 -> 13.157397 | H14: =H13/H12*1000 -> 13.255238 | I14: =I13/I12*1000 -> 13.262983 | J14: =J13/J12*1000 -> 13.08667 | ... O14: =O13/O12*1000 -> 12.721753
B15: Precio (S/ / kg) 1 | C15: 5.642802 | D15: 5.6247761 | E15: 5.6344929 | F15: 5.6283328 | G15: 5.6442206 | H15: 5.6591496 | I15: 5.6525489 | J15: 5.6523702 | K15: 5.655711 | L15: 5.6484916 | M15: 5.6403649 | N15: 5.6276729 | O15: 5.6345836
A16: Porcino | B16: Población (Unidades) | C16: 3465175
B17: Saca (Unidades) | C17: 3775007.8 | D17: 288357 | E17: 287352 | F17: 286001.36 | G17: 286655 | H17: 300393.4 | I17: 296338 | J17: 351507 | K17: 341033 | L17: 327875.67 | M17: 321313.51 | N17: 325867 | O17: 362314.83
B18: Producción carne (t) | C18: 200449.75 | D18: 15115.624 | E18: 15219.905 | F18: 15117.892 | G18: 15145.956 | H18: 15655.419 | I18: 15694.879 | J18: 18647.015 | K18: 18457.165 | L18: 17434.331 | M18: 17090.398 | N18: 17395.944 | O18: 19475.221
B19: Rendimiento (kg/Unidad) | C19: =C18/C17*1000 -> 53.099162 | D19: =D18/D17*1000 -> 52.419827 | E19: =E18/E17*1000 -> 52.966067 | F19: =F18/F17*1000 -> 52.85951 | G19: =G18/G17*1000 -> 52.836882 | H19: =H18/H17*1000 -> 52.116389 | I19: =I18/I17*1000 -> 52.962761 | J19: =J18/J17*1000 -> 53.048774 | ... O19: =O18/O17*1000 -> 53.752205
B20: Precio (S/ / kg) 1 | C20: 7.191717 | D20: 7.0313978 | E20: 7.0866984 | F20: 7.1045109 | G20: 7.1418767 | H20: 7.1545774 | I20: 7.1764034 | J20: 7.2366341 | K20: 7.2412086 | L20: 7.2419794 | M20: 7.2486005 | N20: 7.2547963 | O20: 7.305703
A21: Vacuno | B21: Población (Unidades) | C21: 5866167.5
B22: Saca (Unidades) | C22: 1344664.5 | D22: 104446 | E22: 107096 | F22: 108528.09 | G22: 114969.3 | H22: 116998.14 | I22: 117929 | J22: 118989 | K22: 115593 | L22: 111689.19 | M22: 107336.41 | N22: 109281 | O22: 111809.32
B23: Producción carne (t) | C23: 198722.99 | D23: 15197.981 | E23: 15757.699 | F23: 16037.05 | G23: 17124.765 | H23: 17489.006 | I23: 17509.319 | J23: 17574.268 | K23: 17121.698 | L23: 16535.44 | M23: 15735.957 | N23: 16044.873 | O23: 16594.938
B24: Rendimiento (kg/Unidad) | C24: =C23/C22*1000 -> 147.78631 | D24: =D23/D22*1000 -> 145.51042 | E24: =E23/E22*1000 -> 147.1362 | F24: =F23/F22*1000 -> 147.76865 | G24: =G23/G22*1000 -> 148.95076 | H24: =H23/H22*1000 -> 149.48106 | I24: =I23/I22*1000 -> 148.4734 | J24: =J23/J22*1000 -> 147.69658 | ... O24: =O23/O22*1000 -> 148.42178
B25: Precio (S/ / kg) 1 | C25: 5.8597287 | D25: 5.8638497 | E25: 5.8705442 | F25: 5.8591164 | G25: 5.8536293 | H25: 5.8601761 | I25: 5.8554888 | J25: 5.8530359 | K25: 5.8621898 | L25: 5.866672 | M25: 5.8699931 | N25: 5.8569467 | O25: 5.8471594
A26: Caprino | B26: Población (Unidades) | C26: 1764665
B27: Saca (Unidades) | C27: 388995.53 | D27: 30905 | E27: 31139 | F27: 32056.91 | G27: 32096.47 | H27: 33792 | I27: 34733 | J27: 35313 | K27: 33744.7 | L27: 31546.462 | M27: 29943.014 | N27: 30848.126 | O27: 32877.85
B28: Producción carne (t) | C28: 4940.9882 | D28: 388.17734 | E28: 394.65632 | F28: 411.88325 | G28: 419.27067 | H28: 435.40445 | I28: 453.67245 | J28: 448.81376 | K28: 426.53956 | L28: 389.83701 | M28: 374.1607 | N28: 385.32629 | O28: 413.24644
B29: Rendimiento (kg/Unidad) | C29: =C28/C27*1000 -> 12.701915 | D29: =D28/D27*1000 -> 12.560341 | E29: =E28/E27*1000 -> 12.67402 | F29: =F28/F27*1000 -> 12.848501 | G29: =G28/G27*1000 -> 13.062828 | H29: =H28/H27*1000 -> 12.884838 | I29: =I28/I27*1000 -> 13.061712 | J29: =J28/J27*1000 -> 12.70959 | ... O29: =O28/O27*1000 -> 12.569144
B30: Precio (S/ / kg) 1 | C30: 4.8108362 | D30: 4.80914 | E30: 4.8347654 | F30: 4.8073188 | G30: 4.8026351 | H30: 4.8014883 | I30: 4.8054181 | J30: 4.8076731 | K30: 4.8133627 | L30: 4.8165249 | M30: 4.8099543 | N30: 4.8091431 | O30: 4.8150343
A31: Alpaca | B31: Población (Unidades) | C31: 4483838
B32: Saca (Unidades) | C32: 483247.08 | D32: 32670 | E32: 37990.91 | F32: 40377 | G32: 48071 | H32: 47906.02 | I32: 46714 | J32: 46958 | K32: 42906.15 | L32: 37859 | M32: 36333 | N32: 34265 | O32: 31197
B33: Producción carne (t) | C33: 12845.54 | D33: 854.43353 | E33: 1013.532 | F33: 1086.6222 | G33: 1308.3049 | H33: 1312.1878 | I33: 1267.5005 | J33: 1262.2828 | K33: 1121.547 | L33: 989.84311 | M33: 936.67214 | N33: 887.74573 | O33: 804.8685
B34: Rendimiento (kg/Unidad) | C34: =C33/C32*1000 -> 26.581723 | D34: =D33/D32*1000 -> 26.15346 | E34: =E33/E32*1000 -> 26.678277 | F34: =F33/F32*1000 -> 26.911911 | G34: =G33/G32*1000 -> 27.216095 | H34: =H33/H32*1000 -> 27.390874 | I34: =I33/I32*1000 -> 27.133204 | J34: =J33/J32*1000 -> 26.881102 | ... O34: =O33/O32*1000 -> 25.799548
B35: Precio (S/ / kg) 1 | C35: 4.7835597 | D35: 4.7484699 | E35: 4.8096089 | F35: 4.8137992 | G35: 4.8419665 | H35: 4.8234262 | I35: 4.7966743 | J35: 4.7897057 | K35: 4.785992 | L35: 4.7631911 | M35: 4.7457209 | N35: 4.7342501 | O35: 4.6770398
A36: Llama | B36: Población (Unidades) | C36: 1071971
B37: Saca (Unidades) | C37: 120200 | D37: 8816 | E37: 9419 | F37: 9773 | G37: 10947 | H37: 11002 | I37: 11616 | J37: 10860 | K37: 10359 | L37: 9623 | M37: 9248 | N37: 8909 | O37: 9628
B38: Producción carne (t) | C38: 4021.2754 | D38: 287.65027 | E38: 317.62567 | F38: 333.10303 | G38: 385.20438 | H38: 384.77203 | I38: 398.34695 | J38: 366.18107 | K38: 340.97814 | L38: 315.61311 | M38: 297.01907 | N38: 284.8951 | O38: 309.88655
B39: Rendimiento (kg/Unidad) | C39: =C38/C37*1000 -> 33.45487 | D39: =D38/D37*1000 -> 32.628206 | E39: =E38/E37*1000 -> 33.721804 | F39: =F38/F37*1000 -> 34.084011 | G39: =G38/G37*1000 -> 35.188123 | H39: =H38/H37*1000 -> 34.972917 | I39: =I38/I37*1000 -> 34.292954 | J39: =J38/J37*1000 -> 33.718331 | ... O39: =O38/O37*1000 -> 32.185973
B40: Precio (S/ / kg) 1 | C40: 3.8021183 | D40: 3.8013971 | E40: 3.8377807 | F40: 3.8347652 | G40: 3.8719856 | H40: 3.8510251 | I40: 3.8211705 | J40: 3.7964557 | K40: 3.7866606 | L40: 3.7796732 | M40: 3.7514742 | N40: 3.7282316 | O40: 3.7221065
A41: Huevo gallina | B41: Gallinas en producción | C41: 28261110 | D41: 28616644 | E41: 27544936 | F41: 27714392 | G41: 27922912 | H41: 28011840 | I41: 28146639 | J41: 28517563 | K41: 28491126 | L41: 28496515 | M41: 28563911 | N41: 28562021 | O41: 28544822
B42: Producción huevo (t) | C42: 503080 | D42: 41933.523 | E42: 40596.852 | F42: 40957.703 | G42: 41256.542 | H42: 41449.169 | I42: 41728.252 | J42: 41959.75 | K42: 42590.325 | L42: 42455.484 | M42: 42513.368 | N42: 42756.065 | O42: 42882.97
...

Sheet C 7
A2: C.7 PERÚ: PRODUCCIÓN PECUARIA POR ESPECIE, SEGÚN REGIÓN, 2023P
A3: (Unidades)
A5: Región | B5: Ave | C5: Ovino | D5: Porcino | E5: Vacuno | F5: Caprino | G5: Alpaca | H5: Llama
A6: Nacional | B6: =(B8+B9+B10+B11+B12+B16+B17+B18+B19+B20+B21+B22+B23+B24+B25+B26+B27+B28+B31+B32+B33+B34+B35+B36) -> 7.8975422e+08 | C6: =(C8+C9+C10+C11+C12+C16+C17+C18+C19+C20+C21+C22+C23+C24+C25+C26+C27+C28+C31+C32+C33+C34+C35+C36) -> 2594569.5 | D6: =(D8+D9+D10+D11+D12+D16+D17+D18+D19+D20+D21+D22+D23+D24+D25+D26+D27+D28+D31+D32+D33+D34+D35+D36) -> 3775007.8 | E6: =(E8+E9+E10+E11+E12+E16+E17+E18+E19+E20+E21+E22+E23+E24+E25+E26+E27+E28+E31+E32+E33+E34+E35+E36) -> 1344664.5 | F6: =(F8+F9+F10+F11+F12+F16+F17+F18+F19+F20+F21+F22+F23+F24+F25+F26+F27+F28+F31+F32+F33+F34+F35+F36) -> 388995.53 | G6: =(G8+G9+G10+G11+G12+G16+G17+G18+G19+G20+G21+G22+G23+G24+G25+G26+G27+G28+G31+G32+G33+G34+G35+G36) -> 483247.08 | H6: =(H8+H9+H10+H11+H12+H16+H17+H18+H19+H20+H21+H22+H23+H24+H25+H26+H27+H28+H31+H32+H33+H34+H35+H36) -> 120200
A8: Tumbes | B8: =+'[2]AVE 04-99'!D1376 -> 91418.996 | C8: =+'[2]OVI 04-99'!D1376 -> 3168 | D8: =+'[2]POR 04-99'!D1376 -> 5883 | E8: =+'[2]VAC 04-99'!D1376 -> 3530 | F8: =+'[2]CAP 04-99'!D1376 -> 24128 | G8: =+'[2]ALP 04-99'!D1376 -> 0 | H8: =+'[2]LLA 04-99'!D1376 -> 0
A9: Piura | B9: =+'[2]AVE 04-99'!D1379 -> 13887145 | C9: =+'[2]OVI 04-99'!D1379 -> 110566.75 | D9: =+'[2]POR 04-99'!D1379 -> 114622.68 | E9: =+'[2]VAC 04-99'!D1379 -> 48982.013 | F9: =+'[2]CAP 04-99'!D1379 -> 93179.237 | G9: =+'[2]ALP 04-99'!D1379 -> 0 | H9: =+'[2]LLA 04-99'!D1379 -> 0
A10: Lambayeque | B10: =+'[2]AVE 04-99'!D1382 -> 11401956 | C10: =+'[2]OVI 04-99'!D1382 -> 24140 | D10: =+'[2]POR 04-99'!D1382 -> 29125 | E10: =+'[2]VAC 04-99'!D1382 -> 20075.4 | F10: =+'[2]CAP 04-99'!D1382 -> 19240 | G10: =+'[2]ALP 04-99'!D1382 -> 0 | H10: =+'[2]LLA 04-99'!D1382 -> 0
A11: La Libertad | B11: =+'[2]AVE 04-99'!D1385 -> 1.3772581e+08 | C11: =+'[2]OVI 04-99'!D1385 -> 215320 | D11: =+'[2]POR 04-99'!D1385 -> 354779 | E11: =+'[2]VAC 04-99'!D1385 -> 62771 | F11: =+'[2]CAP 04-99'!D1385 -> 35316 | G11: =+'[2]ALP 04-99'!D1385 -> 1403 | H11: =+'[2]LLA 04-99'!D1385 -> 0
A12: Cajamarca | B12: =SUM(B13:B15) -> 1594438.1 | C12: =SUM(C13:C15) -> 78516 | D12: =SUM(D13:D15) -> 139710.1 | E12: =SUM(E13:E15) -> 166375 | F12: =SUM(F13:F15) -> 21746.7 | G12: =SUM(G13:G15) -> 0 | H12: =SUM(H13:H15) -> 0
A13: Cajamarca | B13: =+'[2]AVE 04-99'!D1391 -> 1001577.7 | C13: =+'[2]OVI 04-99'!D1391 -> 54819 | D13: =+'[2]POR 04-99'!D1391 -> 55799.7 | E13: =+'[2]VAC 04-99'!D1391 -> 87734 | F13: =+'[2]CAP 04-99'!D1391 -> 12593.7 | G13: =+'[2]ALP 04-99'!D1391 -> 0 | H13: =+'[2]LLA 04-99'!D1391 -> 0
A14: Chota | B14: =+'[2]AVE 04-99'!D1394 -> 278360.37 | C14: =+'[2]OVI 04-99'!D1394 -> 20442 | D14: =+'[2]POR 04-99'!D1394 -> 44265.4 | E14: =+'[2]VAC 04-99'!D1394 -> 49504 | F14: =+'[2]CAP 04-99'!D1394 -> 1282 | G14: =+'[2]ALP 04-99'!D1394 -> 0 | H14: =+'[2]LLA 04-99'!D1394 -> 0
A15: Jaén | B15: =+'[2]AVE 04-99'!D1397 -> 314500.04 | C15: =+'[2]OVI 04-99'!D1397 -> 3255 | D15: =+'[2]POR 04-99'!D1397 -> 39645 | E15: =+'[2]VAC 04-99'!D1397 -> 29137 | F15: =+'[2]CAP 04-99'!D1397 -> 7871 | G15: =+'[2]ALP 04-99'!D1397 -> 0 | H15: =+'[2]LLA 04-99'!D1397 -> 0
A16: Amazonas | B16: =+'[2]AVE 04-99'!D1400 -> 357854.28 | C16: =+'[2]OVI 04-99'!D1400 -> 3480 | D16: =+'[2]POR 04-99'!D1400 -> 35262 | E16: =+'[2]VAC 04-99'!D1400 -> 63582 | F16: =+'[2]CAP 04-99'!D1400 -> 4775 | G16: =+'[2]ALP 04-99'!D1400 -> 0 | H16: =+'[2]LLA 04-99'!D1400 -> 0
A17: Ancash | B17: =+'[2]AVE 04-99'!D1403 -> 16615563 | C17: =+'[2]OVI 04-99'!D1403 -> 134036 | D17: =+'[2]POR 04-99'!D1403 -> 60603 | E17: =+'[2]VAC 04-99'!D1403 -> 62939 | F17: =+'[2]CAP 04-99'!D1403 -> 20958 | G17: =+'[2]ALP 04-99'!D1403 -> 523 | H17: =+'[2]LLA 04-99'!D1403 -> 0
A18: Lima | B18: =+'[2]AVE 04-99'!D1406 -> 4.3697113e+08 | C18: =+'[2]OVI 04-99'!D1406 -> 56794 | D18: =+'[2]POR 04-99'!D1406 -> 1474086.3 | E18: =+'[2]VAC 04-99'!D1406 -> 110685 | F18: =+'[2]CAP 04-99'!D1406 -> 36612 | G18: =+'[2]ALP 04-99'!D1406 -> 3449 | H18: =+'[2]LLA 04-99'!D1406 -> 2120
A19: Ica | B19: =+'[2]AVE 04-99'!D1409 -> 43644691 | C19: =+'[2]OVI 04-99'!D1409 -> 12129 | D19: =+'[2]POR 04-99'!D1409 -> 325151 | E19: =+'[2]VAC 04-99'!D1409 -> 35150 | F19: =+'[2]CAP 04-99'!D1409 -> 22475 | G19: =+'[2]ALP 04-99'!D1409 -> 0 | H19: =+'[2]LLA 04-99'!D1409 -> 0
A20: Huánuco | B20: =+'[2]AVE 04-99'!D1412 -> 583119.76 | C20: =+'[2]OVI 04-99'!D1412 -> 161862 | D20: =+'[2]POR 04-99'!D1412 -> 203305 | E20: =+'[2]VAC 04-99'!D1412 -> 159996 | F20: =+'[2]CAP 04-99'!D1412 -> 24868 | G20: =+'[2]ALP 04-99'!D1412 -> 1643 | H20: =+'[2]LLA 04-99'!D1412 -> 0
A21: Pasco | B21: =+'[2]AVE 04-99'!D1415 -> 249313.67 | C21: =+'[2]OVI 04-99'!D1415 -> 112278 | D21: =+'[2]POR 04-99'!D1415 -> 38740 | E21: =+'[2]VAC 04-99'!D1415 -> 23371 | F21: =+'[2]CAP 04-99'!D1415 -> 1160 | G21: =+'[2]ALP 04-99'!D1415 -> 18075 | H21: =+'[2]LLA 04-99'!D1415 -> 4437
A22: Junín | B22: =+'[2]AVE 04-99'!D1418 -> 4421884.1 | C22: =+'[2]OVI 04-99'!D1418 -> 304399 | D22: =+'[2]POR 04-99'!D1418 -> 127223 | E22: =+'[2]VAC 04-99'!D1418 -> 58979 | F22: =+'[2]CAP 04-99'!D1418 -> 3855 | G22: =+'[2]ALP 04-99'!D1418 -> 14741 | H22: =+'[2]LLA 04-99'!D1418 -> 9188
A23: Huancavelica | B23: =+'[2]AVE 04-99'!D1421 -> 439667.64 | C23: =+'[2]OVI 04-99'!D1421 -> 97296.77 | D23: =+'[2]POR 04-99'!D1421 -> 34887 | E23: =+'[2]VAC 04-99'!D1421 -> 23777 | F23: =+'[2]CAP 04-99'!D1421 -> 19096 | G23: =+'[2]ALP 04-99'!D1421 -> 20113.79 | H23: =+'[2]LLA 04-99'!D1421 -> 7834
A24: Arequipa | B24: =+'[2]AVE 04-99'!D1424 -> 70966379 | C24: =+'[2]OVI 04-99'!D1424 -> 128397 | D24: =+'[2]POR 04-99'!D1424 -> 218204 | E24: =+'[2]VAC 04-99'!D1424 -> 33219 | F24: =+'[2]CAP 04-99'!D1424 -> 10081 | G24: =+'[2]ALP 04-99'!D1424 -> 48628 | H24: =+'[2]LLA 04-99'!D1424 -> 13353
A25: Moquegua | B25: =+'[2]AVE 04-99'!D1427 -> 87262.749 | C25: =+'[2]OVI 04-99'!D1427 -> 3626 | D25: =+'[2]POR 04-99'!D1427 -> 27989 | E25: =+'[2]VAC 04-99'!D1427 -> 3695 | F25: =+'[2]CAP 04-99'!D1427 -> 966 | G25: =+'[2]ALP 04-99'!D1427 -> 4933 | H25: =+'[2]LLA 04-99'!D1427 -> 1905
A26: Tacna | B26: =+'[2]AVE 04-99'!D1430 -> 8297117.2 | C26: =+'[2]OVI 04-99'!D1430 -> 8681 | D26: =+'[2]POR 04-99'!D1430 -> 70781 | E26: =+'[2]VAC 04-99'!D1430 -> 5396 | F26: =+'[2]CAP 04-99'!D1430 -> 5960 | G26: =+'[2]ALP 04-99'!D1430 -> 9574 | H26: =+'[2]LLA 04-99'!D1430 -> 5408
A27: Ayacucho | B27: =+'[2]AVE 04-99'!D1433 -> 471428.04 | C27: =+'[2]OVI 04-99'!D1433 -> 142224 | D27: =+'[2]POR 04-99'!D1433 -> 67426 | E27: =+'[2]VAC 04-99'!D1433 -> 98128 | F27: =+'[2]CAP 04-99'!D1433 -> 24656 | G27: =+'[2]ALP 04-99'!D1433 -> 29405 | H27: =+'[2]LLA 04-99'!D1433 -> 5640
A28: Apurímac | B28: =SUM(B29:B30) -> 336504.22 | C28: =SUM(C29:C30) -> 69627 | D28: =SUM(D29:D30) -> 55581.7 | E28: =SUM(E29:E30) -> 35287.04 | F28: =SUM(F29:F30) -> 15736.47 | G28: =SUM(G29:G30) -> 20385.29 | H28: =SUM(H29:H30) -> 10090
A29: Abancay | B29: =+'[2]AVE 04-99'!D1439 -> 206162.93 | C29: =+'[2]OVI 04-99'!D1439 -> 35674 | D29: =+'[2]POR 04-99'!D1439 -> 21809 | E29: =+'[2]VAC 04-99'!D1439 -> 17699 | F29: =+'[2]CAP 04-99'!D1439 -> 4637 | G29: =+'[2]ALP 04-99'!D1439 -> 13823.02 | H29: =+'[2]LLA 04-99'!D1439 -> 5624
A30: Andahuaylas | B30: =+'[2]AVE 04-99'!D1442 -> 130341.29 | C30: =+'[2]OVI 04-99'!D1442 -> 33953 | D30: =+'[2]POR 04-99'!D1442 -> 33772.7 | E30: =+'[2]VAC 04-99'!D1442 -> 17588.04 | F30: =+'[2]CAP 04-99'!D1442 -> 11099.47 | G30: =+'[2]ALP 04-99'!D1442 -> 6562.27 | H30: =+'[2]LLA 04-99'!D1442 -> 4466
A31: Cusco | B31: =+'[2]AVE 04-99'!D1445 -> 1689771.6 | C31: =+'[2]OVI 04-99'!D1445 -> 309247 | D31: =+'[2]POR 04-99'!D1445 -> 148458 | E31: =+'[2]VAC 04-99'!D1445 -> 77093 | F31: =+'[2]CAP 04-99'!D1445 -> 4158 | G31: =+'[2]ALP 04-99'!D1445 -> 96769 | H31: =+'[2]LLA 04-99'!D1445 -> 20280
A32: Puno | B32: =+'[2]AVE 04-99'!D1448 -> 1239060.1 | C32: =+'[2]OVI 04-99'!D1448 -> 607205 | D32: =+'[2]POR 04-99'!D1448 -> 76790 | E32: =+'[2]VAC 04-99'!D1448 -> 156710 | F32: =+'[2]CAP 04-99'!D1448 -> 0 | G32: =+'[2]ALP 04-99'!D1448 -> 213605 | H32: =+'[2]LLA 04-99'!D1448 -> 39945
A33: San Martín | B33: =+'[2]AVE 04-99'!D1451 -> 16607362 | C33: =+'[2]OVI 04-99'!D1451 -> 5181 | D33: =+'[2]POR 04-99'!D1451 -> 77484 | E33: =+'[2]VAC 04-99'!D1451 -> 51424 | F33: =+'[2]CAP 04-99'!D1451 -> 0 | G33: =+'[2]ALP 04-99'!D1451 -> 0 | H33: =+'[2]LLA 04-99'!D1451 -> 0
A34: Loreto | B34: =+'[2]AVE 04-99'!D1454 -> 11458804 | C34: =+'[2]OVI 04-99'!D1454 -> 2195 | D34: =+'[2]POR 04-99'!D1454 -> 47114 | E34: =+'[2]VAC 04-99'!D1454 -> 10379 | F34: =+'[2]CAP 04-99'!D1454 -> 29.1256 | G34: =+'[2]ALP 04-99'!D1454 -> 0 | H34: =+'[2]LLA 04-99'!D1454 -> 0
A35: Ucayali | B35: =+'[2]AVE 04-99'!D1457 -> 6526572 | C35: =+'[2]OVI 04-99'!D1457 -> 2564 | D35: =+'[2]POR 04-99'!D1457 -> 20397 | E35: =+'[2]VAC 04-99'!D1457 -> 21472 | F35: =+'[2]CAP 04-99'!D1457 -> 0 | G35: =+'[2]ALP 04-99'!D1457 -> 0 | H35: =+'[2]LLA 04-99'!D1457 -> 0
A36: Madre de Dios | B36: =+'[2]AVE 04-99'!D1460 -> 4089963.7 | C36: =+'[2]OVI 04-99'!D1460 -> 1637 | D36: =+'[2]POR 04-99'!D1460 -> 21406 | E36: =+'[2]VAC 04-99'!D1460 -> 11649 | F36: =+'[2]CAP 04-99'!D1460 -> 0 | G36: =+'[2]ALP 04-99'!D1460 -> 0 | H36: =+'[2]LLA 04-99'!D1460 -> 0
A37: P Preliminar
A38: Fuente: Direcciones Regionales de Agricultura
A39: Elaboración: Ministerio de Desarrollo Agrario y Riego - DGESEP - DEIA

Sheet C 8
A2: C.8 PERÚ: PRODUCCIÓN DE CARNES POR ESPECIE, SEGÚN REGIÓN, 2023P
A3: (Toneladas)
A5: Región | B5: Ave | C5: Ovino | D5: Porcino | E5: Vacuno | F5: Caprino | G5: Alpaca | H5: Llama
A6: Nacional | B6: =(B8+B9+B10+B11+B12+B16+B17+B18+B19+B20+B21+B22+B23+B24+B25+B26+B27+B28+B31+B32+B33+B34+B35+B36) -> 1781472.7 | C6: =(C8+C9+C10+C11+C12+C16+C17+C18+C19+C20+C21+C22+C23+C24+C25+C26+C27+C28+C31+C32+C33+C34+C35+C36) -> 33690.4 | D6: =(D8+D9+D10+D11+D12+D16+D17+D18+D19+D20+D21+D22+D23+D24+D25+D26+D27+D28+D31+D32+D33+D34+D35+D36) -> 200449.75 | E6: =(E8+E9+E10+E11+E12+E16+E17+E18+E19+E20+E21+E22+E23+E24+E25+E26+E27+E28+E31+E32+E33+E34+E35+E36) -> 198722.99 | F6: =(F8+F9+F10+F11+F12+F16+F17+F18+F19+F20+F21+F22+F23+F24+F25+F26+F27+F28+F31+F32+F33+F34+F35+F36) -> 4940.9882 | G6: =(G8+G9+G10+G11+G12+G16+G17+G18+G19+G20+G21+G22+G23+G24+G25+G26+G27+G28+G31+G32+G33+G34+G35+G36) -> 12845.54 | H6: =(H8+H9+H10+H11+H12+H16+H17+H18+H19+H20+H21+H22+H23+H24+H25+H26+H27+H28+H31+H32+H33+H34+H35+H36) -> 4021.2754
A8: Tumbes | B8: =+'[2]AVE 04-99'!D1377 -> 232.05507 | C8: =+'[2]OVI 04-99'!D1377 -> 36.616 | D8: =+'[2]POR 04-99'!D1377 -> 339.86 | E8: =+'[2]VAC 04-99'!D1377 -> 495.6568 | F8: =+'[2]CAP 04-99'!D1377 -> 245.68 | G8: =+'[2]ALP 04-99'!D1377 -> 0 | H8: =+'[2]LLA 04-99'!D1377 -> 0
