Workbook
Name \c: #REF!
Name \x: 'C 5'!#REF!
Name \x: #REF!
Name A: 'C 5'!$W$20:$DB$20
Name A: #REF!
Name A_IMPRESION_IM: 'C 91 - 99'!#REF!
Name A_IMPRESION_IM: #REF!
Name A_impresión_IM: 'C 100 - 101'!$A$1:$K$54
Name A_impresión_IM: 'C 102 - 103'!$A$1:$I$45
Name A_impresión_IM: 'C 104-105'!$A$1:$K$55
Name A_impresión_IM: 'C 106 - 107'!$A$1:$H$45
Name A_impresión_IM: 'C 108 - 109 '!#REF!
Name A_IMPRESIÓN_IM: [1]CYPPOLLO!#REF!
Name A_IMPRESIÓN_IM: [1]CYPPOLLO!#REF!
Name A_IMPRESIÓN_IM: [1]CYPPOLLO!#REF!
Name A_impresión_IM: #REF!
Name A_impresión_IM: 'C 90'!$A$1:$D$44
Name A_IMPRESIÓN_IM: 'C 91 - 99'!$A$3:$DH$40
Name A_IMPRESIÓN_IM: [1]CYPPOLLO!#REF!
Name A_impresión_IM: #REF!
Name A_impresión_IM: 'C-88'!$A$1:$D$44
Name A_impresión_IM: 'C-89'!$A$1:$D$44
Name A_impresión_IM: #REF!

Sheet 1. INDICADORES ECONÓMICOS

Sheet C 1 - C 2 - C 3
A2: C.1 PERÚ: EVOLUCIÓN DEL VALOR BRUTO DE LA PRODUCCIÓN (VBP) AGROPECUARIA POR AÑO, SEGÚN SUB SECTORES Y PRINCIPALES ESPECIES | AQ2: Tasa
A3: Y PRODUCTOS PECUARIOS, 2007-2021
A4: (Millones de soles a precios 2007) | AQ4: Crec.
A6: Sector / Producto | C6: 2000 | D6: 2001 | E6: 2002 | F6: 2003 | G6: 2004 | H6: 2005 | I6: 2006 | J6: 2007 | K6: 2008 | L6: 2009 | M6: 2010 | N6: 2011 | O6: 2012 | P6: 2013 | Q6: 2014 | R6: 2015 | S6: 2016 | T6: 2017 | U6: 2018 | V6: 2019 | W6: 2020P | X6: 2021P | Y6: Var. % 21/20
A7: Sector agropecuario | C7: 17474.3 | D7: 17601.8 | E7: 18603.6 | F7: 18969.3 | G7: 19096 | H7: 20511.9 | I7: 22151.7 | J7: 22808.2 | K7: 24741.8 | L7: 25379.1 | M7: 26407.4 | N7: 27861.2 | O7: 29538.1 | P7: 30131.9 | Q7: 30698.2 | R7: 31894 | S7: 32592.3 | T7: 33502.4 | U7: 36117.6 | V7: 37417.505 | W7: 37800.561 | X7: 39405.013 | Y7: =((X7/W7)-1)*100 -> 4.244521 | AQ7: 3.9
A8: Subsector agrícola | C8: 11577.1 | D8: 11537.3 | E8: 12282.8 | F8: 12444.9 | G8: 12391.7 | H8: 13289.3 | I8: 14340.7 | J8: 14533.2 | K8: 15862.1 | L8: 15991.2 | M8: 16616 | N8: 17377.3 | O8: 18471.3 | P8: 18672.8 | Q8: 18833.5 | R8: 19407.9 | S8: 19601 | T8: 20149 | U8: 22019.3 | V8: 22754.466 | W8: 23395.877 | X8: 24712.508 | Y8: =((X8/W8)-1)*100 -> 5.6276175 | AQ8: 3.3
A9: Subsector pecuario | C9: 5897.2 | D9: 6064.5 | E9: 6320.8 | F9: 6524.4 | G9: 6704.3 | H9: 7222.6 | I9: 7811 | J9: 8275 | K9: 8879.7 | L9: 9387.9 | M9: 9791.4 | N9: 10483.9 | O9: 11066.7 | P9: 11459.1 | Q9: 11864.7 | R9: 12486.1 | S9: 12991.3 | T9: 13353.4 | U9: 14098.3 | V9: 14663.039 | W9: 14404.683 | X9: 14692.505 | Y9: =((X9/W9)-1)*100 -> 1.9981158 | AQ9: 4.9
B11: Industria avícola 1 | C11: =SUM(C12:C14) -> 2892.6 | D11: =SUM(D12:D14) -> 2958.5 | E11: =SUM(E12:E14) -> 3140.9 | F11: =SUM(F12:F14) -> 3262.9 | G11: =SUM(G12:G14) -> 3280.1 | H11: =SUM(H12:H14) -> 3623.2 | I11: =SUM(I12:I14) -> 4017.6 | J11: =J12+J14 -> 4330.6 | K11: =K12+K14 -> 4847.7 | L11: =L12+L14 -> 5254.6 | M11: =M12+M14 -> 5560.1 | N11: =N12+N14 -> 6092.8 | O11: =O12+O14 -> 6526.6 | P11: =P12+P14 -> 6835.4 | Q11: =Q12+Q14 -> 7152.1 | ... X11: =X12+X14 -> 9593.4758 | Y11: =((X11/W11)-1)*100 -> 1.5810271 | AQ11: 6.5
A12: 1 | B12: Ave | C12: 2340.6 | D12: 2376.6 | E12: 2551.2 | F12: 2651.8 | G12: 2655 | H12: 2983.5 | I12: 3259.4 | J12: 3534.8 | K12: 4024.4 | L12: 4424.6 | M12: 4679.4 | N12: 5111.6 | O12: 5556.6 | P12: 5754.9 | Q12: 6044.3 | R12: 6531.3 | S12: 6945.9 | T12: 7199.8 | U12: 7742.8 | V12: 8087.8781 | W12: 7907.3051 | X12: 8036.2737 | Y12: =((X12/W12)-1)*100 -> 1.6310055 | AQ12: 6.8
B13: Pollo | J13: 3273.1 | K13: 3727.9 | L13: 4121.7 | M13: 4362.7 | N13: 4582.9 | O13: 5195.8 | P13: 5394.3 | Q13: 5657.9 | R13: 6101.3 | S13: 6448.2 | T13: 6719.3 | U13: 7257.1 | V13: 7579.0435 | W13: 7415.882 | X13: 7520.4687 | Y13: =((X13/W13)-1)*100 -> 1.4103066
B14: Huevo de Gallina | C14: 552 | D14: 581.9 | E14: 589.7 | F14: 611.1 | G14: 625.1 | H14: 639.7 | I14: 758.2 | J14: 795.8 | K14: 823.3 | L14: 830 | M14: 880.7 | N14: 981.2 | O14: 970 | P14: 1080.5 | Q14: 1107.8 | R14: 1193.1 | S14: 1238.6 | T14: 1283 | U14: 1397 | V14: 1508.9284 | W14: 1536.8559 | X14: 1557.2021 | Y14: =((X14/W14)-1)*100 -> 1.3238826 | AQ14: 5.1
A15: 2 | B15: Ovino | C15: 378.7 | D15: 388.4 | E15: 383.2 | F15: 389.2 | G15: 410.8 | H15: 410.6 | I15: 413.3 | J15: 412.5 | K15: 406.5 | L15: 407.8 | M15: 410.4 | N15: 417.6 | O15: 430.3 | P15: 425.5 | Q15: 419.6 | R15: 404.2 | S15: 413.9 | T15: 407.8 | U15: 410.4 | V15: 411.76818 | W15: 395.15458 | X15: 405.4087 | Y15: =((X15/W15)-1)*100 -> 2.5949651 | AQ15: 0.4
A16: 3 | B16: Porcino | C16: 433.8 | D16: 442.2 | E16: 438.5 | F16: 439.5 | G16: 468.6 | H16: 494 | I16: 516.6 | J16: 542.7 | K16: 545.9 | L16: 543.6 | M16: 548.1 | N16: 557.2 | O16: 579.8 | P16: 605 | Q16: 641.6 | R16: 677.3 | S16: 708 | T16: 747.5 | U16: 781.6 | V16: 821.01301 | W16: 805.12164 | X16: 834.71251 | Y16: =((X16/W16)-1)*100 -> 3.6753299 | AQ16: 3.3
A17: 4 | B17: Vacuno | C17: 1114.1 | D17: 1114.3 | E17: 1147.4 | F17: 1174.2 | G17: 1227.9 | H17: 1304.4 | I17: 1382.1 | J17: 1396.3 | K17: 1397 | L17: 1408.9 | M17: 1470.2 | N17: 1531.9 | O17: 1596.3 | P17: 1651.6 | Q17: 1678.5 | R17: 1676.7 | S17: 1648.4 | T17: 1614.4 | U17: 1622.7 | V17: 1650.2126 | W17: 1573.4119 | X17: 1624.5795 | Y17: =((X17/W17)-1)*100 -> 3.2520143 | AQ17: 2.2
A18: 5 | B18: Caprino | C18: 57.6 | D18: 54.4 | E18: 53.3 | F18: 57.9 | G18: 59.5 | H18: 60.8 | I18: 62.3 | J18: 61.5 | K18: 59 | L18: 56.6 | M18: 56.4 | N18: 56.5 | O18: 57.4 | P18: 59.2 | Q18: 56.7 | R18: 54.3 | S18: 53.6 | T18: 50.5 | U18: 45.7 | V18: 46.913211 | W18: 1573.4119 | X18: 1624.5795 | Y18: =((X18/W18)-1)*100 -> 3.2520143 | AQ18: -0.7
A19: 6 | B19: Alpaca | C19: 130.1 | D19: 137.3 | E19: 147.3 | F19: 146 | G19: 148.2 | H19: 154.4 | I19: 156.5 | J19: 166.7 | K19: 169.6 | L19: 181.4 | M19: 191.6 | N19: 201.5 | O19: 213.6 | P19: 216.6 | Q19: 224.2 | R19: 212.1 | S19: 221.5 | T19: 226.9 | U19: 225.9 | V19: 223.9348 | W19: 45.580929 | X19: 45.495875 | Y19: =((X19/W19)-1)*100 -> -0.18660049 | AQ19: 3.3
A20: 7 | B20: Llama | C20: 25.2 | D20: 25.5 | E20: 25.5 | F20: 27.5 | G20: 29.1 | H20: 30.4 | I20: 30.3 | J20: 31.9 | K20: 31.3 | L20: 32.9 | M20: 32.1 | N20: 33.4 | O20: 34.3 | P20: 32.9 | Q20: 32.9 | R20: 31.4 | S20: 31.3 | T20: 31.6 | U20: 31.5 | V20: 30.317809 | W20: 220.07176 | X20: 223.96327 | Y20: =((X20/W20)-1)*100 -> 1.7682919 | AQ20: 1.3
A21: 9 | B21: Leche Fresca de Vaca | C21: 750.6 | D21: 822.4 | E21: 873.8 | F21: 918.1 | G21: 968.1 | H21: 1027.8 | I21: 1119.3 | J21: 1209.8 | K21: 1301 | L21: 1372.9 | M21: 1394.7 | N21: 1458.8 | O21: 1488 | P21: 1502.3 | Q21: 1529.2 | R21: 1581.5 | S21: 1624 | T21: 1673.4 | U21: 1717.8 | V21: 1762.855 | W21: 1774.9174 | X21: 1815.6804 | Y21: =((X21/W21)-1)*100 -> 2.2966172 | AQ21: 4.8
A22: 10 | B22: Fibra Alpaca | C22: 57 | D22: 62.3 | E22: 58 | F22: 56.9 | G22: 59.6 | H22: 66 | I22: 64.3 | J22: 71.4 | K22: 73.7 | L22: 80.4 | M22: 79.8 | N22: 85.5 | O22: 88 | P22: 81 | Q22: 82.2 | R22: 81.4 | S22: 82.7 | T22: 79.1 | U22: 83.9 | V22: 81.647227 | W22: 79.78887 | X22: 80.735847 | Y22: =((X22/W22)-1)*100 -> 1.1868538 | AQ22: 1.9
A23: 11 | B23: Fibra Llama | C23: 4.6 | D23: 4.7 | E23: 3.8 | F23: 3.9 | G23: 3.8 | H23: 3.7 | I23: 3.8 | J23: 4.5 | K23: 4.3 | L23: 4.3 | M23: 3.9 | N23: 4.2 | O23: 4.6 | P23: 4.4 | Q23: 4.6 | R23: 4 | S23: 4.1 | T23: 4.2 | U23: 4 | V23: 4.0275383 | W23: 4.0731775 | X23: 4.1239382 | Y23: =((X23/W23)-1)*100 -> 1.2462175 | AQ23: -0.5
A24: 12 | B24: Lana Ovino | C24: 53.5 | D24: 54.4 | E24: 48.9 | F24: 49 | G24: 48.6 | H24: 47.2 | I24: 44.9 | J24: 47.2 | K24: 43.6 | L24: 44.5 | M24: 44.2 | N24: 44.5 | O24: 47.7 | P24: 45 | Q24: 43.2 | R24: 38.8 | S24: 40.5 | T24: 35.2 | U24: 34.9 | V24: 33.542736 | W24: 32.314588 | X24: 33.283412 | Y24: =((X24/W24)-1)*100 -> 2.9981019 | AQ24: -2.4
A25: P Preliminar
A26: 1 Considera ave y huevo de gallina
A27: Fuente: Direcciones Regionales de Agricultura
A28: Elaboración: Ministerio de Desarrollo Agrario y Riego - DGESEP - DEIA
A30: C.2 PERÚ: PARTICIPACIÓN POR AÑO, SEGÚN SUB SECTORES Y PRINCIPALES ESPECIES Y PRODUCTOS PECUARIOS EN EL VALOR BRUTO, 2007-2021
A31: (%)
A33: Sector / Producto | C33: 2000 | D33: 2001 | E33: 2002 | F33: 2003 | G33: 2004 | H33: 2005 | I33: 2006 | J33: 2007 | K33: 2008 | L33: 2009 | M33: 2010 | N33: 2011 | O33: 2012 | P33: 2013 | Q33: 2014 | R33: 2015 | S33: 2016 | T33: 2017 | U33: 2018 | V33: 2019 | W33: 2020P | X33: 2021P
A34: Sector agropecuario | C34: =C7/$C$7*100 -> 100 | D34: =D7/$D$7*100 -> 100 | E34: =E7/$E$7*100 -> 100 | F34: =F7/$F$7*100 -> 100 | G34: =G7/$G$7*100 -> 100 | H34: =H7/$H$7*100 -> 100 | I34: =I7/$I$7*100 -> 100 | J34: =J7/$J$7*100 -> 100 | K34: =K7/$K$7*100 -> 100 | L34: =L7/$L$7*100 -> 100 | M34: =M7/$M$7*100 -> 100 | N34: =N7/$N$7*100 -> 100 | O34: =O7/$O$7*100 -> 100 | P34: =P7/$P$7*100 -> 100 | Q34: =Q7/$Q$7*100 -> 100 | R34: =R7/$R$7*100 -> 100 | S34: =S7/$S$7*100 -> 100 | T34: =T7/$T$7*100 -> 100 | U34: =U7/$U$7*100 -> 100 | V34: =V7/$V$7*100 -> 100 | W34: =W7/$W$7*100 -> 100 | X34: =X7/X$7*100 -> 100
A35: Subsector agrícola | C35: =C8/$C$7*100 -> 66.252153 | D35: =D8/$D$7*100 -> 65.546137 | E35: =E8/$E$7*100 -> 66.02378 | F35: =F8/$F$7*100 -> 65.605478 | G35: =G8/$G$7*100 -> 64.8916 | H35: =H8/$H$7*100 -> 64.788245 | I35: =I8/$I$7*100 -> 64.738598 | J35: =J8/$J$7*100 -> 63.719189 | K35: =K8/$K$7*100 -> 64.110534 | L35: =L8/$L$7*100 -> 63.009327 | M35: =M8/$M$7*100 -> 62.921757 | N35: =N8/$N$7*100 -> 62.370968 | O35: =O8/$O$7*100 -> 62.533812 | P35: =P8/$P$7*100 -> 61.970204 | Q35: =Q8/$Q$7*100 -> 61.350503 | R35: =R8/$R$7*100 -> 60.851257 | S35: =S8/$S$7*100 -> 60.139972 | T35: =T8/$T$7*100 -> 60.14196 | U35: =U8/$U$7*100 -> 60.965568 | V35: =V8/$V$7*100 -> 60.812356 | W35: =W8/$W$7*100 -> 61.892938 | X35: =X8/X$7*100 -> 62.714121
A36: Subsector pecuario | C36: =C9/$C$7*100 -> 33.747847 | D36: =D9/$D$7*100 -> 34.453863 | E36: =E9/$E$7*100 -> 33.97622 | F36: =F9/$F$7*100 -> 34.394522 | G36: =G9/$G$7*100 -> 35.1084 | H36: =H9/$H$7*100 -> 35.211755 | I36: =I9/$I$7*100 -> 35.261402 | J36: =J9/$J$7*100 -> 36.280811 | K36: =K9/$K$7*100 -> 35.889466 | L36: =L9/$L$7*100 -> 36.990673 | M36: =M9/$M$7*100 -> 37.078243 | N36: =N9/$N$7*100 -> 37.629032 | O36: =O9/$O$7*100 -> 37.465849 | P36: =P9/$P$7*100 -> 38.029796 | Q36: =Q9/$Q$7*100 -> 38.649497 | R36: =R9/$R$7*100 -> 39.148743 | S36: =S9/$S$7*100 -> 39.860028 | T36: =T9/$T$7*100 -> 39.85804 | U36: =U9/$U$7*100 -> 39.034432 | V36: =V9/$V$7*100 -> 39.187644 | W36: =W9/$W$7*100 -> 38.107062 | X36: =X9/X$7*100 -> 37.285879
B38: Industria avícola 1 | C38: =C11/$C$7*100 -> 16.553453 | D38: =D11/$D$7*100 -> 16.80794 | E38: =E11/$E$7*100 -> 16.883291 | F38: =F11/$F$7*100 -> 17.200951 | G38: =G11/$G$7*100 -> 17.176896 | H38: =H11/$H$7*100 -> 17.663893 | I38: =I11/$I$7*100 -> 18.136757 | J38: =J11/$J$7*100 -> 18.987031 | K38: =K11/$K$7*100 -> 19.593158 | L38: =L11/$L$7*100 -> 20.704438 | M38: =M11/$M$7*100 -> 21.055083 | N38: =N11/$N$7*100 -> 21.868405 | O38: =O11/$O$7*100 -> 22.095531 | P38: =P11/$P$7*100 -> 22.684929 | Q38: =Q11/$Q$7*100 -> 23.298109 | R38: =R11/$R$7*100 -> 24.218975 | S38: =S11/$S$7*100 -> 25.11176 | T38: =T11/$T$7*100 -> 25.319977 | U38: =U11/$U$7*100 -> 25.305668 | V38: =V11/$V$7*100 -> 25.647906 | W38: =W11/$W$7*100 -> 24.984182 | X38: =X11/$X$7*100 -> 24.345825
B39: Ave | C39: =C12/$C$7*100 -> 13.394528 | D39: =D12/$D$7*100 -> 13.502028 | E39: =E12/$E$7*100 -> 13.713475 | F39: =F12/$F$7*100 -> 13.97943 | G39: =G12/$G$7*100 -> 13.903435 | H39: =H12/$H$7*100 -> 14.545215 | I39: =I12/$I$7*100 -> 14.713995 | J39: =J12/$J$7*100 -> 15.497935 | K39: =K12/$K$7*100 -> 16.265591 | L39: =L12/$L$7*100 -> 17.43403 | M39: =M12/$M$7*100 -> 17.720033 | N39: =N12/$N$7*100 -> 18.346661 | O39: =O12/$O$7*100 -> 18.811636 | P39: =P12/$P$7*100 -> 19.099028 | Q39: =Q12/$Q$7*100 -> 19.689428 | R39: =R12/$R$7*100 -> 20.478146 | S39: =S12/$S$7*100 -> 21.311475 | T39: =T12/$T$7*100 -> 21.490401 | U39: =U12/$U$7*100 -> 21.437748 | V39: =V12/$V$7*100 -> 21.615226 | W39: =W12/$W$7*100 -> 20.918486 | X39: =X12/$X$7*100 -> 20.394039
B40: Pollo | J40: =J13/$J$7*100 -> 14.350541 | K40: =K13/$K$7*100 -> 15.067214 | L40: =L13/$L$7*100 -> 16.240529 | M40: =M13/$M$7*100 -> 16.520748 | N40: =N13/$N$7*100 -> 16.44904 | O40: =O13/$O$7*100 -> 17.590163 | P40: =P13/$P$7*100 -> 17.90229 | Q40: =Q13/$Q$7*100 -> 18.430722 | R40: =R13/$R$7*100 -> 19.12993 | S40: =S13/$S$7*100 -> 19.784428 | T40: =T13/$T$7*100 -> 20.056175 | U40: =U13/$U$7*100 -> 20.092974 | V40: =V13/$V$7*100 -> 20.255342 | W40: =W13/$W$7*100 -> 19.618445 | X40: =X13/$X$7*100 -> 19.085056
A41: 1 | B41: Huevo de Gallina | C41: =C14/$C$7*100 -> 3.1589248 | D41: =D14/$D$7*100 -> 3.3059119 | E41: =E14/$E$7*100 -> 3.1698166 | F41: =F14/$F$7*100 -> 3.2215211 | G41: =G14/$G$7*100 -> 3.2734604 | H41: =H14/$H$7*100 -> 3.1186775 | I41: =I14/$I$7*100 -> 3.4227621 | J41: =J14/$J$7*100 -> 3.489096 | K41: =K14/$K$7*100 -> 3.3275671 | L41: =L14/$L$7*100 -> 3.2704075 | M41: =M14/$M$7*100 -> 3.33505 | N41: =N14/$N$7*100 -> 3.5217435 | O41: =O14/$O$7*100 -> 3.2838944 | P41: =P14/$P$7*100 -> 3.5859007 | Q41: =Q14/$Q$7*100 -> 3.6086806 | R41: =R14/$R$7*100 -> 3.740829 | S41: =S14/$S$7*100 -> 3.8002841 | T41: =T14/$T$7*100 -> 3.8295764 | U41: =U14/$U$7*100 -> 3.8679203 | V41: =V14/$V$7*100 -> 4.0326805 | W41: =W14/$W$7*100 -> 4.0656961 | X41: =X14/$X$7*100 -> 3.9517867
B42: Ovino | C42: =C15/$C$7*100 -> 2.1671827 | D42: =D15/$D$7*100 -> 2.2065925 | E42: =E15/$E$7*100 -> 2.0598164 | F42: =F15/$F$7*100 -> 2.0517362 | G42: =G15/$G$7*100 -> 2.1512359 | H42: =H15/$H$7*100 -> 2.0017648 | I42: =I15/$I$7*100 -> 1.865771 | J42: =J15/$J$7*100 -> 1.8085601 | K42: =K15/$K$7*100 -> 1.6429686 | L42: =L15/$L$7*100 -> 1.606834 | M42: =M15/$M$7*100 -> 1.5541098 | N42: =N15/$N$7*100 -> 1.4988586 | O42: =O15/$O$7*100 -> 1.4567626 | P42: =P15/$P$7*100 -> 1.4121247 | Q42: =Q15/$Q$7*100 -> 1.3668554 | R42: =R15/$R$7*100 -> 1.267323 | S42: =S15/$S$7*100 -> 1.2699319 | T42: =T15/$T$7*100 -> 1.2172262 | U42: =U15/$U$7*100 -> 1.1362881 | V42: =V15/$V$7*100 -> 1.1004694 | W42: =W15/$W$7*100 -> 1.045367 | X42: =X15/$X$7*100 -> 1.0288252
B43: Porcino | C43: =C16/$C$7*100 -> 2.4825029 | D43: =D16/$D$7*100 -> 2.5122431 | E43: =E16/$E$7*100 -> 2.3570707 | F43: =F16/$F$7*100 -> 2.3169015 | G43: =G16/$G$7*100 -> 2.4539171 | H43: =H16/$H$7*100 -> 2.4083581 | I43: =I16/$I$7*100 -> 2.3321009 | J43: =J16/$J$7*100 -> 2.3794074 | K43: =K16/$K$7*100 -> 2.2063876 | L43: =L16/$L$7*100 -> 2.1419199 | M43: =M16/$M$7*100 -> 2.0755546 | N43: =N16/$N$7*100 -> 1.9999139 | O43: =O16/$O$7*100 -> 1.9628886 | P43: =P16/$P$7*100 -> 2.0078389 | Q43: =Q16/$Q$7*100 -> 2.0900248 | R43: =R16/$R$7*100 -> 2.1235969 | S43: =S16/$S$7*100 -> 2.1722922 | T43: =T16/$T$7*100 -> 2.2311834 | U43: =U16/$U$7*100 -> 2.1640419 | V43: =V16/$V$7*100 -> 2.194195 | W43: =W16/$W$7*100 -> 2.1299198 | X43: =X16/$X$7*100 -> 2.1182901
B44: Vacuno | C44: =C17/$C$7*100 -> 6.3756488 | D44: =D17/$D$7*100 -> 6.3306026 | E44: =E17/$E$7*100 -> 6.1676235 | F44: =F17/$F$7*100 -> 6.1900017 | G44: =G17/$G$7*100 -> 6.4301424 | H44: =H17/$H$7*100 -> 6.3592354 | I44: =I17/$I$7*100 -> 6.2392503 | J44: =J17/$J$7*100 -> 6.1219211 | K44: =K17/$K$7*100 -> 5.6463151 | L44: =L17/$L$7*100 -> 5.5514183 | M44: =M17/$M$7*100 -> 5.5673788 | N44: =N17/$N$7*100 -> 5.4983274 | O44: =O17/$O$7*100 -> 5.4042068 | P44: =P17/$P$7*100 -> 5.4812342 | Q44: =Q17/$Q$7*100 -> 5.4677473 | R44: =R17/$R$7*100 -> 5.2571016 | S44: =S17/$S$7*100 -> 5.0576363 | T44: =T17/$T$7*100 -> 4.8187593 | U44: =U17/$U$7*100 -> 4.4928234 | V44: =V17/$V$7*100 -> 4.4102691 | W44: =W17/$W$7*100 -> 4.1624036 | X44: =X17/$X$7*100 -> 4.1227736
B45: Caprino | C45: =C18/$C$7*100 -> 0.32962694 | D45: =D18/$D$7*100 -> 0.3090593 | E45: =E18/$E$7*100 -> 0.28650369 | F45: =F18/$F$7*100 -> 0.30523003 | G45: =G18/$G$7*100 -> 0.31158358 | H45: =H18/$H$7*100 -> 0.2964133 | I45: =I18/$I$7*100 -> 0.28124252 | J45: =J18/$J$7*100 -> 0.26963987 | K45: =K18/$K$7*100 -> 0.23846284 | L45: =L18/$L$7*100 -> 0.22301815 | M45: =M18/$M$7*100 -> 0.2135765 | N45: =N18/$N$7*100 -> 0.20279098 | O45: =O18/$O$7*100 -> 0.1943253 | P45: =P18/$P$7*100 -> 0.19646952 | Q45: =Q18/$Q$7*100 -> 0.18470138 | R45: =R18/$R$7*100 -> 0.17025146 | S45: =S18/$S$7*100 -> 0.16445602 | T45: =T18/$T$7*100 -> 0.15073547 | U45: =U18/$U$7*100 -> 0.12653111 | V45: =V18/$V$7*100 -> 0.12537771 | W45: =W18/$W$7*100 -> 4.1624036 | X45: =X18/$X$7*100 -> 4.1227736
B46: Alpaca | C46: =C19/$C$7*100 -> 0.74452196 | D46: =D19/$D$7*100 -> 0.78003386 | E46: =E19/$E$7*100 -> 0.79178224 | F46: =F19/$F$7*100 -> 0.76966467 | G46: =G19/$G$7*100 -> 0.77607876 | H46: =H19/$H$7*100 -> 0.75273378 | I46: =I19/$I$7*100 -> 0.70649205 | J46: =J19/$J$7*100 -> 0.73087749 | K46: =K19/$K$7*100 -> 0.68547963 | L46: =L19/$L$7*100 -> 0.71476136 | M46: =M19/$M$7*100 -> 0.7255542 | N46: =N19/$N$7*100 -> 0.723228 | O46: =O19/$O$7*100 -> 0.72313385 | P46: =P19/$P$7*100 -> 0.7188395 | Q46: =Q19/$Q$7*100 -> 0.73033598 | R46: =R19/$R$7*100 -> 0.66501536 | S46: =S19/$S$7*100 -> 0.67960837 | T46: =T19/$T$7*100 -> 0.67726491 | U46: =U19/$U$7*100 -> 0.62545684 | V46: =V19/$V$7*100 -> 0.59847604 | W46: =W19/$W$7*100 -> 0.12058268 | X46: =X19/$X$7*100 -> 0.11545707
...

Sheet 2. POBLACION Y ...

Sheet C-4
A2: C.4 PERÚ: POBLACIÓN PECUARIA POR ESPECIE, SEGÚN REGIÓN, 2021P
A3: (Unidades)
A5: Región | B5: Ave | C5: Alpaca | D5: LLama | E5: Caprino | F5: Ovino | G5: Porcino | H5: Vacuno | I5: Vacas en Ordeño
A6: Total Nacional | B6: =(B8+B9+B10+B11+B12+B16+B17+B18+B19+B20+B21+B22+B23+B24+B25+B26+B27+B28+B31+B32+B33+B34+B35+B36) -> 1.8937475e+08 | C6: =(C8+C9+C10+C11+C12+C16+C17+C18+C19+C20+C21+C22+C23+C24+C25+C26+C27+C28+C31+C32+C33+C34+C35+C36) -> 4484888 | D6: =(D8+D9+D10+D11+D12+D16+D17+D18+D19+D20+D21+D22+D23+D24+D25+D26+D27+D28+D31+D32+D33+D34+D35+D36) -> 1075425 | E6: =(E8+E9+E10+E11+E12+E16+E17+E18+E19+E20+E21+E22+E23+E24+E25+E26+E27+E28+E31+E32+E33+E34+E35+E36) -> 1754968.1 | F6: =(F8+F9+F10+F11+F12+F16+F17+F18+F19+F20+F21+F22+F23+F24+F25+F26+F27+F28+F31+F32+F33+F34+F35+F36) -> 10942309 | G6: =(G8+G9+G10+G11+G12+G16+G17+G18+G19+G20+G21+G22+G23+G24+G25+G26+G27+G28+G31+G32+G33+G34+G35+G36) -> 3342910.5 | H6: =(H8+H9+H10+H11+H12+H16+H17+H18+H19+H20+H21+H22+H23+H24+H25+H26+H27+H28+H31+H32+H33+H34+H35+H36) -> 5853660 | I6: =(I8+I9+I10+I11+I12+I16+I17+I18+I19+I20+I21+I22+I23+I24+I25+I26+I27+I28+I31+I32+I33+I34+I35+I36) -> 932318.41
A8: Tumbes | B8: 180350 | C8: 0 | D8: 0 | E8: 63678 | F8: 9063 | G8: 30512 | H8: 20732 | I8: 299.75
A9: Piura | B9: 3905773.8 | C9: 98 | D9: 0 | E9: 305413.09 | F9: 266289.4 | G9: 177302.46 | H9: 292935.98 | I9: 24341
A10: Lambayeque | B10: 2557740 | C10: 0 | D10: 0 | E10: 105680 | F10: 73368 | G10: 71922 | H10: 114053 | I10: 18100.895
A11: La Libertad | B11: 25462693 | C11: 7131 | D11: 0 | E11: 86812 | F11: 36171 | G11: 110020 | H11: 233679 | I11: 52129.25
A12: Cajamarca | B12: 890397 | C12: 1196 | D12: 0 | E12: 106195 | F12: 484087 | G12: 292447 | H12: 658353 | I12: =SUM(I13:I15) -> 167899.95
A13: Cajamarca | B13: 379170 | C13: 1196 | D13: 0 | E13: 65749 | F13: 344674 | G13: 78439 | H13: 263930 | I13: 98542.992
A14: Chota | B14: 211860 | C14: 0 | D14: 0 | E14: 20682 | F14: 103286 | G14: 103681 | H14: 275043 | I14: 63450.375
A15: Jaén | B15: 299367 | C15: 0 | D15: 0 | E15: 19764 | F15: 36127 | G15: 110327 | H15: 119380 | I15: 5906.5833
A16: Amazonas | B16: 1530189 | C16: 0 | D16: 0 | E16: 14397 | F16: 27990 | G16: 92127 | H16: 382797 | I16: 80864.333
A17: Ancash | B17: 2640982 | C17: 10940 | D17: 0 | E17: 167891 | F17: 672384 | G17: 171027 | H17: 307349 | I17: 17044.833
A18: LimaP | B18: 90509068 | C18: 46625 | D18: 18780 | E18: 158415 | F18: 294505 | G18: 490151 | H18: 269325 | I18: 74209.007
A19: Ica | B19: 17230945 | C19: 0 | D19: 0 | E19: 75606 | F19: 26813 | G19: 99656 | H19: 48306 | I19: 15056.75
A20: Huánuco | B20: 1758941 | C20: 6701 | D20: 3485 | E20: 101673 | F20: 527633 | G20: 405632 | H20: 289367 | I20: 39351.75
A21: Pasco | B21: 139084 | C21: 131020 | D21: 44276 | E21: 6384 | F21: 684682 | G21: 53247 | H21: 119084 | I21: 30414.5
A22: Junín | B22: 2568943 | C22: 105903 | D22: 63128 | E22: 14890 | F22: 1611208 | G22: 193340 | H22: 340566 | I22: 41643.083
A23: Huancavelica | B23: 388647 | C23: 269324 | D23: 129587 | E23: 186563 | F23: 623587 | G23: 156489 | H23: 179834 | I23: 12360.925
A24: Arequipa | B24: 19026568 | C24: 471546 | D24: 94372 | E24: 26786 | F24: 217639 | G24: 116838 | H24: 232737 | I24: 75901.333
... A27: Ayacucho | B27: 580691 | C27: 296478 | D27: 78681 | E27: 171647 | F27: 609447 | G27: 112392 | H27: 422983 | I27: 32477.833
A28: Apurímac | B28: 307099 | C28: 212220 | D28: 72280 | E28: 108668 | F28: 454797 | G28: 137715 | H28: 294844 | I28: =SUM(I29:I30) -> 30696.883
A29: Abancay | B29: 188730 | C29: 192347 | D29: 53987 | E29: 55687 | F29: 311589 | G29: 49568 | H29: 188947 | I29: 19190.083
A30: Andahuaylas | B30: 118369 | C30: 19873 | D30: 18293 | E30: 52981 | F30: 143208 | G30: 88147 | H30: 105897 | I30: 11506.8
A31: Cusco | B31: 1202695 | C31: 673731 | D31: 144965 | E31: 28204 | F31: 1417593 | G31: 121716 | H31: 442818 | I31: 83162
A32: Puno | B32: 1597475 | C32: 2030525 | D32: 359415 | E32: 0 | F32: 2787942 | G32: 122635 | H32: 740290 | I32: 98942.083
A33: San Martín | B33: 4751632 | C33: 0 | D33: 0 | E33: 0 | F33: 9188 | G33: 179258 | H33: 214357 | I33: 20316.417
A34: Loreto | B34: 4190254 | C34: 0 | D34: 0 | E34: 290 | F34: 10791 | G34: 97342 | H34: 79677 | I34: 1216.5
A35: Ucayali | B35: 6213568 | C35: 0 | D35: 0 | E35: 182 | F35: 8439 | G35: 46273 | H35: 66095 | I35: 3692.4167
A36: Madre de Dios | B36: 489694 | C36: 0 | D36: 0 | E36: 220 | F36: 4669 | G36: 12680 | H36: 60875 | I36: 1007.9167
A37: P Preliminar
A38: Fuente: Direcciones Regionales de Agricultura
A39: Elaboración: Ministerio de Desarrollo Agrario y Riego - DGESEP - DEIA

Sheet C 5
A2: C.5 PERÚ: EVOLUCIÓN DE LA POBLACIÓN, SACA, PRODUCCIÓN, RENDIMIENTO Y PRECIOS RECIBIDOS POR EL PRODUCTOR POR AÑO, SEGÚN ESPECIE Y PRODUCTO, 2007-2021
A4: Especie/ Producto | B4: Variable | C4: 2000 | D4: 2001 | E4: 2002 | F4: 2003 | G4: 2004 | H4: 2005 | I4: 2006 | J4: 2007 | K4: 2008 | L4: 2009 | M4: 2010 | N4: 2011 | O4: 2012 | P4: 2013 | Q4: 2014 | R4: 2015 | S4: 2016 | T4: 2017 | U4: 2018 | V4: 2019 | W4: 2020 P | X4: 2021 P
B5: Población (Miles) | C5: 88010358 | D5: 85621159 | E5: 90354182 | F5: 92846109 | G5: 97761003 | H5: 99278818 | I5: 117976702 | J5: 120227.6 | K5: 131179.1 | L5: 137838 | M5: 130779 | N5: 128943.5 | O5: 138554.1 | P5: 138179.8 | Q5: 144703.7 | R5: 151000.9 | S5: 158263.2 | T5: 156637.7 | U5: 160959.32 | V5: 168172.64 | W5: 178159.63 | X5: 189374.75
B6: Saca (Miles) | C6: 283733046 | D6: 287860594 | E6: 307094298 | F6: 310943489 | G6: 308485309 | H6: 342073628 | I6: 368545799 | J6: 394749.6 | K6: 435909.3 | L6: 476340.3 | M6: 504986.8 | N6: 535421.1 | O6: 575566.4 | P6: 594004.2 | Q6: 621140.1 | R6: 645016.2 | S6: 690892.3 | T6: 709233 | U6: 755841.1 | V6: 786256.92 | W6: 753602.34 | X6: 776641.17
A7: Ave | B7: Produción carne (t) | C7: 510161 | D7: 518010 | E7: 556076 | F7: 577989 | G7: 578693 | H7: 650296 | I7: 710428 | J7: 770444 | K7: 877171 | L7: 964407 | M7: 1019935 | N7: 1108345 | O7: 1211140 | P7: 1254348 | Q7: 1317426 | R7: 1423586 | S7: 1513950 | T7: 1569280 | U7: 1687636 | V7: 1762855.6 | W7: 1723497.5 | X7: 1751607.8
B8: Rendimiento (kg/Unidad) | C8: =(C7/C6)*1000 -> 1.7980317 | D8: =(D7/D6)*1000 -> 1.7995169 | E8: =(E7/E6)*1000 -> 1.8107663 | F8: =(F7/F6)*1000 -> 1.8588233 | G8: =(G7/G6)*1000 -> 1.8759175 | H8: =(H7/H6)*1000 -> 1.901041 | I8: =(I7/I6)*1000 -> 1.9276519 | J8: =(J7/J6) -> 1.9517284 | K8: =(K7/K6) -> 2.0122787 | L8: =(L7/L6) -> 2.0246177 | M8: =(M7/M6) -> 2.0197261 | N8: =(N7/N6) -> 2.0700436 | O8: =(O7/O6) -> 2.1042576 | P8: =(P7/P6) -> 2.111682 | Q8: =(Q7/Q6) -> 2.1209804 | ... X8: =(X7/X6) -> 2.2553631
B9: Precio (S/ / kg) | C9: 3.06 | D9: 3.19 | E9: 3.07 | F9: 3.09 | G9: 3.48 | H9: 3.46 | I9: 3.6 | J9: 3.63 | K9: 4.18 | L9: 4.33 | M9: 4.64 | N9: 4.67 | O9: 4.7 | P9: 4.75 | Q9: 4.78 | R9: 4.82 | S9: 4.84 | T9: 4.84 | U9: 4.86 | V9: 4.67 | W9: 5.02
B10: Población (Unidades) | C10: 14800991 | D10: 14727155 | E10: 14690547 | F10: 14721243 | G10: 14696522 | H10: 14813786 | I10: 14675255 | J10: 14580166 | K10: 14509628 | L10: 14137690 | M10: 14159720 | N10: 14050173 | O10: 12184143 | P10: 11830977 | Q10: 11652272 | R10: 11982580 | S10: 11450657 | T10: 11338424 | U10: 11330908 | V10: 11371637 | W10: 11071699 | X10: 10942309
B11: Saca (Unidades) | C11: 2521661 | D11: 2571321 | E11: 2517896 | F11: 2535935 | G11: 2709847 | H11: 2685627 | I11: 2692776 | J11: 2681208 | K11: 2678241 | L11: 2753681 | M11: 2788507 | N11: 2844228 | O11: 2910166 | P11: 2832371 | Q11: 2788555 | R11: 2698887 | S11: 2745951 | T11: 2699282 | U11: 2687624 | V11: 2682837 | W11: 2544650.7 | X11: 2576571.6
A12: Ovino | B12: Produción carne (t) | C12: 31068 | D12: 31868 | E12: 31437 | F12: 31926 | G12: 33698 | H12: 33686 | I12: 33904 | J12: 33839 | K12: 33350 | L12: 33458 | M12: 33669 | N12: 34256 | O12: 35304 | P12: 34906 | Q12: 34421 | R12: 33163 | S12: 33955 | T12: 33458 | U12: 33672 | V12: 33780.947 | W12: 32310.988 | X12: 33259.223
B13: Rendimiento (kg/Unidad) | C13: =(C12/C11)*1000 -> 12.320451 | D13: =(D12/D11)*1000 -> 12.39363 | E13: =(E12/E11)*1000 -> 12.485424 | F13: =(F12/F11)*1000 -> 12.589439 | G13: =(G12/G11)*1000 -> 12.435388 | H13: =(H12/H11)*1000 -> 12.543067 | I13: =(I12/I11)*1000 -> 12.590724 | J13: =(J12/J11)*1000 -> 12.620804 | ... X13: =(X12/X11)*1000 -> 12.908325
B14: Precio (S/ / kg) | C14: 2.99 | D14: 3.13 | E14: 3.29 | F14: 3.29 | G14: 3.27 | H14: 3.31 | I14: 3.32 | J14: 3.49 | K14: 3.9 | L14: 4.13 | M14: 4.46 | N14: 4.52 | O14: 4.9 | P14: 5.04 | Q14: 5.72 | R14: 5.72 | S14: 5.9 | T14: 5.6 | U14: 5.56 | V14: 5.58 | W14: 5.43 | X14: 5.43
B15: Población (Unidades) | C15: 2845573 | D15: 2809888 | E15: 2941036 | F15: 2990499 | G15: 3000199 | H15: 3010724 | I15: 3073855 | J15: 3115772 | K15: 3151406 | L15: 3256809 | M15: 3254413 | N15: 3263254 | O15: 2987315 | P15: 3176115 | Q15: 3173015 | R15: 3200714 | S15: 3104911 | T15: 3217254 | U15: 3215742 | V15: 3269537.5 | W15: 3270742 | X15: 3342910.5
B16: Saca (Unidades) | C16: 1540534 | D16: 1650886 | E16: 1637129 | F16: 1670387 | G16: 1884573 | H16: 1991346 | I16: 2074715 | J16: 2153141 | K16: 2131518 | L16: 2213057 | M16: 2186978 | N16: 2298432 | O16: 2401634 | P16: 2499031 | Q16: 2629566 | R16: 2764884 | S16: 2876803 | T16: 3073656 | U16: 3090907 | V16: 3284606.4 | W16: 3191164.1 | X16: 3314890.6
A17: Porcino | B17: Produción carne (t) | C17: 91554 | D17: 93313 | E17: 92530 | F17: 92738 | G17: 98880 | H17: 104254 | I17: 109010 | J17: 114520 | K17: 115196 | L17: 114719 | M17: 115655 | N17: 117588 | O17: 122353 | P17: 127684 | Q17: 135390 | R17: 142925 | S17: 149399 | T17: 157824 | U17: 162421 | V17: 173258.66 | W17: 169804.68 | X17: 176149.67
B18: Rendimiento (kg/Unidad) | C18: =(C17/C16)*1000 -> 59.430042 | D18: =(D17/D16)*1000 -> 56.522982 | E18: =(E17/E16)*1000 -> 56.519676 | F18: =(F17/F16)*1000 -> 55.518871 | G18: =(G17/G16)*1000 -> 52.468119 | H18: =(H17/H16)*1000 -> 52.353534 | I18: =(I17/I16)*1000 -> 52.542156 | J18: =(J17/J16)*1000 -> 53.187413 | ... X18: =(X17/X16)*1000 -> 53.138911
B19: Precio (S/ / kg) | C19: 3.31 | D19: 3.34 | E19: 3.35 | F19: 3.39 | G19: 3.42 | H19: 3.43 | I19: 3.47 | J19: 3.5 | K19: 3.8 | L19: 4.12 | M19: 4.25 | N19: 5.05 | O19: 5.24 | P19: 5.91 | Q19: 6.07 | R19: 6.42 | S19: 6.77 | T19: 6.96 | U19: 7.05 | V19: 6.94 | W19: 6.72 | X19: 6.72
B20: Población (Unidades) | C20: 4980291 | D20: 5035612 | E20: 5163700 | F20: 5193414 | G20: 5184822 | H20: 5249783 | I20: 5241102 | J20: 5420865 | K20: 5442989 | L20: 5459435 | M20: 5520200 | N20: 5589173 | O20: 5660984 | P20: 5555988 | Q20: 5577959 | R20: 5553470 | S20: 5525454 | T20: 5535569 | U20: 5595483 | V20: 5599893 | W20: 5688461 | X20: 5853660
B21: Saca (Unidades) | C21: 875746 | D21: 920031 | E21: 951383 | F21: 986402 | G21: 1020294 | H21: 1074578 | I21: 1127321 | J21: 1138578 | K21: 1151906 | L21: 1168497 | M21: 1218723 | N21: 1266710 | O21: 1319404 | P21: 1375095 | Q21: 1376391 | R21: 1367797 | S21: 1364230 | T21: 1331223 | U21: 1348165 | V21: 1357066.5 | W21: 1250069 | X21: 1303069.6
A22: Vacuno | B22: Produción carne (t) | C22: 130249 | D22: 130269 | E22: 134137 | F22: 137271 | G22: 143554 | H22: 152497 | I22: 161578 | J22: 163235 | K22: 163318 | L22: 164704 | M22: 171872 | N22: 179084 | O22: 186617 | P22: 193087 | Q22: 196232 | R22: 196015 | S22: 192703 | T22: 188738 | U22: 189703 | V22: 192919.59 | W22: 183941.13 | X22: 189922.92
B23: Rendimiento (kg/Unidad) | C23: =(C22/C21)*1000 -> 148.7292 | D23: =(D22/D21)*1000 -> 141.59197 | E23: =(E22/E21)*1000 -> 140.99159 | F23: =(F22/F21)*1000 -> 139.16334 | G23: =(G22/G21)*1000 -> 140.69866 | H23: =(H22/H21)*1000 -> 141.91338 | I23: =(I22/I21)*1000 -> 143.32918 | J23: =(J22/J21)*1000 -> 143.36743 | ... X23: =(X22/X21)*1000 -> 145.7504
B24: Precio (S/ / kg) | C24: 3.34 | D24: 3.41 | E24: 3.29 | F24: 3.52 | G24: 3.33 | H24: 3.36 | I24: 3.4 | J24: 3.5 | K24: 3.77 | L24: 4.08 | M24: 4.1 | N24: 4.25 | O24: 4.69 | P24: 4.84 | Q24: 5.23 | R24: 5.41 | S24: 5.45 | T24: 5.53 | U24: 5.64 | V24: 5.69 | W24: 6.73 | X24: 6.73
B25: Población (Unidades) | C25: 2034914 | D25: 2017808 | E25: 1983128 | F25: 1983302 | G25: 1971863 | H25: 1952956 | I25: 1936855 | J25: 1925912 | K25: 1904124 | L25: 1928678 | M25: 1968306 | N25: 1946117 | O25: 1949502 | P25: 1928631 | Q25: 1905462 | R25: 1882361 | S25: 1865047 | T25: 1814704 | U25: 1812530 | V25: 1801882 | W25: 1784685 | X25: 1754968.1
B26: Saca (Unidades) | C26: 451247 | D26: 468861 | E26: 476569 | F26: 523993 | G26: 524448 | H26: 527096 | I26: 518663 | J26: 506927 | K26: 496706 | L26: 505880 | M26: 499447 | N26: 489915 | O26: 496626 | P26: 505262 | Q26: 489956 | R26: 464018 | S26: 458812 | T26: 444799 | U26: 410567 | V26: 411262.69 | W26: 392865.58 | X26: 390291.64
A27: Caprino | B27: Produción carne (t) | C27: 6268 | D27: 5912 | E27: 5793 | F27: 6294 | G27: 6476 | H27: 6618 | I27: 6772 | J27: 6686 | K27: 6419 | L27: 6153 | M27: 6131 | N27: 6150 | O27: 6247 | P27: 6439 | Q27: 6167 | R27: 5901 | S27: 5827 | T27: 5494 | U27: 4966 | V27: 5102.2518 | W27: 4957.3536 | X27: 4948.0032
B28: Rendimiento (kg/Unidad) | C28: =(C27/C26)*1000 -> 13.890397 | D28: =(D27/D26)*1000 -> 12.609281 | E28: =(E27/E26)*1000 -> 12.155637 | F28: =(F27/F26)*1000 -> 12.011611 | G28: =(G27/G26)*1000 -> 12.348221 | H28: =(H27/H26)*1000 -> 12.555588 | I28: =(I27/I26)*1000 -> 13.056648 | J28: =(J27/J26)*1000 -> 13.189276 | ... X28: =(X27/X26)*1000 -> 12.677707
B29: Precio (S/ / kg) | C29: 3.33 | D29: 3.28 | E29: 3.31 | F29: 3.22 | G29: 3.27 | H29: 3.05 | I29: 3.01 | J29: 3.17 | K29: 3.41 | L29: 3.61 | M29: 3.38 | N29: 3.53 | O29: 3.68 | P29: 3.93 | Q29: 4.04 | R29: 4.28 | S29: 4.66 | T29: 4.74 | U29: 4.79 | V29: 4.81 | W29: 4.8 | X29: 4.8
B30: Población (Unidades) | C30: 3078524 | D30: 3190373 | E30: 3335721 | F30: 3422557 | G30: 3429019 | H30: 3594515 | I30: 3625627 | J30: 3687340 | K30: 3780806 | L30: 4105582 | M30: 4177499 | N30: 4322258 | O30: 3927361 | P30: 4005315 | Q30: 4315793 | R30: 4318457 | S30: 4319228 | T30: 4330710 | U30: 4384846 | V30: 4456049 | W30: 4450422 | X30: 4484888
B31: Saca (Unidades) | C31: 269643 | D31: 288318 | E31: 313415 | F31: 304890 | G31: 312092 | H31: 321478 | I31: 330072 | J31: 355174 | K31: 365555 | L31: 387980 | M31: 410085 | N31: 424100 | O31: 455558 | P31: 463354 | Q31: 481847 | R31: 446199 | S31: 474135 | T31: 479033 | U31: 470464 | V31: 473283 | W31: 464229.43 | X31: 469624.4
A32: Alpaca | B32: Produción carne (t) | C32: 7307 | D32: 7713 | E32: 8277 | F32: 8204 | G32: 8323 | H32: 8671 | I32: 8793 | J32: 9366 | K32: 9527 | L32: 10189 | M32: 10761 | N32: 11318 | O32: 11999 | P32: 12169 | Q32: 12594 | R32: 11917 | S32: 12445 | T32: 12747 | U32: 12689 | V32: 12579.638 | W32: 12362.63 | X32: 12581.237
B33: Rendimiento (kg/Unidad) | C33: =(C32/C31)*1000 -> 27.098794 | D33: =(D32/D31)*1000 -> 26.751712 | E33: =(E32/E31)*1000 -> 26.409074 | F33: =(F32/F31)*1000 -> 26.908065 | G33: =(G32/G31)*1000 -> 26.668418 | H33: =(H32/H31)*1000 -> 26.972297 | I33: =(I32/I31)*1000 -> 26.639642 | J33: =(J32/J31)*1000 -> 26.370173 | ... X33: =(X32/X31)*1000 -> 26.789999
B34: Precio (S/ / kg) | C34: 2.4 | D34: 2.57 | E34: 2.48 | F34: 2.53 | G34: 2.66 | H34: 2.61 | I34: 2.51 | J34: 2.5 | K34: 2.91 | L34: 3.13 | M34: 3.43 | N34: 3.65 | O34: 4.03 | P34: 4.43 | Q34: 4.77 | R34: 4.63 | S34: 4.81 | T34: 4.91 | U34: 4.96 | V34: 4.94 | W34: 5 | X34: 5
X35: sigue…
A36: continúa C.5
A37: Especie/ Producto | B37: Variable | C37: 2000 | D37: 2001 | E37: 2002 | F37: 2003 | G37: 2004 | H37: 2005 | I37: 2006 | J37: 2007 | K37: 2008 | L37: 2009 | M37: 2010 | N37: 2011 | O37: 2012 | P37: 2013 | Q37: 2014 | R37: 2015 | S37: 2016 | T37: 2017 | U37: 2018 | V37: 2019 | W37: 2020 P | X37: 2021 P
B39: Población (Unidades) | C39: 1183908 | D39: 1179088 | E39: 1207275 | F39: 1230543 | G39: 1236984 | H39: 1269979 | I39: 1256101 | J39: 1274425 | K39: 1262782 | L39: 1237593 | M39: 1245169 | N39: 1226612 | O39: 1194404 | P39: 1234089 | Q39: 1211917 | R39: 1194708 | S39: 1105018 | T39: 1106201 | U39: 1093124 | V39: 1095920.5 | W39: 1085549.7 | X39: 1075425
B40: Saca (Unidades) | C40: 91890 | D40: 95157 | E40: 97389 | F40: 101826 | G40: 109330 | H40: 112106 | I40: 113801 | J40: 118399 | K40: 119237 | L40: 127316 | M40: 123384 | N40: 128346 | O40: 130530 | P40: 125729 | Q40: 123360 | R40: 119806 | S40: 119195 | T40: 120748 | U40: 119726 | V40: 115790.03 | W40: 113685.48 | X40: 117682.3
A41: Llama | B41: Produción carne (t) | C41: 3194 | D41: 3232 | E41: 3242 | F41: 3496 | G41: 3699 | H41: 3863 | I41: 3839 | J41: 4053 | K41: 3971 | L41: 4175 | M41: 4075 | N41: 4235 | O41: 4350 | P41: 4179 | Q41: 4170 | R41: 3980 | S41: 3977 | T41: 4009 | U41: 4003 | V41: 3847.5921 | W41: 3818.352 | X41: 3940.039
B42: Rendimiento (kg/Unidad) | C42: =(C41/C40)*1000 -> 34.758951 | D42: =(D41/D40)*1000 -> 33.964921 | E42: =(E41/E40)*1000 -> 33.289181 | F42: =(F41/F40)*1000 -> 34.333078 | G42: =(G41/G40)*1000 -> 33.833349 | H42: =(H41/H40)*1000 -> 34.458459 | I42: =(I41/I40)*1000 -> 33.734326 | J42: =(J41/J40)*1000 -> 34.231708 | ... X42: =(X41/X40)*1000 -> 33.480303
B43: Precio (S/ / kg) | C43: 1.93 | D43: 2.18 | E43: 2.39 | F43: 2.4 | G43: 2.45 | H43: 2.49 | I43: 2.39 | J43: 2.31 | K43: 2.7 | L43: 2.88 | M43: 3.02 | N43: 3.4 | O43: 3.61 | P43: 3.87 | Q43: 4.25 | R43: 4.09 | S43: 4.32 | T43: 4.25 | U43: 4.28 | V43: 4.27 | W43: 4.13 | X43: 4.13
...

Sheet C -6
A2: C.6 PERÚ: POBLACIÓN, SACA, PRODUCCIÓN, RENDIMIENTO Y PRECIOS RECIBIDOS POR EL PRODUCTOR POR MES, SEGÚN PRINCIPALES ESPECIES Y PRODUCTOS PECUARIOS, 2021P
A4: Especie/ Producto | B4: Variable | C4: Anual | D4: Ene | E4: Feb | F4: Mar | G4: Abr | H4: May | I4: Jun | J4: Jul | K4: Ago | L4: Set | M4: Oct | N4: Nov | O4: Dic
A5: Ave | B5: Población (Unidades) | C5: 1.8937475e+08
B6: Saca (Unidades) | C6: =SUM(D6:O6) -> 7.7625019e+08 | D6: 61484735 | E6: 57901618 | F6: 62726891 | G6: 62985014 | H6: 63709187 | I6: 64890138 | J6: 67731820 | K6: 66769554 | L6: 65892065 | M6: 68096992 | N6: 64843619 | O6: 69218562
B7: Producción carne (t) | C7: =SUM(D7:O7) -> 1751607.8 | D7: 142130.31 | E7: 126558.53 | F7: 142649.8 | G7: 145935.12 | H7: 147356.03 | I7: 147397.16 | J7: 153808.68 | K7: 149327.29 | L7: 148195.59 | M7: 150730.59 | N7: 144655.84 | O7: 152862.87
B8: Rendimiento (kg/Unidad) | C8: =(C7/C6)*1000 -> 2.256499 | D8: =D7/D6*1000 -> 2.3116358 | E8: =E7/E6*1000 -> 2.1857512 | F8: =F7/F6*1000 -> 2.2741411 | G8: =G7/G6*1000 -> 2.3169816 | H8: =H7/H6*1000 -> 2.3129479 | I8: =I7/I6*1000 -> 2.2714878 | J8: =J7/J6*1000 -> 2.2708481 | K8: =K7/K6*1000 -> 2.2364579 | ... O8: =O7/O6*1000 -> 2.2084086
B9: Precio (S/ / kg) 1 | C9: 5.8541695 | D9: 5.6625318 | E9: 5.2017569 | F9: 5.5079456 | G9: 5.2118614 | H9: 5.6580874 | I9: 5.8551402 | J9: 6.0642205 | K9: 6.1368041 | L9: 6.1539554 | M9: 6.1815113 | N9: 6.2311012 | O9: 6.2393204
A10: Ovino | B10: Población (Unidades) | C10: 10942309
B11: Saca (Unidades) | C11: =SUM(D11:O11) -> 2576571.6 | D11: 185408 | E11: 193956.76 | F11: 204600.29 | G11: 228104.1 | H11: 238346.2 | I11: 242261.97 | J11: 234251 | K11: 228190 | L11: 214400 | M11: 201518 | N11: 201845.3 | O11: 203690
B12: Producción carne (t) | C12: =SUM(D12:O12) -> 33259.223 | D12: 2366.6121 | E12: 2498.3525 | F12: 2657.3563 | G12: 2976.8923 | H12: 3130.3179 | I12: 3176.6751 | J12: 3050.8546 | K12: 2954.5303 | L12: 2740.096 | M12: 2560.0555 | N12: 2552.0449 | O12: 2595.4357
B13: Rendimiento (kg/Unidad) | C13: =(C12/C11)*1000 -> 12.908325 | D13: =D12/D11*1000 -> 12.764347 | E13: =E12/E11*1000 -> 12.880977 | F13: =F12/F11*1000 -> 12.988038 | G13: =G12/G11*1000 -> 13.050587 | H13: =H12/H11*1000 -> 13.133492 | I13: =I12/I11*1000 -> 13.112562 | J13: =J12/J11*1000 -> 13.02387 | K13: =K12/K11*1000 -> 12.947677 | ... O13: =O12/O11*1000 -> 12.742087
B14: Precio (S/ / kg) 1 | C14: 5.5840669 | D14: 5.5592817 | E14: 5.559167 | F14: 5.5806845 | G14: 5.5932817 | H14: 5.5830191 | I14: 5.5998275 | J14: 5.5863963 | K14: 5.602627 | L14: 5.5958725 | M14: 5.5869831 | N14: 5.5742318 | O14: 5.5759681
A15: Porcino | B15: Población (Unidades) | C15: 3342910.5
B16: Saca (Unidades) | C16: =SUM(D16:O16) -> 3314890.6 | D16: 264828.9 | E16: 257701.03 | F16: 261597.52 | G16: 269460.99 | H16: 268029.6 | I16: 274886.66 | J16: 288221.96 | K16: 286632.94 | L16: 275380.91 | M16: 282198.82 | N16: 270567.22 | O16: 315384
B17: Producción carne (t) | C17: =SUM(D17:O17) -> 176149.67 | D17: 14231.74 | E17: 13717.629 | F17: 13764.216 | G17: 14109.704 | H17: 14027.758 | I17: 14440.992 | J17: 15376.978 | K17: 15432.036 | L17: 14686.729 | M17: 15005.231 | N17: 14325.795 | O17: 17030.865
B18: Rendimiento (kg/Unidad) | C18: =(C17/C16)*1000 -> 53.138911 | D18: =D17/D16*1000 -> 53.739377 | E18: =E17/E16*1000 -> 53.230788 | F18: =F17/F16*1000 -> 52.616003 | G18: =G17/G16*1000 -> 52.362698 | H18: =H17/H16*1000 -> 52.336599 | I18: =I17/I16*1000 -> 52.534352 | J18: =J17/J16*1000 -> 53.351167 | K18: =K17/K16*1000 -> 53.839018 | ... O18: =O17/O16*1000 -> 54.00041
B19: Precio (S/ / kg) 1 | C19: 6.9547942 | D19: 6.911476 | E19: 6.9091938 | F19: 6.9246884 | G19: 6.9275362 | H19: 6.9047069 | I19: 6.8998366 | J19: 6.9408416 | K19: 6.9603049 | L19: 6.9822814 | M19: 7.0017687 | N19: 7.0137932 | O19: 7.0553768
A20: Vacuno | B20: Población (Unidades) | C20: 5853660
B21: Saca (Unidades) | C21: =SUM(D21:O21) -> 1303069.6 | D21: 100417.78 | E21: 103791.19 | F21: 103950 | G21: 112031.75 | H21: 115937.46 | I21: 115795.46 | J21: 116368 | K21: 111585 | L21: 109506 | M21: 102818 | N21: 104012 | O21: 106857
B22: Producción carne (t) | C22: =SUM(D22:O22) -> 189922.92 | D22: 14550.805 | E22: 15115.469 | F22: 15145.482 | G22: 16388.811 | H22: 16960.281 | I22: 16877.95 | J22: 17066.791 | K22: 16307.557 | L22: 15768.891 | M22: 14986.558 | N22: 15158.487 | O22: 15595.834
B23: Rendimiento (kg/Unidad) | C23: =(C22/C21)*1000 -> 145.7504 | D23: =D22/D21*1000 -> 144.90268 | E23: =E22/E21*1000 -> 145.63345 | F23: =F22/F21*1000 -> 145.69968 | G23: =G22/G21*1000 -> 146.28721 | H23: =H22/H21*1000 -> 146.28818 | I23: =I22/I21*1000 -> 145.75658 | J23: =J22/J21*1000 -> 146.66224 | K23: =K22/K21*1000 -> 146.14471 | ... O23: =O22/O21*1000 -> 145.95052
B24: Precio (S/ / kg) 1 | C24: 5.8129741 | D24: 5.7802722 | E24: 5.7992644 | F24: 5.7951412 | G24: 5.7861198 | H24: 5.7768489 | I24: 5.7897873 | J24: 5.8111518 | K24: 5.8239397 | L24: 5.8327338 | M24: 5.849389 | N24: 5.8530574 | O24: 5.863286
A25: Caprino | B25: Población (Unidades) | C25: 1754968.1
B26: Saca (Unidades) | C26: =SUM(D26:O26) -> 390291.64 | D26: 29916.338 | E26: 30404.487 | F26: 31436.04 | G26: 32338.853 | H26: 33991.066 | I26: 35244.106 | J26: 35764.393 | K26: 34711.98 | L26: 31985.088 | M26: 30476.436 | N26: 30894.849 | O26: 33128
B27: Producción carne (t) | C27: =SUM(D27:O27) -> 4948.0032 | D27: 383.41776 | E27: 388.6357 | F27: 408.22744 | G27: 416.23068 | H27: 442.23191 | I27: 458.97431 | J27: 451.08731 | K27: 434.6116 | L27: 396.00514 | M27: 376.86019 | N27: 381.7875 | O27: 409.93365
B28: Rendimiento (kg/Unidad) | C28: =(C27/C26)*1000 -> 12.677707 | D28: =D27/D26*1000 -> 12.816333 | E28: =E27/E26*1000 -> 12.782182 | F28: =F27/F26*1000 -> 12.985969 | G28: =G27/G26*1000 -> 12.870916 | H28: =H27/H26*1000 -> 13.010239 | I28: =I27/I26*1000 -> 13.022725 | J28: =J27/J26*1000 -> 12.612749 | K28: =K27/K26*1000 -> 12.520508 | ... O28: =O27/O26*1000 -> 12.374235
B29: Precio (S/ / kg) 1 | C29: 4.786704 | D29: 4.7866382 | E29: 4.7870509 | F29: 4.760636 | G29: 4.7636286 | H29: 4.7453883 | I29: 4.7746606 | J29: 4.7842232 | K29: 4.7969968 | L29: 4.8161801 | M29: 4.8121902 | N29: 4.8050227 | O29: 4.8167333
A30: Alpaca | B30: Población (Unidades) | C30: 4484888
B31: Saca (Unidades) | C31: =SUM(D31:O31) -> 469624.4 | D31: 31909 | E31: 37109 | F31: 39691 | G31: 47138.4 | H31: 46675 | I31: 46584 | J31: 45093 | K31: 41561 | L31: 36489 | M31: 34135 | N31: 33249 | O31: 29991
B32: Producción carne (t) | C32: =SUM(D32:O32) -> 12581.237 | D32: 840.1604 | E32: 993.12301 | F32: 1069.9518 | G32: 1281.0791 | H32: 1273.6916 | I32: 1269.0322 | J32: 1217.7832 | K32: 1116.671 | L32: 970.7628 | M32: 901.66808 | N32: 866.0732 | O32: 781.2409
B33: Rendimiento (kg/Unidad) | C33: =(C32/C31)*1000 -> 26.789999 | D33: =D32/D31*1000 -> 26.329888 | E33: =E32/E31*1000 -> 26.762322 | F33: =F32/F31*1000 -> 26.957038 | G33: =G32/G31*1000 -> 27.176975 | H33: =H32/H31*1000 -> 27.288518 | I33: =I32/I31*1000 -> 27.241804 | J33: =J32/J31*1000 -> 27.006035 | K33: =K32/K31*1000 -> 26.868242 | ... O33: =O32/O31*1000 -> 26.049178
B34: Precio (S/ / kg) 1 | C34: 4.8818983 | D34: 4.8785259 | E34: 4.9288758 | F34: 4.9329262 | G34: 4.9882818 | H34: 4.9278986 | I34: 4.9228209 | J34: 4.9002567 | K34: 4.8652448 | L34: 4.8290924 | M34: 4.8075086 | N34: 4.7798817 | O34: 4.6997568
O35: sigue…
A36: continúa C.6
A37: Especie/ Producto | B37: Variable | C37: Anual | D37: Ene | E37: Feb | F37: Mar | G37: Abr | H37: May | I37: Jun | J37: Jul | K37: Ago | L37: Set | M37: Oct | N37: Nov | O37: Dic
A38: Llama | B38: Población (Unidades) | C38: 1075425
B39: Saca (Unidades) | C39: =SUM(D39:O39) -> 117682.3 | D39: 8476 | E39: 9312 | F39: 9568 | G39: 10873.6 | H39: 10832.7 | I39: 11434 | J39: 10821 | K39: 10145 | L39: 9620 | M39: 8730 | N39: 8684 | O39: 9186
B40: Producción carne (t) | C40: =SUM(D40:O40) -> 3940.039 | D40: 281.25364 | E40: 312.73076 | F40: 323.73958 | G40: 375.36016 | H40: 370.75405 | I40: 388.67278 | J40: 361.71082 | K40: 334.5073 | L40: 315.1218 | M40: 287.9964 | N40: 284.12048 | O40: 304.07126
B41: Rendimiento (kg/Unidad) | C41: =(C40/C39)*1000 -> 33.480303 | D41: =D40/D39*1000 -> 33.182355 | E41: =E40/E39*1000 -> 33.583629 | F41: =F40/F39*1000 -> 33.835659 | G41: =G40/G39*1000 -> 34.520321 | H41: =H40/H39*1000 -> 34.225452 | I41: =I40/I39*1000 -> 33.992722 | J41: =J40/J39*1000 -> 33.426746 | K41: =K40/K39*1000 -> 32.972627 | ... O41: =O40/O39*1000 -> 33.101596
B42: Precio (S/ / kg) 1 | C42: 3.9672457 | D42: 4.0222022 | E42: 4.0269202 | F42: 4.0185405 | G42: 4.0624039 | H42: 4.0249369 | I42: 4.0046348 | J42: 3.9691419 | K42: 3.9419222 | L42: 3.9174154 | M42: 3.8786712 | N42: 3.8422249 | O42: 3.8427781
...

Sheet C 7
A2: C.7 PERÚ: PRODUCCIÓN PECUARIA POR ESPECIE, SEGÚN REGIÓN, 2021P
A3: (Unidades)
A5: Región | B5: Ave | C5: Ovino | D5: Porcino | E5: Vacuno | F5: Caprino | G5: Alpaca | H5: Llama
A6: Nacional | B6: =(B8+B9+B10+B11+B12+B16+B17+B18+B19+B20+B21+B22+B23+B24+B25+B26+B27+B28+B31+B32+B33+B34+B35+B36) -> 7.7625019e+08 | C6: =(C8+C9+C10+C11+C12+C16+C17+C18+C19+C20+C21+C22+C23+C24+C25+C26+C27+C28+C31+C32+C33+C34+C35+C36) -> 2576571.6 | D6: =(D8+D9+D10+D11+D12+D16+D17+D18+D19+D20+D21+D22+D23+D24+D25+D26+D27+D28+D31+D32+D33+D34+D35+D36) -> 3314890.6 | E6: =(E8+E9+E10+E11+E12+E16+E17+E18+E19+E20+E21+E22+E23+E24+E25+E26+E27+E28+E31+E32+E33+E34+E35+E36) -> 1303069.6 | F6: =(F8+F9+F10+F11+F12+F16+F17+F18+F19+F20+F21+F22+F23+F24+F25+F26+F27+F28+F31+F32+F33+F34+F35+F36) -> 390291.64 | G6: =(G8+G9+G10+G11+G12+G16+G17+G18+G19+G20+G21+G22+G23+G24+G25+G26+G27+G28+G31+G32+G33+G34+G35+G36) -> 469624.4 | H6: =(H8+H9+H10+H11+H12+H16+H17+H18+H19+H20+H21+H22+H23+H24+H25+H26+H27+H28+H31+H32+H33+H34+H35+H36) -> 117682.3
A8: Tumbes | B8: 97536.997 | C8: 2324 | D8: 6016 | E8: 3668 | F8: 18005 | G8: 0 | H8: 0
A9: Piura | B9: 14581622 | C9: 110536.07 | D9: 116132.97 | E9: 47401.125 | F9: 91624.251 | G9: 0 | H9: 0
A10: Lambayeque | B10: 11658328 | C10: 27955.248 | D10: 29327.577 | E10: 20429.627 | F10: 20843.36 | G10: 0 | H10: 0
A11: La Libertad | B11: 1.3765274e+08 | C11: 196709 | D11: 337947 | E11: 60986 | F11: 37305 | G11: 1412 | H11: 0
A12: Cajamarca | B12: 1734004.9 | C12: 83113.3 | D12: 138143.4 | E12: 184568.4 | F12: 23407 | G12: 0 | H12: 0
A13: Cajamarca | B13: 1096600.8 | C13: 57613 | D13: 53143 | E13: 102436 | F13: 13749 | G13: 0 | H13: 0
A14: Chota | B14: 306012.89 | C14: 21248.2 | D14: 47236 | E14: 51850 | F14: 1318 | G14: 0 | H14: 0
A15: Jaén | B15: 331391.23 | C15: 4252.1 | D15: 37764.4 | E15: 30282.4 | F15: 8340 | G15: 0 | H15: 0
A16: Amazonas | B16: 380125.98 | C16: 3190 | D16: 28738 | E16: 50960 | F16: 4290 | G16: 0 | H16: 0
A17: Ancash | B17: 16434268 | C17: 131663 | D17: 60397 | E17: 62644 | F17: 20114 | G17: 433 | H17: 0
A18: Lima | B18: 4.1553995e+08 | C18: 57729 | D18: 1182774 | E18: 109767 | F18: 35830 | G18: 3031 | H18: 2126
A19: Ica | B19: 43909224 | C19: 13489 | D19: 246350 | E19: 20410 | F19: 23824.424 | G19: 0 | H19: 0
... A36: Madre de Dios | B36: 4303100 | C36: 1676 | D36: 19078 | E36: 13775 | F36: 0 | G36: 0 | H36: 0
A37: P Preliminar
A38: Fuente: Direcciones Regionales de Agricultura
A39: Elaboración: Ministerio de Desarrollo Agrario y Riego - DGESEP - DEIA

Sheet C 8
A2: C.8 PERÚ: PRODUCCIÓN DE CARNES POR ESPECIE, SEGÚN REGIÓN, 2021P
A3: (Toneladas)
A5: Región | B5: Ave | C5: Ovino | D5: Porcino | E5: Vacuno | F5: Caprino | G5: Alpaca | H5: Llama
A6: Nacional | B6: =(B8+B9+B10+B11+B12+B16+B17+B18+B19+B20+B21+B22+B23+B24+B25+B26+B27+B28+B31+B32+B33+B34+B35+B36) -> 1751607.8 | C6: =(C8+C9+C10+C11+C12+C16+C17+C18+C19+C20+C21+C22+C23+C24+C25+C26+C27+C28+C31+C32+C33+C34+C35+C36) -> 33259.223 | D6: =(D8+D9+D10+D11+D12+D16+D17+D18+D19+D20+D21+D22+D23+D24+D25+D26+D27+D28+D31+D32+D33+D34+D35+D36) -> 176149.67 | E6: =(E8+E9+E10+E11+E12+E16+E17+E18+E19+E20+E21+E22+E23+E24+E25+E26+E27+E28+E31+E32+E33+E34+E35+E36) -> 189922.92 | F6: =(F8+F9+F10+F11+F12+F16+F17+F18+F19+F20+F21+F22+F23+F24+F25+F26+F27+F28+F31+F32+F33+F34+F35+F36) -> 4947.7848 | G6: =(G8+G9+G10+G11+G12+G16+G17+G18+G19+G20+G21+G22+G23+G24+G25+G26+G27+G28+G31+G32+G33+G34+G35+G36) -> 12581.237 | H6: =(H8+H9+H10+H11+H12+H16+H17+H18+H19+H20+H21+H22+H23+H24+H25+H26+H27+H28+H31+H32+H33+H34+H35+H36) -> 3940.039
A8: Tumbes | B8: 245.57838 | C8: 28.366681 | D8: 306.00197 | E8: 555.17007 | F8: 188.9932 | G8: 0 | H8: 0
A9: Piura | B9: 32474.21 | C9: 1767.7067 | D9: 6077.5738 | E9: 7283.2216 | F9: 1330.3794 | G9: 0 | H9: 0
A10: Lambayeque | B10: 26085.997 | C10: 448.49784 | D10: 1522.9778 | E10: 3002.8518 | F10: 312.3998 | G10: 0 | H10: 0
A11: La Libertad | B11: 311654.48 | C11: 2608.0328 | D11: 19651.835 | E11: 8647.0824 | F11: 472.11923 | G11: 43.977823 | H11: 0
A12: Cajamarca | B12: 3688.5931 | C12: 953.61878 | D12: 5799.7488 | E12: 24252.658 | F12: 248.71133 | G12: 0 | H12: 0
A13: Cajamarca | B13: 2382.3105 | C13: 648.81109 | D13: 1987.0559 | E13: 12457.474 | F13: 139.3636 | G13: 0 | H13: 0
A14: Chota | B14: 628.64295 | C14: 258.59021 | D14: 1983.1561 | E14: 7109.6929 | F14: 16.67229 | G14: 0 | H14: 0
A15: Jaén | B15: 677.63968 | C15: 46.217476 | D15: 1829.5369 | E15: 4685.4916 | F15: 92.675441 | G15: 0 | H15: 0
A16: Amazonas | B16: 806.67446 | C16: 50.7064 | D16: 1513.2698 | E16: 7369.1027 | F16: 54.0548 | G16: 0 | H16: 0
A17: Ancash | B17: 37543.044 | C17: 1421.5318 | D17: 1799.3087 | E17: 8650.8109 | F17: 205.29895 | G17: 12.328675 | H17: 0
A18: Lima | B18: 941312.95 | C18: 707.65369 | D18: 75883.194 | E18: 21186.779 | F18: 472.98122 | G18: 88.68902 | H18: 63.390755
A19: Ica | B19: 97956.899 | C19: 138.28906 | D19: 12576.483 | E19: 2694.5477 | F19: 294.05111 | G19: 0 | H19: 0
... A36: Madre de Dios | B36: 9490.9265 | C36: 28.891 | D36: 1240.1157 | E36: 2221.7814 | F36: 0 | G36: 0 | H36: 0
A37: P Preliminar
A38: Fuente: Direcciones Regionales de Agricultura
A39: Elaboración: Ministerio de Desarrollo Agrario y Riego - DGESEP - DEIA

Sheet C 9
A2: C.9 PERÚ: RENDIMIENTO DE CARNES POR ESPECIE, SEGÚN REGIÓN, 2021P
A3: (Kg/Unidad )
A5: Región | B5: Ave | C5: Ovino | D5: Porcino | E5: Vacuno | F5: Caprino | G5: Alpaca | H5: Llama
A6: Nacional | B6: =('C 8'!B6/'C 7'!B6)*1000 -> 2.256499 | C6: =('C 8'!C6/'C 7'!C6)*1000 -> 12.908325 | D6: =('C 8'!D6/'C 7'!D6)*1000 -> 53.138911 | E6: =('C 8'!E6/'C 7'!E6)*1000 -> 145.7504 | F6: =('C 8'!F6/'C 7'!F6)*1000 -> 12.677148 | G6: =('C 8'!G6/'C 7'!G6)*1000 -> 26.789999 | H6: =('C 8'!H6/'C 7'!H6)*1000 -> 33.480303
A8: Tumbes | B8: ='C 8'!B8/'C 7'!B8*1000 -> 2.5177972 | C8: ='C 8'!C8/'C 7'!C8*1000 -> 12.205973 | D8: ='C 8'!D8/'C 7'!D8*1000 -> 50.864689 | E8: ='C 8'!E8/'C 7'!E8*1000 -> 151.35498 | F8: ='C 8'!F8/'C 7'!F8*1000 -> 10.496706 | G8: 0 | H8: 0 | I8: -
A9: Piura | B9: ='C 8'!B9/'C 7'!B9*1000 -> 2.2270643 | C9: ='C 8'!C9/'C 7'!C9*1000 -> 15.992124 | D9: ='C 8'!D9/'C 7'!D9*1000 -> 52.332891 | E9: ='C 8'!E9/'C 7'!E9*1000 -> 153.65082 | F9: ='C 8'!F9/'C 7'!F9*1000 -> 14.519948 | G9: 0 | H9: 0
A10: Lambayeque | B10: ='C 8'!B10/'C 7'!B10*1000 -> 2.237542 | C10: ='C 8'!C10/'C 7'!C10*1000 -> 16.043422 | D10: ='C 8'!D10/'C 7'!D10*1000 -> 51.929887 | E10: ='C 8'!E10/'C 7'!E10*1000 -> 146.98515 | F10: ='C 8'!F10/'C 7'!F10*1000 -> 14.987977 | G10: 0 | H10: 0
A11: La Libertad | B11: ='C 8'!B11/'C 7'!B11*1000 -> 2.2640631 | C11: ='C 8'!C11/'C 7'!C11*1000 -> 13.25833 | D11: ='C 8'!D11/'C 7'!D11*1000 -> 58.150642 | E11: ='C 8'!E11/'C 7'!E11*1000 -> 141.78799 | F11: ='C 8'!F11/'C 7'!F11*1000 -> 12.655656 | G11: ='C 8'!G11/'C 7'!G11*1000 -> 31.145767 | H11: 0
A12: Cajamarca | B12: ='C 8'!B12/'C 7'!B12*1000 -> 2.1272103 | C12: ='C 8'!C12/'C 7'!C12*1000 -> 11.473721 | D12: ='C 8'!D12/'C 7'!D12*1000 -> 41.983539 | E12: ='C 8'!E12/'C 7'!E12*1000 -> 131.40201 | F12: ='C 8'!F12/'C 7'!F12*1000 -> 10.625511 | G12: 0 | H12: 0
A13: Cajamarca | B13: ='C 8'!B13/'C 7'!B13*1000 -> 2.17245 | C13: ='C 8'!C13/'C 7'!C13*1000 -> 11.26154 | D13: ='C 8'!D13/'C 7'!D13*1000 -> 37.390735 | E13: ='C 8'!E13/'C 7'!E13*1000 -> 121.61226 | F13: ='C 8'!F13/'C 7'!F13*1000 -> 10.136272 | G13: 0 | H13: 0
A14: Chota | B14: ='C 8'!B14/'C 7'!B14*1000 -> 2.0543022 | C14: ='C 8'!C14/'C 7'!C14*1000 -> 12.169982 | D14: ='C 8'!D14/'C 7'!D14*1000 -> 41.983996 | E14: ='C 8'!E14/'C 7'!E14*1000 -> 137.1204 | F14: ='C 8'!F14/'C 7'!F14*1000 -> 12.649689 | G14: 0 | H14: 0
A15: Jaén | B15: ='C 8'!B15/'C 7'!B15*1000 -> 2.0448329 | C15: ='C 8'!C15/'C 7'!C15*1000 -> 10.86933 | D15: ='C 8'!D15/'C 7'!D15*1000 -> 48.446073 | E15: ='C 8'!E15/'C 7'!E15*1000 -> 154.72656 | F15: ='C 8'!F15/'C 7'!F15*1000 -> 11.112163 | G15: 0 | H15: 0
A16: Amazonas | B16: ='C 8'!B16/'C 7'!B16*1000 -> 2.122124 | C16: ='C 8'!C16/'C 7'!C16*1000 -> 15.895423 | D16: ='C 8'!D16/'C 7'!D16*1000 -> 52.657448 | E16: ='C 8'!E16/'C 7'!E16*1000 -> 144.60563 | F16: ='C 8'!F16/'C 7'!F16*1000 -> 12.600186 | G16: 0 | H16: 0
A17: Ancash | B17: ='C 8'!B17/'C 7'!B17*1000 -> 2.2844366 | C17: ='C 8'!C17/'C 7'!C17*1000 -> 10.796745 | D17: ='C 8'!D17/'C 7'!D17*1000 -> 29.791359 | E17: ='C 8'!E17/'C 7'!E17*1000 -> 138.0948 | F17: ='C 8'!F17/'C 7'!F17*1000 -> 10.206769 | G17: ='C 8'!G17/'C 7'!G17*1000 -> 28.47269 | H17: 0
A18: Lima | B18: ='C 8'!B18/'C 7'!B18*1000 -> 2.2652766 | C18: ='C 8'!C18/'C 7'!C18*1000 -> 12.258201 | D18: ='C 8'!D18/'C 7'!D18*1000 -> 64.156968 | E18: ='C 8'!E18/'C 7'!E18*1000 -> 193.01593 | F18: ='C 8'!F18/'C 7'!F18*1000 -> 13.200704 | G18: ='C 8'!G18/'C 7'!G18*1000 -> 29.260647 | H18: ='C 8'!H18/'C 7'!H18*1000 -> 29.816912
A19: Ica | B19: ='C 8'!B19/'C 7'!B19*1000 -> 2.2308957 | C19: ='C 8'!C19/'C 7'!C19*1000 -> 10.251988 | D19: ='C 8'!D19/'C 7'!D19*1000 -> 51.051282 | E19: ='C 8'!E19/'C 7'!E19*1000 -> 132.02096 | F19: ='C 8'!F19/'C 7'!F19*1000 -> 12.342422 | G19: 0 | H19: 0
A20: Huánuco | B20: ='C 8'!B20/'C 7'!B20*1000 -> 2.1179577 | C20: ='C 8'!C20/'C 7'!C20*1000 -> 11.404804 | D20: ='C 8'!D20/'C 7'!D20*1000 -> 38.355228 | E20: ='C 8'!E20/'C 7'!E20*1000 -> 166.70148 | F20: ='C 8'!F20/'C 7'!F20*1000 -> 10.31916 | G20: ='C 8'!G20/'C 7'!G20*1000 -> 26.00032 | H20: 0
A21: Pasco | B21: ='C 8'!B21/'C 7'!B21*1000 -> 2.1632854 | C21: ='C 8'!C21/'C 7'!C21*1000 -> 12.330895 | D21: ='C 8'!D21/'C 7'!D21*1000 -> 36.305282 | E21: ='C 8'!E21/'C 7'!E21*1000 -> 159.67853 | F21: ='C 8'!F21/'C 7'!F21*1000 -> 11.445038 | G21: ='C 8'!G21/'C 7'!G21*1000 -> 22.97866 | H21: ='C 8'!H21/'C 7'!H21*1000 -> 28.889331
A22: Junín | B22: ='C 8'!B22/'C 7'!B22*1000 -> 2.2293591 | C22: ='C 8'!C22/'C 7'!C22*1000 -> 11.104166 | D22: ='C 8'!D22/'C 7'!D22*1000 -> 44.824076 | E22: ='C 8'!E22/'C 7'!E22*1000 -> 130.3358 | F22: ='C 8'!F22/'C 7'!F22*1000 -> 10.239828 | G22: ='C 8'!G22/'C 7'!G22*1000 -> 22.539488 | H22: ='C 8'!H22/'C 7'!H22*1000 -> 27.708504
A23: Huancavelica | B23: ='C 8'!B23/'C 7'!B23*1000 -> 2.0806777 | C23: ='C 8'!C23/'C 7'!C23*1000 -> 13.254359 | D23: ='C 8'!D23/'C 7'!D23*1000 -> 37.591142 | E23: ='C 8'!E23/'C 7'!E23*1000 -> 115.18558 | F23: ='C 8'!F23/'C 7'!F23*1000 -> 12.908444 | G23: ='C 8'!G23/'C 7'!G23*1000 -> 25.886984 | H23: ='C 8'!H23/'C 7'!H23*1000 -> 31.417847
A24: Arequipa | B24: ='C 8'!B24/'C 7'!B24*1000 -> 2.2503126 | C24: ='C 8'!C24/'C 7'!C24*1000 -> 14.518312 | D24: ='C 8'!D24/'C 7'!D24*1000 -> 56.046504 | E24: ='C 8'!E24/'C 7'!E24*1000 -> 164.22557 | F24: ='C 8'!F24/'C 7'!F24*1000 -> 11.813424 | G24: ='C 8'!G24/'C 7'!G24*1000 -> 24.519552 | H24: ='C 8'!H24/'C 7'!H24*1000 -> 34.505582
A25: Moquegua | B25: ='C 8'!B25/'C 7'!B25*1000 -> 2.1204949 | C25: ='C 8'!C25/'C 7'!C25*1000 -> 21.18493 | D25: ='C 8'!D25/'C 7'!D25*1000 -> 47.522149 | E25: ='C 8'!E25/'C 7'!E25*1000 -> 201.045 | F25: ='C 8'!F25/'C 7'!F25*1000 -> 16.889405 | G25: ='C 8'!G25/'C 7'!G25*1000 -> 29.647143 | H25: ='C 8'!H25/'C 7'!H25*1000 -> 36.255016
A26: Tacna | B26: ='C 8'!B26/'C 7'!B26*1000 -> 2.2491213 | C26: ='C 8'!C26/'C 7'!C26*1000 -> 23.301537 | D26: ='C 8'!D26/'C 7'!D26*1000 -> 40.530005 | E26: ='C 8'!E26/'C 7'!E26*1000 -> 190.40328 | F26: ='C 8'!F26/'C 7'!F26*1000 -> 14.577684 | G26: ='C 8'!G26/'C 7'!G26*1000 -> 28.747211 | H26: ='C 8'!H26/'C 7'!H26*1000 -> 29.332199
A27: Ayacucho | B27: ='C 8'!B27/'C 7'!B27*1000 -> 2.0952724 | C27: ='C 8'!C27/'C 7'!C27*1000 -> 11.848303 | D27: ='C 8'!D27/'C 7'!D27*1000 -> 44.626769 | E27: ='C 8'!E27/'C 7'!E27*1000 -> 127.6151 | F27: ='C 8'!F27/'C 7'!F27*1000 -> 12.302555 | G27: ='C 8'!G27/'C 7'!G27*1000 -> 26.280105 | H27: ='C 8'!H27/'C 7'!H27*1000 -> 30.664547
A28: Apurímac | B28: ='C 8'!B28/'C 7'!B28*1000 -> 2.0302852 | C28: ='C 8'!C28/'C 7'!C28*1000 -> 11.124741 | D28: ='C 8'!D28/'C 7'!D28*1000 -> 40.479921 | E28: ='C 8'!E28/'C 7'!E28*1000 -> 111.69813 | F28: ='C 8'!F28/'C 7'!F28*1000 -> 11.202378 | G28: ='C 8'!G28/'C 7'!G28*1000 -> 25.618709 | H28: ='C 8'!H28/'C 7'!H28*1000 -> 27.794131
A29: Abancay | B29: ='C 8'!B29/'C 7'!B29*1000 -> 2.0187196 | C29: ='C 8'!C29/'C 7'!C29*1000 -> 11.57976 | D29: ='C 8'!D29/'C 7'!D29*1000 -> 37.571721 | E29: ='C 8'!E29/'C 7'!E29*1000 -> 115.44694 | F29: ='C 8'!F29/'C 7'!F29*1000 -> 11.802264 | G29: ='C 8'!G29/'C 7'!G29*1000 -> 25.647395 | H29: ='C 8'!H29/'C 7'!H29*1000 -> 27.698774
A30: Andahuaylas | B30: ='C 8'!B30/'C 7'!B30*1000 -> 2.0487662 | C30: ='C 8'!C30/'C 7'!C30*1000 -> 10.638855 | D30: ='C 8'!D30/'C 7'!D30*1000 -> 42.192127 | E30: ='C 8'!E30/'C 7'!E30*1000 -> 107.97321 | F30: ='C 8'!F30/'C 7'!F30*1000 -> 10.942294 | G30: ='C 8'!G30/'C 7'!G30*1000 -> 25.556015 | H30: ='C 8'!H30/'C 7'!H30*1000 -> 27.894357
A31: Cusco | B31: ='C 8'!B31/'C 7'!B31*1000 -> 2.1555497 | C31: ='C 8'!C31/'C 7'!C31*1000 -> 13.11334 | D31: ='C 8'!D31/'C 7'!D31*1000 -> 40.412116 | E31: ='C 8'!E31/'C 7'!E31*1000 -> 155.70929 | F31: ='C 8'!F31/'C 7'!F31*1000 -> 12.900935 | G31: ='C 8'!G31/'C 7'!G31*1000 -> 27.008306 | H31: ='C 8'!H31/'C 7'!H31*1000 -> 30.554367
A32: Puno | B32: ='C 8'!B32/'C 7'!B32*1000 -> 2.0631265 | C32: ='C 8'!C32/'C 7'!C32*1000 -> 13.95088 | D32: ='C 8'!D32/'C 7'!D32*1000 -> 33.858448 | E32: ='C 8'!E32/'C 7'!E32*1000 -> 143.90513 | F32: 0 | G32: ='C 8'!G32/'C 7'!G32*1000 -> 27.82096 | H32: ='C 8'!H32/'C 7'!H32*1000 -> 39.207485
A33: San Martín | B33: ='C 8'!B33/'C 7'!B33*1000 -> 2.2296872 | C33: ='C 8'!C33/'C 7'!C33*1000 -> 12.114001 | D33: ='C 8'!D33/'C 7'!D33*1000 -> 41.458379 | E33: ='C 8'!E33/'C 7'!E33*1000 -> 107.04509 | F33: 0 | G33: 0 | H33: 0
A34: Loreto | B34: ='C 8'!B34/'C 7'!B34*1000 -> 2.2205377 | C34: ='C 8'!C34/'C 7'!C34*1000 -> 13.630609 | D34: ='C 8'!D34/'C 7'!D34*1000 -> 44.748705 | E34: ='C 8'!E34/'C 7'!E34*1000 -> 143.4348 | F34: ='C 8'!F34/'C 7'!F34*1000 -> 3.5172414 | G34: 0 | H34: 0
A35: Ucayali | B35: ='C 8'!B35/'C 7'!B35*1000 -> 2.1807275 | C35: ='C 8'!C35/'C 7'!C35*1000 -> 11.711454 | D35: ='C 8'!D35/'C 7'!D35*1000 -> 44.938144 | E35: ='C 8'!E35/'C 7'!E35*1000 -> 127.53925 | F35: 0 | G35: 0 | H35: 0
A36: Madre de Dios | B36: ='C 8'!B36/'C 7'!B36*1000 -> 2.2056021 | C36: ='C 8'!C36/'C 7'!C36*1000 -> 17.238067 | D36: ='C 8'!D36/'C 7'!D36*1000 -> 65.002397 | E36: ='C 8'!E36/'C 7'!E36*1000 -> 161.29085 | F36: 0 | G36: 0 | H36: 0
A37: P Preliminar
A38: Fuente: Direcciones Regionales de Agricultura
A39: Elaboración: Ministerio de Desarrollo Agrario y Riego - DGESEP - DEIA

Sheet C 10
A2: C.10 PERÚ: ESPECIES PECUARIAS EN PRODUCCIÓN Y ANIMALES ESQUILADOS POR ESPECIE,
A3: SEGÚN REGIÓN, 2021P
A4: (Unidades)
A6: Región | B6: Gallinas en Postura | C6: Vacas en Ordeño | D6: Alpacas Esquiladas | E6: Llamas Esquiladas | F6: Ovinos Esquilados
A7: Nacional | B7: =(B9+B10+B11+B12+B13+B17++B18+B19+B20+B21+B22+B23+B24+B25+B26+B27+B28+B29+B32+B33+B34+B35+B36+B37) -> 28938922 | C7: =(C9+C10+C11+C12+C13+C17++C18+C19+C20+C21+C22+C23+C24+C25+C26+C27+C28+C29+C32+C33+C34+C35+C36+C37) -> 932744.59 | D7: =(D9+D10+D11+D12+D13+D17++D18+D19+D20+D21+D22+D23+D24+D25+D26+D27+D28+D29+D32+D33+D34+D35+D36+D37) -> 2119402.2 | E7: =(E9+E10+E11+E12+E13+E17++E18+E19+E20+E21+E22+E23+E24+E25+E26+E27+E28+E29+E32+E33+E34+E35+E36+E37) -> 338242.3 | F7: =(F9+F10+F11+F12+F13+F17++F18+F19+F20+F21+F22+F23+F24+F25+F26+F27+F28+F29+F32+F33+F34+F35+F36+F37) -> 4237001.4
A9: Tumbes | B9: 11313.173 | C9: 299.75 | D9: 0 | E9: 0 | F9: 0
A10: Piura | B10: 391496.06 | C10: 24341 | D10: 49 | E10: 0 | F10: 23982
A11: Lambayeque | B11: 453900.64 | C11: 18100.895 | D11: 0 | E11: 0 | F11: 0
A12: La Libertad | B12: 4766950.1 | C12: 52129.25 | D12: 6052 | E12: 0 | F12: 254269
A13: Cajamarca | B13: 411010.9 | C13: 169643.54 | D13: 0 | E13: 0 | F13: 159350.13
A14: Cajamarca | B14: 193186.78 | C14: 100286.58 | D14: 0 | E14: 0 | F14: 124989.13
A15: Chota | B15: 140540.88 | C15: 63450.375 | D15: 0 | E15: 0 | F15: 34361
A16: Jaén | B16: 77283.25 | C16: 5906.5833 | D16: 0 | E16: 0 | F16: 0
A17: Amazonas | B17: 129592.67 | C17: 80864.333 | D17: 0 | E17: 0 | F17: 6224
A18: Ancash | B18: 207400.15 | C18: 16461.5 | D18: 0 | E18: 0 | F18: 6488
A19: Lima | B19: 7647608.6 | C19: 74209.007 | D19: 19457.2 | E19: 1915 | F19: 115395.7
A20: Ica | B20: 10336666 | C20: 15390.083 | D20: 0 | E20: 0 | F20: 0
... A37: Madre de Dios | B37: 203149.22 | C37: 999.58333 | D37: 0 | E37: 0 | F37: 0
A38: P Preliminar
A39: Fuente: Direcciones Regionales de Agricultura
A40: Elaboración: Ministerio de Desarrollo Agrario y Riego - DGESEP - DEIA

Sheet C 11
A2: C.11 PERÚ: PRODUCCIÓN DE PRINCIPALES PRODUCTOS PECUARIOS SEGÚN REGIÓN, 2021P
A3: (Toneladas)
A5: Región | B5: Huevo de Gallina | C5: Leche Fresca de Vaca | D5: Fibra de Alpaca | E5: Fibra de Llama | F5: Lana de Ovino
