Workbook
Name \c: #REF!
Name \x: 'C 5'!#REF!
Name \x: #REF!
Name A: 'C 5'!$W$20:$DB$20
Name A: #REF!
Name A_IMPRESION_IM: 'C 91 - 99'!#REF!
Name A_IMPRESION_IM: #REF!
Name A_impresión_IM: 'C 100 - 101'!$A$1:$K$52
Name A_impresión_IM: 'C 102 - 103'!$A$1:$I$45
Name A_impresión_IM: 'C 104-105'!$A$1:$K$53
Name A_impresión_IM: 'C 106 - 107'!$A$1:$H$45
Name A_impresión_IM: 'C 108 - 109 '!#REF!
Name A_IMPRESIÓN_IM: [1]CYPPOLLO!#REF!
Name A_IMPRESIÓN_IM: [1]CYPPOLLO!#REF!
Name A_IMPRESIÓN_IM: [1]CYPPOLLO!#REF!
Name A_impresión_IM: #REF!
Name A_impresión_IM: 'C 90'!$A$1:$D$44
Name A_IMPRESIÓN_IM: 'C 91 - 99'!$A$3:$DH$40
Name A_IMPRESIÓN_IM: [1]CYPPOLLO!#REF!
Name A_impresión_IM: #REF!
Name A_impresión_IM: 'C-88'!$A$1:$D$44
Name A_impresión_IM: 'C-89'!$A$1:$D$44
Name A_impresión_IM: #REF!

Sheet 1. INDICADORES ECONÓMICOS

Sheet C 1 - C 2 - C 3
A2: C.1 PERÚ: EVOLUCIÓN DEL VALOR BRUTO DE LA PRODUCCIÓN (VBP) AGROPECUARIA POR AÑO, SEGÚN SUB SECTORES Y PRINCIPALES ESPECIES | AP2: Tasa
A3: Y PRODUCTOS PECUARIOS, 2007-20
A4: (Millones de soles a precios 2007) | AP4: Crec.
A6: Sector / Producto | C6: 2000 | D6: 2001 | E6: 2002 | F6: 2003 | G6: 2004 | H6: 2005 | I6: 2006 | J6: 2007 | K6: 2008 | L6: 2009 | M6: 2010 | N6: 2011 | O6: 2012 | P6: 2013 | Q6: 2014 | R6: 2015 | S6: 2016 | T6: 2017 | U6: 2018 | V6: 2019 | W6: 2020P | X6: Var. % 20/19
A7: Sector agropecuario | C7: 17474.3 | D7: 17601.8 | E7: 18603.6 | F7: 18969.3 | G7: 19096 | H7: 20511.9 | I7: 22151.7 | J7: 22808.2 | K7: 24741.8 | L7: 25379.1 | M7: 26407.4 | N7: 27861.2 | O7: 29538.1 | P7: 30131.9 | Q7: 30698.2 | R7: 31894 | S7: 32592.3 | T7: 33502.4 | U7: 36117.6 | V7: 37417.505 | W7: 37946.306 | X7: =((W7/V7)-1)*100 -> 1.4132447 | AP7: 3.9
A8: Subsector agrícola | C8: 11577.1 | D8: 11537.3 | E8: 12282.8 | F8: 12444.9 | G8: 12391.7 | H8: 13289.3 | I8: 14340.7 | J8: 14533.2 | K8: 15862.1 | L8: 15991.2 | M8: 16616 | N8: 17377.3 | O8: 18471.3 | P8: 18672.8 | Q8: 18833.5 | R8: 19407.9 | S8: 19601 | T8: 20149 | U8: 22019.3 | V8: 22754.466 | W8: 23543.403 | X8: =((W8/V8)-1)*100 -> 3.4671721 | AP8: 3.3
A9: Subsector pecuario | C9: 5897.2 | D9: 6064.5 | E9: 6320.8 | F9: 6524.4 | G9: 6704.3 | H9: 7222.6 | I9: 7811 | J9: 8275 | K9: 8879.7 | L9: 9387.9 | M9: 9791.4 | N9: 10483.9 | O9: 11066.7 | P9: 11459.1 | Q9: 11864.7 | R9: 12486.1 | S9: 12991.3 | T9: 13353.4 | U9: 14098.3 | V9: 14663.039 | W9: 14402.903 | X9: =((W9/V9)-1)*100 -> -1.7740907 | AP9: 4.9
B11: Industria avícola 1 | C11: =SUM(C12:C14) -> 2892.6 | D11: =SUM(D12:D14) -> 2958.5 | E11: =SUM(E12:E14) -> 3140.9 | F11: =SUM(F12:F14) -> 3262.9 | G11: =SUM(G12:G14) -> 3280.1 | H11: =SUM(H12:H14) -> 3623.2 | I11: =SUM(I12:I14) -> 4017.6 | J11: =J12+J14 -> 4330.6 | K11: =K12+K14 -> 4847.7 | L11: =L12+L14 -> 5254.6 | M11: =M12+M14 -> 5560.1 | N11: =N12+N14 -> 6092.8 | O11: =O12+O14 -> 6526.6 | P11: =P12+P14 -> 6835.4 | Q11: =Q12+Q14 -> 7152.1 | ... W11: =W12+W14 -> 9444.161 | X11: =((W11/V11)-1)*100 -> -1.5905866 | AP11: 6.5
A12: 1 | B12: Ave | C12: 2340.6 | D12: 2376.6 | E12: 2551.2 | F12: 2651.8 | G12: 2655 | H12: 2983.5 | I12: 3259.4 | J12: 3534.8 | K12: 4024.4 | L12: 4424.6 | M12: 4679.4 | N12: 5111.6 | O12: 5556.6 | P12: 5754.9 | Q12: 6044.3 | R12: 6531.3 | S12: 6945.9 | T12: 7199.8 | U12: 7742.8 | V12: 8087.8781 | W12: 7907.3051 | X12: =((W12/V12)-1)*100 -> -2.2326376 | AP12: 6.8
B13: Pollo | J13: 3273.1 | K13: 3727.9 | L13: 4121.7 | M13: 4362.7 | N13: 4582.9 | O13: 5195.8 | P13: 5394.3 | Q13: 5657.9 | R13: 6101.3 | S13: 6448.2 | T13: 6719.3 | U13: 7257.1 | V13: 7579.0435 | W13: 7415.882 | X13: =((W13/V13)-1)*100 -> -2.152797
B14: Huevo de Gallina | C14: 552 | D14: 581.9 | E14: 589.7 | F14: 611.1 | G14: 625.1 | H14: 639.7 | I14: 758.2 | J14: 795.8 | K14: 823.3 | L14: 830 | M14: 880.7 | N14: 981.2 | O14: 970 | P14: 1080.5 | Q14: 1107.8 | R14: 1193.1 | S14: 1238.6 | T14: 1283 | U14: 1397 | V14: 1508.9284 | W14: 1536.8559 | X14: =((W14/V14)-1)*100 -> 1.8508164 | AP14: 5.1
A15: 2 | B15: Ovino | C15: 378.7 | D15: 388.4 | E15: 383.2 | F15: 389.2 | G15: 410.8 | H15: 410.6 | I15: 413.3 | J15: 412.5 | K15: 406.5 | L15: 407.8 | M15: 410.4 | N15: 417.6 | O15: 430.3 | P15: 425.5 | Q15: 419.6 | R15: 404.2 | S15: 413.9 | T15: 407.8 | U15: 410.4 | V15: 411.76818 | W15: 393.85032 | X15: =((W15/V15)-1)*100 -> -4.3514444 | AP15: 0.4
A16: 3 | B16: Porcino | C16: 433.8 | D16: 442.2 | E16: 438.5 | F16: 439.5 | G16: 468.6 | H16: 494 | I16: 516.6 | J16: 542.7 | K16: 545.9 | L16: 543.6 | M16: 548.1 | N16: 557.2 | O16: 579.8 | P16: 605 | Q16: 641.6 | R16: 677.3 | S16: 708 | T16: 747.5 | U16: 781.6 | V16: 821.01301 | W16: 804.64578 | X16: =((W16/V16)-1)*100 -> -1.9935406 | AP16: 3.3
A17: 4 | B17: Vacuno | C17: 1114.1 | D17: 1114.3 | E17: 1147.4 | F17: 1174.2 | G17: 1227.9 | H17: 1304.4 | I17: 1382.1 | J17: 1396.3 | K17: 1397 | L17: 1408.9 | M17: 1470.2 | N17: 1531.9 | O17: 1596.3 | P17: 1651.6 | Q17: 1678.5 | R17: 1676.7 | S17: 1648.4 | T17: 1614.4 | U17: 1622.7 | V17: 1650.2126 | W17: 1573.4119 | X17: =((W17/V17)-1)*100 -> -4.6539914 | AP17: 2.2
A18: 5 | B18: Caprino | C18: 57.6 | D18: 54.4 | E18: 53.3 | F18: 57.9 | G18: 59.5 | H18: 60.8 | I18: 62.3 | J18: 61.5 | K18: 59 | L18: 56.6 | M18: 56.4 | N18: 56.5 | O18: 57.4 | P18: 59.2 | Q18: 56.7 | R18: 54.3 | S18: 53.6 | T18: 50.5 | U18: 45.7 | V18: 46.913211 | W18: 45.580929 | X18: =((W18/V18)-1)*100 -> -2.8398869 | AP18: -0.7
A19: 6 | B19: Alpaca | C19: 130.1 | D19: 137.3 | E19: 147.3 | F19: 146 | G19: 148.2 | H19: 154.4 | I19: 156.5 | J19: 166.7 | K19: 169.6 | L19: 181.4 | M19: 191.6 | N19: 201.5 | O19: 213.6 | P19: 216.6 | Q19: 224.2 | R19: 212.1 | S19: 221.5 | T19: 226.9 | U19: 225.9 | V19: 223.9348 | W19: 220.07176 | X19: =((W19/V19)-1)*100 -> -1.7250749 | AP19: 3.3
A20: 7 | B20: Llama | C20: 25.2 | D20: 25.5 | E20: 25.5 | F20: 27.5 | G20: 29.1 | H20: 30.4 | I20: 30.3 | J20: 31.9 | K20: 31.3 | L20: 32.9 | M20: 32.1 | N20: 33.4 | O20: 34.3 | P20: 32.9 | Q20: 32.9 | R20: 31.4 | S20: 31.3 | T20: 31.6 | U20: 31.5 | V20: 30.317809 | W20: 30.087406 | X20: =((W20/V20)-1)*100 -> -0.75995854 | AP20: 1.3
A21: 9 | B21: Leche Fresca de Vaca | C21: 750.6 | D21: 822.4 | E21: 873.8 | F21: 918.1 | G21: 968.1 | H21: 1027.8 | I21: 1119.3 | J21: 1209.8 | K21: 1301 | L21: 1372.9 | M21: 1394.7 | N21: 1458.8 | O21: 1488 | P21: 1502.3 | Q21: 1529.2 | R21: 1581.5 | S21: 1624 | T21: 1673.4 | U21: 1717.8 | V21: 1762.855 | W21: 1774.9174 | X21: =((W21/V21)-1)*100 -> 0.68425107 | AP21: 4.8
A22: 10 | B22: Fibra Alpaca | C22: 57 | D22: 62.3 | E22: 58 | F22: 56.9 | G22: 59.6 | H22: 66 | I22: 64.3 | J22: 71.4 | K22: 73.7 | L22: 80.4 | M22: 79.8 | N22: 85.5 | O22: 88 | P22: 81 | Q22: 82.2 | R22: 81.4 | S22: 82.7 | T22: 79.1 | U22: 83.9 | V22: 81.647227 | W22: 79.78887 | X22: =((W22/V22)-1)*100 -> -2.2760813 | AP22: 1.9
A23: 11 | B23: Fibra Llama | C23: 4.6 | D23: 4.7 | E23: 3.8 | F23: 3.9 | G23: 3.8 | H23: 3.7 | I23: 3.8 | J23: 4.5 | K23: 4.3 | L23: 4.3 | M23: 3.9 | N23: 4.2 | O23: 4.6 | P23: 4.4 | Q23: 4.6 | R23: 4 | S23: 4.1 | T23: 4.2 | U23: 4 | V23: 4.0275383 | W23: 4.0731775 | X23: =((W23/V23)-1)*100 -> 1.1331784 | AP23: -0.5
A24: 12 | B24: Lana Ovino | C24: 53.5 | D24: 54.4 | E24: 48.9 | F24: 49 | G24: 48.6 | H24: 47.2 | I24: 44.9 | J24: 47.2 | K24: 43.6 | L24: 44.5 | M24: 44.2 | N24: 44.5 | O24: 47.7 | P24: 45 | Q24: 43.2 | R24: 38.8 | S24: 40.5 | T24: 35.2 | U24: 34.9 | V24: 33.542736 | W24: 32.314588 | X24: =((W24/V24)-1)*100 -> -3.6614432 | AP24: -2.4
A25: P Preliminar
A26: 1 Considera ave y huevo de gallina
A27: Fuente: Direcciones Regionales de Agricultura
A28: Elaboración: Ministerio de Desarrollo Agrario y Riego - DGESEP - DEIA
A30: C.2 PERÚ: PARTICIPACIÓN POR AÑO, SEGÚN SUB SECTORES Y PRINCIPALES ESPECIES Y PRODUCTOS PECUARIOS EN EL VALOR BRUTO, 2007-20
A31: (%)
A33: Sector / Producto | C33: 2000 | D33: 2001 | E33: 2002 | F33: 2003 | G33: 2004 | H33: 2005 | I33: 2006 | J33: 2007 | K33: 2008 | L33: 2009 | M33: 2010 | N33: 2011 | O33: 2012 | P33: 2013 | Q33: 2014 | R33: 2015 | S33: 2016 | T33: 2017 | U33: 2018 | V33: 2019 | W33: 2020P
A34: Sector agropecuario | C34: =C7/$C$7*100 -> 100 | D34: =D7/$D$7*100 -> 100 | E34: =E7/$E$7*100 -> 100 | F34: =F7/$F$7*100 -> 100 | G34: =G7/$G$7*100 -> 100 | H34: =H7/$H$7*100 -> 100 | I34: =I7/$I$7*100 -> 100 | J34: =J7/$J$7*100 -> 100 | K34: =K7/$K$7*100 -> 100 | L34: =L7/$L$7*100 -> 100 | M34: =M7/$M$7*100 -> 100 | N34: =N7/$N$7*100 -> 100 | O34: =O7/$O$7*100 -> 100 | P34: =P7/$P$7*100 -> 100 | Q34: =Q7/$Q$7*100 -> 100 | R34: =R7/$R$7*100 -> 100 | S34: =S7/$S$7*100 -> 100 | T34: =T7/$T$7*100 -> 100 | U34: =U7/$U$7*100 -> 100 | V34: =V7/$V$7*100 -> 100 | W34: =W7/$W$7*100 -> 100
A35: Subsector agrícola | C35: =C8/$C$7*100 -> 66.252153 | D35: =D8/$D$7*100 -> 65.546137 | E35: =E8/$E$7*100 -> 66.02378 | F35: =F8/$F$7*100 -> 65.605478 | G35: =G8/$G$7*100 -> 64.8916 | H35: =H8/$H$7*100 -> 64.788245 | I35: =I8/$I$7*100 -> 64.738598 | J35: =J8/$J$7*100 -> 63.719189 | K35: =K8/$K$7*100 -> 64.110534 | L35: =L8/$L$7*100 -> 63.009327 | M35: =M8/$M$7*100 -> 62.921757 | N35: =N8/$N$7*100 -> 62.370968 | O35: =O8/$O$7*100 -> 62.533812 | P35: =P8/$P$7*100 -> 61.970204 | Q35: =Q8/$Q$7*100 -> 61.350503 | R35: =R8/$R$7*100 -> 60.851257 | S35: =S8/$S$7*100 -> 60.139972 | T35: =T8/$T$7*100 -> 60.14196 | U35: =U8/$U$7*100 -> 60.965568 | V35: =V8/$V$7*100 -> 60.812356 | W35: =W8/$W$7*100 -> 62.043991
A36: Subsector pecuario | C36: =C9/$C$7*100 -> 33.747847 | D36: =D9/$D$7*100 -> 34.453863 | E36: =E9/$E$7*100 -> 33.97622 | F36: =F9/$F$7*100 -> 34.394522 | G36: =G9/$G$7*100 -> 35.1084 | H36: =H9/$H$7*100 -> 35.211755 | I36: =I9/$I$7*100 -> 35.261402 | J36: =J9/$J$7*100 -> 36.280811 | K36: =K9/$K$7*100 -> 35.889466 | L36: =L9/$L$7*100 -> 36.990673 | M36: =M9/$M$7*100 -> 37.078243 | N36: =N9/$N$7*100 -> 37.629032 | O36: =O9/$O$7*100 -> 37.465849 | P36: =P9/$P$7*100 -> 38.029796 | Q36: =Q9/$Q$7*100 -> 38.649497 | R36: =R9/$R$7*100 -> 39.148743 | S36: =S9/$S$7*100 -> 39.860028 | T36: =T9/$T$7*100 -> 39.85804 | U36: =U9/$U$7*100 -> 39.034432 | V36: =V9/$V$7*100 -> 39.187644 | W36: =W9/$W$7*100 -> 37.956009
B38: Industria avícola 1 | C38: =C11/$C$7*100 -> 16.553453 | D38: =D11/$D$7*100 -> 16.80794 | E38: =E11/$E$7*100 -> 16.883291 | F38: =F11/$F$7*100 -> 17.200951 | G38: =G11/$G$7*100 -> 17.176896 | H38: =H11/$H$7*100 -> 17.663893 | I38: =I11/$I$7*100 -> 18.136757 | J38: =J11/$J$7*100 -> 18.987031 | K38: =K11/$K$7*100 -> 19.593158 | L38: =L11/$L$7*100 -> 20.704438 | M38: =M11/$M$7*100 -> 21.055083 | N38: =N11/$N$7*100 -> 21.868405 | O38: =O11/$O$7*100 -> 22.095531 | P38: =P11/$P$7*100 -> 22.684929 | Q38: =Q11/$Q$7*100 -> 23.298109 | R38: =R11/$R$7*100 -> 24.218975 | S38: =S11/$S$7*100 -> 25.11176 | T38: =T11/$T$7*100 -> 25.319977 | U38: =U11/$U$7*100 -> 25.305668 | V38: =V11/$V$7*100 -> 25.647906 | W38: =W11/$W$7*100 -> 24.888223
B39: Ave | C39: =C12/$C$7*100 -> 13.394528 | D39: =D12/$D$7*100 -> 13.502028 | E39: =E12/$E$7*100 -> 13.713475 | F39: =F12/$F$7*100 -> 13.97943 | G39: =G12/$G$7*100 -> 13.903435 | H39: =H12/$H$7*100 -> 14.545215 | I39: =I12/$I$7*100 -> 14.713995 | J39: =J12/$J$7*100 -> 15.497935 | K39: =K12/$K$7*100 -> 16.265591 | L39: =L12/$L$7*100 -> 17.43403 | M39: =M12/$M$7*100 -> 17.720033 | N39: =N12/$N$7*100 -> 18.346661 | O39: =O12/$O$7*100 -> 18.811636 | P39: =P12/$P$7*100 -> 19.099028 | Q39: =Q12/$Q$7*100 -> 19.689428 | R39: =R12/$R$7*100 -> 20.478146 | S39: =S12/$S$7*100 -> 21.311475 | T39: =T12/$T$7*100 -> 21.490401 | U39: =U12/$U$7*100 -> 21.437748 | V39: =V12/$V$7*100 -> 21.615226 | W39: =W12/$W$7*100 -> 20.838142
B40: Pollo | J40: =J13/$J$7*100 -> 14.350541 | K40: =K13/$K$7*100 -> 15.067214 | L40: =L13/$L$7*100 -> 16.240529 | M40: =M13/$M$7*100 -> 16.520748 | N40: =N13/$N$7*100 -> 16.44904 | O40: =O13/$O$7*100 -> 17.590163 | P40: =P13/$P$7*100 -> 17.90229 | Q40: =Q13/$Q$7*100 -> 18.430722 | R40: =R13/$R$7*100 -> 19.12993 | S40: =S13/$S$7*100 -> 19.784428 | T40: =T13/$T$7*100 -> 20.056175 | U40: =U13/$U$7*100 -> 20.092974 | V40: =V13/$V$7*100 -> 20.255342 | W40: =W13/$W$7*100 -> 19.543094
A41: 1 | B41: Huevo de Gallina | C41: =C14/$C$7*100 -> 3.1589248 | D41: =D14/$D$7*100 -> 3.3059119 | E41: =E14/$E$7*100 -> 3.1698166 | F41: =F14/$F$7*100 -> 3.2215211 | G41: =G14/$G$7*100 -> 3.2734604 | H41: =H14/$H$7*100 -> 3.1186775 | I41: =I14/$I$7*100 -> 3.4227621 | J41: =J14/$J$7*100 -> 3.489096 | K41: =K14/$K$7*100 -> 3.3275671 | L41: =L14/$L$7*100 -> 3.2704075 | M41: =M14/$M$7*100 -> 3.33505 | N41: =N14/$N$7*100 -> 3.5217435 | O41: =O14/$O$7*100 -> 3.2838944 | P41: =P14/$P$7*100 -> 3.5859007 | Q41: =Q14/$Q$7*100 -> 3.6086806 | R41: =R14/$R$7*100 -> 3.740829 | S41: =S14/$S$7*100 -> 3.8002841 | T41: =T14/$T$7*100 -> 3.8295764 | U41: =U14/$U$7*100 -> 3.8679203 | V41: =V14/$V$7*100 -> 4.0326805 | W41: =W14/$W$7*100 -> 4.0500805
B42: Ovino | C42: =C15/$C$7*100 -> 2.1671827 | D42: =D15/$D$7*100 -> 2.2065925 | E42: =E15/$E$7*100 -> 2.0598164 | F42: =F15/$F$7*100 -> 2.0517362 | G42: =G15/$G$7*100 -> 2.1512359 | H42: =H15/$H$7*100 -> 2.0017648 | I42: =I15/$I$7*100 -> 1.865771 | J42: =J15/$J$7*100 -> 1.8085601 | K42: =K15/$K$7*100 -> 1.6429686 | L42: =L15/$L$7*100 -> 1.606834 | M42: =M15/$M$7*100 -> 1.5541098 | N42: =N15/$N$7*100 -> 1.4988586 | O42: =O15/$O$7*100 -> 1.4567626 | P42: =P15/$P$7*100 -> 1.4121247 | Q42: =Q15/$Q$7*100 -> 1.3668554 | R42: =R15/$R$7*100 -> 1.267323 | S42: =S15/$S$7*100 -> 1.2699319 | T42: =T15/$T$7*100 -> 1.2172262 | U42: =U15/$U$7*100 -> 1.1362881 | V42: =V15/$V$7*100 -> 1.1004694 | W42: =W15/$W$7*100 -> 1.0379148
B43: Porcino | C43: =C16/$C$7*100 -> 2.4825029 | D43: =D16/$D$7*100 -> 2.5122431 | E43: =E16/$E$7*100 -> 2.3570707 | F43: =F16/$F$7*100 -> 2.3169015 | G43: =G16/$G$7*100 -> 2.4539171 | H43: =H16/$H$7*100 -> 2.4083581 | I43: =I16/$I$7*100 -> 2.3321009 | J43: =J16/$J$7*100 -> 2.3794074 | K43: =K16/$K$7*100 -> 2.2063876 | L43: =L16/$L$7*100 -> 2.1419199 | M43: =M16/$M$7*100 -> 2.0755546 | N43: =N16/$N$7*100 -> 1.9999139 | O43: =O16/$O$7*100 -> 1.9628886 | P43: =P16/$P$7*100 -> 2.0078389 | Q43: =Q16/$Q$7*100 -> 2.0900248 | R43: =R16/$R$7*100 -> 2.1235969 | S43: =S16/$S$7*100 -> 2.1722922 | T43: =T16/$T$7*100 -> 2.2311834 | U43: =U16/$U$7*100 -> 2.1640419 | V43: =V16/$V$7*100 -> 2.194195 | W43: =W16/$W$7*100 -> 2.1204852
B44: Vacuno | C44: =C17/$C$7*100 -> 6.3756488 | D44: =D17/$D$7*100 -> 6.3306026 | E44: =E17/$E$7*100 -> 6.1676235 | F44: =F17/$F$7*100 -> 6.1900017 | G44: =G17/$G$7*100 -> 6.4301424 | H44: =H17/$H$7*100 -> 6.3592354 | I44: =I17/$I$7*100 -> 6.2392503 | J44: =J17/$J$7*100 -> 6.1219211 | K44: =K17/$K$7*100 -> 5.6463151 | L44: =L17/$L$7*100 -> 5.5514183 | M44: =M17/$M$7*100 -> 5.5673788 | N44: =N17/$N$7*100 -> 5.4983274 | O44: =O17/$O$7*100 -> 5.4042068 | P44: =P17/$P$7*100 -> 5.4812342 | Q44: =Q17/$Q$7*100 -> 5.4677473 | R44: =R17/$R$7*100 -> 5.2571016 | S44: =S17/$S$7*100 -> 5.0576363 | T44: =T17/$T$7*100 -> 4.8187593 | U44: =U17/$U$7*100 -> 4.4928234 | V44: =V17/$V$7*100 -> 4.4102691 | W44: =W17/$W$7*100 -> 4.1464165
B45: Caprino | C45: =C18/$C$7*100 -> 0.32962694 | D45: =D18/$D$7*100 -> 0.3090593 | E45: =E18/$E$7*100 -> 0.28650369 | F45: =F18/$F$7*100 -> 0.30523003 | G45: =G18/$G$7*100 -> 0.31158358 | H45: =H18/$H$7*100 -> 0.2964133 | I45: =I18/$I$7*100 -> 0.28124252 | J45: =J18/$J$7*100 -> 0.26963987 | K45: =K18/$K$7*100 -> 0.23846284 | L45: =L18/$L$7*100 -> 0.22301815 | M45: =M18/$M$7*100 -> 0.2135765 | N45: =N18/$N$7*100 -> 0.20279098 | O45: =O18/$O$7*100 -> 0.1943253 | P45: =P18/$P$7*100 -> 0.19646952 | Q45: =Q18/$Q$7*100 -> 0.18470138 | R45: =R18/$R$7*100 -> 0.17025146 | S45: =S18/$S$7*100 -> 0.16445602 | T45: =T18/$T$7*100 -> 0.15073547 | U45: =U18/$U$7*100 -> 0.12653111 | V45: =V18/$V$7*100 -> 0.12537771 | W45: =W18/$W$7*100 -> 0.12011954
B46: Alpaca | C46: =C19/$C$7*100 -> 0.74452196 | D46: =D19/$D$7*100 -> 0.78003386 | E46: =E19/$E$7*100 -> 0.79178224 | F46: =F19/$F$7*100 -> 0.76966467 | G46: =G19/$G$7*100 -> 0.77607876 | H46: =H19/$H$7*100 -> 0.75273378 | I46: =I19/$I$7*100 -> 0.70649205 | J46: =J19/$J$7*100 -> 0.73087749 | K46: =K19/$K$7*100 -> 0.68547963 | L46: =L19/$L$7*100 -> 0.71476136 | M46: =M19/$M$7*100 -> 0.7255542 | N46: =N19/$N$7*100 -> 0.723228 | O46: =O19/$O$7*100 -> 0.72313385 | P46: =P19/$P$7*100 -> 0.7188395 | Q46: =Q19/$Q$7*100 -> 0.73033598 | R46: =R19/$R$7*100 -> 0.66501536 | S46: =S19/$S$7*100 -> 0.67960837 | T46: =T19/$T$7*100 -> 0.67726491 | U46: =U19/$U$7*100 -> 0.62545684 | V46: =V19/$V$7*100 -> 0.59847604 | W46: =W19/$W$7*100 -> 0.57995569
...

Sheet 2. POBLACION Y ...

Sheet C-4
A2: C.4 PERÚ: POBLACIÓN PECUARIA POR ESPECIE, SEGÚN REGIÓN, 2020P
A3: (Unidades)
A5: Región | B5: Ave | C5: Alpaca | D5: LLama | E5: Caprino | F5: Ovino | G5: Porcino | H5: Vacuno | I5: Vacas en Ordeño
A6: Total Nacional | B6: =(B8+B9+B10+B11+B12+B16+B17+B18+B19+B20+B21+B22+B23+B24+B25+B26+B27+B28+B31+B32+B33+B34+B35+B36) -> 1.7105863e+08 | C6: =(C8+C9+C10+C11+C12+C16+C17+C18+C19+C20+C21+C22+C23+C24+C25+C26+C27+C28+C31+C32+C33+C34+C35+C36) -> 4492025 | D6: =(D8+D9+D10+D11+D12+D16+D17+D18+D19+D20+D21+D22+D23+D24+D25+D26+D27+D28+D31+D32+D33+D34+D35+D36) -> 1092770.7 | E6: =(E8+E9+E10+E11+E12+E16+E17+E18+E19+E20+E21+E22+E23+E24+E25+E26+E27+E28+E31+E32+E33+E34+E35+E36) -> 1801257 | F6: =(F8+F9+F10+F11+F12+F16+F17+F18+F19+F20+F21+F22+F23+F24+F25+F26+F27+F28+F31+F32+F33+F34+F35+F36) -> 11097551 | G6: =(G8+G9+G10+G11+G12+G16+G17+G18+G19+G20+G21+G22+G23+G24+G25+G26+G27+G28+G31+G32+G33+G34+G35+G36) -> 3265145 | H6: =(H8+H9+H10+H11+H12+H16+H17+H18+H19+H20+H21+H22+H23+H24+H25+H26+H27+H28+H31+H32+H33+H34+H35+H36) -> 5636388 | I6: =(I8+I9+I10+I11+I12+I16+I17+I18+I19+I20+I21+I22+I23+I24+I25+I26+I27+I28+I31+I32+I33+I34+I35+I36) -> 906688.63
A8: Tumbes | B8: 183420 | C8: 0 | D8: 0 | E8: 63823 | F8: 10210 | G8: 29015 | H8: 19258 | I8: 310.45
A9: Piura | B9: 5987048 | C9: 92 | D9: 0 | E9: 330308 | F9: 263119 | G9: 157810 | H9: 265987 | I9: 24007.677
A10: Lambayeque | B10: 2626033 | C10: 0 | D10: 0 | E10: 105050 | F10: 73859 | G10: 70227 | H10: 114530 | I10: 17819.717
A11: La Libertad | B11: 24980325 | C11: 7650 | D11: 0 | E11: 88812 | F11: 360982 | G11: 111448 | H11: 234083 | I11: 49775
A12: Cajamarca | B12: =SUM(B13:B15) -> 887067 | C12: =SUM(C13:C15) -> 1181 | D12: =SUM(D13:D15) -> 0 | E12: =SUM(E13:E15) -> 106138 | F12: =SUM(F13:F15) -> 484440 | G12: =SUM(G13:G15) -> 288467 | H12: =SUM(H13:H15) -> 657166 | I12: 164025.34
A13: Cajamarca | B13: 379140 | C13: 1181 | D13: 0 | E13: 65890 | F13: 342580 | G13: 75685 | H13: 264587 | I13: 99168.333
A14: Chota | B14: 211030 | C14: 0 | D14: 0 | E14: 20796 | F14: 102895 | G14: 104325 | H14: 274122 | I14: 59224.253
A15: Jaén | B15: 296897 | C15: 0 | D15: 0 | E15: 19452 | F15: 38965 | G15: 108457 | H15: 118457 | I15: 5632.75
A16: Amazonas | B16: 1528411 | C16: 0 | D16: 0 | E16: 14397 | F16: 27990 | G16: 92127 | H16: 252797 | I16: 79621.833
A17: Ancash | B17: 2628030 | C17: 11654 | D17: 0 | E17: 168457 | F17: 670125 | G17: 170544 | H17: 308564 | I17: 14894.083
A18: Lima | B18: 73917840 | C18: 46625 | D18: 19780 | E18: 168458 | F18: 312547 | G18: 470025 | H18: 251406 | I18: 71842.292
A19: Ica | B19: 16978545 | C19: 0 | D19: 0 | E19: 75149 | F19: 26787 | G19: 91117 | H19: 47756 | I19: 14028.083
A20: Huánuco | B20: 1750450 | C20: 6648 | D20: 3460 | E20: 101568 | F20: 526457 | G20: 402365 | H20: 290125 | I20: 37713.417
A21: Pasco | B21: 140558 | C21: 131241 | D21: 46750 | E21: 6430 | F21: 680129 | G21: 52698 | H21: 118658 | I21: 29894
A22: Junín | B22: 2567455 | C22: 100923 | D22: 65597 | E22: 13304 | F22: 1547309 | G22: 178317 | H22: 320442 | I22: 41323.917
A23: Huancavelica | B23: 387425 | C23: 268457 | D23: 129197.67 | E23: 188124 | F23: 622124 | G23: 155475 | H23: 180546 | I23: 12124.987
A24: Arequipa | B24: 16305432 | C24: 471737 | D24: 94372 | E24: 26786 | F24: 190639 | G24: 116838 | H24: 232737 | I24: 75698.583
... A27: Ayacucho | B27: 570441 | C27: 295233 | D27: 78570 | E27: 180518 | F27: 602326 | G27: 111843 | H27: 457818 | I27: 28386.333
A28: Apurímac | B28: =SUM(B29:B30) -> 305020 | C28: =SUM(C29:C30) -> 214727 | D28: =SUM(D29:D30) -> 72240 | E28: =SUM(E29:E30) -> 107810 | F28: =SUM(F29:F30) -> 454242 | G28: =SUM(G29:G30) -> 140538 | H28: =SUM(H29:H30) -> 295076 | I28: 31233.119
A29: Abancay | B29: 187565 | C29: 194877 | D29: 54090 | E29: 54720 | F29: 310988 | G29: 48951 | H29: 189748 | I29: 19696.651
A30: Andahuaylas | B30: 117455 | C30: 19850 | D30: 18150 | E30: 53090 | F30: 143254 | G30: 91587 | H30: 105328 | I30: 11536.468
A31: Cusco | B31: 1205779 | C31: 675889 | D31: 148034 | E31: 30039 | F31: 1425497 | G31: 123995 | H31: 440840 | I31: 82653.167
A32: Puno | B32: 1699105 | C32: 2039330 | D32: 369725 | E32: 0 | F32: 2699105 | G32: 120306 | H32: 733660 | I32: 95302.5
A33: San Martín | B33: 4565213 | C33: 0 | D33: 0 | E33: 0 | F33: 9080 | G33: 180451 | H33: 212548 | I33: 19157.667
A34: Loreto | B34: 4190254 | C34: 0 | D34: 0 | E34: 291 | F34: 11303 | G34: 95430 | H34: 48827 | I34: 1180.75
A35: Ucayali | B35: 5924587 | C35: 0 | D35: 0 | E35: 178 | F35: 8931 | G35: 43273 | H35: 50090 | I35: 3479.3867
A36: Madre de Dios | B36: 485451.1 | C36: 0 | D36: 0 | E36: 210 | F36: 6669 | G36: 12684 | H36: 60875 | I36: 1005.6667
A37: P Preliminar
A38: Fuente: Direcciones Regionales de Agricultura
A39: Elaboración: Ministerio de Desarrollo Agrario y Riego - DGESEP - DEIA

Sheet C 5
A2: C.5 PERÚ: EVOLUCIÓN DE LA POBLACIÓN, SACA, PRODUCCIÓN, RENDIMIENTO Y PRECIOS RECIBIDOS POR EL PRODUCTOR POR AÑO, SEGÚN ESPECIE Y PRODUCTO, 2007-20
A4: Especie/ Producto | B4: Variable | C4: 2000 | D4: 2001 | E4: 2002 | F4: 2003 | G4: 2004 | H4: 2005 | I4: 2006 | J4: 2007 | K4: 2008 | L4: 2009 | M4: 2010 | N4: 2011 | O4: 2012 | P4: 2013 | Q4: 2014 | R4: 2015 | S4: 2016 | T4: 2017 | U4: 2018 | V4: 2019 | W4: 2020 P
B5: Población (Miles) | C5: 88010358 | D5: 85621159 | E5: 90354182 | F5: 92846109 | G5: 97761003 | H5: 99278818 | I5: 117976702 | J5: 120227.6 | K5: 131179.1 | L5: 137838 | M5: 130779 | N5: 128943.5 | O5: 138554.1 | P5: 138179.8 | Q5: 144703.7 | R5: 151000.9 | S5: 158263.2 | T5: 156637.7 | U5: 160959.3 | V5: 168172.6 | W5: 171058.63
B6: Saca (Miles) | C6: 283733046 | D6: 287860594 | E6: 307094298 | F6: 310943489 | G6: 308485309 | H6: 342073628 | I6: 368545799 | J6: 394749.6 | K6: 435909.3 | L6: 476340.3 | M6: 504986.8 | N6: 535421.1 | O6: 575566.4 | P6: 594004.2 | Q6: 621140.1 | R6: 645016.2 | S6: 690892.3 | T6: 709233 | U6: 755841.1 | V6: 786256.92 | W6: 753602.34
A7: Ave | B7: Produción carne (t) | C7: 510161 | D7: 518010 | E7: 556076 | F7: 577989 | G7: 578693 | H7: 650296 | I7: 710428 | J7: 770444 | K7: 877171 | L7: 964407 | M7: 1019935 | N7: 1108345 | O7: 1211140 | P7: 1254348 | Q7: 1317426 | R7: 1423586 | S7: 1513950 | T7: 1569280 | U7: 1687636 | V7: 1762855.6 | W7: 1723497.5
B8: Rendimiento (Kg/Unidad) | C8: =(C7/C6)*1000 -> 1.7980317 | D8: =(D7/D6)*1000 -> 1.7995169 | E8: =(E7/E6)*1000 -> 1.8107663 | F8: =(F7/F6)*1000 -> 1.8588233 | G8: =(G7/G6)*1000 -> 1.8759175 | H8: =(H7/H6)*1000 -> 1.901041 | I8: =(I7/I6)*1000 -> 1.9276519 | J8: =(J7/J6) -> 1.9517284 | K8: =(K7/K6) -> 2.0122787 | L8: =(L7/L6) -> 2.0246177 | M8: =(M7/M6) -> 2.0197261 | N8: =(N7/N6) -> 2.0700436 | O8: =(O7/O6) -> 2.1042576 | P8: =(P7/P6) -> 2.111682 | Q8: =(Q7/Q6) -> 2.1209804 | ... W8: =(W7/W6) -> 2.2870118
B9: Precio (S/ x Kg) | C9: 3.06 | D9: 3.19 | E9: 3.07 | F9: 3.09 | G9: 3.48 | H9: 3.46 | I9: 3.6 | J9: 3.63 | K9: 4.18 | L9: 4.33 | M9: 4.64 | N9: 4.67 | O9: 4.7 | P9: 4.75 | Q9: 4.78 | R9: 4.82 | S9: 4.84 | T9: 4.84 | U9: 4.86 | V9: 4.67 | W9: 5.02
B10: Población (Unidades) | C10: 14800991 | D10: 14727155 | E10: 14690547 | F10: 14721243 | G10: 14696522 | H10: 14813786 | I10: 14675255 | J10: 14580166 | K10: 14509628 | L10: 14137690 | M10: 14159720 | N10: 14050173 | O10: 12184143 | P10: 11830977 | Q10: 11652272 | R10: 11982580 | S10: 11450657 | T10: 11338424 | U10: 11331908 | V10: 11261557 | W10: 11097551
B11: Saca (Unidades) | C11: 2521661 | D11: 2571321 | E11: 2517896 | F11: 2535935 | G11: 2709847 | H11: 2685627 | I11: 2692776 | J11: 2681208 | K11: 2678241 | L11: 2753681 | M11: 2788507 | N11: 2844228 | O11: 2910166 | P11: 2832371 | Q11: 2788555 | R11: 2698887 | S11: 2745951 | T11: 2699282 | U11: 2687624 | V11: 2682837 | W11: 2544650.7
A12: Ovino | B12: Produción carne (t) | C12: 31068 | D12: 31868 | E12: 31437 | F12: 31926 | G12: 33698 | H12: 33686 | I12: 33904 | J12: 33839 | K12: 33350 | L12: 33458 | M12: 33669 | N12: 34256 | O12: 35304 | P12: 34906 | Q12: 34421 | R12: 33163 | S12: 33955 | T12: 33458 | U12: 33672 | V12: 33780.947 | W12: 32310.988
B13: Rendimiento (Kg/Unidad) | C13: =(C12/C11)*1000 -> 12.320451 | D13: =(D12/D11)*1000 -> 12.39363 | E13: =(E12/E11)*1000 -> 12.485424 | F13: =(F12/F11)*1000 -> 12.589439 | G13: =(G12/G11)*1000 -> 12.435388 | H13: =(H12/H11)*1000 -> 12.543067 | I13: =(I12/I11)*1000 -> 12.590724 | J13: =(J12/J11)*1000 -> 12.620804 | ... W13: =(W12/W11)*1000 -> 12.697612
B14: Precio (S/ x Kg) | C14: 2.99 | D14: 3.13 | E14: 3.29 | F14: 3.29 | G14: 3.27 | H14: 3.31 | I14: 3.32 | J14: 3.49 | K14: 3.9 | L14: 4.13 | M14: 4.46 | N14: 4.52 | O14: 4.9 | P14: 5.04 | Q14: 5.72 | R14: 5.72 | S14: 5.9 | T14: 5.6 | U14: 5.56 | V14: 5.58 | W14: 5.43
B15: Población (Unidades) | C15: 2845573 | D15: 2809888 | E15: 2941036 | F15: 2990499 | G15: 3000199 | H15: 3010724 | I15: 3073855 | J15: 3115772 | K15: 3151406 | L15: 3256809 | M15: 3254413 | N15: 3263254 | O15: 2987315 | P15: 3176115 | Q15: 3173015 | R15: 3200714 | S15: 3104911 | T15: 3217254 | U15: 3209742 | V15: 3258808 | W15: 3265145
B16: Saca (Unidades) | C16: 1540534 | D16: 1650886 | E16: 1637129 | F16: 1670387 | G16: 1884573 | H16: 1991346 | I16: 2074715 | J16: 2153141 | K16: 2131518 | L16: 2213057 | M16: 2186978 | N16: 2298432 | O16: 2401634 | P16: 2499031 | Q16: 2629566 | R16: 2764884 | S16: 2876803 | T16: 3073656 | U16: 3090907 | V16: 3284606.4 | W16: 3191164.1
A17: Porcino | B17: Produción carne (t) | C17: 91554 | D17: 93313 | E17: 92530 | F17: 92738 | G17: 98880 | H17: 104254 | I17: 109010 | J17: 114520 | K17: 115196 | L17: 114719 | M17: 115655 | N17: 117588 | O17: 122353 | P17: 127684 | Q17: 135390 | R17: 142925 | S17: 149399 | T17: 157824 | U17: 162421 | V17: 173258.66 | W17: 169804.68
B18: Rendimiento (Kg/Unidad) | C18: =(C17/C16)*1000 -> 59.430042 | D18: =(D17/D16)*1000 -> 56.522982 | E18: =(E17/E16)*1000 -> 56.519676 | F18: =(F17/F16)*1000 -> 55.518871 | G18: =(G17/G16)*1000 -> 52.468119 | H18: =(H17/H16)*1000 -> 52.353534 | I18: =(I17/I16)*1000 -> 52.542156 | J18: =(J17/J16)*1000 -> 53.187413 | ... W18: =(W17/W16)*1000 -> 53.21089
B19: Precio (S/ x Kg) | C19: 3.31 | D19: 3.34 | E19: 3.35 | F19: 3.39 | G19: 3.42 | H19: 3.43 | I19: 3.47 | J19: 3.5 | K19: 3.8 | L19: 4.12 | M19: 4.25 | N19: 5.05 | O19: 5.24 | P19: 5.91 | Q19: 6.07 | R19: 6.42 | S19: 6.77 | T19: 6.96 | U19: 7.05 | V19: 6.94 | W19: 6.72
B20: Población (Unidades) | C20: 4980291 | D20: 5035612 | E20: 5163700 | F20: 5193414 | G20: 5184822 | H20: 5249783 | I20: 5241102 | J20: 5420865 | K20: 5442989 | L20: 5459435 | M20: 5520200 | N20: 5589173 | O20: 5660984 | P20: 5555988 | Q20: 5577959 | R20: 5553470 | S20: 5525454 | T20: 5535569 | U20: 5575483 | V20: 5599890.5 | W20: 5636388
B21: Saca (Unidades) | C21: 875746 | D21: 920031 | E21: 951383 | F21: 986402 | G21: 1020294 | H21: 1074578 | I21: 1127321 | J21: 1138578 | K21: 1151906 | L21: 1168497 | M21: 1218723 | N21: 1266710 | O21: 1319404 | P21: 1375095 | Q21: 1376391 | R21: 1367797 | S21: 1364230 | T21: 1331223 | U21: 1348165 | V21: 1357066.5 | W21: 1250069
A22: Vacuno | B22: Produción carne (t) | C22: 130249 | D22: 130269 | E22: 134137 | F22: 137271 | G22: 143554 | H22: 152497 | I22: 161578 | J22: 163235 | K22: 163318 | L22: 164704 | M22: 171872 | N22: 179084 | O22: 186617 | P22: 193087 | Q22: 196232 | R22: 196015 | S22: 192703 | T22: 188738 | U22: 189703 | V22: 192919.59 | W22: 183941.13
B23: Rendimiento (Kg/Unidad) | C23: =(C22/C21)*1000 -> 148.7292 | D23: =(D22/D21)*1000 -> 141.59197 | E23: =(E22/E21)*1000 -> 140.99159 | F23: =(F22/F21)*1000 -> 139.16334 | G23: =(G22/G21)*1000 -> 140.69866 | H23: =(H22/H21)*1000 -> 141.91338 | I23: =(I22/I21)*1000 -> 143.32918 | J23: =(J22/J21)*1000 -> 143.36743 | ... W23: =(W22/W21)*1000 -> 147.14478
B24: Precio (S/ x Kg) | C24: 3.34 | D24: 3.41 | E24: 3.29 | F24: 3.52 | G24: 3.33 | H24: 3.36 | I24: 3.4 | J24: 3.5 | K24: 3.77 | L24: 4.08 | M24: 4.1 | N24: 4.25 | O24: 4.69 | P24: 4.84 | Q24: 5.23 | R24: 5.41 | S24: 5.45 | T24: 5.53 | U24: 5.64 | V24: 5.69 | W24: 6.73
B25: Población (Unidades) | C25: 2034914 | D25: 2017808 | E25: 1983128 | F25: 1983302 | G25: 1971863 | H25: 1952956 | I25: 1936855 | J25: 1925912 | K25: 1904124 | L25: 1928678 | M25: 1968306 | N25: 1946117 | O25: 1949502 | P25: 1928631 | Q25: 1905462 | R25: 1882361 | S25: 1865047 | T25: 1814704 | U25: 1811630 | V25: 1807959 | W25: 1801257
B26: Saca (Unidades) | C26: 451247 | D26: 468861 | E26: 476569 | F26: 523993 | G26: 524448 | H26: 527096 | I26: 518663 | J26: 506927 | K26: 496706 | L26: 505880 | M26: 499447 | N26: 489915 | O26: 496626 | P26: 505262 | Q26: 489956 | R26: 464018 | S26: 458812 | T26: 444799 | U26: 410567 | V26: 411262.69 | W26: 392865.58
A27: Caprino | B27: Produción carne (t) | C27: 6268 | D27: 5912 | E27: 5793 | F27: 6294 | G27: 6476 | H27: 6618 | I27: 6772 | J27: 6686 | K27: 6419 | L27: 6153 | M27: 6131 | N27: 6150 | O27: 6247 | P27: 6439 | Q27: 6167 | R27: 5901 | S27: 5827 | T27: 5494 | U27: 4966 | V27: 5102.2518 | W27: 4957.3536
B28: Rendimiento (Kg/Unidad) | C28: =(C27/C26)*1000 -> 13.890397 | D28: =(D27/D26)*1000 -> 12.609281 | E28: =(E27/E26)*1000 -> 12.155637 | F28: =(F27/F26)*1000 -> 12.011611 | G28: =(G27/G26)*1000 -> 12.348221 | H28: =(H27/H26)*1000 -> 12.555588 | I28: =(I27/I26)*1000 -> 13.056648 | J28: =(J27/J26)*1000 -> 13.189276 | ... W28: =(W27/W26)*1000 -> 12.618447
B29: Precio (S/ x Kg) | C29: 3.33 | D29: 3.28 | E29: 3.31 | F29: 3.22 | G29: 3.27 | H29: 3.05 | I29: 3.01 | J29: 3.17 | K29: 3.41 | L29: 3.61 | M29: 3.38 | N29: 3.53 | O29: 3.68 | P29: 3.93 | Q29: 4.04 | R29: 4.28 | S29: 4.66 | T29: 4.74 | U29: 4.79 | V29: 4.81 | W29: 4.8
B30: Población (Unidades) | C30: 3078524 | D30: 3190373 | E30: 3335721 | F30: 3422557 | G30: 3429019 | H30: 3594515 | I30: 3625627 | J30: 3687340 | K30: 3780806 | L30: 4105582 | M30: 4177499 | N30: 4322258 | O30: 3927361 | P30: 4005315 | Q30: 4315793 | R30: 4318457 | S30: 4319228 | T30: 4330710 | U30: 4384846 | V30: 4449505 | W30: 4492025
B31: Saca (Unidades) | C31: 269643 | D31: 288318 | E31: 313415 | F31: 304890 | G31: 312092 | H31: 321478 | I31: 330072 | J31: 355174 | K31: 365555 | L31: 387980 | M31: 410085 | N31: 424100 | O31: 455558 | P31: 463354 | Q31: 481847 | R31: 446199 | S31: 474135 | T31: 479033 | U31: 470464 | V31: 473283 | W31: 464229.43
A32: Alpaca | B32: Produción carne (t) | C32: 7307 | D32: 7713 | E32: 8277 | F32: 8204 | G32: 8323 | H32: 8671 | I32: 8793 | J32: 9366 | K32: 9527 | L32: 10189 | M32: 10761 | N32: 11318 | O32: 11999 | P32: 12169 | Q32: 12594 | R32: 11917 | S32: 12445 | T32: 12747 | U32: 12689 | V32: 12579.638 | W32: 12362.63
B33: Rendimiento (Kg/Unidad) | C33: =(C32/C31)*1000 -> 27.098794 | D33: =(D32/D31)*1000 -> 26.751712 | E33: =(E32/E31)*1000 -> 26.409074 | F33: =(F32/F31)*1000 -> 26.908065 | G33: =(G32/G31)*1000 -> 26.668418 | H33: =(H32/H31)*1000 -> 26.972297 | I33: =(I32/I31)*1000 -> 26.639642 | J33: =(J32/J31)*1000 -> 26.370173 | ... W33: =(W32/W31)*1000 -> 26.630431
B34: Precio (S/ x Kg) | C34: 2.4 | D34: 2.57 | E34: 2.48 | F34: 2.53 | G34: 2.66 | H34: 2.61 | I34: 2.51 | J34: 2.5 | K34: 2.91 | L34: 3.13 | M34: 3.43 | N34: 3.65 | O34: 4.03 | P34: 4.43 | Q34: 4.77 | R34: 4.63 | S34: 4.81 | T34: 4.91 | U34: 4.96 | V34: 4.94 | W34: 5
W35: sigue…
A36: continúa C.5
A37: Especie/ Producto | B37: Variable | C37: 2000 | D37: 2001 | E37: 2002 | F37: 2003 | G37: 2004 | H37: 2005 | I37: 2006 | J37: 2007 | K37: 2008 | L37: 2009 | M37: 2010 | N37: 2011 | O37: 2012 | P37: 2013 | Q37: 2014 | R37: 2015 | S37: 2016 | T37: 2017 | U37: 2018 | V37: 2019 | W37: 2020 P
B38: Población (Unidades) | C38: 1183908 | D38: 1179088 | E38: 1207275 | F38: 1230543 | G38: 1236984 | H38: 1269979 | I38: 1256101 | J38: 1274425 | K38: 1262782 | L38: 1237593 | M38: 1245169 | N38: 1226612 | O38: 1194404 | P38: 1234089 | Q38: 1211917 | R38: 1194708 | S38: 1105018 | T38: 1106201 | U38: 1093124 | V38: 1089699 | W38: 1092770.7
B39: Saca (Unidades) | C39: 91890 | D39: 95157 | E39: 97389 | F39: 101826 | G39: 109330 | H39: 112106 | I39: 113801 | J39: 118399 | K39: 119237 | L39: 127316 | M39: 123384 | N39: 128346 | O39: 130530 | P39: 125729 | Q39: 123360 | R39: 119806 | S39: 119195 | T39: 120748 | U39: 119726 | V39: 115790.03 | W39: 113685.48
A40: Llama | B40: Produción carne (t) | C40: 3194 | D40: 3232 | E40: 3242 | F40: 3496 | G40: 3699 | H40: 3863 | I40: 3839 | J40: 4053 | K40: 3971 | L40: 4175 | M40: 4075 | N40: 4235 | O40: 4350 | P40: 4179 | Q40: 4170 | R40: 3980 | S40: 3977 | T40: 4009 | U40: 4003 | V40: 3847.5921 | W40: 3818.352
B41: Rendimiento (Kg/Unidad) | C41: =(C40/C39)*1000 -> 34.758951 | D41: =(D40/D39)*1000 -> 33.964921 | E41: =(E40/E39)*1000 -> 33.289181 | F41: =(F40/F39)*1000 -> 34.333078 | G41: =(G40/G39)*1000 -> 33.833349 | H41: =(H40/H39)*1000 -> 34.458459 | I41: =(I40/I39)*1000 -> 33.734326 | J41: =(J40/J39)*1000 -> 34.231708 | ... W41: =(W40/W39)*1000 -> 33.58698
B42: Precio (S/ x Kg) | C42: 1.93 | D42: 2.18 | E42: 2.39 | F42: 2.4 | G42: 2.45 | H42: 2.49 | I42: 2.39 | J42: 2.31 | K42: 2.7 | L42: 2.88 | M42: 3.02 | N42: 3.4 | O42: 3.61 | P42: 3.87 | Q42: 4.25 | R42: 4.09 | S42: 4.32 | T42: 4.25 | U42: 4.28 | V42: 4.27 | W42: 4.13
...

Sheet C -6
A2: C.6 PERÚ: POBLACIÓN, SACA, PRODUCCIÓN, RENDIMIENTO Y PRECIOS RECIBIDOS POR EL PRODUCTOR POR MES, SEGÚN PRINCIPALES ESPECIES Y PRODUCTOS PECUARIOS, 2020P
A4: Especie/ producto | B4: Variable | C4: Anual | D4: Ene | E4: Feb | F4: Mar | G4: Abr | H4: May | I4: Jun | J4: Jul | K4: Ago | L4: Set | M4: Oct | N4: Nov | O4: Dic
A5: Ave | B5: Población | C5: 1.7105863e+08
B6: Saca (Unidades) | C6: =SUM(D6:O6) -> 7.5360234e+08 | D6: 64118997 | E6: 58577201 | F6: 64403431 | G6: 64613064 | H6: 62012170 | I6: 62062473 | J6: 64398250 | K6: 61433493 | L6: 61327093 | M6: 63875776 | N6: 60870050 | O6: 65910343
B7: Producción carne (t) | C7: =SUM(D7:O7) -> 1723497.5 | D7: 144266.58 | E7: 129817.51 | F7: 145281.01 | G7: 148722.82 | H7: 145796.07 | I7: 145025.13 | J7: 148818.41 | K7: 143127.77 | L7: 142346.86 | M7: 145100.21 | N7: 138327.51 | O7: 146867.58
B8: Rendimiento (Kg/Unidad) | C8: =(C7/C6)*1000 -> 2.2870118 | D8: =D7/D6*1000 -> 2.2499819 | E8: =E7/E6*1000 -> 2.2161781 | F8: =F7/F6*1000 -> 2.2557961 | G8: =G7/G6*1000 -> 2.3017454 | H8: =H7/H6*1000 -> 2.3510881 | I8: =I7/I6*1000 -> 2.3367604 | J8: =J7/J6*1000 -> 2.3109077 | K8: =K7/K6*1000 -> 2.3298002 | ... O8: =O7/O6*1000 -> 2.2282934
B9: Precio (S/ x Kg) 1/ | C9: 4.65 | D9: 4.69 | E9: 4.66 | F9: 4.69 | G9: 4.68 | H9: 4.71 | I9: 4.68 | J9: 4.66 | K9: 4.62 | L9: 4.6 | M9: 4.6 | N9: 4.61 | O9: 4.66
A10: Ovino | B10: Población | C10: 11097551
B11: Saca (Unidades) | C11: =SUM(D11:O11) -> 2544650.7 | D11: 189001.38 | E11: 200339 | F11: 203461.3 | G11: 216344.2 | H11: 226159.66 | I11: 235601.05 | J11: 229788.6 | K11: 228044.8 | L11: 210860.1 | M11: 201767.14 | N11: 202013 | O11: 201270.5
B12: Producción carne (t) | C12: =SUM(D12:O12) -> 32310.988 | D12: 2350.3108 | E12: 2519.4602 | F12: 2611.7116 | G12: 2820.3902 | H12: 2952.2476 | I12: 3091.549 | J12: 2858.4396 | K12: 2873.6862 | L12: 2669.0461 | M12: 2535.2993 | N12: 2506.6117 | O12: 2522.2356
B13: Rendimiento (Kg/Unidad) | C13: =(C12/C11)*1000 -> 12.697612 | D13: =D12/D11*1000 -> 12.435416 | E13: =E12/E11*1000 -> 12.575985 | F13: =F12/F11*1000 -> 12.836405 | G13: =G12/G11*1000 -> 13.036588 | H13: =H12/H11*1000 -> 13.053821 | I13: =I12/I11*1000 -> 13.121966 | J13: =J12/J11*1000 -> 12.439432 | K13: =K12/K11*1000 -> 12.601411 | ... O13: =O12/O11*1000 -> 12.531571
B14: Precio (S/ x Kg) 1/ | C14: 5.6 | D14: 5.57 | E14: 5.59 | F14: 5.61 | G14: 5.64 | H14: 5.64 | I14: 5.62 | J14: 5.61 | K14: 5.6 | L14: 5.58 | M14: 5.57 | N14: 5.57 | O14: 5.56
A15: Porcino | B15: Población | C15: 3265145
B16: Saca (Unidades) | C16: =SUM(D16:O16) -> 3191164.1 | D16: 270097.12 | E16: 261956.32 | F16: 259264.4 | G16: 258589.55 | H16: 253079.02 | I16: 258781.51 | J16: 274432.18 | K16: 265488.39 | L16: 263808.71 | M16: 260745.74 | N16: 263761.33 | O16: 301159.8
B17: Producción carne (t) | C17: =SUM(D17:O17) -> 169804.68 | D17: 14423.923 | E17: 13947.495 | F17: 13785.016 | G17: 13531.404 | H17: 13222.615 | I17: 13544.055 | J17: 14728.738 | K17: 14194.711 | L17: 14091.127 | M17: 13814.507 | N17: 14101.269 | O17: 16419.821
B18: Rendimiento (Kg/Unidad) | C18: =(C17/C16)*1000 -> 53.21089 | D18: =D17/D16*1000 -> 53.402727 | E18: =E17/E16*1000 -> 53.243591 | F18: =F17/F16*1000 -> 53.169721 | G18: =G17/G16*1000 -> 52.327729 | H18: =H17/H16*1000 -> 52.246984 | I18: =I17/I16*1000 -> 52.3378 | J18: =J17/J16*1000 -> 53.669867 | K18: =K17/K16*1000 -> 53.466409 | ... O18: =O17/O16*1000 -> 54.521955
B19: Precio (S/ x Kg) 1/ | C19: 7.04 | D19: 6.91 | E19: 6.9 | F19: 6.91 | G19: 6.93 | H19: 6.94 | I19: 6.93 | J19: 6.95 | K19: 6.96 | L19: 6.96 | M19: 6.97 | N19: 6.98 | O19: 7.03
A20: Vacuno | B20: Población | C20: 5636388
B21: Saca (Unidades) | C21: =SUM(D21:O21) -> 1250069 | D21: 101473.12 | E21: 105888 | F21: 101864.26 | G21: 103678.3 | H21: 106418.65 | I21: 107177.6 | J21: 108943.83 | K21: 104423.3 | L21: 102214.14 | M21: 100253.2 | N21: 102554.6 | O21: 105180
B22: Producción carne (t) | C22: =SUM(D22:O22) -> 183941.13 | D22: 14705.702 | E22: 15540.037 | F22: 14888.801 | G22: 15372.888 | H22: 15737.35 | I22: 15799.316 | J22: 16052.969 | K22: 15459.912 | L22: 15079.657 | M22: 14724.681 | N22: 15008 | O22: 15571.811
B23: Rendimiento (Kg/Unidad) | C23: =(C22/C21)*1000 -> 147.14478 | D23: =D22/D21*1000 -> 144.92214 | E23: =E22/E21*1000 -> 146.75919 | F23: =F22/F21*1000 -> 146.16315 | G23: =G22/G21*1000 -> 148.27488 | H23: =H22/H21*1000 -> 147.88151 | I23: =I22/I21*1000 -> 147.41248 | J23: =J22/J21*1000 -> 147.35088 | K23: =K22/K21*1000 -> 148.05041 | ... O23: =O22/O21*1000 -> 148.04917
B24: Precio (S/ x Kg) 1/ | C24: 5.64 | D24: 5.65 | E24: 5.67 | F24: 5.68 | G24: 5.69 | H24: 5.69 | I24: 5.69 | J24: 5.69 | K24: 5.69 | L24: 5.68 | M24: 5.69 | N24: 5.68 | O24: 5.69
A25: Caprino | B25: Población | C25: 1801257
B26: Saca (Unidades) | C26: =SUM(D26:O26) -> 392865.58 | D26: 30348 | E26: 31542 | F26: 32832.02 | G26: 33212 | H26: 33582.86 | I26: 35071.7 | J26: 34927.3 | K26: 34222.6 | L26: 31664 | M26: 31718.6 | N26: 30864.5 | O26: 32880
B27: Producción carne (t) | C27: =SUM(D27:O27) -> 4957.3536 | D27: 378.06962 | E27: 396.38737 | F27: 407.65505 | G27: 412.85324 | H27: 424.31851 | I27: 456.70795 | J27: 451.82706 | K27: 437.98508 | L27: 400.56208 | M27: 385.8977 | N27: 388.37199 | O27: 416.71798
B28: Rendimiento (Kg/Unidad) | C28: =(C27/C26)*1000 -> 12.618447 | D28: =D27/D26*1000 -> 12.45781 | E28: =E27/E26*1000 -> 12.56697 | F28: =F27/F26*1000 -> 12.416387 | G28: =G27/G26*1000 -> 12.430846 | H28: =H27/H26*1000 -> 12.634972 | I28: =I27/I26*1000 -> 13.022122 | J28: =J27/J26*1000 -> 12.936215 | K28: =K27/K26*1000 -> 12.798124 | ... O28: =O27/O26*1000 -> 12.673904
B29: Precio (S/ x Kg) 1/ | C29: 4.79 | D29: 4.81 | E29: 4.81 | F29: 4.81 | G29: 4.8 | H29: 4.81 | I29: 4.8 | J29: 4.81 | K29: 4.81 | L29: 4.82 | M29: 4.82 | N29: 4.82 | O29: 4.84
A30: Alpaca | B30: Población | C30: 4492025
B31: Saca (Unidades) | C31: =SUM(D31:O31) -> 464229.44 | D31: 31720 | E31: 37786 | F31: 40577.407 | G31: 46625 | H31: 45108.65 | I31: 44763.05 | J31: 45015.428 | K31: 41217.9 | L31: 36015 | M31: 32850.2 | N31: 33051.4 | O31: 29499.4
B32: Producción carne (t) | C32: =SUM(D32:O32) -> 12363.609 | D32: 830.2483 | E32: 1000.0565 | F32: 1071.9981 | G32: 1272.714 | H32: 1227.0379 | I32: 1217.2462 | J32: 1217.9604 | K32: 1097.4494 | L32: 948.6679 | M32: 860.74126 | N32: 852.79958 | O32: 766.68924
B33: Rendimiento (Kg/Unidad) | C33: =(C32/C31)*1000 -> 26.63254 | D33: =D32/D31*1000 -> 26.174284 | E33: =E32/E31*1000 -> 26.466323 | F33: =F32/F31*1000 -> 26.418596 | G33: =G32/G31*1000 -> 27.296816 | H33: =H32/H31*1000 -> 27.201832 | I33: =I32/I31*1000 -> 27.193103 | J33: =J32/J31*1000 -> 27.056509 | K33: =K32/K31*1000 -> 26.625554 | ... O33: =O32/O31*1000 -> 25.989994
B34: Precio (S/ x Kg) 1/ | C34: 4.96 | D34: 4.91 | E34: 4.97 | F34: 4.98 | G34: 5.02 | H34: 4.98 | I34: 4.96 | J34: 4.95 | K34: 4.92 | L34: 4.89 | M34: 4.89 | N34: 4.87 | O34: 4.8
O35: sigue…
A36: continúa C.6
A37: Especie/ producto | B37: Variable | C37: Anual | D37: Ene | E37: Feb | F37: Mar | G37: Abr | H37: May | I37: Jun | J37: Jul | K37: Ago | L37: Set | M37: Oct | N37: Nov | O37: Dic
A38: Llama | B38: Población | C38: 1092770.7
B39: Saca (Unidades) | C39: =SUM(D39:O39) -> 113685.48 | D39: 8109 | E39: 9264 | F39: 9732.5 | G39: 10326 | H39: 10020.12 | I39: 10521.82 | J39: 10442.2 | K39: 9835.3 | L39: 9010 | M39: 8463.54 | N39: 8516 | O39: 9445
B40: Producción carne (t) | C40: =SUM(D40:O40) -> 3818.352 | D40: 269.3921 | E40: 308.61304 | F40: 322.00654 | G40: 359.60536 | H40: 346.47366 | I40: 361.73254 | J40: 353.22221 | K40: 328.99652 | L40: 301.24878 | M40: 284.44055 | N40: 276.72933 | O40: 305.89131
B41: Rendimiento (Kg/Unidad) | C41: =(C40/C39)*1000 -> 33.58698 | D41: =D40/D39*1000 -> 33.221371 | E41: =E40/E39*1000 -> 33.313152 | F41: =F40/F39*1000 -> 33.085697 | G41: =G40/G39*1000 -> 34.825234 | H41: =H40/H39*1000 -> 34.577796 | I41: =I40/I39*1000 -> 34.379274 | J41: =J40/J39*1000 -> 33.826416 | K41: =K40/K39*1000 -> 33.450583 | ... O41: =O40/O39*1000 -> 32.386587
B42: Precio (S/ x Kg) 1/ | C42: 4.28 | D42: 4.27 | E42: 4.3 | F42: 4.29 | G42: 4.33 | H42: 4.31 | I42: 4.29 | J42: 4.26 | K42: 4.25 | L42: 4.25 | M42: 4.22 | N42: 4.21 | O42: 4.22
...

Sheet C 7
A2: C.7 PERÚ: PRODUCCIÓN PECUARIA POR ESPECIE, SEGÚN REGIÓN, 2020P
A3: (Unidades)
A5: Región | B5: Ave | C5: Ovino | D5: Porcino | E5: Vacuno | F5: Caprino | G5: Alpaca | H5: Llama
A6: Nacional | B6: =(B8+B9+B10+B11+B12+B16+B17+B18+B19+B20+B21+B22+B23+B24+B25+B26+B27+B28+B31+B32+B33+B34+B35+B36) -> 7.5360234e+08 | C6: =(C8+C9+C10+C11+C12+C16+C17+C18+C19+C20+C21+C22+C23+C24+C25+C26+C27+C28+C31+C32+C33+C34+C35+C36) -> 2544650.7 | D6: =(D8+D9+D10+D11+D12+D16+D17+D18+D19+D20+D21+D22+D23+D24+D25+D26+D27+D28+D31+D32+D33+D34+D35+D36) -> 3191164.1 | E6: =(E8+E9+E10+E11+E12+E16+E17+E18+E19+E20+E21+E22+E23+E24+E25+E26+E27+E28+E31+E32+E33+E34+E35+E36) -> 1250069 | F6: =(F8+F9+F10+F11+F12+F16+F17+F18+F19+F20+F21+F22+F23+F24+F25+F26+F27+F28+F31+F32+F33+F34+F35+F36) -> 392865.58 | G6: =(G8+G9+G10+G11+G12+G16+G17+G18+G19+G20+G21+G22+G23+G24+G25+G26+G27+G28+G31+G32+G33+G34+G35+G36) -> 464229.43 | H6: =(H8+H9+H10+H11+H12+H16+H17+H18+H19+H20+H21+H22+H23+H24+H25+H26+H27+H28+H31+H32+H33+H34+H35+H36) -> 113685.48
A8: Tumbes | B8: 100948.61 | C8: 2585 | D8: 6827.8 | E8: 4115.21 | F8: 18938.32 | G8: 0 | H8: 0
A9: Piura | B9: 14541835 | C9: 115546.38 | D9: 114836.54 | E9: 47306.123 | F9: 95060 | G9: 0 | H9: 0
A10: Lambayeque | B10: 11620617 | C10: 29877.52 | D10: 29989.18 | E10: 19737.6 | F10: 22921.44 | G10: 0 | H10: 0
A11: La Libertad | B11: 1.3730516e+08 | C11: 192047 | D11: 326814 | E11: 60576 | F11: 37143 | G11: 1394 | H11: 0
A12: Cajamarca | B12: 1742873.7 | C12: 79719 | D12: 131905 | E12: 165617 | F12: 23891.62 | G12: 0 | H12: 0
A13: Cajamarca | B13: 1105896.5 | C13: 55394 | D13: 53946 | E13: 85203 | F13: 12615 | G13: 0 | H13: 0
A14: Chota | B14: 307028.04 | C14: 19568 | D14: 41348 | E14: 50035 | F14: 1379.62 | G14: 0 | H14: 0
A15: Jaén | B15: 329949.08 | C15: 4757 | D15: 36611 | E15: 30379 | F15: 9897 | G15: 0 | H15: 0
A16: Amazonas | B16: 394488.31 | C16: 2948 | D16: 30202 | E16: 54126 | F16: 4182 | G16: 0 | H16: 0
A17: Ancash | B17: 16264595 | C17: 132083 | D17: 49768 | E17: 68633 | F17: 19925 | G17: 391 | H17: 0
A18: Lima | B18: 3.9272628e+08 | C18: 57495 | D18: 1147785.7 | E18: 106805 | F18: 37543 | G18: 2694 | H18: 2296
A19: Ica | B19: 44486452 | C19: 10985 | D19: 218375 | E19: 15834 | F19: 19360 | G19: 0 | H19: 0
... A36: Madre de Dios | B36: 4244124.4 | C36: 2043 | D36: 17486 | E36: 12717 | F36: 0 | G36: 0 | H36: 0
A37: P Preliminar
A38: Fuente: Direcciones Regionales de Agricultura
A39: Elaboración: Ministerio de Desarrollo Agrario y Riego - DGESEP - DEIA

Sheet C 8
A2: C.8 PERÚ: PRODUCCIÓN DE CARNES POR ESPECIE, SEGÚN REGIÓN, 2020P
A3: (Toneladas)
A5: Región | B5: Ave | C5: Ovino | D5: Porcino | E5: Vacuno | F5: Caprino | G5: Alpaca | H5: Llama
A6: Nacional | B6: =(B8+B9+B10+B11+B12+B16+B17+B18+B19+B20+B21+B22+B23+B24+B25+B26+B27+B28+B31+B32+B33+B34+B35+B36) -> 1723497.5 | C6: =(C8+C9+C10+C11+C12+C16+C17+C18+C19+C20+C21+C22+C23+C24+C25+C26+C27+C28+C31+C32+C33+C34+C35+C36) -> 32310.988 | D6: =(D8+D9+D10+D11+D12+D16+D17+D18+D19+D20+D21+D22+D23+D24+D25+D26+D27+D28+D31+D32+D33+D34+D35+D36) -> 169804.68 | E6: =(E8+E9+E10+E11+E12+E16+E17+E18+E19+E20+E21+E22+E23+E24+E25+E26+E27+E28+E31+E32+E33+E34+E35+E36) -> 183941.13 | F6: =(F8+F9+F10+F11+F12+F16+F17+F18+F19+F20+F21+F22+F23+F24+F25+F26+F27+F28+F31+F32+F33+F34+F35+F36) -> 4957.3536 | G6: =(G8+G9+G10+G11+G12+G16+G17+G18+G19+G20+G21+G22+G23+G24+G25+G26+G27+G28+G31+G32+G33+G34+G35+G36) -> 12362.63 | H6: =(H8+H9+H10+H11+H12+H16+H17+H18+H19+H20+H21+H22+H23+H24+H25+H26+H27+H28+H31+H32+H33+H34+H35+H36) -> 3818.352
A8: Tumbes | B8: 253.11027 | C8: 29.791768 | D8: 332.68621 | E8: 627.00292 | F8: 203.86113 | G8: 0 | H8: 0
A9: Piura | B9: 32603.805 | C9: 1615.8147 | D9: 6006.9631 | E9: 7051.1532 | F9: 1306.847 | G9: 0 | H9: 0
A10: Lambayeque | B10: 25696.715 | C10: 476.24322 | D10: 1625.3261 | E10: 2872.9791 | F10: 344.65964 | G10: 0 | H10: 0
A11: La Libertad | B11: 309576.61 | C11: 2545.5254 | D11: 18996.627 | E11: 8574.3473 | F11: 455.7058 | G11: 43.434243 | H11: 0
A12: Cajamarca | B12: 3679.7746 | C12: 907.51533 | D12: 5721.8283 | E12: 21897.775 | F12: 256.92216 | G12: 0 | H12: 0
A13: Cajamarca | B13: 2373.7829 | C13: 596.42185 | D13: 1953.6544 | E13: 10407.211 | F13: 140.42062 | G13: 0 | H13: 0
A14: Chota | B14: 632.48005 | C14: 264.94776 | D14: 1987.9771 | E14: 6922.8868 | F14: 16.969734 | G14: 0 | H14: 0
A15: Jaén | B15: 673.51168 | C15: 46.14572 | D15: 1780.1967 | E15: 4567.677 | F15: 99.531805 | G15: 0 | H15: 0
A16: Amazonas | B16: 816.72477 | C16: 46.8512 | D16: 1707.2014 | E16: 8181.5494 | F16: 52.8744 | G16: 0 | H16: 0
A17: Ancash | B17: 37251.835 | C17: 1275.2907 | D17: 1605.4004 | E17: 9772.9746 | F17: 213.96908 | G17: 10.036891 | H17: 0
A18: Lima | B18: 920320.72 | C18: 705.27152 | D18: 73425.731 | E18: 20562.92 | F18: 498.62511 | G18: 73.473435 | H18: 68.831775
A19: Ica | B19: 96610.451 | C19: 130.74823 | D19: 11271.689 | E19: 2158.732 | F19: 280.42021 | G19: 0 | H19: 0
... A36: Madre de Dios | B36: 9412.4821 | C36: 32.7436 | D36: 1107.8706 | E36: 2061.5452 | F36: 0 | G36: 0 | H36: 0
A37: P Preliminar
A38: Fuente: Direcciones Regionales de Agricultura
A39: Elaboración: Ministerio de Desarrollo Agrario y Riego - DGESEP - DEIA

Sheet C 9
A2: C.9 PERÚ: RENDIMIENTO DE CARNES POR ESPECIE, SEGÚN REGIÓN, 2020P
A3: (Kg/Unidad )
A5: Región | B5: Ave | C5: Ovino | D5: Porcino | E5: Vacuno | F5: Caprino | G5: Alpaca | H5: Llama
A6: Nacional | B6: =('C 8'!B6/'C 7'!B6)*1000 -> 2.2870118 | C6: =('C 8'!C6/'C 7'!C6)*1000 -> 12.697612 | D6: =('C 8'!D6/'C 7'!D6)*1000 -> 53.21089 | E6: =('C 8'!E6/'C 7'!E6)*1000 -> 147.14478 | F6: =('C 8'!F6/'C 7'!F6)*1000 -> 12.618447 | G6: =('C 8'!G6/'C 7'!G6)*1000 -> 26.630431 | H6: =('C 8'!H6/'C 7'!H6)*1000 -> 33.58698
A8: Tumbes | B8: =('C 8'!B8/'C 7'!B8)*1000 -> 2.5073181 | C8: =('C 8'!C8/'C 7'!C8)*1000 -> 11.524862 | D8: =('C 8'!D8/'C 7'!D8)*1000 -> 48.725242 | E8: ='C 8'!E8/'C 7'!E8*1000 -> 152.36231 | F8: =('C 8'!F8/'C 7'!F8)*1000 -> 10.764478 | G8: 0 | H8: 0 | I8: -
A9: Piura | B9: =('C 8'!B9/'C 7'!B9)*1000 -> 2.2420696 | C9: =('C 8'!C9/'C 7'!C9)*1000 -> 13.984122 | D9: =('C 8'!D9/'C 7'!D9)*1000 -> 52.308814 | E9: =('C 8'!E9/'C 7'!E9)*1000 -> 149.05371 | F9: =('C 8'!F9/'C 7'!F9)*1000 -> 13.747601 | G9: 0 | H9: 0
A10: Lambayeque | B10: =('C 8'!B10/'C 7'!B10)*1000 -> 2.2113038 | C10: =('C 8'!C10/'C 7'!C10)*1000 -> 15.939851 | D10: =('C 8'!D10/'C 7'!D10)*1000 -> 54.197085 | E10: =('C 8'!E10/'C 7'!E10)*1000 -> 145.55869 | F10: =('C 8'!F10/'C 7'!F10)*1000 -> 15.036562 | G10: 0 | H10: 0
A11: La Libertad | B11: =('C 8'!B11/'C 7'!B11)*1000 -> 2.2546611 | C11: =('C 8'!C11/'C 7'!C11)*1000 -> 13.2547 | D11: =('C 8'!D11/'C 7'!D11)*1000 -> 58.126724 | E11: =('C 8'!E11/'C 7'!E11)*1000 -> 141.54694 | F11: =('C 8'!F11/'C 7'!F11)*1000 -> 12.268955 | G11: =('C 8'!G11/'C 7'!G11)*1000 -> 31.157994 | H11: 0
A12: Cajamarca | B12: =('C 8'!B12/'C 7'!B12)*1000 -> 2.1113261 | C12: =('C 8'!C12/'C 7'!C12)*1000 -> 11.383928 | D12: =('C 8'!D12/'C 7'!D12)*1000 -> 43.378403 | E12: =('C 8'!E12/'C 7'!E12)*1000 -> 132.21937 | F12: =('C 8'!F12/'C 7'!F12)*1000 -> 10.753652 | G12: 0 | H12: 0
A13: Cajamarca | B13: =('C 8'!B13/'C 7'!B13)*1000 -> 2.1464783 | C13: =('C 8'!C13/'C 7'!C13)*1000 -> 10.766903 | D13: =('C 8'!D13/'C 7'!D13)*1000 -> 36.215 | E13: =('C 8'!E13/'C 7'!E13)*1000 -> 122.14607 | F13: =('C 8'!F13/'C 7'!F13)*1000 -> 11.131242 | G13: 0 | H13: 0
A14: Chota | B14: =('C 8'!B14/'C 7'!B14)*1000 -> 2.0600074 | C14: =('C 8'!C14/'C 7'!C14)*1000 -> 13.539849 | D14: =('C 8'!D14/'C 7'!D14)*1000 -> 48.079161 | E14: =('C 8'!E14/'C 7'!E14)*1000 -> 138.36088 | F14: =('C 8'!F14/'C 7'!F14)*1000 -> 12.300296 | G14: 0 | H14: 0
A15: Jaén | B15: =('C 8'!B15/'C 7'!B15)*1000 -> 2.0412595 | C15: =('C 8'!C15/'C 7'!C15)*1000 -> 9.7005929 | D15: =('C 8'!D15/'C 7'!D15)*1000 -> 48.624641 | E15: =('C 8'!E15/'C 7'!E15)*1000 -> 150.3564 | F15: =('C 8'!F15/'C 7'!F15)*1000 -> 10.056765 | G15: 0 | H15: 0
A16: Amazonas | B16: =('C 8'!B16/'C 7'!B16)*1000 -> 2.0703396 | C16: =('C 8'!C16/'C 7'!C16)*1000 -> 15.892537 | D16: =('C 8'!D16/'C 7'!D16)*1000 -> 56.526103 | E16: =('C 8'!E16/'C 7'!E16)*1000 -> 151.15747 | F16: =('C 8'!F16/'C 7'!F16)*1000 -> 12.643329 | G16: 0 | H16: 0
A17: Ancash | B17: =('C 8'!B17/'C 7'!B17)*1000 -> 2.2903635 | C17: =('C 8'!C17/'C 7'!C17)*1000 -> 9.655222 | D17: =('C 8'!D17/'C 7'!D17)*1000 -> 32.257683 | E17: =('C 8'!E17/'C 7'!E17)*1000 -> 142.39469 | F17: =('C 8'!F17/'C 7'!F17)*1000 -> 10.738724 | G17: =('C 8'!G17/'C 7'!G17)*1000 -> 25.669799 | H17: 0
A18: Lima | B18: =('C 8'!B18/'C 7'!B18)*1000 -> 2.3434151 | C18: =('C 8'!C18/'C 7'!C18)*1000 -> 12.266658 | D18: =('C 8'!D18/'C 7'!D18)*1000 -> 63.97164 | E18: =('C 8'!E18/'C 7'!E18)*1000 -> 192.5277 | F18: =('C 8'!F18/'C 7'!F18)*1000 -> 13.28144 | G18: =('C 8'!G18/'C 7'!G18)*1000 -> 27.27299 | H18: =('C 8'!H18/'C 7'!H18)*1000 -> 29.978996
A19: Ica | B19: =('C 8'!B19/'C 7'!B19)*1000 -> 2.1716825 | C19: =('C 8'!C19/'C 7'!C19)*1000 -> 11.902434 | D19: =('C 8'!D19/'C 7'!D19)*1000 -> 51.616206 | E19: =('C 8'!E19/'C 7'!E19)*1000 -> 136.33523 | F19: =('C 8'!F19/'C 7'!F19)*1000 -> 14.484515 | G19: 0 | H19: 0
A20: Huánuco | B20: =('C 8'!B20/'C 7'!B20)*1000 -> 2.0760786 | C20: =('C 8'!C20/'C 7'!C20)*1000 -> 11.23413 | D20: =('C 8'!D20/'C 7'!D20)*1000 -> 35.442513 | E20: =('C 8'!E20/'C 7'!E20)*1000 -> 167.86276 | F20: =('C 8'!F20/'C 7'!F20)*1000 -> 10.281768 | G20: =('C 8'!G20/'C 7'!G20)*1000 -> 26.333364 | H20: 0
A21: Pasco | B21: =('C 8'!B21/'C 7'!B21)*1000 -> 2.1400884 | C21: =('C 8'!C21/'C 7'!C21)*1000 -> 12.484944 | D21: =('C 8'!D21/'C 7'!D21)*1000 -> 36.586599 | E21: =('C 8'!E21/'C 7'!E21)*1000 -> 160.50904 | F21: =('C 8'!F21/'C 7'!F21)*1000 -> 11.516306 | G21: =('C 8'!G21/'C 7'!G21)*1000 -> 21.896224 | H21: =('C 8'!H21/'C 7'!H21)*1000 -> 27.987284
A22: Junín | B22: =('C 8'!B22/'C 7'!B22)*1000 -> 2.2330118 | C22: =('C 8'!C22/'C 7'!C22)*1000 -> 10.741145 | D22: =('C 8'!D22/'C 7'!D22)*1000 -> 44.55075 | E22: =('C 8'!E22/'C 7'!E22)*1000 -> 131.24322 | F22: =('C 8'!F22/'C 7'!F22)*1000 -> 11.325165 | G22: =('C 8'!G22/'C 7'!G22)*1000 -> 22.386266 | H22: =('C 8'!H22/'C 7'!H22)*1000 -> 27.552146
A23: Huancavelica | B23: =('C 8'!B23/'C 7'!B23)*1000 -> 2.03487 | C23: =('C 8'!C23/'C 7'!C23)*1000 -> 13.496113 | D23: =('C 8'!D23/'C 7'!D23)*1000 -> 38.877429 | E23: =('C 8'!E23/'C 7'!E23)*1000 -> 116.27745 | F23: =('C 8'!F23/'C 7'!F23)*1000 -> 13.194386 | G23: =('C 8'!G23/'C 7'!G23)*1000 -> 25.999276 | H23: =('C 8'!H23/'C 7'!H23)*1000 -> 33.978729
A24: Arequipa | B24: =('C 8'!B24/'C 7'!B24)*1000 -> 2.2113093 | C24: =('C 8'!C24/'C 7'!C24)*1000 -> 14.580505 | D24: =('C 8'!D24/'C 7'!D24)*1000 -> 56.044835 | E24: =('C 8'!E24/'C 7'!E24)*1000 -> 163.36053 | F24: =('C 8'!F24/'C 7'!F24)*1000 -> 12.212188 | G24: =('C 8'!G24/'C 7'!G24)*1000 -> 24.548749 | H24: =('C 8'!H24/'C 7'!H24)*1000 -> 34.490646
A25: Moquegua | B25: =('C 8'!B25/'C 7'!B25)*1000 -> 2.0635919 | C25: =('C 8'!C25/'C 7'!C25)*1000 -> 19.249974 | D25: =('C 8'!D25/'C 7'!D25)*1000 -> 47.342332 | E25: =('C 8'!E25/'C 7'!E25)*1000 -> 206.53076 | F25: =('C 8'!F25/'C 7'!F25)*1000 -> 16.635244 | G25: =('C 8'!G25/'C 7'!G25)*1000 -> 31.235426 | H25: =('C 8'!H25/'C 7'!H25)*1000 -> 42.82171
A26: Tacna | B26: =('C 8'!B26/'C 7'!B26)*1000 -> 2.2914593 | C26: =('C 8'!C26/'C 7'!C26)*1000 -> 23.260524 | D26: =('C 8'!D26/'C 7'!D26)*1000 -> 40.143288 | E26: =('C 8'!E26/'C 7'!E26)*1000 -> 190.71608 | F26: =('C 8'!F26/'C 7'!F26)*1000 -> 14.886726 | G26: =('C 8'!G26/'C 7'!G26)*1000 -> 28.463639 | H26: =('C 8'!H26/'C 7'!H26)*1000 -> 29.445232
A27: Ayacucho | B27: =('C 8'!B27/'C 7'!B27)*1000 -> 2.0626968 | C27: =('C 8'!C27/'C 7'!C27)*1000 -> 11.744101 | D27: =('C 8'!D27/'C 7'!D27)*1000 -> 44.899494 | E27: =('C 8'!E27/'C 7'!E27)*1000 -> 123.34209 | F27: =('C 8'!F27/'C 7'!F27)*1000 -> 11.720316 | G27: =('C 8'!G27/'C 7'!G27)*1000 -> 26.911491 | H27: =('C 8'!H27/'C 7'!H27)*1000 -> 29.614371
A28: Apurímac | B28: =('C 8'!B28/'C 7'!B28)*1000 -> 2.0013809 | C28: =('C 8'!C28/'C 7'!C28)*1000 -> 11.277563 | D28: =('C 8'!D28/'C 7'!D28)*1000 -> 38.89589 | E28: =('C 8'!E28/'C 7'!E28)*1000 -> 110.55161 | F28: =('C 8'!F28/'C 7'!F28)*1000 -> 10.543656 | G28: =('C 8'!G28/'C 7'!G28)*1000 -> 24.255781 | H28: =('C 8'!H28/'C 7'!H28)*1000 -> 30.047484
A29: Abancay | B29: =('C 8'!B29/'C 7'!B29)*1000 -> 2.0103034 | C29: =('C 8'!C29/'C 7'!C29)*1000 -> 11.828433 | D29: =('C 8'!D29/'C 7'!D29)*1000 -> 36.56015 | E29: =('C 8'!E29/'C 7'!E29)*1000 -> 113.6524 | F29: =('C 8'!F29/'C 7'!F29)*1000 -> 10.739684 | G29: =('C 8'!G29/'C 7'!G29)*1000 -> 24.763179 | H29: =('C 8'!H29/'C 7'!H29)*1000 -> 30.855738
A30: Andahuaylas | B30: =('C 8'!B30/'C 7'!B30)*1000 -> 1.9877572 | C30: =('C 8'!C30/'C 7'!C30)*1000 -> 10.692459 | D30: =('C 8'!D30/'C 7'!D30)*1000 -> 40.230823 | E30: =('C 8'!E30/'C 7'!E30)*1000 -> 107.39706 | F30: =('C 8'!F30/'C 7'!F30)*1000 -> 10.455073 | G30: =('C 8'!G30/'C 7'!G30)*1000 -> 23.188496 | H30: =('C 8'!H30/'C 7'!H30)*1000 -> 29.247136
A31: Cusco | B31: =('C 8'!B31/'C 7'!B31)*1000 -> 2.1531972 | C31: =('C 8'!C31/'C 7'!C31)*1000 -> 12.682441 | D31: =('C 8'!D31/'C 7'!D31)*1000 -> 43.164651 | E31: =('C 8'!E31/'C 7'!E31)*1000 -> 152.77604 | F31: =('C 8'!F31/'C 7'!F31)*1000 -> 12.822769 | G31: =('C 8'!G31/'C 7'!G31)*1000 -> 26.644636 | H31: =('C 8'!H31/'C 7'!H31)*1000 -> 29.644704
A32: Puno | B32: =('C 8'!B32/'C 7'!B32)*1000 -> 2.000433 | C32: =('C 8'!C32/'C 7'!C32)*1000 -> 13.915551 | D32: =('C 8'!D32/'C 7'!D32)*1000 -> 33.665354 | E32: =('C 8'!E32/'C 7'!E32)*1000 -> 143.78144 | F32: 0 | G32: =('C 8'!G32/'C 7'!G32)*1000 -> 27.712455 | H32: =('C 8'!H32/'C 7'!H32)*1000 -> 38.737677
A33: San Martín | B33: =('C 8'!B33/'C 7'!B33)*1000 -> 2.1989427 | C33: =('C 8'!C33/'C 7'!C33)*1000 -> 11.094977 | D33: =('C 8'!D33/'C 7'!D33)*1000 -> 41.986596 | E33: =('C 8'!E33/'C 7'!E33)*1000 -> 133.62624 | F33: 0 | G33: 0 | H33: 0
A34: Loreto | B34: =('C 8'!B34/'C 7'!B34)*1000 -> 2.2115663 | C34: =('C 8'!C34/'C 7'!C34)*1000 -> 12.930233 | D34: =('C 8'!D34/'C 7'!D34)*1000 -> 45.816782 | E34: =('C 8'!E34/'C 7'!E34)*1000 -> 133.95768 | F34: 0 | G34: 0 | H34: 0
A35: Ucayali | B35: =('C 8'!B35/'C 7'!B35)*1000 -> 2.1537397 | C35: =('C 8'!C35/'C 7'!C35)*1000 -> 10.556676 | D35: =('C 8'!D35/'C 7'!D35)*1000 -> 45.15856 | E35: =('C 8'!E35/'C 7'!E35)*1000 -> 126.37458 | F35: 0 | G35: 0 | H35: 0
A36: Madre de Dios | B36: =('C 8'!B36/'C 7'!B36)*1000 -> 2.2177677 | C36: =('C 8'!C36/'C 7'!C36)*1000 -> 16.027215 | D36: =('C 8'!D36/'C 7'!D36)*1000 -> 63.357575 | E36: =('C 8'!E36/'C 7'!E36)*1000 -> 162.10939 | F36: 0 | G36: 0 | H36: 0
A37: P Preliminar
A38: Fuente: Direcciones Regionales de Agricultura
A39: Elaboración: Ministerio de Desarrollo Agrario y Riego - DGESEP - DEIA

Sheet C 10
A2: C.10 PERÚ: ESPECIES PECUARIAS EN PRODUCCIÓN Y ANIMALES ESQUILADOS POR ESPECIE, SEGÚN REGIÓN, 2020P
A3: (Unidades)
A5: Región | B5: Gallinas en Postura | C5: Vacas en Ordeño | D5: Alpacas esquiladas | E5: LLamas esquiladas | F5: Ovinos esquilados
A6: Nacional | B6: =(B8+B9+B10+B11+B12+B16++B17+B18+B19+B20+B21+B22+B23+B24+B25+B26+B27+B28+B31+B32+B33+B34+B35+B36) -> 29325849 | C6: =(C8+C9+C10+C11+C12+C16++C17+C18+C19+C20+C21+C22+C23+C24+C25+C26+C27+C28+C31+C32+C33+C34+C35+C36) -> 906688.63 | D6: =(D8+D9+D10+D11+D12+D16++D17+D18+D19+D20+D21+D22+D23+D24+D25+D26+D27+D28+D31+D32+D33+D34+D35+D36) -> 2131029 | E6: =(E8+E9+E10+E11+E12+E16++E17+E18+E19+E20+E21+E22+E23+E24+E25+E26+E27+E28+E31+E32+E33+E34+E35+E36) -> 331804.37 | F6: =(F8+F9+F10+F11+F12+F16++F17+F18+F19+F20+F21+F22+F23+F24+F25+F26+F27+F28+F31+F32+F33+F34+F35+F36) -> 4099800.6
A8: Tumbes | B8: 15260.655 | C8: 310.45 | D8: 0 | E8: 0 | F8: 0
A9: Piura | B9: 391273.16 | C9: 24007.677 | D9: 56 | E9: 0 | F9: 23964
A10: Lambayeque | B10: 499455.72 | C10: 17819.717 | D10: 0 | E10: 0 | F10: 0
A11: La Libertad | B11: 4899576.3 | C11: 49775 | D11: 6479 | E11: 0 | F11: 252084
A12: Cajamarca | B12: 425471.93 | C12: 164025.34 | D12: 0 | E12: 0 | F12: 158054
A13: Cajamarca | B13: 206410.29 | C13: 99168.333 | D13: 0 | E13: 0 | F13: 120763.5
A14: Chota | B14: 143234.26 | C14: 59224.253 | D14: 0 | E14: 0 | F14: 37290.5
A15: Jaén | B15: 75827.371 | C15: 5632.75 | D15: 0 | E15: 0 | F15: 0
A16: Amazonas | B16: 129176.53 | C16: 79621.833 | D16: 0 | E16: 0 | F16: 6041
A17: Ancash | B17: 207275.47 | C17: 14894.083 | D17: 0 | E17: 0 | F17: 6515
A18: Lima | B18: 7463067.3 | C18: 71842.292 | D18: 17667.42 | E18: 1792 | F18: 84125
A19: Ica | B19: 10644513 | C19: 14028.083 | D19: 0 | E19: 0 | F19: 0
... A36: Madre de Dios | B36: 212380.47 | C36: 1005.6667 | D36: 0 | E36: 0 | F36: 0
A37: P Preliminar
A38: Fuente: Direcciones Regionales de Agricultura
A39: Elaboración: Ministerio de Desarrollo Agrario y Riego - DGESEP - DEIA

Sheet C 11
A2: C.11 PERÚ: PRODUCCIÓN DE PRINCIPALES PRODUCTOS PECUARIOS SEGÚN REGIÓN, 2020P
A3: (Toneladas)
A5: Región | B5: Huevo gallina | C5: Leche fresca | D5: Fibra Alpaca | E5: Fibra Llama | F5: Lana ovino
A6: Nacional | B6: =(B8+B9+B10+B11+B12+B16++B17+B18+B19+B20+B21+B22+B23+B24+B25+B26+B27+B28+B31+B32+B33+B34+B35+B36) -> 497525.39 | C6: =(C8+C9+C10+C11+C12+C16++C17+C18+C19+C20+C21+C22+C23+C24+C25+C26+C27+C28+C31+C32+C33+C34+C35+C36) -> 2135881.3 | D6: =(D8+D9+D10+D11+D12+D16++D17+D18+D19+D20+D21+D22+D23+D24+D25+D26+D27+D28+D31+D32+D33+D34+D35+D36) -> 4351.6747 | E6: =(E8+E9+E10+E11+E12+E16++E17+E18+E19+E20+E21+E22+E23+E24+E25+E26+E27+E28+E31+E32+E33+E34+E35+E36) -> 664.55614 | F6: =(F8+F9+F10+F11+F12+F16++F17+F18+F19+F20+F21+F22+F23+F24+F25+F26+F27+F28+F31+F32+F33+F34+F35+F36) -> 7466.402
A8: Tumbes | B8: 100.7665 | C8: 343.13043 | D8: 0 | E8: 0 | F8: 0
A9: Piura | B9: 4715.9462 | C9: 42903.995 | D9: 0.0745205 | E9: 0 | F9: 25.021439
A10: Lambayeque | B10: 7811.0701 | C10: 54175.979 | D10: 0 | E10: 0 | F10: 0
A11: La Libertad | B11: 86530.85 | C11: 157622.84 | D11: 18.554976 | E11: 0 | F11: 745.2646
A12: Cajamarca | B12: 2364.8413 | C12: 367230.59 | D12: 0 | E12: 0 | F12: 271.59382
A13: Cajamarca | B13: 1340.7068 | C13: 225330.28 | D13: 0 | E13: 0 | F13: 217.9815
A14: Chota | B14: 664.21623 | C14: 132792.26 | D14: 0 | E14: 0 | F14: 53.61232
A15: Jaén | B15: 359.91819 | C15: 9108.054 | D15: 0 | E15: 0 | F15: 0
A16: Amazonas | B16: 1446.1817 | C16: 100570.05 | D16: 0 | E16: 0 | F16: 3.8134152
A17: Ancash | B17: 1354.9921 | C17: 18261.065 | D17: 0 | E17: 0 | F17: 9.223
A18: Lima | B18: 134863.95 | C18: 362239.61 | D18: 26.269337 | E18: 2.4248128 | F18: 109.95337
A19: Ica | B19: 200811.02 | C19: 78920.453 | D19: 0 | E19: 0 | F19: 0
