Workbook
Name \c: #REF!
Name \x: 'C 5'!$AF$3
Name \x: #REF!
Name A: 'C 5'!$W$21:$DC$21
Name A: #REF!
Name A_IMPRESION_IM: 'C 91 - 99'!#REF!
Name A_IMPRESION_IM: #REF!
Name A_impresión_IM: 'C 100 - 101'!$A$1:$K$50
Name A_impresión_IM: 'C 102 - 103'!$A$1:$I$45
Name A_impresión_IM: 'C 104-105'!$A$1:$K$51
Name A_impresión_IM: 'C 106 - 107'!$A$1:$H$45
Name A_impresión_IM: 'C 108 - 109 '!#REF!
Name A_IMPRESIÓN_IM: [1]CYPPOLLO!#REF!
Name A_IMPRESIÓN_IM: [1]CYPPOLLO!#REF!
Name A_IMPRESIÓN_IM: [1]CYPPOLLO!#REF!
Name A_impresión_IM: #REF!
Name A_impresión_IM: 'C 90'!$A$1:$D$44
Name A_IMPRESIÓN_IM: 'C 91 - 99'!$A$3:$DH$40
Name A_IMPRESIÓN_IM: [1]CYPPOLLO!#REF!
Name A_impresión_IM: #REF!
Name A_impresión_IM: 'C-88'!$A$1:$D$44
Name A_impresión_IM: 'C-89'!$A$1:$D$44
Name A_impresión_IM: #REF!

Sheet 1. INDICADORES ECONÓMICOS

Sheet C 1 - C 2 - C 3
A2: C.1 PERÚ: EVOLUCIÓN DEL VALOR BRUTO DE LA PRODUDUCCIÓN (VBP) AGROPECUARIA POR SUBSECTORES Y | AO2: Tasa
A3: PRINCIPALES ESPECIES Y PRODUCTOS, 2007-19.
A4: (Millones de soles a precios 2007) | AO4: Crec.
A6: Sector / Producto | C6: 2000 | D6: 2001 | E6: 2002 | F6: 2003 | G6: 2004 | H6: 2005 | I6: 2006 | J6: 2007 | K6: 2008 | L6: 2009 | M6: 2010 | N6: 2011 | O6: 2012 | P6: 2013 | Q6: 2014 | R6: 2015 | S6: 2016 | T6: 2017 | U6: 2018 P | V6: 2019P | W6: Var. % 19/18
A7: Sector agropecuario | C7: 17474.3 | D7: 17601.8 | E7: 18603.6 | F7: 18969.3 | G7: 19096 | H7: 20511.9 | I7: 22151.7 | J7: 22808.2 | K7: 24741.8 | L7: 25379.1 | M7: 26407.4 | N7: 27861.2 | O7: 29538.1 | P7: 30131.9 | Q7: 30698.2 | R7: 31894 | S7: 32592.3 | T7: 33502.4 | U7: 36117.6 | V7: 37262.5 | W7: =((V7/U7)-1)*100 -> 3.1699227 | AO7: 3.9
A8: Subsector agrícola | C8: 11577.1 | D8: 11537.3 | E8: 12282.8 | F8: 12444.9 | G8: 12391.7 | H8: 13289.3 | I8: 14340.7 | J8: 14533.2 | K8: 15862.1 | L8: 15991.2 | M8: 16616 | N8: 17377.3 | O8: 18471.3 | P8: 18672.8 | Q8: 18833.5 | R8: 19407.9 | S8: 19601 | T8: 20149 | U8: 22019.3 | V8: 22592.8 | W8: =((V8/U8)-1)*100 -> 2.6045333 | AO8: 3.3
A9: Subsector pecuario | C9: 5897.2 | D9: 6064.5 | E9: 6320.8 | F9: 6524.4 | G9: 6704.3 | H9: 7222.6 | I9: 7811 | J9: 8275 | K9: 8879.7 | L9: 9387.9 | M9: 9791.4 | N9: 10483.9 | O9: 11066.7 | P9: 11459.1 | Q9: 11864.7 | R9: 12486.1 | S9: 12991.3 | T9: 13353.4 | U9: 14098.3 | V9: 14669.7 | W9: =((V9/U9)-1)*100 -> 4.0529709 | AO9: 4.9
B11: Industria avícola 1 | C11: =SUM(C12:C14) -> 2892.6 | D11: =SUM(D12:D14) -> 2958.5 | E11: =SUM(E12:E14) -> 3140.9 | F11: =SUM(F12:F14) -> 3262.9 | G11: =SUM(G12:G14) -> 3280.1 | H11: =SUM(H12:H14) -> 3623.2 | I11: =SUM(I12:I14) -> 4017.6 | J11: =J12+J14 -> 4330.6 | K11: =K12+K14 -> 4847.7 | L11: =L12+L14 -> 5254.6 | M11: =M12+M14 -> 5560.1 | N11: =N12+N14 -> 6092.8 | O11: =O12+O14 -> 6526.6 | P11: =P12+P14 -> 6835.4 | Q11: =Q12+Q14 -> 7152.1 | ... V11: =V12+V14 -> 9596.8 | W11: =((V11/U11)-1)*100 -> 5.0001094 | AO11: 6.5
A12: 1 | B12: Ave | C12: 2340.6 | D12: 2376.6 | E12: 2551.2 | F12: 2651.8 | G12: 2655 | H12: 2983.5 | I12: 3259.4 | J12: 3534.8 | K12: 4024.4 | L12: 4424.6 | M12: 4679.4 | N12: 5111.6 | O12: 5556.6 | P12: 5754.9 | Q12: 6044.3 | R12: 6531.3 | S12: 6945.9 | T12: 7199.8 | U12: 7742.8 | V12: 8087.9 | W12: =((V12/U12)-1)*100 -> 4.457044 | AO12: 6.8
B13: Pollo | J13: 3273.1 | K13: 3727.9 | L13: 4121.7 | M13: 4362.7 | N13: 4582.9 | O13: 5195.8 | P13: 5394.3 | Q13: 5657.9 | R13: 6101.3 | S13: 6448.2 | T13: 6719.3 | U13: 7257.1 | V13: 7579 | W13: =((V13/U13)-1)*100 -> 4.4356561
B14: Huevo de Gallina | C14: 552 | D14: 581.9 | E14: 589.7 | F14: 611.1 | G14: 625.1 | H14: 639.7 | I14: 758.2 | J14: 795.8 | K14: 823.3 | L14: 830 | M14: 880.7 | N14: 981.2 | O14: 970 | P14: 1080.5 | Q14: 1107.8 | R14: 1193.1 | S14: 1238.6 | T14: 1283 | U14: 1397 | V14: 1508.9 | W14: =((V14/U14)-1)*100 -> 8.0100215 | AO14: 5.1
A15: 2 | B15: Ovino | C15: 378.7 | D15: 388.4 | E15: 383.2 | F15: 389.2 | G15: 410.8 | H15: 410.6 | I15: 413.3 | J15: 412.5 | K15: 406.5 | L15: 407.8 | M15: 410.4 | N15: 417.6 | O15: 430.3 | P15: 425.5 | Q15: 419.6 | R15: 404.2 | S15: 413.9 | T15: 407.8 | U15: 410.4 | V15: 411.8 | W15: =((V15/U15)-1)*100 -> 0.3411306 | AO15: 0.4
A16: 3 | B16: Porcino | C16: 433.8 | D16: 442.2 | E16: 438.5 | F16: 439.5 | G16: 468.6 | H16: 494 | I16: 516.6 | J16: 542.7 | K16: 545.9 | L16: 543.6 | M16: 548.1 | N16: 557.2 | O16: 579.8 | P16: 605 | Q16: 641.6 | R16: 677.3 | S16: 708 | T16: 747.5 | U16: 781.6 | V16: 821 | W16: =((V16/U16)-1)*100 -> 5.0409417 | AO16: 3.3
A17: 4 | B17: Vacuno | C17: 1114.1 | D17: 1114.3 | E17: 1147.4 | F17: 1174.2 | G17: 1227.9 | H17: 1304.4 | I17: 1382.1 | J17: 1396.3 | K17: 1397 | L17: 1408.9 | M17: 1470.2 | N17: 1531.9 | O17: 1596.3 | P17: 1651.6 | Q17: 1678.5 | R17: 1676.7 | S17: 1648.4 | T17: 1614.4 | U17: 1622.7 | V17: 1650.2 | W17: =((V17/U17)-1)*100 -> 1.6947064 | AO17: 2.2
A18: 5 | B18: Caprino | C18: 57.6 | D18: 54.4 | E18: 53.3 | F18: 57.9 | G18: 59.5 | H18: 60.8 | I18: 62.3 | J18: 61.5 | K18: 59 | L18: 56.6 | M18: 56.4 | N18: 56.5 | O18: 57.4 | P18: 59.2 | Q18: 56.7 | R18: 54.3 | S18: 53.6 | T18: 50.5 | U18: 45.7 | V18: 46.9 | W18: =((V18/U18)-1)*100 -> 2.6258206 | AO18: -0.7
A19: 6 | B19: Alpaca | C19: 130.1 | D19: 137.3 | E19: 147.3 | F19: 146 | G19: 148.2 | H19: 154.4 | I19: 156.5 | J19: 166.7 | K19: 169.6 | L19: 181.4 | M19: 191.6 | N19: 201.5 | O19: 213.6 | P19: 216.6 | Q19: 224.2 | R19: 212.1 | S19: 221.5 | T19: 226.9 | U19: 225.9 | V19: 223.9 | W19: =((V19/U19)-1)*100 -> -0.8853475 | AO19: 3.3
A20: 7 | B20: Llama | C20: 25.2 | D20: 25.5 | E20: 25.5 | F20: 27.5 | G20: 29.1 | H20: 30.4 | I20: 30.3 | J20: 31.9 | K20: 31.3 | L20: 32.9 | M20: 32.1 | N20: 33.4 | O20: 34.3 | P20: 32.9 | Q20: 32.9 | R20: 31.4 | S20: 31.3 | T20: 31.6 | U20: 31.5 | V20: 30.3 | W20: =((V20/U20)-1)*100 -> -3.8095238 | AO20: 1.3
A21: 9 | B21: Leche Fresca de Vaca | C21: 750.6 | D21: 822.4 | E21: 873.8 | F21: 918.1 | G21: 968.1 | H21: 1027.8 | I21: 1119.3 | J21: 1209.8 | K21: 1301 | L21: 1372.9 | M21: 1394.7 | N21: 1458.8 | O21: 1488 | P21: 1502.3 | Q21: 1529.2 | R21: 1581.5 | S21: 1624 | T21: 1673.4 | U21: 1717.8 | V21: 1769.5 | W21: =((V21/U21)-1)*100 -> 3.0096635 | AO21: 4.8
A22: 10 | B22: Fibra Alpaca | C22: 57 | D22: 62.3 | E22: 58 | F22: 56.9 | G22: 59.6 | H22: 66 | I22: 64.3 | J22: 71.4 | K22: 73.7 | L22: 80.4 | M22: 79.8 | N22: 85.5 | O22: 88 | P22: 81 | Q22: 82.2 | R22: 81.4 | S22: 82.7 | T22: 79.1 | U22: 83.9 | V22: 81.6 | W22: =((V22/U22)-1)*100 -> -2.7413588 | AO22: 1.9
A23: 11 | B23: Fibra Llama | C23: 4.6 | D23: 4.7 | E23: 3.8 | F23: 3.9 | G23: 3.8 | H23: 3.7 | I23: 3.8 | J23: 4.5 | K23: 4.3 | L23: 4.3 | M23: 3.9 | N23: 4.2 | O23: 4.6 | P23: 4.4 | Q23: 4.6 | R23: 4 | S23: 4.1 | T23: 4.2 | U23: 4 | V23: 4 | W23: =((V23/U23)-1)*100 -> 0 | AO23: -0.5
A24: 12 | B24: Lana Ovino | C24: 53.5 | D24: 54.4 | E24: 48.9 | F24: 49 | G24: 48.6 | H24: 47.2 | I24: 44.9 | J24: 47.2 | K24: 43.6 | L24: 44.5 | M24: 44.2 | N24: 44.5 | O24: 47.7 | P24: 45 | Q24: 43.2 | R24: 38.8 | S24: 40.5 | T24: 35.2 | U24: 34.9 | V24: 33.5 | W24: =((V24/U24)-1)*100 -> -4.0114613 | AO24: -2.4
A25: P Preliminar.
A26: 1 Considera ave y huevo de gallina.
A27: Fuente:Direcciones Regionales de Agricultura.
A28: Elaboración: MInisterio de Agricultura y Riego - DGESEP - DEA.
A30: C.2 PERÚ: PARTICIPACIÓN POR SUBSECTORES Y PRINCIPALES ESPECIES Y PRODUCTOS EN EL VALOR BRUTO DE LA PRODUCCIÓN AGROPECUARIA, 2007-19.
A31: (%)
A33: Sector / Producto | C33: 2000 | D33: 2001 | E33: 2002 | F33: 2003 | G33: 2004 | H33: 2005 | I33: 2006 | J33: 2007 | K33: 2008 | L33: 2009 | M33: 2010 | N33: 2011 | O33: 2012 | P33: 2013 | Q33: 2014 | R33: 2015 | S33: 2016 | T33: 2017 | U33: 2018 | V33: 2019P
A34: Sector agropecuario | C34: =C7/$C$7*100 -> 100 | D34: =D7/$D$7*100 -> 100 | E34: =E7/$E$7*100 -> 100 | F34: =F7/$F$7*100 -> 100 | G34: =G7/$G$7*100 -> 100 | H34: =H7/$H$7*100 -> 100 | I34: =I7/$I$7*100 -> 100 | J34: =J7/$J$7*100 -> 100 | K34: =K7/$K$7*100 -> 100 | L34: =L7/$L$7*100 -> 100 | M34: =M7/$M$7*100 -> 100 | N34: =N7/$N$7*100 -> 100 | O34: =O7/$O$7*100 -> 100 | P34: =P7/$P$7*100 -> 100 | Q34: =Q7/$Q$7*100 -> 100 | R34: =R7/$R$7*100 -> 100 | S34: =S7/$S$7*100 -> 100 | T34: =T7/$T$7*100 -> 100 | U34: =U7/$U$7*100 -> 100 | V34: =V7/$V$7*100 -> 100
A35: Subsector agrícola | C35: =C8/$C$7*100 -> 66.252153 | D35: =D8/$D$7*100 -> 65.546137 | E35: =E8/$E$7*100 -> 66.02378 | F35: =F8/$F$7*100 -> 65.605478 | G35: =G8/$G$7*100 -> 64.8916 | H35: =H8/$H$7*100 -> 64.788245 | I35: =I8/$I$7*100 -> 64.738598 | J35: =J8/$J$7*100 -> 63.719189 | K35: =K8/$K$7*100 -> 64.110534 | L35: =L8/$L$7*100 -> 63.009327 | M35: =M8/$M$7*100 -> 62.921757 | N35: =N8/$N$7*100 -> 62.370968 | O35: =O8/$O$7*100 -> 62.533812 | P35: =P8/$P$7*100 -> 61.970204 | Q35: =Q8/$Q$7*100 -> 61.350503 | R35: =R8/$R$7*100 -> 60.851257 | S35: =S8/$S$7*100 -> 60.139972 | T35: =T8/$T$7*100 -> 60.14196 | U35: =U8/$U$7*100 -> 60.965568 | V35: =V8/$V$7*100 -> 60.631466
A36: Subsector pecuario | C36: =C9/$C$7*100 -> 33.747847 | D36: =D9/$D$7*100 -> 34.453863 | E36: =E9/$E$7*100 -> 33.97622 | F36: =F9/$F$7*100 -> 34.394522 | G36: =G9/$G$7*100 -> 35.1084 | H36: =H9/$H$7*100 -> 35.211755 | I36: =I9/$I$7*100 -> 35.261402 | J36: =J9/$J$7*100 -> 36.280811 | K36: =K9/$K$7*100 -> 35.889466 | L36: =L9/$L$7*100 -> 36.990673 | M36: =M9/$M$7*100 -> 37.078243 | N36: =N9/$N$7*100 -> 37.629032 | O36: =O9/$O$7*100 -> 37.465849 | P36: =P9/$P$7*100 -> 38.029796 | Q36: =Q9/$Q$7*100 -> 38.649497 | R36: =R9/$R$7*100 -> 39.148743 | S36: =S9/$S$7*100 -> 39.860028 | T36: =T9/$T$7*100 -> 39.85804 | U36: =U9/$U$7*100 -> 39.034432 | V36: =V9/$V$7*100 -> 39.368534
B38: Industria avícola 1 | C38: =C11/$C$7*100 -> 16.553453 | D38: =D11/$D$7*100 -> 16.80794 | E38: =E11/$E$7*100 -> 16.883291 | F38: =F11/$F$7*100 -> 17.200951 | G38: =G11/$G$7*100 -> 17.176896 | H38: =H11/$H$7*100 -> 17.663893 | I38: =I11/$I$7*100 -> 18.136757 | J38: =J11/$J$7*100 -> 18.987031 | K38: =K11/$K$7*100 -> 19.593158 | L38: =L11/$L$7*100 -> 20.704438 | M38: =M11/$M$7*100 -> 21.055083 | N38: =N11/$N$7*100 -> 21.868405 | O38: =O11/$O$7*100 -> 22.095531 | P38: =P11/$P$7*100 -> 22.684929 | Q38: =Q11/$Q$7*100 -> 23.298109 | R38: =R11/$R$7*100 -> 24.218975 | S38: =S11/$S$7*100 -> 25.11176 | T38: =T11/$T$7*100 -> 25.319977 | U38: =U11/$U$7*100 -> 25.305668 | V38: =V11/$V$7*100 -> 25.754579
B39: Ave | C39: =C12/$C$7*100 -> 13.394528 | D39: =D12/$D$7*100 -> 13.502028 | E39: =E12/$E$7*100 -> 13.713475 | F39: =F12/$F$7*100 -> 13.97943 | G39: =G12/$G$7*100 -> 13.903435 | H39: =H12/$H$7*100 -> 14.545215 | I39: =I12/$I$7*100 -> 14.713995 | J39: =J12/$J$7*100 -> 15.497935 | K39: =K12/$K$7*100 -> 16.265591 | L39: =L12/$L$7*100 -> 17.43403 | M39: =M12/$M$7*100 -> 17.720033 | N39: =N12/$N$7*100 -> 18.346661 | O39: =O12/$O$7*100 -> 18.811636 | P39: =P12/$P$7*100 -> 19.099028 | Q39: =Q12/$Q$7*100 -> 19.689428 | R39: =R12/$R$7*100 -> 20.478146 | S39: =S12/$S$7*100 -> 21.311475 | T39: =T12/$T$7*100 -> 21.490401 | U39: =U12/$U$7*100 -> 21.437748 | V39: =V12/$V$7*100 -> 21.7052
B40: Pollo | J40: =J13/$J$7*100 -> 14.350541 | K40: =K13/$K$7*100 -> 15.067214 | L40: =L13/$L$7*100 -> 16.240529 | M40: =M13/$M$7*100 -> 16.520748 | N40: =N13/$N$7*100 -> 16.44904 | O40: =O13/$O$7*100 -> 17.590163 | P40: =P13/$P$7*100 -> 17.90229 | Q40: =Q13/$Q$7*100 -> 18.430722 | R40: =R13/$R$7*100 -> 19.12993 | S40: =S13/$S$7*100 -> 19.784428 | T40: =T13/$T$7*100 -> 20.056175 | U40: =U13/$U$7*100 -> 20.092974 | V40: =V13/$V$7*100 -> 20.339483
A41: 1 | B41: Huevo de Gallina | C41: =C14/$C$7*100 -> 3.1589248 | D41: =D14/$D$7*100 -> 3.3059119 | E41: =E14/$E$7*100 -> 3.1698166 | F41: =F14/$F$7*100 -> 3.2215211 | G41: =G14/$G$7*100 -> 3.2734604 | H41: =H14/$H$7*100 -> 3.1186775 | I41: =I14/$I$7*100 -> 3.4227621 | J41: =J14/$J$7*100 -> 3.489096 | K41: =K14/$K$7*100 -> 3.3275671 | L41: =L14/$L$7*100 -> 3.2704075 | M41: =M14/$M$7*100 -> 3.33505 | N41: =N14/$N$7*100 -> 3.5217435 | O41: =O14/$O$7*100 -> 3.2838944 | P41: =P14/$P$7*100 -> 3.5859007 | Q41: =Q14/$Q$7*100 -> 3.6086806 | R41: =R14/$R$7*100 -> 3.740829 | S41: =S14/$S$7*100 -> 3.8002841 | T41: =T14/$T$7*100 -> 3.8295764 | U41: =U14/$U$7*100 -> 3.8679203 | V41: =V14/$V$7*100 -> 4.0493794
B42: Ovino | C42: =C15/$C$7*100 -> 2.1671827 | D42: =D15/$D$7*100 -> 2.2065925 | E42: =E15/$E$7*100 -> 2.0598164 | F42: =F15/$F$7*100 -> 2.0517362 | G42: =G15/$G$7*100 -> 2.1512359 | H42: =H15/$H$7*100 -> 2.0017648 | I42: =I15/$I$7*100 -> 1.865771 | J42: =J15/$J$7*100 -> 1.8085601 | K42: =K15/$K$7*100 -> 1.6429686 | L42: =L15/$L$7*100 -> 1.606834 | M42: =M15/$M$7*100 -> 1.5541098 | N42: =N15/$N$7*100 -> 1.4988586 | O42: =O15/$O$7*100 -> 1.4567626 | P42: =P15/$P$7*100 -> 1.4121247 | Q42: =Q15/$Q$7*100 -> 1.3668554 | R42: =R15/$R$7*100 -> 1.267323 | S42: =S15/$S$7*100 -> 1.2699319 | T42: =T15/$T$7*100 -> 1.2172262 | U42: =U15/$U$7*100 -> 1.1362881 | V42: =V15/$V$7*100 -> 1.1051325
B43: Porcino | C43: =C16/$C$7*100 -> 2.4825029 | D43: =D16/$D$7*100 -> 2.5122431 | E43: =E16/$E$7*100 -> 2.3570707 | F43: =F16/$F$7*100 -> 2.3169015 | G43: =G16/$G$7*100 -> 2.4539171 | H43: =H16/$H$7*100 -> 2.4083581 | I43: =I16/$I$7*100 -> 2.3321009 | J43: =J16/$J$7*100 -> 2.3794074 | K43: =K16/$K$7*100 -> 2.2063876 | L43: =L16/$L$7*100 -> 2.1419199 | M43: =M16/$M$7*100 -> 2.0755546 | N43: =N16/$N$7*100 -> 1.9999139 | O43: =O16/$O$7*100 -> 1.9628886 | P43: =P16/$P$7*100 -> 2.0078389 | Q43: =Q16/$Q$7*100 -> 2.0900248 | R43: =R16/$R$7*100 -> 2.1235969 | S43: =S16/$S$7*100 -> 2.1722922 | T43: =T16/$T$7*100 -> 2.2311834 | U43: =U16/$U$7*100 -> 2.1640419 | V43: =V16/$V$7*100 -> 2.2032875
B44: Vacuno | C44: =C17/$C$7*100 -> 6.3756488 | D44: =D17/$D$7*100 -> 6.3306026 | E44: =E17/$E$7*100 -> 6.1676235 | F44: =F17/$F$7*100 -> 6.1900017 | G44: =G17/$G$7*100 -> 6.4301424 | H44: =H17/$H$7*100 -> 6.3592354 | I44: =I17/$I$7*100 -> 6.2392503 | J44: =J17/$J$7*100 -> 6.1219211 | K44: =K17/$K$7*100 -> 5.6463151 | L44: =L17/$L$7*100 -> 5.5514183 | M44: =M17/$M$7*100 -> 5.5673788 | N44: =N17/$N$7*100 -> 5.4983274 | O44: =O17/$O$7*100 -> 5.4042068 | P44: =P17/$P$7*100 -> 5.4812342 | Q44: =Q17/$Q$7*100 -> 5.4677473 | R44: =R17/$R$7*100 -> 5.2571016 | S44: =S17/$S$7*100 -> 5.0576363 | T44: =T17/$T$7*100 -> 4.8187593 | U44: =U17/$U$7*100 -> 4.4928234 | V44: =V17/$V$7*100 -> 4.428581
B45: Caprino | C45: =C18/$C$7*100 -> 0.32962694 | D45: =D18/$D$7*100 -> 0.3090593 | E45: =E18/$E$7*100 -> 0.28650369 | F45: =F18/$F$7*100 -> 0.30523003 | G45: =G18/$G$7*100 -> 0.31158358 | H45: =H18/$H$7*100 -> 0.2964133 | I45: =I18/$I$7*100 -> 0.28124252 | J45: =J18/$J$7*100 -> 0.26963987 | K45: =K18/$K$7*100 -> 0.23846284 | L45: =L18/$L$7*100 -> 0.22301815 | M45: =M18/$M$7*100 -> 0.2135765 | N45: =N18/$N$7*100 -> 0.20279098 | O45: =O18/$O$7*100 -> 0.1943253 | P45: =P18/$P$7*100 -> 0.19646952 | Q45: =Q18/$Q$7*100 -> 0.18470138 | R45: =R18/$R$7*100 -> 0.17025146 | S45: =S18/$S$7*100 -> 0.16445602 | T45: =T18/$T$7*100 -> 0.15073547 | U45: =U18/$U$7*100 -> 0.12653111 | V45: =V18/$V$7*100 -> 0.1258638
B46: Alpaca | C46: =C19/$C$7*100 -> 0.74452196 | D46: =D19/$D$7*100 -> 0.78003386 | E46: =E19/$E$7*100 -> 0.79178224 | F46: =F19/$F$7*100 -> 0.76966467 | G46: =G19/$G$7*100 -> 0.77607876 | H46: =H19/$H$7*100 -> 0.75273378 | I46: =I19/$I$7*100 -> 0.70649205 | J46: =J19/$J$7*100 -> 0.73087749 | K46: =K19/$K$7*100 -> 0.68547963 | L46: =L19/$L$7*100 -> 0.71476136 | M46: =M19/$M$7*100 -> 0.7255542 | N46: =N19/$N$7*100 -> 0.723228 | O46: =O19/$O$7*100 -> 0.72313385 | P46: =P19/$P$7*100 -> 0.7188395 | Q46: =Q19/$Q$7*100 -> 0.73033598 | R46: =R19/$R$7*100 -> 0.66501536 | S46: =S19/$S$7*100 -> 0.67960837 | T46: =T19/$T$7*100 -> 0.67726491 | U46: =U19/$U$7*100 -> 0.62545684 | V46: =V19/$V$7*100 -> 0.60087219
...

Sheet 2. POBLACION Y ...

Sheet C-4
A2: C.4 PERÚ:POBLACIÓN PECUARIA POR REGIÓN SEGÚN ESPECIE, 2019P.
A3: (Unidades)
A5: Región | B5: Ave | C5: Alpaca | D5: LLama | E5: Caprino | F5: Ovino | G5: Porcino | H5: Vacuno | I5: Vacas en Ordeño
A6: Total Nacional | B6: =(B8+B9+B10+B11+B12+B16+B17+B18+B19+B20+B21+B22+B23+B24+B25+B26+B27+B28+B31+B32+B33+B34+B35+B36) -> 168172635 | C6: =(C8+C9+C10+C11+C12+C16+C17+C18+C19+C20+C21+C22+C23+C24+C25+C26+C27+C28+C31+C32+C33+C34+C35+C36) -> 4449506 | D6: =(D8+D9+D10+D11+D12+D16+D17+D18+D19+D20+D21+D22+D23+D24+D25+D26+D27+D28+D31+D32+D33+D34+D35+D36) -> 1089701 | E6: =(E8+E9+E10+E11+E12+E16+E17+E18+E19+E20+E21+E22+E23+E24+E25+E26+E27+E28+E31+E32+E33+E34+E35+E36) -> 1807961 | F6: =(F8+F9+F10+F11+F12+F16+F17+F18+F19+F20+F21+F22+F23+F24+F25+F26+F27+F28+F31+F32+F33+F34+F35+F36) -> 11261559 | G6: =(G8+G9+G10+G11+G12+G16+G17+G18+G19+G20+G21+G22+G23+G24+G25+G26+G27+G28+G31+G32+G33+G34+G35+G36) -> 3258809 | H6: =(H8+H9+H10+H11+H12+H16+H17+H18+H19+H20+H21+H22+H23+H24+H25+H26+H27+H28+H31+H32+H33+H34+H35+H36) -> 5599893 | I6: =(I8+I9+I10+I11+I12+I16+I17+I18+I19+I20+I21+I22+I23+I24+I25+I26+I27+I28+I31+I32+I33+I34+I35+I36) -> 905818
A8: Tumbes | B8: 157220 | C8: 0 | D8: 0 | E8: 65320 | F8: 7515 | G8: 30010 | H8: 22200 | I8: 362
A9: Piura | B9: 5858230 | C9: 100 | D9: 0 | E9: 330221 | F9: 274119 | G9: 167860 | H9: 258181 | I9: 24072
A10: Lambayeque | B10: 2489462 | C10: 0 | D10: 0 | E10: 106151 | F10: 68325 | G10: 73428 | H10: 113602 | I10: 17837
A11: La Libertad | B11: 24963293 | C11: 7710 | D11: 0 | E11: 91388 | F11: 344949 | G11: 113341 | H11: 235457 | I11: 48823
A12: Cajamarca | B12: =SUM(B13:B15) -> 870494 | C12: =SUM(C13:C15) -> 1190 | D12: =SUM(D13:D15) -> 0 | E12: =SUM(E13:E15) -> 107350 | F12: =SUM(F13:F15) -> 480072 | G12: =SUM(G13:G15) -> 288252 | H12: =SUM(H13:H15) -> 655840 | I12: =SUM(I13:I15) -> 164222
A13: Cajamarca | B13: 367692 | C13: 1190 | D13: 0 | E13: 66574 | F13: 344402 | G13: 79774 | H13: 263239 | I13: 97194
A14: Chota | B14: 208383 | C14: 0 | D14: 0 | E14: 20745 | F14: 104272 | G14: 103450 | H14: 276060 | I14: 61574
A15: Jaén | B15: 294419 | C15: 0 | D15: 0 | E15: 20031 | F15: 31398 | G15: 105028 | H15: 116541 | I15: 5454
A16: Amazonas | B16: 1525969 | C16: 0 | D16: 0 | E16: 12575 | F16: 23047 | G16: 85700 | H16: 247855 | I16: 79623
A17: Ancash | B17: 2632858 | C17: 10200 | D17: 0 | E17: 169698 | F17: 671829 | G17: 171477 | H17: 306065 | I17: 14847
A18: Lima | B18: 68879430 | C18: 46625 | D18: 21780 | E18: 169383 | F18: 315962 | G18: 464900 | H18: 250851 | I18: 71092
A19: Ica | B19: 17467343 | C19: 0 | D19: 0 | E19: 75880 | F19: 27552 | G19: 102767 | H19: 50530 | I19: 12537
A20: Huánuco | B20: 1761432 | C20: 6760 | D20: 3513 | E20: 102260 | F20: 529832 | G20: 405725 | H20: 292866 | I20: 34916
A21: Pasco | B21: 139895 | C21: 130778 | D21: 43880 | E21: 6345 | F21: 691923 | G21: 53567 | H21: 119542 | I21: 29614
A22: Junín | B22: 3562423 | C22: 94111 | D22: 61081 | E22: 10833 | F22: 1516644 | G22: 171904 | H22: 326506 | I22: 40669
A23: Huancavelica | B23: 389033 | C23: 270053 | D23: 131322 | E23: 181228 | F23: 625574 | G23: 157545 | H23: 182010 | I23: 12120
A24: Arequipa | B24: 17146598 | C24: 430134 | D24: 88209 | E24: 16611 | F24: 188221 | G24: 107120 | H24: 212744 | I24: 75737
... A27: Ayacucho | B27: 664511 | C27: 309833 | D27: 79754 | E27: 192115 | F27: 617461 | G27: 118454 | H27: 453426 | I27: 33695
A28: Apurímac | B28: =SUM(B29:B30) -> 309739 | C28: =SUM(C29:C30) -> 215340 | D28: =SUM(D29:D30) -> 72611 | E28: =SUM(E29:E30) -> 109518 | F28: =SUM(F29:F30) -> 456405 | G28: =SUM(G29:G30) -> 133037 | H28: =SUM(H29:H30) -> 296567 | I28: =SUM(I29:I30) -> 31825
A29: Abancay | B29: 189884 | C29: 195550 | D29: 54521 | E29: 55360 | F29: 314716 | G29: 50341 | H29: 190150 | I29: 20027
A30: Andahuaylas | B30: 119855 | C30: 19790 | D30: 18090 | E30: 54158 | F30: 141689 | G30: 82696 | H30: 106417 | I30: 11798
A31: Cusco | B31: 1201279 | C31: 669365 | D31: 150801 | E31: 34907 | F31: 1443471 | G31: 127738 | H31: 439168 | I31: 80570
A32: Puno | B32: 1698765 | C32: 2035280 | D32: 369690 | E32: 0 | F32: 2852165 | G32: 119760 | H32: 733260 | I32: 95949
A33: San Martín | B33: 4536966 | C33: 0 | D33: 0 | E33: 0 | F33: 9269 | G33: 170291 | H33: 211843 | I33: 19732
A34: Loreto | B34: 4183526 | C34: 0 | D34: 0 | E34: 375 | F34: 12385 | G34: 84515 | H34: 46190 | I34: 1228
A35: Ucayali | B35: 6002549 | C35: 0 | D35: 0 | E35: 170 | F35: 10049 | G35: 48466 | H35: 45705 | I35: 3631
A36: Madre de Dios | B36: 486548 | C36: 0 | D36: 0 | E36: 220 | F36: 9494 | G36: 13495 | H36: 56880 | I36: 1354
A37: P Preliminar.
A38: Fuente:Direcciones Regionales de Agricultura.
A39: Elaboración: MInisterio de Agricultura y Riego - DGESEP - DEA.

Sheet C 5
A2: C.5 PERÚ: EVOLUCIÓN DE LA POBLACIÓN, SACA, PRODUCCIÓN, RENDIMIENTO Y PRECIOS RECIBIDOS POR EL PRODUCTOR,
A3: POR ESPECIE Y PRODUCTO, 2007-19.
A5: Especie/ Producto | B5: Variable | C5: 2000 | D5: 2001 | E5: 2002 | F5: 2003 | G5: 2004 | H5: 2005 | I5: 2006 | J5: 2007 | K5: 2008 | L5: 2009 | M5: 2010 | N5: 2011 | O5: 2012 | P5: 2013 | Q5: 2014 | R5: 2015 | S5: 2016 | T5: 2017 | U5: 2018 | V5: 2019 P
B6: Población (Miles) | C6: 88010358 | D6: 85621159 | E6: 90354182 | F6: 92846109 | G6: 97761003 | H6: 99278818 | I6: 117976702 | J6: 120227.6 | K6: 131179.1 | L6: 137838 | M6: 130779 | N6: 128943.5 | O6: 138554.1 | P6: 138179.8 | Q6: 144703.7 | R6: 151000.9 | S6: 158263.2 | T6: 156637.7 | U6: 160959.3 | V6: 168172.6
B7: Saca (Miles) | C7: 283733046 | D7: 287860594 | E7: 307094298 | F7: 310943489 | G7: 308485309 | H7: 342073628 | I7: 368545799 | J7: 394749.6 | K7: 435909.3 | L7: 476340.3 | M7: 504986.8 | N7: 535421.1 | O7: 575566.4 | P7: 594004.2 | Q7: 621140.1 | R7: 645016.2 | S7: 690892.3 | T7: 709233 | U7: 755841.1 | V7: 786549.7
A8: Ave | B8: Produción carne (t) | C8: 510161 | D8: 518010 | E8: 556076 | F8: 577989 | G8: 578693 | H8: 650296 | I8: 710428 | J8: 770444 | K8: 877171 | L8: 964407 | M8: 1019935 | N8: 1108345 | O8: 1211140 | P8: 1254348 | Q8: 1317426 | R8: 1423586 | S8: 1513950 | T8: 1569280 | U8: 1687636 | V8: 1762856
B9: Rendimiento (Kg/Unidad) | C9: =(C8/C7)*1000 -> 1.7980317 | D9: =(D8/D7)*1000 -> 1.7995169 | E9: =(E8/E7)*1000 -> 1.8107663 | F9: =(F8/F7)*1000 -> 1.8588233 | G9: =(G8/G7)*1000 -> 1.8759175 | H9: =(H8/H7)*1000 -> 1.901041 | I9: =(I8/I7)*1000 -> 1.9276519 | J9: =(J8/J7) -> 1.9517284 | K9: =(K8/K7) -> 2.0122787 | L9: =(L8/L7) -> 2.0246177 | M9: =(M8/M7) -> 2.0197261 | N9: =(N8/N7) -> 2.0700436 | O9: =(O8/O7) -> 2.1042576 | P9: =(P8/P7) -> 2.111682 | Q9: =(Q8/Q7) -> 2.1209804 | ... V9: =(V8/V7) -> 2.2412519
B10: Precio (S/ x Kg) | C10: 3.06 | D10: 3.19 | E10: 3.07 | F10: 3.09 | G10: 3.48 | H10: 3.46 | I10: 3.6 | J10: 3.63 | K10: 4.18 | L10: 4.33 | M10: 4.64 | N10: 4.67 | O10: 4.7 | P10: 4.75 | Q10: 4.78 | R10: 4.82 | S10: 4.84 | T10: 4.84 | U10: 4.86 | V10: 4.65
B11: Población (Miles) | C11: 14800991 | D11: 14727155 | E11: 14690547 | F11: 14721243 | G11: 14696522 | H11: 14813786 | I11: 14675255 | J11: 14580166 | K11: 14509628 | L11: 14137690 | M11: 14159720 | N11: 14050173 | O11: 12184143 | P11: 11830977 | Q11: 11652272 | R11: 11982580 | S11: 11450657 | T11: 11338424 | U11: 11331908 | V11: 11261557
B12: Saca (Miles) | C12: 2521661 | D12: 2571321 | E12: 2517896 | F12: 2535935 | G12: 2709847 | H12: 2685627 | I12: 2692776 | J12: 2681208 | K12: 2678241 | L12: 2753681 | M12: 2788507 | N12: 2844228 | O12: 2910166 | P12: 2832371 | Q12: 2788555 | R12: 2698887 | S12: 2745951 | T12: 2699282 | U12: 2687624 | V12: 2682837
A13: Ovino | B13: Produción carne (t) | C13: 31068 | D13: 31868 | E13: 31437 | F13: 31926 | G13: 33698 | H13: 33686 | I13: 33904 | J13: 33839 | K13: 33350 | L13: 33458 | M13: 33669 | N13: 34256 | O13: 35304 | P13: 34906 | Q13: 34421 | R13: 33163 | S13: 33955 | T13: 33458 | U13: 33672 | V13: 33781
B14: Rendimiento (Kg/Unidad) | C14: =(C13/C12)*1000 -> 12.320451 | D14: =(D13/D12)*1000 -> 12.39363 | E14: =(E13/E12)*1000 -> 12.485424 | F14: =(F13/F12)*1000 -> 12.589439 | G14: =(G13/G12)*1000 -> 12.435388 | H14: =(H13/H12)*1000 -> 12.543067 | I14: =(I13/I12)*1000 -> 12.590724 | J14: =(J13/J12)*1000 -> 12.620804 | ... V14: =(V13/V12)*1000 -> 12.591522
B15: Precio (S/ x Kg) | C15: 2.99 | D15: 3.13 | E15: 3.29 | F15: 3.29 | G15: 3.27 | H15: 3.31 | I15: 3.32 | J15: 3.49 | K15: 3.9 | L15: 4.13 | M15: 4.46 | N15: 4.52 | O15: 4.9 | P15: 5.04 | Q15: 5.72 | R15: 5.72 | S15: 5.9 | T15: 5.6 | U15: 5.56 | V15: 5.6
B16: Población (Miles) | C16: 2845573 | D16: 2809888 | E16: 2941036 | F16: 2990499 | G16: 3000199 | H16: 3010724 | I16: 3073855 | J16: 3115772 | K16: 3151406 | L16: 3256809 | M16: 3254413 | N16: 3263254 | O16: 2987315 | P16: 3176115 | Q16: 3173015 | R16: 3200714 | S16: 3104911 | T16: 3217254 | U16: 3209742 | V16: 3258808
B17: Saca (Miles) | C17: 1540534 | D17: 1650886 | E17: 1637129 | F17: 1670387 | G17: 1884573 | H17: 1991346 | I17: 2074715 | J17: 2153141 | K17: 2131518 | L17: 2213057 | M17: 2186978 | N17: 2298432 | O17: 2401634 | P17: 2499031 | Q17: 2629566 | R17: 2764884 | S17: 2876803 | T17: 3073656 | U17: 3090907 | V17: 3284606
A18: Porcino | B18: Produción carne (t) | C18: 91554 | D18: 93313 | E18: 92530 | F18: 92738 | G18: 98880 | H18: 104254 | I18: 109010 | J18: 114520 | K18: 115196 | L18: 114719 | M18: 115655 | N18: 117588 | O18: 122353 | P18: 127684 | Q18: 135390 | R18: 142925 | S18: 149399 | T18: 157824 | U18: 162421 | V18: 173259
B19: Rendimiento (Kg/Unidad) | C19: =(C18/C17)*1000 -> 59.430042 | D19: =(D18/D17)*1000 -> 56.522982 | E19: =(E18/E17)*1000 -> 56.519676 | F19: =(F18/F17)*1000 -> 55.518871 | G19: =(G18/G17)*1000 -> 52.468119 | H19: =(H18/H17)*1000 -> 52.353534 | I19: =(I18/I17)*1000 -> 52.542156 | J19: =(J18/J17)*1000 -> 53.187413 | ... V19: =(V18/V17)*1000 -> 52.748792
B20: Precio (S/ x Kg) | C20: 3.31 | D20: 3.34 | E20: 3.35 | F20: 3.39 | G20: 3.42 | H20: 3.43 | I20: 3.47 | J20: 3.5 | K20: 3.8 | L20: 4.12 | M20: 4.25 | N20: 5.05 | O20: 5.24 | P20: 5.91 | Q20: 6.07 | R20: 6.42 | S20: 6.77 | T20: 6.96 | U20: 7.05 | V20: 6.95
B21: Población (Miles) | C21: 4980291 | D21: 5035612 | E21: 5163700 | F21: 5193414 | G21: 5184822 | H21: 5249783 | I21: 5241102 | J21: 5420865 | K21: 5442989 | L21: 5459435 | M21: 5520200 | N21: 5589173 | O21: 5660984 | P21: 5555988 | Q21: 5577959 | R21: 5553470 | S21: 5525454 | T21: 5535569 | U21: 5575483 | V21: 5599890.5
B22: Saca (Miles) | C22: 875746 | D22: 920031 | E22: 951383 | F22: 986402 | G22: 1020294 | H22: 1074578 | I22: 1127321 | J22: 1138578 | K22: 1151906 | L22: 1168497 | M22: 1218723 | N22: 1266710 | O22: 1319404 | P22: 1375095 | Q22: 1376391 | R22: 1367797 | S22: 1364230 | T22: 1331223 | U22: 1348165 | V22: 1357067
A23: Vacuno | B23: Produción carne (t) | C23: 130249 | D23: 130269 | E23: 134137 | F23: 137271 | G23: 143554 | H23: 152497 | I23: 161578 | J23: 163235 | K23: 163318 | L23: 164704 | M23: 171872 | N23: 179084 | O23: 186617 | P23: 193087 | Q23: 196232 | R23: 196015 | S23: 192703 | T23: 188738 | U23: 189703 | V23: 192920
B24: Rendimiento (Kg/Unidad) | C24: =(C23/C22)*1000 -> 148.7292 | D24: =(D23/D22)*1000 -> 141.59197 | E24: =(E23/E22)*1000 -> 140.99159 | F24: =(F23/F22)*1000 -> 139.16334 | G24: =(G23/G22)*1000 -> 140.69866 | H24: =(H23/H22)*1000 -> 141.91338 | I24: =(I23/I22)*1000 -> 143.32918 | J24: =(J23/J22)*1000 -> 143.36743 | ... V24: =(V23/V22)*1000 -> 142.15952
B25: Precio (S/ x Kg) | C25: 3.34 | D25: 3.41 | E25: 3.29 | F25: 3.52 | G25: 3.33 | H25: 3.36 | I25: 3.4 | J25: 3.5 | K25: 3.77 | L25: 4.08 | M25: 4.1 | N25: 4.25 | O25: 4.69 | P25: 4.84 | Q25: 5.23 | R25: 5.41 | S25: 5.45 | T25: 5.53 | U25: 5.64 | V25: 5.68
B26: Población (Miles) | C26: 2034914 | D26: 2017808 | E26: 1983128 | F26: 1983302 | G26: 1971863 | H26: 1952956 | I26: 1936855 | J26: 1925912 | K26: 1904124 | L26: 1928678 | M26: 1968306 | N26: 1946117 | O26: 1949502 | P26: 1928631 | Q26: 1905462 | R26: 1882361 | S26: 1865047 | T26: 1814704 | U26: 1811630 | V26: 1807959
B27: Saca (Miles) | C27: 451247 | D27: 468861 | E27: 476569 | F27: 523993 | G27: 524448 | H27: 527096 | I27: 518663 | J27: 506927 | K27: 496706 | L27: 505880 | M27: 499447 | N27: 489915 | O27: 496626 | P27: 505262 | Q27: 489956 | R27: 464018 | S27: 458812 | T27: 444799 | U27: 410567 | V27: 411263
A28: Caprino | B28: Produción carne (t) | C28: 6268 | D28: 5912 | E28: 5793 | F28: 6294 | G28: 6476 | H28: 6618 | I28: 6772 | J28: 6686 | K28: 6419 | L28: 6153 | M28: 6131 | N28: 6150 | O28: 6247 | P28: 6439 | Q28: 6167 | R28: 5901 | S28: 5827 | T28: 5494 | U28: 4966 | V28: 5102
B29: Rendimiento (Kg/Unidad) | C29: =(C28/C27)*1000 -> 13.890397 | D29: =(D28/D27)*1000 -> 12.609281 | E29: =(E28/E27)*1000 -> 12.155637 | F29: =(F28/F27)*1000 -> 12.011611 | G29: =(G28/G27)*1000 -> 12.348221 | H29: =(H28/H27)*1000 -> 12.555588 | I29: =(I28/I27)*1000 -> 13.056648 | J29: =(J28/J27)*1000 -> 13.189276 | ... V29: =(V28/V27)*1000 -> 12.405687
B30: Precio (S/ x Kg) | C30: 3.33 | D30: 3.28 | E30: 3.31 | F30: 3.22 | G30: 3.27 | H30: 3.05 | I30: 3.01 | J30: 3.17 | K30: 3.41 | L30: 3.61 | M30: 3.38 | N30: 3.53 | O30: 3.68 | P30: 3.93 | Q30: 4.04 | R30: 4.28 | S30: 4.66 | T30: 4.74 | U30: 4.79 | V30: 4.81
B31: Población (Miles) | C31: 3078524 | D31: 3190373 | E31: 3335721 | F31: 3422557 | G31: 3429019 | H31: 3594515 | I31: 3625627 | J31: 3687340 | K31: 3780806 | L31: 4105582 | M31: 4177499 | N31: 4322258 | O31: 3927361 | P31: 4005315 | Q31: 4315793 | R31: 4318457 | S31: 4319228 | T31: 4330710 | U31: 4384846 | V31: 4449505
B32: Saca (Miles) | C32: 269643 | D32: 288318 | E32: 313415 | F32: 304890 | G32: 312092 | H32: 321478 | I32: 330072 | J32: 355174 | K32: 365555 | L32: 387980 | M32: 410085 | N32: 424100 | O32: 455558 | P32: 463354 | Q32: 481847 | R32: 446199 | S32: 474135 | T32: 479033 | U32: 470464 | V32: 473283
A33: Alpaca | B33: Produción carne (t) | C33: 7307 | D33: 7713 | E33: 8277 | F33: 8204 | G33: 8323 | H33: 8671 | I33: 8793 | J33: 9366 | K33: 9527 | L33: 10189 | M33: 10761 | N33: 11318 | O33: 11999 | P33: 12169 | Q33: 12594 | R33: 11917 | S33: 12445 | T33: 12747 | U33: 12689 | V33: 12580
B34: Rendimiento (Kg/Unidad) | C34: =(C33/C32)*1000 -> 27.098794 | D34: =(D33/D32)*1000 -> 26.751712 | E34: =(E33/E32)*1000 -> 26.409074 | F34: =(F33/F32)*1000 -> 26.908065 | G34: =(G33/G32)*1000 -> 26.668418 | H34: =(H33/H32)*1000 -> 26.972297 | I34: =(I33/I32)*1000 -> 26.639642 | J34: =(J33/J32)*1000 -> 26.370173 | ... V34: =(V33/V32)*1000 -> 26.580291
B35: Precio (S/ x Kg) | C35: 2.4 | D35: 2.57 | E35: 2.48 | F35: 2.53 | G35: 2.66 | H35: 2.61 | I35: 2.51 | J35: 2.5 | K35: 2.91 | L35: 3.13 | M35: 3.43 | N35: 3.65 | O35: 4.03 | P35: 4.43 | Q35: 4.77 | R35: 4.63 | S35: 4.81 | T35: 4.91 | U35: 4.96 | V35: 4.94
V36: sigue…
A37: continúa C.5
A38: Especie/ Producto | B38: Variable | C38: 2000 | D38: 2001 | E38: 2002 | F38: 2003 | G38: 2004 | H38: 2005 | I38: 2006 | J38: 2007 | K38: 2008 | L38: 2009 | M38: 2010 | N38: 2011 | O38: 2012 | P38: 2013 | Q38: 2014 | R38: 2015 | S38: 2016 | T38: 2017 | U38: 2018 | V38: 2019 P
B39: Población (Miles) | C39: 1183908 | D39: 1179088 | E39: 1207275 | F39: 1230543 | G39: 1236984 | H39: 1269979 | I39: 1256101 | J39: 1274425 | K39: 1262782 | L39: 1237593 | M39: 1245169 | N39: 1226612 | O39: 1194404 | P39: 1234089 | Q39: 1211917 | R39: 1194708 | S39: 1105018 | T39: 1106201 | U39: 1093124 | V39: 1089699
B40: Saca (Miles) | C40: 91890 | D40: 95157 | E40: 97389 | F40: 101826 | G40: 109330 | H40: 112106 | I40: 113801 | J40: 118399 | K40: 119237 | L40: 127316 | M40: 123384 | N40: 128346 | O40: 130530 | P40: 125729 | Q40: 123360 | R40: 119806 | S40: 119195 | T40: 120748 | U40: 119726 | V40: 115790
A41: Llama | B41: Produción carne (t) | C41: 3194 | D41: 3232 | E41: 3242 | F41: 3496 | G41: 3699 | H41: 3863 | I41: 3839 | J41: 4053 | K41: 3971 | L41: 4175 | M41: 4075 | N41: 4235 | O41: 4350 | P41: 4179 | Q41: 4170 | R41: 3980 | S41: 3977 | T41: 4009 | U41: 4003 | V41: 3848
B42: Rendimiento (Kg/Unidad) | C42: =(C41/C40)*1000 -> 34.758951 | D42: =(D41/D40)*1000 -> 33.964921 | E42: =(E41/E40)*1000 -> 33.289181 | F42: =(F41/F40)*1000 -> 34.333078 | G42: =(G41/G40)*1000 -> 33.833349 | H42: =(H41/H40)*1000 -> 34.458459 | I42: =(I41/I40)*1000 -> 33.734326 | J42: =(J41/J40)*1000 -> 34.231708 | ... V42: =(V41/V40)*1000 -> 33.232576
...

Sheet C -6
A2: C.6 PERÚ: POBLACIÓN, SACA, PRODUCCIÓN, RENDIMIENTO Y PRECIOS RECIBIDOS POR EL PRODUCTOR POR PRINCIPALES ESPECIES Y PRODUCTOS PECUARIOS, 2019 P.
A4: Especie/ producto | B4: Variable | C4: Anual | D4: Ene | E4: Feb | F4: Mar | G4: Abr | H4: May | I4: Jun | J4: Jul | K4: Ago | L4: Set | M4: Oct | N4: Nov | O4: Dic
A5: Ave | B5: Población | C5: 168172635
B6: Saca (Unidades) | C6: =SUM(D6:O6) -> 786549677 | D6: 64482640 | E6: 59808205 | F6: 65184340 | G6: 66960116 | H6: 67285534 | I6: 63960438 | J6: 66480292 | K6: 66888702 | L6: 64219960 | M6: 67851094 | N6: 65360518 | O6: 68067838
B7: Producción carne (t) | C7: =SUM(D7:O7) -> 1762857 | D7: 139841 | E7: 125499 | F7: 141111 | G7: 145604 | H7: 149321 | I7: 149264 | J7: 154342 | K7: 156728 | L7: 150536 | M7: 152033 | N7: 144887 | O7: 153691
B8: Rendimiento (Kg/Unidad) | C8: =(C7/C6)*1000 -> 2.2412532 | D8: =D7/D6*1000 -> 2.1686612 | E8: =E7/E6*1000 -> 2.0983576 | F8: =F7/F6*1000 -> 2.1647991 | G8: =G7/G6*1000 -> 2.1744885 | H8: =H7/H6*1000 -> 2.219214 | I8: =I7/I6*1000 -> 2.3336926 | J8: =J7/J6*1000 -> 2.3216204 | K8: =K7/K6*1000 -> 2.3431162 | ... O8: =O7/O6*1000 -> 2.2579092
B9: Precio (S/ x Kg) 1/ | C9: 4.65 | D9: 4.69 | E9: 4.66 | F9: 4.69 | G9: 4.68 | H9: 4.71 | I9: 4.68 | J9: 4.66 | K9: 4.62 | L9: 4.6 | M9: 4.6 | N9: 4.61 | O9: 4.66
A10: Ovino | B10: Población | C10: 11261557
B11: Saca (Unidades) | C11: =SUM(D11:O11) -> 2682837 | D11: 188821 | E11: 204090 | F11: 215610 | G11: 240544 | H11: 249396 | I11: 250022 | J11: 246648 | K11: 236866 | L11: 221878 | M11: 211596 | N11: 208319 | O11: 209047
B12: Producción carne (t) | C12: =SUM(D12:O12) -> 33782 | D12: 2331 | E12: 2548 | F12: 2727 | G12: 3082 | H12: 3211 | I12: 3209 | J12: 3121 | K12: 2961 | L12: 2806 | M12: 2613 | N12: 2572 | O12: 2601
B13: Rendimiento (Kg/Unidad) | C13: =(C12/C11)*1000 -> 12.591894 | D13: =D12/D11*1000 -> 12.345025 | E13: =E12/E11*1000 -> 12.484688 | F13: =F12/F11*1000 -> 12.647836 | G13: =G12/G11*1000 -> 12.812625 | H13: =H12/H11*1000 -> 12.875106 | I13: =I12/I11*1000 -> 12.834871 | J13: =J12/J11*1000 -> 12.65366 | K13: =K12/K11*1000 -> 12.500739 | ... O13: =O12/O11*1000 -> 12.442178
B14: Precio (S/ x Kg) 1/ | C14: 5.6 | D14: 5.57 | E14: 5.59 | F14: 5.61 | G14: 5.64 | H14: 5.64 | I14: 5.62 | J14: 5.61 | K14: 5.6 | L14: 5.58 | M14: 5.57 | N14: 5.57 | O14: 5.56
A15: Porcino | B15: Población | C15: 3258808
B16: Saca (Unidades) | C16: =SUM(D16:O16) -> 3284607 | D16: 255815 | E16: 252824 | F16: 262772 | G16: 266086 | H16: 273122 | I16: 281219 | J16: 295570 | K16: 275132 | L16: 271226 | M16: 269811 | N16: 270579 | O16: 310451
B17: Producción carne (t) | C17: =SUM(D17:O17) -> 173259 | D17: 13622 | E17: 13370 | F17: 13687 | G17: 13794 | H17: 14008 | I17: 14959 | J17: 16019 | K17: 14759 | L17: 14337 | M17: 14208 | N17: 14073 | O17: 16423
B18: Rendimiento (Kg/Unidad) | C18: =(C17/C16)*1000 -> 52.748776 | D18: =D17/D16*1000 -> 53.249419 | E18: =E17/E16*1000 -> 52.882638 | F18: =F17/F16*1000 -> 52.08698 | G18: =G17/G16*1000 -> 51.840382 | H18: =H17/H16*1000 -> 51.288435 | I18: =I17/I16*1000 -> 53.193419 | J18: =J17/J16*1000 -> 54.196975 | K18: =K17/K16*1000 -> 53.643342 | ... O18: =O17/O16*1000 -> 52.900458
B19: Precio (S/ x Kg) 1/ | C19: 7.04 | D19: 6.91 | E19: 6.9 | F19: 6.91 | G19: 6.93 | H19: 6.94 | I19: 6.93 | J19: 6.95 | K19: 6.96 | L19: 6.96 | M19: 6.97 | N19: 6.98 | O19: 7.03
A20: Vacuno | B20: Población | C20: 5599891
B21: Saca (Unidades) | C21: =SUM(D21:O21) -> 1357067 | D21: 101272 | E21: 104739 | F21: 109634 | G21: 118371 | H21: 121905 | I21: 121838 | J21: 120691 | K21: 115388 | L21: 111677 | M21: 109303 | N21: 108195 | O21: 114054
B22: Producción carne (t) | C22: =SUM(D22:O22) -> 192920 | D22: 14436 | E22: 15165 | F22: 15698 | G22: 16742 | H22: 17211 | I22: 17310 | J22: 16979 | K22: 16417 | L22: 15835 | M22: 15544 | N22: 15493 | O22: 16090
B23: Rendimiento (Kg/Unidad) | C23: =(C22/C21)*1000 -> 142.15952 | D23: =D22/D21*1000 -> 142.5468 | E23: =E22/E21*1000 -> 144.78847 | F23: =F22/F21*1000 -> 143.18551 | G23: =G22/G21*1000 -> 141.43667 | H23: =H22/H21*1000 -> 141.18371 | I23: =I22/I21*1000 -> 142.0739 | J23: =J22/J21*1000 -> 140.68158 | K23: =K22/K21*1000 -> 142.27649 | ... O23: =O22/O21*1000 -> 141.07353
B24: Precio (S/ x Kg) 1/ | C24: 5.64 | D24: 5.65 | E24: 5.67 | F24: 5.68 | G24: 5.69 | H24: 5.69 | I24: 5.69 | J24: 5.69 | K24: 5.69 | L24: 5.68 | M24: 5.69 | N24: 5.68 | O24: 5.69
A25: Caprino | B25: Población | C25: 1807959
B26: Saca (Unidades) | C26: =SUM(D26:O26) -> 411261.9 | D26: 29495.9 | E26: 32141 | F26: 34355 | G26: 35093 | H26: 36517 | I26: 37280 | J26: 36748 | K26: 35448 | L26: 32809 | M26: 32185 | N26: 33208 | O26: 35982
B27: Producción carne (t) | C27: =SUM(D27:O27) -> 5102 | D27: 373 | E27: 404 | F27: 421 | G27: 432 | H27: 448 | I27: 472 | J27: 465 | K27: 444 | L27: 405 | M27: 386 | N27: 407 | O27: 445
B28: Rendimiento (Kg/Unidad) | C28: =(C27/C26)*1000 -> 12.40572 | D28: =D27/D26*1000 -> 12.645825 | E28: =E27/E26*1000 -> 12.569615 | F28: =F27/F26*1000 -> 12.254403 | G28: =G27/G26*1000 -> 12.310147 | H28: =H27/H26*1000 -> 12.268259 | I28: =I27/I26*1000 -> 12.660944 | J28: =J27/J26*1000 -> 12.65375 | K28: =K27/K26*1000 -> 12.525389 | ... O28: =O27/O26*1000 -> 12.367295
B29: Precio (S/ x Kg) 1/ | C29: 4.79 | D29: 4.81 | E29: 4.81 | F29: 4.81 | G29: 4.8 | H29: 4.81 | I29: 4.8 | J29: 4.81 | K29: 4.81 | L29: 4.82 | M29: 4.82 | N29: 4.82 | O29: 4.84
A30: Alpaca | B30: Población | C30: 4449505
B31: Saca (Unidades) | C31: =SUM(D31:O31) -> 473283 | D31: 31345 | E31: 37344 | F31: 40945 | G31: 47971 | H31: 46678 | I31: 47120 | J31: 45906 | K31: 41956 | L31: 36148 | M31: 33531 | N31: 33340 | O31: 30999
B32: Producción carne (t) | C32: =SUM(D32:O32) -> 12581 | D32: 821 | E32: 990 | F32: 1088 | G32: 1306 | H32: 1265 | I32: 1265 | J32: 1236 | K32: 1115 | L32: 952 | M32: 869 | N32: 866 | O32: 808
B33: Rendimiento (Kg/Unidad) | C33: =(C32/C31)*1000 -> 26.582404 | D33: =D32/D31*1000 -> 26.192375 | E33: =E32/E31*1000 -> 26.510283 | F33: =F32/F31*1000 -> 26.572231 | G33: =G32/G31*1000 -> 27.224782 | H33: =H32/H31*1000 -> 27.100561 | I33: =I32/I31*1000 -> 26.84635 | J33: =J32/J31*1000 -> 26.924585 | K33: =K32/K31*1000 -> 26.57546 | ... O33: =O32/O31*1000 -> 26.065357
B34: Precio (S/ x Kg) 1/ | C34: 4.96 | D34: 4.91 | E34: 4.97 | F34: 4.98 | G34: 5.02 | H34: 4.98 | I34: 4.96 | J34: 4.95 | K34: 4.92 | L34: 4.89 | M34: 4.89 | N34: 4.87 | O34: 4.8
O35: sigue…
A36: continúa C.6
A37: Especie/producto | B37: Variable | C37: Anual | D37: Ene | E37: Feb | F37: Mar | G37: Abr | H37: May | I37: Jun | J37: Jul | K37: Ago | L37: Set | M37: Oct | N37: Nov | O37: Dic
A38: Llama | B38: Población | C38: 1089699
B39: Saca (Unidades) | C39: =SUM(D39:O39) -> 115790 | D39: 7838 | E39: 9132 | F39: 9654 | G39: 10848 | H39: 10828 | I39: 11282 | J39: 10677 | K39: 9934 | L39: 9126 | M39: 8321 | N39: 8415 | O39: 9735
B40: Producción carne (t) | C40: =SUM(D40:O40) -> 3849 | D40: 259 | E40: 302 | F40: 322 | G40: 373 | H40: 370 | I40: 381 | J40: 355 | K40: 327 | L40: 298 | M40: 271 | N40: 272 | O40: 319
B41: Rendimiento (Kg/Unidad) | C41: =(C40/C39)*1000 -> 33.241213 | D41: =D40/D39*1000 -> 33.044144 | E41: =E40/E39*1000 -> 33.070521 | F41: =F40/F39*1000 -> 33.35405 | G41: =G40/G39*1000 -> 34.384218 | H41: =H40/H39*1000 -> 34.170669 | I41: =I40/I39*1000 -> 33.770608 | J41: =J40/J39*1000 -> 33.24904 | K41: =K40/K39*1000 -> 32.917254 | ... O41: =O40/O39*1000 -> 32.768362
B42: Precio (S/ x Kg) 1/ | C42: 4.28 | D42: 4.27 | E42: 4.3 | F42: 4.29 | G42: 4.33 | H42: 4.31 | I42: 4.29 | J42: 4.26 | K42: 4.25 | L42: 4.25 | M42: 4.22 | N42: 4.21 | O42: 4.22
...

Sheet C 7
A2: C.7 PERÚ: PRODUCCIÓN PECUARIA POR ESPECIE SEGÚN REGIÓN, 2019 P.
A3: (Unidades)
A5: Región | B5: Ave | C5: Ovino | D5: Porcino | E5: Vacuno | F5: Caprino | G5: Alpaca | H5: Llama
A6: Nacional | B6: =(B8+B9+B10+B11+B12+B16+B17+B18+B19+B20+B21+B22+B23+B24+B25+B26+B27+B28+B31+B32+B33+B34+B35+B36) -> 786256916 | C6: =(C8+C9+C10+C11+C12+C16+C17+C18+C19+C20+C21+C22+C23+C24+C25+C26+C27+C28+C31+C32+C33+C34+C35+C36) -> 2682837 | D6: =(D8+D9+D10+D11+D12+D16+D17+D18+D19+D20+D21+D22+D23+D24+D25+D26+D27+D28+D31+D32+D33+D34+D35+D36) -> 3284607 | E6: =(E8+E9+E10+E11+E12+E16+E17+E18+E19+E20+E21+E22+E23+E24+E25+E26+E27+E28+E31+E32+E33+E34+E35+E36) -> 1357067 | F6: =(F8+F9+F10+F11+F12+F16+F17+F18+F19+F20+F21+F22+F23+F24+F25+F26+F27+F28+F31+F32+F33+F34+F35+F36) -> 411263 | G6: =(G8+G9+G10+G11+G12+G16+G17+G18+G19+G20+G21+G22+G23+G24+G25+G26+G27+G28+G31+G32+G33+G34+G35+G36) -> 473283 | H6: =(H8+H9+H10+H11+H12+H16+H17+H18+H19+H20+H21+H22+H23+H24+H25+H26+H27+H28+H31+H32+H33+H34+H35+H36) -> 115790
A8: Tumbes | B8: 132083 | C8: 2941 | D8: 6339 | E8: 4510 | F8: 22337 | G8: 0 | H8: 0
A9: Piura | B9: 14783876 | C9: 120555 | D9: 113620 | E9: 47805 | F9: 93286 | G9: 0 | H9: 0
A10: Lambayeque | B10: 12079398 | C10: 31831 | D10: 31654 | E10: 21454 | F10: 26996 | G10: 0 | H10: 0
A11: La Libertad | B11: 140698998 | C11: 188941 | D11: 309578 | E11: 58195 | F11: 35654 | G11: 1377 | H11: 0
A12: Cajamarca | B12: 1768812 | C12: 99840 | D12: 150866 | E12: 196668 | F12: 28924 | G12: 0 | H12: 0
A13: Cajamarca | B13: 1142164 | C13: 71305 | D13: 64954 | E13: 111060 | F13: 16773 | G13: 0 | H13: 0
A14: Chota | B14: 306022 | C14: 22463 | D14: 48684 | E14: 54560 | F14: 1551 | G14: 0 | H14: 0
A15: Jaén | B15: 320626 | C15: 6072 | D15: 37228 | E15: 31048 | F15: 10600 | G15: 0 | H15: 0
A16: Amazonas | B16: 102828 | C16: 3532 | D16: 34042 | E16: 62118 | F16: 4816 | G16: 0 | H16: 0
A17: Ancash | B17: 17185743 | C17: 132633 | D17: 49555 | E17: 72763 | F17: 20509 | G17: 390 | H17: 0
A18: Lima | B18: 416797807 | C18: 64093 | D18: 1178439 | E18: 113481 | F18: 40739 | G18: 2831 | H18: 2030
A19: Ica | B19: 45451220 | C19: 9044 | D19: 212080 | E19: 13058 | F19: 17363 | G19: 0 | H19: 0
... A36: Madre de Dios | B36: 4328446 | C36: 2072 | D36: 17517 | E36: 14653 | F36: 0 | G36: 0 | H36: 0
A37: P Preliminar.
A38: Fuente:Direcciones Regionales de Agricultura.
A39: Elaboración: MInisterio de Agricultura y Riego - DGESEP - DEA.

Sheet C 8
A2: C.8 PERÚ: PRODUCCIÓN DE CARNE POR ESPECIE POR REGIÓN, 2019 P.
A3: (Toneladas)
A5: Región | B5: Ave | C5: Ovino | D5: Porcino | E5: Vacuno | F5: Caprino | G5: Alpaca | H5: Llama
A6: Nacional | B6: =(B8+B9+B10+B11+B12+B16+B17+B18+B19+B20+B21+B22+B23+B24+B25+B26+B27+B28+B31+B32+B33+B34+B35+B36) -> 1762857 | C6: =(C8+C9+C10+C11+C12+C16+C17+C18+C19+C20+C21+C22+C23+C24+C25+C26+C27+C28+C31+C32+C33+C34+C35+C36) -> 33782 | D6: =(D8+D9+D10+D11+D12+D16+D17+D18+D19+D20+D21+D22+D23+D24+D25+D26+D27+D28+D31+D32+D33+D34+D35+D36) -> 173258 | E6: =(E8+E9+E10+E11+E12+E16+E17+E18+E19+E20+E21+E22+E23+E24+E25+E26+E27+E28+E31+E32+E33+E34+E35+E36) -> 192919 | F6: =(F8+F9+F10+F11+F12+F16+F17+F18+F19+F20+F21+F22+F23+F24+F25+F26+F27+F28+F31+F32+F33+F34+F35+F36) -> 5100.4 | G6: =(G8+G9+G10+G11+G12+G16+G17+G18+G19+G20+G21+G22+G23+G24+G25+G26+G27+G28+G31+G32+G33+G34+G35+G36) -> 12579 | H6: =(H8+H9+H10+H11+H12+H16+H17+H18+H19+H20+H21+H22+H23+H24+H25+H26+H27+H28+H31+H32+H33+H34+H35+H36) -> 3849
A8: Tumbes | B8: 294 | C8: 33 | D8: 345 | E8: 685 | F8: 220 | G8: 0 | H8: 0
A9: Piura | B9: 33053 | C9: 1493 | D9: 5825 | E9: 7217 | F9: 1283 | G9: 0 | H9: 0
A10: Lambayeque | B10: 26358 | C10: 529 | D10: 1721 | E10: 3101 | F10: 375 | G10: 0 | H10: 0
A11: La Libertad | B11: 316907 | C11: 2504 | D11: 17654 | E11: 8227 | F11: 437 | G11: 43 | H11: 0
A12: Cajamarca | B12: 3667 | C12: 1211 | D12: 6484 | E12: 24659 | F12: 296 | G12: 0 | H12: 0
A13: Cajamarca | B13: 2388 | C13: 862 | D13: 2349 | E13: 12584 | F13: 170 | G13: 0 | H13: 0
A14: Chota | B14: 623 | C14: 288 | D14: 2320 | E14: 7372 | F14: 18 | G14: 0 | H14: 0
A15: Jaén | B15: 657 | C15: 61 | D15: 1815 | E15: 4703 | F15: 108 | G15: 0 | H15: 0
A16: Amazonas | B16: 820 | C16: 56 | D16: 1806 | E16: 9172 | F16: 60 | G16: 0 | H16: 0
A17: Ancash | B17: 38410 | C17: 1403 | D17: 1593 | E17: 9831 | F17: 219 | G17: 11 | H17: 0
A18: Lima | B18: 942813 | C18: 793 | D18: 74813 | E18: 21608 | F18: 533 | G18: 76 | H18: 63
A19: Ica | B19: 95536 | C19: 128 | D19: 11484 | E19: 1992 | F19: 247 | G19: 0 | H19: 0
... A36: Madre de Dios | B36: 9719 | C36: 36 | D36: 1050 | E36: 2373 | F36: 0 | G36: 0 | H36: 0
A37: P Preliminar.
A38: Fuente:Direcciones Regionales de Agricultura.
A39: Elaboración: MInisterio de Agricultura y Riego - DGESEP - DEA.

Sheet C 9
A2: C.9 PERÚ: RENDIMIENTO DE CARNE POR ESPECIESEGÚN REGIÓN, 2018 P.
A3: (Kg/Unidad )
A5: Región | B5: Ave | C5: Ovino | D5: Porcino | E5: Vacuno | F5: Caprino | G5: Alpaca | H5: Llama
A6: Nacional | B6: =('C 8'!B6/'C 7'!B6)*1000 -> 2.2420878 | C6: =('C 8'!C6/'C 7'!C6)*1000 -> 12.591894 | D6: =('C 8'!D6/'C 7'!D6)*1000 -> 52.748472 | E6: =('C 8'!E6/'C 7'!E6)*1000 -> 142.15879 | F6: =('C 8'!F6/'C 7'!F6)*1000 -> 12.401796 | G6: =('C 8'!G6/'C 7'!G6)*1000 -> 26.578178 | H6: =('C 8'!H6/'C 7'!H6)*1000 -> 33.241213
A8: Tumbes | B8: =('C 8'!B8/'C 7'!B8)*1000 -> 2.2258731 | C8: =('C 8'!C8/'C 7'!C8)*1000 -> 11.220673 | D8: =('C 8'!D8/'C 7'!D8)*1000 -> 54.424988 | E8: ='C 8'!E8/'C 7'!E8*1000 -> 151.8847 | F8: =('C 8'!F8/'C 7'!F8)*1000 -> 9.8491292 | G8: 0 | H8: 0 | I8: -
A9: Piura | B9: =('C 8'!B9/'C 7'!B9)*1000 -> 2.2357466 | C9: =('C 8'!C9/'C 7'!C9)*1000 -> 12.384389 | D9: =('C 8'!D9/'C 7'!D9)*1000 -> 51.267383 | E9: =('C 8'!E9/'C 7'!E9)*1000 -> 150.96747 | F9: =('C 8'!F9/'C 7'!F9)*1000 -> 13.753404 | G9: 0 | H9: 0
A10: Lambayeque | B10: =('C 8'!B10/'C 7'!B10)*1000 -> 2.1820624 | C10: =('C 8'!C10/'C 7'!C10)*1000 -> 16.619019 | D10: =('C 8'!D10/'C 7'!D10)*1000 -> 54.369116 | E10: =('C 8'!E10/'C 7'!E10)*1000 -> 144.54181 | F10: =('C 8'!F10/'C 7'!F10)*1000 -> 13.890947 | G10: 0 | H10: 0
A11: La Libertad | B11: =('C 8'!B11/'C 7'!B11)*1000 -> 2.2523757 | C11: =('C 8'!C11/'C 7'!C11)*1000 -> 13.252814 | D11: =('C 8'!D11/'C 7'!D11)*1000 -> 57.026016 | E11: =('C 8'!E11/'C 7'!E11)*1000 -> 141.36953 | F11: =('C 8'!F11/'C 7'!F11)*1000 -> 12.256689 | G11: =('C 8'!G11/'C 7'!G11)*1000 -> 31.227306 | H11: 0
A12: Cajamarca | B12: =('C 8'!B12/'C 7'!B12)*1000 -> 2.0731429 | C12: =('C 8'!C12/'C 7'!C12)*1000 -> 12.129407 | D12: =('C 8'!D12/'C 7'!D12)*1000 -> 42.978537 | E12: =('C 8'!E12/'C 7'!E12)*1000 -> 125.3839 | F12: =('C 8'!F12/'C 7'!F12)*1000 -> 10.233716 | G12: 0 | H12: 0
A13: Cajamarca | B13: =('C 8'!B13/'C 7'!B13)*1000 -> 2.0907681 | C13: =('C 8'!C13/'C 7'!C13)*1000 -> 12.088914 | D13: =('C 8'!D13/'C 7'!D13)*1000 -> 36.164055 | E13: =('C 8'!E13/'C 7'!E13)*1000 -> 113.30812 | F13: =('C 8'!F13/'C 7'!F13)*1000 -> 10.135337 | G13: 0 | H13: 0
A14: Chota | B14: =('C 8'!B14/'C 7'!B14)*1000 -> 2.0358013 | C14: =('C 8'!C14/'C 7'!C14)*1000 -> 12.821084 | D14: =('C 8'!D14/'C 7'!D14)*1000 -> 47.65426 | E14: =('C 8'!E14/'C 7'!E14)*1000 -> 135.1173 | F14: =('C 8'!F14/'C 7'!F14)*1000 -> 11.605416 | G14: 0 | H14: 0
A15: Jaén | B15: =('C 8'!B15/'C 7'!B15)*1000 -> 2.0491164 | C15: =('C 8'!C15/'C 7'!C15)*1000 -> 10.046113 | D15: =('C 8'!D15/'C 7'!D15)*1000 -> 48.753626 | E15: =('C 8'!E15/'C 7'!E15)*1000 -> 151.47514 | F15: =('C 8'!F15/'C 7'!F15)*1000 -> 10.188679 | G15: 0 | H15: 0
A16: Amazonas | B16: =('C 8'!B16/'C 7'!B16)*1000 -> 7.9744817 | C16: =('C 8'!C16/'C 7'!C16)*1000 -> 15.85504 | D16: =('C 8'!D16/'C 7'!D16)*1000 -> 53.052112 | E16: =('C 8'!E16/'C 7'!E16)*1000 -> 147.65446 | F16: =('C 8'!F16/'C 7'!F16)*1000 -> 12.458472 | G16: 0 | H16: 0
A17: Ancash | B17: =('C 8'!B17/'C 7'!B17)*1000 -> 2.2349921 | C17: =('C 8'!C17/'C 7'!C17)*1000 -> 10.578061 | D17: =('C 8'!D17/'C 7'!D17)*1000 -> 32.1461 | E17: =('C 8'!E17/'C 7'!E17)*1000 -> 135.10988 | F17: =('C 8'!F17/'C 7'!F17)*1000 -> 10.678239 | G17: =('C 8'!G17/'C 7'!G17)*1000 -> 28.205128 | H17: 0
A18: Lima | B18: =('C 8'!B18/'C 7'!B18)*1000 -> 2.2620393 | C18: =('C 8'!C18/'C 7'!C18)*1000 -> 12.372646 | D18: =('C 8'!D18/'C 7'!D18)*1000 -> 63.48483 | E18: =('C 8'!E18/'C 7'!E18)*1000 -> 190.41073 | F18: =('C 8'!F18/'C 7'!F18)*1000 -> 13.083286 | G18: =('C 8'!G18/'C 7'!G18)*1000 -> 26.845638 | H18: =('C 8'!H18/'C 7'!H18)*1000 -> 31.034483
A19: Ica | B19: =('C 8'!B19/'C 7'!B19)*1000 -> 2.1019458 | C19: =('C 8'!C19/'C 7'!C19)*1000 -> 14.15303 | D19: =('C 8'!D19/'C 7'!D19)*1000 -> 54.149378 | E19: =('C 8'!E19/'C 7'!E19)*1000 -> 152.55016 | F19: =('C 8'!F19/'C 7'!F19)*1000 -> 14.225652 | G19: 0 | H19: 0
A20: Huánuco | B20: =('C 8'!B20/'C 7'!B20)*1000 -> 2.0431223 | C20: =('C 8'!C20/'C 7'!C20)*1000 -> 11.425922 | D20: =('C 8'!D20/'C 7'!D20)*1000 -> 38.762331 | E20: =('C 8'!E20/'C 7'!E20)*1000 -> 153.87502 | F20: =('C 8'!F20/'C 7'!F20)*1000 -> 10.159901 | G20: =('C 8'!G20/'C 7'!G20)*1000 -> 27.070064 | H20: 0
A21: Pasco | B21: =('C 8'!B21/'C 7'!B21)*1000 -> 2.139401 | C21: =('C 8'!C21/'C 7'!C21)*1000 -> 12.490781 | D21: =('C 8'!D21/'C 7'!D21)*1000 -> 36.65673 | E21: =('C 8'!E21/'C 7'!E21)*1000 -> 158.46359 | F21: =('C 8'!F21/'C 7'!F21)*1000 -> 11.331445 | G21: =('C 8'!G21/'C 7'!G21)*1000 -> 22.992166 | H21: =('C 8'!H21/'C 7'!H21)*1000 -> 28.966597
A22: Junín | B22: =('C 8'!B22/'C 7'!B22)*1000 -> 2.1899126 | C22: =('C 8'!C22/'C 7'!C22)*1000 -> 10.810651 | D22: =('C 8'!D22/'C 7'!D22)*1000 -> 42.449572 | E22: =('C 8'!E22/'C 7'!E22)*1000 -> 130.41913 | F22: =('C 8'!F22/'C 7'!F22)*1000 -> 12.273361 | G22: =('C 8'!G22/'C 7'!G22)*1000 -> 22.037487 | H22: =('C 8'!H22/'C 7'!H22)*1000 -> 27.790644
A23: Huancavelica | B23: =('C 8'!B23/'C 7'!B23)*1000 -> 1.9840099 | C23: =('C 8'!C23/'C 7'!C23)*1000 -> 12.998025 | D23: =('C 8'!D23/'C 7'!D23)*1000 -> 36.746175 | E23: =('C 8'!E23/'C 7'!E23)*1000 -> 117.5877 | F23: =('C 8'!F23/'C 7'!F23)*1000 -> 13.021339 | G23: =('C 8'!G23/'C 7'!G23)*1000 -> 25.236028 | H23: =('C 8'!H23/'C 7'!H23)*1000 -> 34.054944
A24: Arequipa | B24: =('C 8'!B24/'C 7'!B24)*1000 -> 2.2414992 | C24: =('C 8'!C24/'C 7'!C24)*1000 -> 14.631455 | D24: =('C 8'!D24/'C 7'!D24)*1000 -> 55.711695 | E24: =('C 8'!E24/'C 7'!E24)*1000 -> 156.42808 | F24: =('C 8'!F24/'C 7'!F24)*1000 -> 12.578616 | G24: =('C 8'!G24/'C 7'!G24)*1000 -> 24.635522 | H24: =('C 8'!H24/'C 7'!H24)*1000 -> 34.545261
A25: Moquegua | B25: =('C 8'!B25/'C 7'!B25)*1000 -> 2.07204 | C25: =('C 8'!C25/'C 7'!C25)*1000 -> 20.332259 | D25: =('C 8'!D25/'C 7'!D25)*1000 -> 44.711853 | E25: =('C 8'!E25/'C 7'!E25)*1000 -> 214.30615 | F25: =('C 8'!F25/'C 7'!F25)*1000 -> 14.513788 | G25: =('C 8'!G25/'C 7'!G25)*1000 -> 30.847705 | H25: =('C 8'!H25/'C 7'!H25)*1000 -> 43.6068
A26: Tacna | B26: =('C 8'!B26/'C 7'!B26)*1000 -> 2.2762368 | C26: =('C 8'!C26/'C 7'!C26)*1000 -> 23.046586 | D26: =('C 8'!D26/'C 7'!D26)*1000 -> 39.299662 | E26: =('C 8'!E26/'C 7'!E26)*1000 -> 192.65873 | F26: =('C 8'!F26/'C 7'!F26)*1000 -> 14.224219 | G26: =('C 8'!G26/'C 7'!G26)*1000 -> 28.406234 | H26: =('C 8'!H26/'C 7'!H26)*1000 -> 29.462366
A27: Ayacucho | B27: =('C 8'!B27/'C 7'!B27)*1000 -> 2.027511 | C27: =('C 8'!C27/'C 7'!C27)*1000 -> 11.780491 | D27: =('C 8'!D27/'C 7'!D27)*1000 -> 44.240119 | E27: =('C 8'!E27/'C 7'!E27)*1000 -> 126.18741 | F27: =('C 8'!F27/'C 7'!F27)*1000 -> 12.071651 | G27: =('C 8'!G27/'C 7'!G27)*1000 -> 26.640763 | H27: =('C 8'!H27/'C 7'!H27)*1000 -> 29.818956
A28: Apurímac | B28: =('C 8'!B28/'C 7'!B28)*1000 -> 2.0066164 | C28: =('C 8'!C28/'C 7'!C28)*1000 -> 11.604294 | D28: =('C 8'!D28/'C 7'!D28)*1000 -> 38.896598 | E28: =('C 8'!E28/'C 7'!E28)*1000 -> 109.8927 | F28: =('C 8'!F28/'C 7'!F28)*1000 -> 10.603589 | G28: =('C 8'!G28/'C 7'!G28)*1000 -> 24.32196 | H28: =('C 8'!H28/'C 7'!H28)*1000 -> 28.620377
A29: Abancay | B29: =('C 8'!B29/'C 7'!B29)*1000 -> 2.0156857 | C29: =('C 8'!C29/'C 7'!C29)*1000 -> 12.303891 | D29: =('C 8'!D29/'C 7'!D29)*1000 -> 36.598077 | E29: =('C 8'!E29/'C 7'!E29)*1000 -> 113.14842 | F29: =('C 8'!F29/'C 7'!F29)*1000 -> 10.684884 | G29: =('C 8'!G29/'C 7'!G29)*1000 -> 24.890096 | H29: =('C 8'!H29/'C 7'!H29)*1000 -> 30.347734
A30: Andahuaylas | B30: =('C 8'!B30/'C 7'!B30)*1000 -> 1.9927038 | C30: =('C 8'!C30/'C 7'!C30)*1000 -> 10.874607 | D30: =('C 8'!D30/'C 7'!D30)*1000 -> 40.206866 | E30: =('C 8'!E30/'C 7'!E30)*1000 -> 106.59658 | F30: =('C 8'!F30/'C 7'!F30)*1000 -> 10.56699 | G30: =('C 8'!G30/'C 7'!G30)*1000 -> 22.997835 | H30: =('C 8'!H30/'C 7'!H30)*1000 -> 27.037466
A31: Cusco | B31: =('C 8'!B31/'C 7'!B31)*1000 -> 2.1363281 | C31: =('C 8'!C31/'C 7'!C31)*1000 -> 11.987494 | D31: =('C 8'!D31/'C 7'!D31)*1000 -> 41.064045 | E31: =('C 8'!E31/'C 7'!E31)*1000 -> 148.83358 | F31: =('C 8'!F31/'C 7'!F31)*1000 -> 12.817226 | G31: =('C 8'!G31/'C 7'!G31)*1000 -> 26.595804 | H31: =('C 8'!H31/'C 7'!H31)*1000 -> 29.071537
A32: Puno | B32: =('C 8'!B32/'C 7'!B32)*1000 -> 1.9828146 | C32: =('C 8'!C32/'C 7'!C32)*1000 -> 13.793377 | D32: =('C 8'!D32/'C 7'!D32)*1000 -> 33.43272 | E32: =('C 8'!E32/'C 7'!E32)*1000 -> 143.66245 | F32: 0 | G32: =('C 8'!G32/'C 7'!G32)*1000 -> 27.648316 | H32: =('C 8'!H32/'C 7'!H32)*1000 -> 38.495254
A33: San Martín | B33: =('C 8'!B33/'C 7'!B33)*1000 -> 2.1950136 | C33: =('C 8'!C33/'C 7'!C33)*1000 -> 10.358915 | D33: =('C 8'!D33/'C 7'!D33)*1000 -> 42.905831 | E33: =('C 8'!E33/'C 7'!E33)*1000 -> 110.34471 | F33: 0 | G33: 0 | H33: 0
A34: Loreto | B34: =('C 8'!B34/'C 7'!B34)*1000 -> 2.2314167 | C34: =('C 8'!C34/'C 7'!C34)*1000 -> 12.293345 | D34: =('C 8'!D34/'C 7'!D34)*1000 -> 45.058188 | E34: =('C 8'!E34/'C 7'!E34)*1000 -> 117.14429 | F34: 0 | G34: 0 | H34: 0
A35: Ucayali | B35: =('C 8'!B35/'C 7'!B35)*1000 -> 2.1492617 | C35: =('C 8'!C35/'C 7'!C35)*1000 -> 12.237762 | D35: =('C 8'!D35/'C 7'!D35)*1000 -> 39.008234 | E35: =('C 8'!E35/'C 7'!E35)*1000 -> 128.21162 | F35: 0 | G35: 0 | H35: 0
A36: Madre de Dios | B36: =('C 8'!B36/'C 7'!B36)*1000 -> 2.2453786 | C36: =('C 8'!C36/'C 7'!C36)*1000 -> 17.374517 | D36: =('C 8'!D36/'C 7'!D36)*1000 -> 59.941771 | E36: =('C 8'!E36/'C 7'!E36)*1000 -> 161.94636 | F36: 0 | G36: 0 | H36: 0
A37: P Preliminar.
A38: Fuente:Direcciones Regionales de Agricultura.
A39: Elaboración: MInisterio de Agricultura y Riego - DGESEP - DEA.

Sheet C 10
A2: C.10 PERÚ: ESPECIES PECUARIAS EN PRODUCCIÓN Y ANIMALES ESQUILADOS POR REGIÓN, 2019 P.
A3: (Unidades)
A5: Región | B5: Gallinas en Postura | C5: Vacas en Ordeño | D5: Alpacas esquiladas | E5: LLamas esquiladas | F5: Ovinos esquilados
A6: Nacional | B6: =(B8+B9+B10+B11+B12+B16++B17+B18+B19+B20+B21+B22+B23+B24+B25+B26+B27+B28+B31+B32+B33+B34+B35+B36) -> 29468987 | C6: =(C8+C9+C10+C11+C12+C16++C17+C18+C19+C20+C21+C22+C23+C24+C25+C26+C27+C28+C31+C32+C33+C34+C35+C36) -> 905818 | D6: =(D8+D9+D10+D11+D12+D16++D17+D18+D19+D20+D21+D22+D23+D24+D25+D26+D27+D28+D31+D32+D33+D34+D35+D36) -> 2254980 | E6: =(E8+E9+E10+E11+E12+E16++E17+E18+E19+E20+E21+E22+E23+E24+E25+E26+E27+E28+E31+E32+E33+E34+E35+E36) -> 340347 | F6: =(F8+F9+F10+F11+F12+F16++F17+F18+F19+F20+F21+F22+F23+F24+F25+F26+F27+F28+F31+F32+F33+F34+F35+F36) -> 4304515
A8: Tumbes | B8: 15503 | C8: 362 | D8: 0 | E8: 0 | F8: 0
A9: Piura | B9: 394729 | C9: 24072 | D9: 53 | E9: 0 | F9: 18515
A10: Lambayeque | B10: 498472 | C10: 17837 | D10: 0 | E10: 0 | F10: 0
A11: La Libertad | B11: 4838790 | C11: 48823 | D11: 6520 | E11: 0 | F11: 249612
A12: Cajamarca | B12: 429010 | C12: 164222 | D12: 0 | E12: 0 | F12: 165750
A13: Cajamarca | B13: 209563 | C13: 97194 | D13: 0 | E13: 0 | F13: 126012
A14: Chota | B14: 145201 | C14: 61574 | D14: 0 | E14: 0 | F14: 39738
A15: Jaén | B15: 74246 | C15: 5454 | D15: 0 | E15: 0 | F15: 0
A16: Amazonas | B16: 137753 | C16: 79623 | D16: 0 | E16: 0 | F16: 5255
A17: Ancash | B17: 206001 | C17: 14847 | D17: 0 | E17: 0 | F17: 7076
A18: Lima | B18: 7383051 | C18: 71092 | D18: 18461 | E18: 1325 | F18: 91432
A19: Ica | B19: 10940573 | C19: 12537 | D19: 0 | E19: 0 | F19: 0
... A36: Madre de Dios | B36: 209906 | C36: 1354 | D36: 0 | E36: 0 | F36: 0
A37: P Preliminar.
A38: Fuente:Direcciones Regionales de Agricultura.
A39: Elaboración: MInisterio de Agricultura y Riego - DGESEP - DEA.

Sheet C 11
A2: C.11 PERÚ: PRODUCCIÓN DE PRINCIPALES PRODUCTOS PECUARIOS SEGÚN REGIÓN, 2019 P.
A3: (Toneladas)
A5: Región | B5: Huevo | C5: Leche fresca | D5: Fibra Alpaca | E5: Fibra Llama | F5: Lana ovino
A6: Nacional | B6: =(B8+B9+B10+B11+B12+B16++B17+B18+B19+B20+B21+B22+B23+B24+B25+B26+B27+B28+B31+B32+B33+B34+B35+B36) -> 488487 | C6: =(C8+C9+C10+C11+C12+C16++C17+C18+C19+C20+C21+C22+C23+C24+C25+C26+C27+C28+C31+C32+C33+C34+C35+C36) -> 2129366 | D6: =(D8+D9+D10+D11+D12+D16++D17+D18+D19+D20+D21+D22+D23+D24+D25+D26+D27+D28+D31+D32+D33+D34+D35+D36) -> 4453 | E6: =(E8+E9+E10+E11+E12+E16++E17+E18+E19+E20+E21+E22+E23+E24+E25+E26+E27+E28+E31+E32+E33+E34+E35+E36) -> 656 | F6: =(F8+F9+F10+F11+F12+F16++F17+F18+F19+F20+F21+F22+F23+F24+F25+F26+F27+F28+F31+F32+F33+F34+F35+F36) -> 7750
A8: Tumbes | B8: 103 | C8: 374 | D8: 0 | E8: 0 | F8: 0
A9: Piura | B9: 4739 | C9: 42122 | D9: 0 | E9: 0 | F9: 25
A10: Lambayeque | B10: 7663 | C10: 56665 | D10: 0 | E10: 0 | F10: 0
A11: La Libertad | B11: 84438 | C11: 151171 | D11: 17 | E11: 0 | F11: 734
A12: Cajamarca | B12: 2392 | C12: 391136 | D12: 0 | E12: 0 | F12: 286
A13: Cajamarca | B13: 1364 | C13: 240341 | D13: 0 | E13: 0 | F13: 227
A14: Chota | B14: 679 | C14: 141614 | D14: 0 | E14: 0 | F14: 59
A15: Jaén | B15: 349 | C15: 9180 | D15: 0 | E15: 0 | F15: 0
A16: Amazonas | B16: 1458 | C16: 98574 | D16: 0 | E16: 0 | F16: 3
A17: Ancash | B17: 1324 | C17: 18181 | D17: 0 | E17: 0 | F17: 9
A18: Lima | B18: 131293 | C18: 352868 | D18: 29 | E18: 2 | F18: 120
A19: Ica | B19: 197407 | C19: 68271 | D19: 0 | E19: 0 | F19: 0
... A36: Madre de Dios | B36: 3471 | C36: 1687 | D36: 0 | E36: 0 | F36: 0
A37: P Preliminar.
A38: Fuente:Direcciones Regionales de Agricultura.
A39: Elaboración: MInisterio de Agricultura y Riego - DGESEP - DEA.

Sheet C 12
A2: C.12 PERÚ: RENDIMIENTO POR PRODUCTO SEGÚN REGIÓN, 2019 P.
A3: (Kg/Unidad/Año )
A5: Región | B5: Huevo de gallina | C5: Leche fresca | D5: Fibra Alpaca | E5: Fibra Llama | F5: Lana ovino
A6: Nacional | B6: =('C 11'!B6/'C 10'!B6)*1000 -> 16.576308 | C6: =('C 11'!C6/'C 10'!C6)*1000 -> 2350.7658 | D6: =('C 11'!D6/'C 10'!D6)*1000 -> 1.9747404 | E6: =('C 11'!E6/'C 10'!E6)*1000 -> 1.9274446 | F6: =('C 11'!F6/'C 10'!F6)*1000 -> 1.8004351
A8: Tumbes | B8: =('C 11'!B8/'C 10'!B8)*1000 -> 6.6438754 | C8: =('C 11'!C8/'C 10'!C8)*1000 -> 1033.1492 | D8: 0 | E8: 0 | F8: 0
A9: Piura | B9: =('C 11'!B9/'C 10'!B9)*1000 -> 12.005705 | C9: =('C 11'!C9/'C 10'!C9)*1000 -> 1749.8338 | D9: 0 | E9: 0 | F9: =('C 11'!F9/'C 10'!F9)*1000 -> 1.3502565
A10: Lambayeque | B10: =('C 11'!B10/'C 10'!B10)*1000 -> 15.37298 | C10: =('C 11'!C10/'C 10'!C10)*1000 -> 3176.8235 | D10: 0 | E10: 0 | F10: 0
A11: La Libertad | B11: =('C 11'!B11/'C 10'!B11)*1000 -> 17.45023 | C11: =('C 11'!C11/'C 10'!C11)*1000 -> 3096.3071 | D11: =('C 11'!D11/'C 10'!D11)*1000 -> 2.607362 | E11: 0 | F11: =('C 11'!F11/'C 10'!F11)*1000 -> 2.9405638
A12: Cajamarca | B12: =('C 11'!B12/'C 10'!B12)*1000 -> 5.5756276 | C12: =('C 11'!C12/'C 10'!C12)*1000 -> 2381.7515 | D12: 0 | E12: 0 | F12: =('C 11'!F12/'C 10'!F12)*1000 -> 1.7254902
A13: Cajamarca | B13: =('C 11'!B13/'C 10'!B13)*1000 -> 6.5087826 | C13: =('C 11'!C13/'C 10'!C13)*1000 -> 2472.7967 | D13: 0 | E13: 0 | F13: =('C 11'!F13/'C 10'!F13)*1000 -> 1.8014157
A14: Chota | B14: =('C 11'!B14/'C 10'!B14)*1000 -> 4.6762763 | C14: =('C 11'!C14/'C 10'!C14)*1000 -> 2299.8993 | D14: 0 | E14: 0 | F14: =('C 11'!F14/'C 10'!F14)*1000 -> 1.4847249
A15: Jaén | B15: =('C 11'!B15/'C 10'!B15)*1000 -> 4.7005899 | C15: =('C 11'!C15/'C 10'!C15)*1000 -> 1683.1683 | D15: 0 | E15: 0 | F15: 0
A16: Amazonas | B16: =('C 11'!B16/'C 10'!B16)*1000 -> 10.584162 | C16: =('C 11'!C16/'C 10'!C16)*1000 -> 1238.0091 | D16: 0 | E16: 0 | F16: =('C 11'!F16/'C 10'!F16)*1000 -> 0.57088487
A17: Ancash | B17: =('C 11'!B17/'C 10'!B17)*1000 -> 6.4271533 | C17: =('C 11'!C17/'C 10'!C17)*1000 -> 1224.5571 | D17: 0 | E17: 0 | F17: =('C 11'!F17/'C 10'!F17)*1000 -> 1.271905
A18: Lima | B18: =('C 11'!B18/'C 10'!B18)*1000 -> 17.783028 | C18: =('C 11'!C18/'C 10'!C18)*1000 -> 4963.5402 | D18: =('C 11'!D18/'C 10'!D18)*1000 -> 1.5708792 | E18: =('C 11'!E18/'C 10'!E18)*1000 -> 1.509434 | F18: =('C 11'!F18/'C 10'!F18)*1000 -> 1.3124508
A19: Ica | B19: =('C 11'!B19/'C 10'!B19)*1000 -> 18.04357 | C19: =('C 11'!C19/'C 10'!C19)*1000 -> 5445.5611 | D19: 0 | E19: 0 | F19: 0
A20: Huánuco | B20: =('C 11'!B20/'C 10'!B20)*1000 -> 6.789161 | C20: =('C 11'!C20/'C 10'!C20)*1000 -> 1566.1015 | D20: =('C 11'!D20/'C 10'!D20)*1000 -> 2.7453672 | E20: 0 | F20: =('C 11'!F20/'C 10'!F20)*1000 -> 1.4881164
