Workbook
Name \c: #REF!
Name \x: 'C 5'!$AD$2
Name \x: #REF!
Name A: 'C 5'!$U$25:$DA$25
Name A: #REF!
Name A_IMPRESION_IM: 'C 91 - 99'!#REF!
Name A_IMPRESION_IM: #REF!
Name A_impresión_IM: 'C 100 - 101'!$A$1:$L$48
Name A_impresión_IM: 'C 102 - 103'!$A$1:$H$49
Name A_impresión_IM: 'C 104-105'!$A$1:$J$52
Name A_impresión_IM: 'C 106 - 107'!$A$1:$H$50
Name A_impresión_IM: 'C 108 - 109 '!$A$1:$J$32
Name A_IMPRESIÓN_IM: [1]CYPPOLLO!#REF!
Name A_IMPRESIÓN_IM: [1]CYPPOLLO!#REF!
Name A_IMPRESIÓN_IM: [1]CYPPOLLO!#REF!
Name A_impresión_IM: #REF!
Name A_impresión_IM: 'C 90'!$A$1:$D$43
Name A_IMPRESIÓN_IM: 'C 91 - 99'!$A$3:$DO$41
Name A_IMPRESIÓN_IM: [1]CYPPOLLO!#REF!
Name A_impresión_IM: #REF!
Name A_impresión_IM: 'C-88'!$A$1:$D$43
Name A_impresión_IM: 'C-89'!$A$1:$D$43
Name A_impresión_IM: #REF!
Name agricode: #REF!
Name agriVar: #REF!
Name ajiC: #REF!
Name ajiR: #REF!
Name ajiS: #REF!
Name algodonC: #REF!
Name algodonP: #REF!
Name algodonPr: #REF!
Name algodonR: #REF!
Name algodonS: #REF!
Name amilaceo: #REF!
Name amilaceoC: #REF!
Name amilaceoP: #REF!
Name amilaceoPr: #REF!
Name amilaceoR: #REF!
Name amilaceoS: #REF!
Name apioC: #REF!
Name apioR: #REF!
Name apioS: #REF!
Name arrozC: #REF!
Name arrozP: #REF!
Name arrozPr: #REF!
Name arrozR: #REF!
Name arrozS: #REF!
Name arvejagsC: #REF!
Name arvejagsP: #REF!
Name arvejagsPr: #REF!
Name arvejagsR: #REF!
Name arvejagsS: #REF!
Name betarragaC: #REF!
Name betarragaR: #REF!
Name betarragaS: #REF!
Name cafeC: #REF!
Name cafeP: #REF!
Name cafePr: #REF!
Name cafeR: #REF!
Name cafeS: #REF!

Sheet C 1 - C 2 - C 3
A2: C. 1 PERÚ: EVOLUCIÓN DEL VALOR BRUTO DE LA PRODUCCIÓN (VBP) AGROPECUARIA SEGÚN SUBSECTORES | AL2: Tasa
A3: Y PRINCIPALES ESPECIES Y PRODUCTOS, 2007-17.
A4: (Millones de soles a precios 2007) | AL4: Crec.
A6: Sector/Producto | C6: 2000 | D6: 2001 | E6: 2002 | F6: 2003 | G6: 2004 | H6: 2005 | I6: 2006 | J6: 2007 | K6: 2008 | L6: 2009 | M6: 2010 | N6: 2011 | O6: 2012 | P6: 2013 | Q6: 2014 | R6: 2015 | S6: 2016 | T6: 2017P | U6: Var. % 17/16
A7: Sector agropecuario | C7: 17474.288 | D7: 17601.774 | E7: 18603.601 | F7: 18969.264 | G7: 19095.964 | H7: 20511.888 | I7: 22151.698 | J7: 22808.223 | K7: 24741.782 | L7: 25379.112 | M7: 26407.393 | N7: 27861.221 | O7: 29538.057 | P7: 30131.892 | Q7: 30698.162 | R7: 31894.031 | S7: 32587.912 | T7: 33488.077 | U7: =((T7/S7)-1)*100 -> 2.7622675 | AL7: 3.9003718
A8: Subsector agrícola | C8: 11577.106 | D8: 11537.321 | E8: 12282.801 | F8: 12444.853 | G8: 12391.673 | H8: 13289.257 | I8: 14340.694 | J8: 14533.213 | K8: 15862.117 | L8: 15991.201 | M8: 16616.027 | N8: 17377.315 | O8: 18471.343 | P8: 18672.774 | Q8: 18833.452 | R8: 19407.908 | S8: 19596.629 | T8: 20137.025 | U8: =((T8/S8)-1)*100 -> 2.7576003 | AL8: 3.3096524
A9: Subsector pecuario | C9: 5897.1819 | D9: 6064.4534 | E9: 6320.7995 | F9: 6524.4111 | G9: 6704.2911 | H9: 7222.6312 | I9: 7811.0043 | J9: 8275.0106 | K9: 8879.6649 | L9: 9387.9104 | M9: 9791.3659 | N9: 10483.906 | O9: 11066.714 | P9: 11459.118 | Q9: 11864.71 | R9: 12486.123 | S9: 12991.283 | T9: 13351.052 | U9: =((T9/S9)-1)*100 -> 2.7693078 | AL9: 4.9239817
B11: Industria avícola1 | C11: =SUM(C12:C13) -> 2892.5467 | D11: =SUM(D12:D13) -> 2958.5398 | E11: =SUM(E12:E13) -> 3140.9777 | F11: =SUM(F12:F13) -> 3262.9052 | G11: =SUM(G12:G13) -> 3280.0884 | H11: =SUM(H12:H13) -> 3623.208 | I11: =SUM(I12:I13) -> 4017.5993 | J11: =SUM(J12:J13) -> 4330.5457 | ... T11: =SUM(T12:T13) -> 8482.7392 | U11: =((T11/S11)-1)*100 -> 3.6434732 | AL11: 6.5333618
A12: 1 | B12: Ave | C12: 2340.5868 | D12: 2376.5995 | E12: 2551.2419 | F12: 2651.7805 | G12: 2655.0091 | H12: 2983.5192 | I12: 3259.4009 | J12: 3534.754 | K12: 4024.4096 | L12: 4424.6415 | M12: 4679.4037 | N12: 5111.6331 | O12: 5556.6377 | P12: 5754.8754 | Q12: 6044.2721 | R12: 6531.3279 | S12: 6945.9118 | T12: 7199.7648 | U12: =((T12/S12)-1)*100 -> 3.6547112 | AL12: 6.8330194
B13: Huevo | C13: 551.95981 | D13: 581.94033 | E13: 589.73586 | F13: 611.1247 | G13: 625.0793 | H13: 639.68874 | I13: 758.19836 | J13: 795.79163 | K13: 823.34367 | L13: 830.03573 | M13: 880.67898 | N13: 981.23448 | O13: 970.01986 | P13: 1080.5037 | Q13: 1107.8079 | R13: 1193.1406 | S13: 1238.626 | T13: 1282.9744 | U13: =((T13/S13)-1)*100 -> 3.5804534 | AL13: 5.0866818
A14: 2 | B14: Ovino | C14: 378.69666 | D14: 388.44706 | E14: 383.19881 | F14: 389.15451 | G14: 410.75815 | H14: 410.6108 | I14: 413.26362 | J14: 412.47568 | K14: 406.50953 | L14: 407.83262 | M14: 410.40566 | N14: 417.55629 | O14: 430.33906 | P14: 425.4783 | Q14: 419.56517 | R14: 404.24186 | S14: 413.88606 | T14: 407.71942 | U14: =((T14/S14)-1)*100 -> -1.4899363 | AL14: 0.43531962
A15: 3 | B15: Porcino | C15: 433.84159 | D15: 442.17786 | E15: 438.46552 | F15: 439.45495 | G15: 468.55959 | H15: 494.02564 | I15: 516.56285 | J15: 542.67087 | K15: 545.87427 | L15: 543.61273 | M15: 548.0505 | N15: 557.20936 | O15: 579.78834 | P15: 605.04946 | Q15: 641.56592 | R15: 677.27371 | S15: 707.95125 | T15: 747.47961 | U15: =((T15/S15)-1)*100 -> 5.5834871 | AL15: 3.2519179
A16: 4 | B16: Vacuno | C16: 1114.1376 | D16: 1114.3101 | E16: 1147.3964 | F16: 1174.1982 | G16: 1227.9462 | H16: 1304.4442 | I16: 1382.1225 | J16: 1396.2936 | K16: 1397.0031 | L16: 1408.8557 | M16: 1470.1708 | N16: 1531.8679 | O16: 1596.2999 | P16: 1651.6467 | Q16: 1678.5449 | R16: 1676.6898 | S16: 1648.3585 | T16: 1613.9496 | U16: =((T16/S16)-1)*100 -> -2.0874613 | AL16: 2.203958
A17: 5 | B17: Caprino | C17: 57.628638 | D17: 54.358612 | E17: 53.2678 | F17: 57.86649 | G17: 59.540999 | H17: 60.849631 | I17: 62.265599 | J17: 61.471099 | K17: 59.023487 | L17: 56.575765 | M17: 56.372629 | N17: 56.547053 | O17: 57.436365 | P17: 59.205135 | Q17: 56.705957 | R17: 54.255777 | S17: 53.577298 | T17: 51.003394 | U17: =((T17/S17)-1)*100 -> -4.8040955 | AL17: -0.71582249
A18: 6 | B18: Alpaca | C18: 130.07052 | D18: 137.29939 | E18: 147.34252 | F18: 146.03742 | G18: 148.15292 | H18: 154.35973 | I18: 156.52136 | J18: 166.73576 | K18: 169.59754 | L18: 181.37009 | M18: 191.55737 | N18: 201.48255 | O18: 213.60321 | P18: 216.62584 | Q18: 224.19339 | R18: 212.14603 | S18: 221.52934 | T18: 226.94761 | U18: =((T18/S18)-1)*100 -> 2.4458458 | AL18: 3.3285644
A19: 7 | B19: Llama | C19: 25.164873 | D19: 25.469187 | E19: 25.548012 | F19: 27.548992 | G19: 29.147221 | H19: 30.438379 | I19: 30.250894 | J19: 31.936406 | K19: 31.293959 | L19: 32.901268 | M19: 32.110595 | N19: 33.368022 | O19: 34.277477 | P19: 32.926864 | Q19: 32.858649 | R19: 31.361264 | S19: 31.335787 | T19: 31.588459 | U19: =((T19/S19)-1)*100 -> 0.80633648 | AL19: 1.3462922
A20: 9 | B20: Leche fresca vaca | C20: 750.57252 | D20: 822.44563 | E20: 873.78151 | F20: 918.10562 | G20: 968.0926 | H20: 1027.8104 | I20: 1119.3499 | J20: 1209.7822 | K20: 1300.9539 | L20: 1372.9053 | M20: 1394.7272 | N20: 1458.8443 | O20: 1488.0465 | P20: 1502.2867 | Q20: 1529.2278 | R20: 1581.5399 | S20: 1623.9666 | T20: 1671.1284 | U20: =((T20/S20)-1)*100 -> 2.9041126 | AL20: 4.8209443
A21: 10 | B21: Fibra Alpaca | C21: 57.028737 | D21: 62.315145 | E21: 58.038526 | F21: 56.889792 | G21: 59.561545 | H21: 65.957002 | I21: 64.34826 | J21: 71.411913 | K21: 73.692373 | L21: 80.42743 | M21: 79.790848 | N21: 85.468012 | O21: 87.961213 | P21: 81.046434 | Q21: 82.232222 | R21: 81.371677 | S21: 82.663974 | T21: 79.102304 | U21: =((T21/S21)-1)*100 -> -4.308612 | AL21: 1.943268
A22: 11 | B22: Fibra Llama | C22: 4.5501732 | D22: 4.655693 | E22: 3.8465935 | F22: 3.8834236 | G22: 3.8107969 | H22: 3.7007886 | I22: 3.8203699 | J22: 4.5360321 | K22: 4.3141416 | L22: 4.2647455 | M22: 3.8739118 | N22: 4.151652 | O22: 4.5686388 | P22: 4.4488663 | Q22: 4.5651464 | R22: 4.0206913 | S22: 4.103786 | T22: 4.1711851 | U22: =((T22/S22)-1)*100 -> 1.6423648 | AL22: -0.51025319
A23: 12 | B23: Lana | C23: 53.498434 | D23: 54.434896 | E23: 48.936127 | F23: 48.988537 | G23: 48.632604 | H23: 47.226607 | I23: 44.899717 | J23: 47.151471 | K23: 43.649349 | L23: 44.487539 | M23: 44.223758 | N23: 44.543176 | O23: 47.735271 | P23: 45.024505 | Q23: 43.170807 | R23: 38.753922 | S23: 40.476489 | T23: 35.222878 | U23: =((T23/S23)-1)*100 -> -12.979415 | AL23: -2.4285914
A24: P Preliminar.
A25: 1 Considera ave y huevo.
A26: Fuente:Direcciones Regionales de Agricultura.
A27: Elaboración: MInisterio de Agricultura y Riego-DGESEP-DEA.
A31: C. 2 PERÚ: PARTICIPACIÓN SEGÚN SUBSECTORES Y PRINCIPALES ESPECIES Y PRODUCTOS
A32: EN EL VALOR BRUTO DE LA PRODUCCIÓN AGROPECUARIA, 2007-17.
A33: (%)
A35: Sector/Producto | C35: 2000 | D35: 2001 | E35: 2002 | F35: 2003 | G35: 2004 | H35: 2005 | I35: 2006 | J35: 2007 | K35: 2008 | L35: 2009 | M35: 2010 | N35: 2011 | O35: 2012 | P35: 2013 | Q35: 2014 | R35: 2015 | S35: 2016 | T35: 2017P
A36: Sector agropecuario | C36: =C7/$C$7*100 -> 100 | D36: =D7/$D$7*100 -> 100 | E36: =E7/$E$7*100 -> 100 | F36: =F7/$F$7*100 -> 100 | G36: =G7/$G$7*100 -> 100 | H36: =H7/$H$7*100 -> 100 | I36: =I7/$I$7*100 -> 100 | J36: =J7/$J$7*100 -> 100 | K36: =K7/$K$7*100 -> 100 | L36: =L7/$L$7*100 -> 100 | M36: =M7/$M$7*100 -> 100 | N36: =N7/$N$7*100 -> 100 | O36: =O7/$O$7*100 -> 100 | P36: =P7/$P$7*100 -> 100 | Q36: =Q7/$Q$7*100 -> 100 | R36: =R7/$R$7*100 -> 100 | S36: =S7/$S$7*100 -> 100 | T36: =T7/$T$7*100 -> 100
A37: Subsector agrícola | C37: =C8/$C$7*100 -> 66.252234 | D37: =D8/$D$7*100 -> 65.546351 | E37: =E8/$E$7*100 -> 66.023784 | F37: =F8/$F$7*100 -> 65.605355 | G37: =G8/$G$7*100 -> 64.89158 | H37: =H8/$H$7*100 -> 64.788072 | I37: =I8/$I$7*100 -> 64.738575 | J37: =J8/$J$7*100 -> 63.719179 | K37: =K8/$K$7*100 -> 64.11065 | L37: =L8/$L$7*100 -> 63.009303 | M37: =M8/$M$7*100 -> 62.921875 | N37: =N8/$N$7*100 -> 62.370974 | O37: =O8/$O$7*100 -> 62.53405 | P37: =P8/$P$7*100 -> 61.970135 | Q37: =Q8/$Q$7*100 -> 61.350422 | R37: =R8/$R$7*100 -> 60.851223 | S37: =S8/$S$7*100 -> 60.134655 | T37: =T8/$T$7*100 -> 60.131924
A38: Subsector pecuario | C38: =C9/$C$7*100 -> 33.747766 | D38: =D9/$D$7*100 -> 34.453649 | E38: =E9/$E$7*100 -> 33.976216 | F38: =F9/$F$7*100 -> 34.394645 | G38: =G9/$G$7*100 -> 35.10842 | H38: =H9/$H$7*100 -> 35.211928 | I38: =I9/$I$7*100 -> 35.261425 | J38: =J9/$J$7*100 -> 36.280821 | K38: =K9/$K$7*100 -> 35.88935 | L38: =L9/$L$7*100 -> 36.990697 | M38: =M9/$M$7*100 -> 37.078125 | N38: =N9/$N$7*100 -> 37.629026 | O38: =O9/$O$7*100 -> 37.46595 | P38: =P9/$P$7*100 -> 38.029865 | Q38: =Q9/$Q$7*100 -> 38.649578 | R38: =R9/$R$7*100 -> 39.148777 | S38: =S9/$S$7*100 -> 39.865345 | T38: =T9/$T$7*100 -> 39.868076
B40: Industria avícola1 | C40: =C11/$C$7*100 -> 16.553159 | D40: =D11/$D$7*100 -> 16.808191 | E40: =E11/$E$7*100 -> 16.883709 | F40: =F11/$F$7*100 -> 17.201011 | G40: =G11/$G$7*100 -> 17.176868 | H40: =H11/$H$7*100 -> 17.663942 | I40: =I11/$I$7*100 -> 18.136756 | J40: =J11/$J$7*100 -> 18.986773 | K40: =K11/$K$7*100 -> 19.593387 | L40: =L11/$L$7*100 -> 20.704733 | M40: =M11/$M$7*100 -> 21.055023 | N40: =N11/$N$7*100 -> 21.868631 | O40: =O11/$O$7*100 -> 22.095758 | P40: =P11/$P$7*100 -> 22.684865 | Q40: =Q11/$Q$7*100 -> 23.298072 | R40: =R11/$R$7*100 -> 24.219166 | S40: =S11/$S$7*100 -> 25.115257 | T40: =T11/$T$7*100 -> 25.330625
B41: Ave | C41: =C12/$C$7*100 -> 13.394462 | D41: =D12/$D$7*100 -> 13.502045 | E41: =E12/$E$7*100 -> 13.7137 | F41: =F12/$F$7*100 -> 13.979353 | G41: =G12/$G$7*100 -> 13.903509 | H41: =H12/$H$7*100 -> 14.545318 | I41: =I12/$I$7*100 -> 14.714 | J41: =J12/$J$7*100 -> 15.497718 | K41: =K12/$K$7*100 -> 16.265641 | L41: =L12/$L$7*100 -> 17.434186 | M41: =M12/$M$7*100 -> 17.720052 | N41: =N12/$N$7*100 -> 18.346766 | O41: =O12/$O$7*100 -> 18.811792 | P41: =P12/$P$7*100 -> 19.098951 | Q41: =Q12/$Q$7*100 -> 19.689362 | R41: =R12/$R$7*100 -> 20.478214 | S41: =S12/$S$7*100 -> 21.314381 | T41: =T12/$T$7*100 -> 21.499487
A42: 1 | B42: Huevo | C42: =C13/$C$7*100 -> 3.158697 | D42: =D13/$D$7*100 -> 3.3061459 | E42: =E13/$E$7*100 -> 3.1700093 | F42: =F13/$F$7*100 -> 3.2216574 | G42: =G13/$G$7*100 -> 3.2733582 | H42: =H13/$H$7*100 -> 3.1186244 | I42: =I13/$I$7*100 -> 3.4227551 | J42: =J13/$J$7*100 -> 3.4890557 | K42: =K13/$K$7*100 -> 3.327746 | L42: =L13/$L$7*100 -> 3.2705468 | M42: =M13/$M$7*100 -> 3.3349713 | N42: =N13/$N$7*100 -> 3.5218646 | O42: =O13/$O$7*100 -> 3.2839664 | P42: =P13/$P$7*100 -> 3.585914 | Q42: =Q13/$Q$7*100 -> 3.6087107 | R42: =R13/$R$7*100 -> 3.7409525 | S42: =S13/$S$7*100 -> 3.8008756 | T42: =T13/$T$7*100 -> 3.8311379
B43: Ovino | C43: =C14/$C$7*100 -> 2.1671651 | D43: =D14/$D$7*100 -> 2.2068631 | E43: =E14/$E$7*100 -> 2.0598099 | F43: =F14/$F$7*100 -> 2.0515003 | G43: =G14/$G$7*100 -> 2.1510208 | H43: =H14/$H$7*100 -> 2.0018187 | I43: =I14/$I$7*100 -> 1.865607 | J43: =J14/$J$7*100 -> 1.8084516 | K43: =K14/$K$7*100 -> 1.6430083 | L43: =L14/$L$7*100 -> 1.6069618 | M43: =M14/$M$7*100 -> 1.5541317 | N43: =N14/$N$7*100 -> 1.4987006 | O43: =O14/$O$7*100 -> 1.456897 | P43: =P14/$P$7*100 -> 1.412053 | Q43: =Q14/$Q$7*100 -> 1.3667436 | R43: =R14/$R$7*100 -> 1.267453 | S43: =S14/$S$7*100 -> 1.2700601 | T43: =T14/$T$7*100 -> 1.2175062
B44: Porcino | C44: =C15/$C$7*100 -> 2.4827426 | D44: =D15/$D$7*100 -> 2.512121 | E44: =E15/$E$7*100 -> 2.3568853 | F44: =F15/$F$7*100 -> 2.3166684 | G44: =G15/$G$7*100 -> 2.4537101 | H44: =H15/$H$7*100 -> 2.4084845 | I44: =I15/$I$7*100 -> 2.3319334 | J44: =J15/$J$7*100 -> 2.3792773 | K44: =K15/$K$7*100 -> 2.2062851 | L44: =L15/$L$7*100 -> 2.1419691 | M44: =M15/$M$7*100 -> 2.0753677 | N44: =N15/$N$7*100 -> 1.999946 | O44: =O15/$O$7*100 -> 1.962852 | P44: =P15/$P$7*100 -> 2.0080035 | Q44: =Q15/$Q$7*100 -> 2.0899164 | R44: =R15/$R$7*100 -> 2.1235124 | S44: =S15/$S$7*100 -> 2.1724351 | T44: =T15/$T$7*100 -> 2.2320768
B45: Vacuno | C45: =C16/$C$7*100 -> 6.3758683 | D45: =D16/$D$7*100 -> 6.3306693 | E45: =E16/$E$7*100 -> 6.1676038 | F45: =F16/$F$7*100 -> 6.1900041 | G45: =G16/$G$7*100 -> 6.4303968 | H45: =H16/$H$7*100 -> 6.3594546 | I45: =I16/$I$7*100 -> 6.2393523 | J45: =J16/$J$7*100 -> 6.1218865 | K45: =K16/$K$7*100 -> 5.6463316 | L45: =L16/$L$7*100 -> 5.551241 | M45: =M16/$M$7*100 -> 5.5672698 | N45: =N16/$N$7*100 -> 5.4982083 | O45: =O16/$O$7*100 -> 5.4042145 | P45: =P16/$P$7*100 -> 5.4813906 | Q45: =Q16/$Q$7*100 -> 5.4679004 | R45: =R16/$R$7*100 -> 5.2570645 | S45: =S16/$S$7*100 -> 5.0581899 | T45: =T16/$T$7*100 -> 4.8194753
B46: Caprino | C46: =C17/$C$7*100 -> 0.32979105 | D46: =D17/$D$7*100 -> 0.30882462 | E46: =E17/$E$7*100 -> 0.28633059 | F46: =F17/$F$7*100 -> 0.30505395 | G46: =G17/$G$7*100 -> 0.31179887 | H46: =H17/$H$7*100 -> 0.29665544 | I46: =I17/$I$7*100 -> 0.28108725 | J46: =J17/$J$7*100 -> 0.26951288 | K46: =K17/$K$7*100 -> 0.23855794 | L46: =L17/$L$7*100 -> 0.22292256 | M46: =M17/$M$7*100 -> 0.21347291 | N46: =N17/$N$7*100 -> 0.20295971 | O46: =O17/$O$7*100 -> 0.19444869 | P46: =P17/$P$7*100 -> 0.19648661 | Q46: =Q17/$Q$7*100 -> 0.18472102 | R46: =R17/$R$7*100 -> 0.17011263 | S46: =S17/$S$7*100 -> 0.1644085 | T46: =T17/$T$7*100 -> 0.15230314
B47: Alpaca | C47: =C18/$C$7*100 -> 0.74435378 | D47: =D18/$D$7*100 -> 0.78003155 | E47: =E18/$E$7*100 -> 0.79201076 | F47: =F18/$F$7*100 -> 0.76986338 | G47: =G18/$G$7*100 -> 0.77583367 | H47: =H18/$H$7*100 -> 0.75253788 | I47: =I18/$I$7*100 -> 0.70658853 | J47: =J18/$J$7*100 -> 0.73103351 | K47: =K18/$K$7*100 -> 0.68547018 | L47: =L18/$L$7*100 -> 0.7146432 | M47: =M18/$M$7*100 -> 0.72539295 | N47: =N18/$N$7*100 -> 0.72316481 | O47: =O18/$O$7*100 -> 0.7231458 | P47: =P18/$P$7*100 -> 0.71892546 | Q47: =Q18/$Q$7*100 -> 0.73031535 | R47: =R18/$R$7*100 -> 0.66515904 | S47: =S18/$S$7*100 -> 0.67978992 | T47: =T18/$T$7*100 -> 0.67769674
B48: Llama | C48: =C19/$C$7*100 -> 0.14401087 | D48: =D19/$D$7*100 -> 0.1446967 | E48: =E19/$E$7*100 -> 0.13732832 | F48: =F19/$F$7*100 -> 0.14522963 | G48: =G19/$G$7*100 -> 0.15263551 | H48: =H19/$H$7*100 -> 0.14839385 | I48: =I19/$I$7*100 -> 0.13656242 | J48: =J19/$J$7*100 -> 0.14002146 | K48: =K19/$K$7*100 -> 0.12648223 | L48: =L19/$L$7*100 -> 0.12963917 | M48: =M19/$M$7*100 -> 0.12159699 | N48: =N19/$N$7*100 -> 0.11976511 | O48: =O19/$O$7*100 -> 0.11604513 | P48: =P19/$P$7*100 -> 0.10927579 | Q48: =Q19/$Q$7*100 -> 0.10703784 | R48: =R19/$R$7*100 -> 0.09832957 | S48: =S19/$S$7*100 -> 0.096157701 | T48: =T19/$T$7*100 -> 0.094327478
...

Sheet C-4
A2: C. 4 PERÚ: POBLACIÓN PECUARIA POR ESPECIE SEGÚN REGIÓN, 2017P.
A3: (Unidades)
A5: Región | B5: Ave | C5: Alpaca | D5: LLama | E5: Caprino | F5: Ovino | G5: Porcino | H5: Vacuno | I5: Vacas en ordeño
A6: TOTAL NACIONAL | B6: =(B8+B9+B10+B11+B12+B16+B17+B18+B19+B20+B21+B22+B23+B24+B25+B26+B27+B28+B31+B32+B33+B34+B35+B36) -> 1.566377e+08 | C6: =(C8+C9+C10+C11+C12+C16+C17+C18+C19+C20+C21+C22+C23+C24+C25+C26+C27+C28+C31+C32+C33+C34+C35+C36) -> 4330710 | D6: =(D8+D9+D10+D11+D12+D16+D17+D18+D19+D20+D21+D22+D23+D24+D25+D26+D27+D28+D31+D32+D33+D34+D35+D36) -> 1106201 | E6: =(E8+E9+E10+E11+E12+E16+E17+E18+E19+E20+E21+E22+E23+E24+E25+E26+E27+E28+E31+E32+E33+E34+E35+E36) -> 1814359 | F6: =(F8+F9+F10+F11+F12+F16+F17+F18+F19+F20+F21+F22+F23+F24+F25+F26+F27+F28+F31+F32+F33+F34+F35+F36) -> 11338424 | G6: =(G8+G9+G10+G11+G12+G16+G17+G18+G19+G20+G21+G22+G23+G24+G25+G26+G27+G28+G31+G32+G33+G34+G35+G36) -> 3187254 | H6: =(H8+H9+H10+H11+H12+H16+H17+H18+H19+H20+H21+H22+H23+H24+H25+H26+H27+H28+H31+H32+H33+H34+H35+H36) -> 5535569 | I6: =(I8+I9+I10+I11+I12+I16+I17+I18+I19+I20+I21+I22+I23+I24+I25+I26+I27+I28+I31+I32+I33+I34+I35+I36) -> 889113.94
A8: Tumbes | B8: 154270 | C8: 0 | D8: 0 | E8: 62430 | F8: 7580 | G8: 30480 | H8: 22350 | I8: 388.75
A9: Piura | B9: 6138251 | C9: 79 | D9: 0 | E9: 345496 | F9: 341213 | G9: 169531 | H9: 276247 | I9: 24275.355
A10: Lambayeque | B10: 1868521 | C10: 0 | D10: 0 | E10: 91548 | F10: 68810 | G10: 68810 | H10: 113514 | I10: 18912.667
A11: La Libertad | B11: 25241243 | C11: 7851 | D11: 0 | E11: 98187 | F11: 356486 | G11: 113018 | H11: 237501 | I11: 43041.5
A12: Cajamarca | B12: 839388.71 | C12: 1180 | D12: 0 | E12: =SUM(E13:E15) -> 99202 | F12: 455567.04 | G12: 297734 | H12: 645182 | I12: 162288.83
A13: Cajamarca | B13: 344734.08 | C13: 1180 | D13: 0 | E13: 66334 | F13: 343654 | G13: 89450 | H13: 262247 | I13: 97808.417
A14: Chota | B14: 201456.67 | C14: 0 | D14: 0 | E14: 20460 | F14: 103320.04 | G14: 104650 | H14: 276310 | I14: 59049
A15: Jaén | B15: 293197.96 | C15: 0 | D15: 0 | E15: 12408 | F15: 8592.7585 | G15: 103634 | H15: 106625 | I15: 5431.4167
A16: Amazonas | B16: 1521527 | C16: 0 | D16: 0 | E16: 12640 | F16: 21743.726 | G16: 85690 | H16: 247610 | I16: 74885
A17: Ancash | B17: 2640335.6 | C17: 10320 | D17: 0 | E17: 169610 | F17: 672175.39 | G17: 170334 | H17: 305720 | I17: 13462.833
A18: Lima | B18: 58064430 | C18: 46625 | D18: 21904 | E18: 167335 | F18: 305462 | G18: 460253 | H18: 245851 | I18: 76069.839
A19: Ica | B19: 14767142 | C19: 0 | D19: 0 | E19: 78925 | F19: 29996 | G19: 54124 | H19: 50124 | I19: 11507.333
A20: Huánuco | B20: 1763394.8 | C20: 6850 | D20: 3530 | E20: 102170 | F20: 529452.91 | G20: 405230 | H20: 292412 | I20: 32348.833
A21: Pasco | B21: 141529.7 | C21: 133225 | D21: 44169 | E21: 6173 | F21: 698536 | G21: 51993 | H21: 119663 | I21: 28427
A22: Junín | B22: 3554425.6 | C22: 91678 | D22: 59605 | E22: 10680 | F22: 1478438 | G22: 168586 | H22: 321586 | I22: 37385.917
A23: Huancavelica | B23: 392876.17 | C23: 252713 | D23: 127731 | E23: 171566 | F23: 620737 | G23: 174439 | H23: 174439 | I23: 12803
A24: Arequipa | B24: 19046592 | C24: 421292 | D24: 87181 | E24: 20736 | F24: 187138 | G24: 95391 | H24: 205693 | I24: 75027.083
... A36: Madre de Dios | B36: 485976.32 | C36: 0 | D36: 0 | E36: 0 | F36: 9558.675 | G36: 13750 | H36: 56420 | I36: 1352.1667
A37: P Preliminar.
A38: Fuente:Direcciones Regionales de Agricultura.
A39: Elaboración: MInisterio de Agricultura y Riego-DGESEP-DEA.

Sheet C 5
A2: C. 5 PERÚ: EVOLUCIÓN DE LA POBLACIÓN, SACA, PRODUCCIÓN, RENDIMIENTO Y PRECIOS RECIBIDOS
A3: POR EL PRODUCTOR POR AÑO, SEGÚN PRINCIPALES ESPECIES Y PRODUCTOS PECUARIOS, 2007-17.
A5: Especie/ Producto | B5: Variable | C5: 2000 | D5: 2001 | E5: 2002 | F5: 2003 | G5: 2004 | H5: 2005 | I5: 2006 | J5: 2007 | K5: 2008 | L5: 2009 | M5: 2010 | N5: 2011 | O5: 2012 | P5: 2013 | Q5: 2014 | R5: 2015 | S5: 2016 | T5: 2017 P
A7: Ave | B7: Población (miles) | C7: 88010358 | D7: 85621159 | E7: 90354182 | F7: 92846109 | G7: 97761003 | H7: 99278818 | I7: 1.179767e+08 | J7: 120227.62 | K7: 131179.1 | L7: 137837.98 | M7: 130779.05 | N7: 128943.46 | O7: 138554.11 | P7: 138179.77 | Q7: 144703.73 | R7: 151000.91 | S7: 158263.25 | T7: 156637.7
B8: Saca (miles) | C8: 2.8373305e+08 | D8: 2.8786059e+08 | E8: 3.070943e+08 | F8: 3.1094349e+08 | G8: 3.0848531e+08 | H8: 3.4207363e+08 | I8: 3.685458e+08 | J8: 394749.63 | K8: 435909.32 | L8: 476340.31 | M8: 504986.76 | N8: 535421.14 | O8: 575566.45 | P8: 594004.19 | Q8: 621140.12 | R8: 645016.18 | S8: 690892.31 | T8: 707599.54
B9: Producción carne (t) | C9: 510160.6 | D9: 518010.01 | E9: 556075.54 | F9: 577989.19 | G9: 578692.93 | H9: 650295.87 | I9: 710427.79 | J9: 770444.49 | K9: 877171.13 | L9: 964406.75 | M9: 1019935.4 | N9: 1108345.3 | O9: 1211139.7 | P9: 1254348.1 | Q9: 1317425.8 | R9: 1423585.8 | S9: 1513949.6 | T9: 1569280.1
B10: Rendimiento (kg/unidad) | C10: =(C9/C8)*1000 -> 1.7980302 | D10: =(D9/D8)*1000 -> 1.7995169 | E10: =(E9/E8)*1000 -> 1.8107648 | F10: =(F9/F8)*1000 -> 1.8588239 | G10: =(G9/G8)*1000 -> 1.8759173 | H10: =(H9/H8)*1000 -> 1.9010407 | I10: =(I9/I8)*1000 -> 1.9276513 | J10: =(J9/J8)*1000 -> 1951.7295 | ... T10: =(T9/T8)*1000 -> 2217.7517
B11: Precio (S/. x kg) | C11: 3.0623519 | D11: 3.1873748 | E11: 3.0703652 | F11: 3.0858923 | G11: 3.4803615 | H11: 3.4599896 | I11: 3.5960549 | J11: 3.6294643 | K11: 4.1812821 | L11: 4.3262276 | M11: 4.6350228 | N11: 4.674095 | O11: 4.6970699 | P11: 4.7513647 | Q11: 4.7752413 | R11: 4.8227353 | S11: 4.8421853 | T11: 4.8364133
A13: Ovino | B13: Población (unidades) | C13: 14800991 | D13: 14727155 | E13: 14690547 | F13: 14721243 | G13: 14696522 | H13: 14813786 | I13: 14675255 | J13: 14580166 | K13: 14509628 | L13: 14137690 | M13: 14159720 | N13: 14050173 | O13: 12184143 | P13: 11830977 | Q13: 11652272 | R13: 11973040 | S13: 11441603 | T13: 11338424
B14: Saca (unidades) | C14: 2521661 | D14: 2571321 | E14: 2517896.1 | F14: 2535935.1 | G14: 2709847.1 | H14: 2685627 | I14: 2692775.8 | J14: 2681207.6 | K14: 2678240.6 | L14: 2753680.5 | M14: 2788507.3 | N14: 2844228.5 | O14: 2910165.9 | P14: 2832370.8 | Q14: 2788554.6 | R14: 2698887 | S14: 2745950.6 | T14: 2699041.6
B15: Producción carne (t) | C15: 31067.801 | D15: 31867.711 | E15: 31437.152 | F15: 31925.749 | G15: 33698.085 | H15: 33685.997 | I15: 33903.631 | J15: 33838.989 | K15: 33349.534 | L15: 33458.078 | M15: 33669.167 | N15: 34255.797 | O15: 35304.479 | P15: 34905.708 | Q15: 34420.602 | R15: 33163.497 | S15: 33954.695 | T15: 33448.792
B16: Rendimiento (kg/unidad) | C16: =(C15/C14)*1000 -> 12.320372 | D16: =(D15/D14)*1000 -> 12.393517 | E16: =(E15/E14)*1000 -> 12.485484 | F16: =(F15/F14)*1000 -> 12.58934 | G16: =(G15/G14)*1000 -> 12.435419 | H16: =(H15/H14)*1000 -> 12.543066 | I16: =(I15/I14)*1000 -> 12.590588 | J16: =(J15/J14)*1000 -> 12.620802 | ... T16: =(T15/T14)*1000 -> 12.392841
B17: Precio (S/. x kg) | C17: 2.9883567 | D17: 3.1322603 | E17: 3.2947699 | F17: 3.2854617 | G17: 3.2731932 | H17: 3.312026 | I17: 3.3163458 | J17: 3.4872158 | K17: 3.8994542 | L17: 4.1349665 | M17: 4.4612302 | N17: 4.5239693 | O17: 4.8957108 | P17: 5.0375223 | Q17: 5.7214855 | R17: 5.718746 | S17: 5.8967419 | T17: 5.597156
A19: Porcino | B19: Población (unidades) | C19: 2845573 | D19: 2809888 | E19: 2941036 | F19: 2990499 | G19: 3000199 | H19: 3010724.2 | I19: 3073854.7 | J19: 3115772 | K19: 3151405.9 | L19: 3256809 | M19: 3254413.2 | N19: 3263254 | O19: 2987315 | P19: 3176115 | Q19: 3173014.8 | R19: 3200714.1 | S19: 3104910.5 | T19: 3187254
B20: Saca (unidades) | C20: 1540534 | D20: 1650886 | E20: 1637129 | F20: 1670386.7 | G20: 1884572.9 | H20: 1991345.5 | I20: 2074714.9 | J20: 2153140.7 | K20: 2131518 | L20: 2213056.6 | M20: 2186978.4 | N20: 2298432.4 | O20: 2401633.6 | P20: 2499030.7 | Q20: 2629565.6 | R20: 2764884.4 | S20: 2876803.1 | T20: 3072555.8
B21: Producción carne (t) | C21: 91553.744 | D21: 93312.948 | E21: 92529.532 | F21: 92738.333 | G21: 98880.295 | H21: 104254.4 | I21: 109010.44 | J21: 114520.02 | K21: 115196.04 | L21: 114718.78 | M21: 115655.29 | N21: 117588.09 | O21: 122352.94 | P21: 127683.8 | Q21: 135389.88 | R21: 142925.31 | S21: 149399.2 | T21: 157740.89
B22: Rendimiento (kg/unidad) | C22: =(C21/C20)*1000 -> 59.429876 | D22: =(D21/D20)*1000 -> 56.522951 | E22: =(E21/E20)*1000 -> 56.51939 | F22: =(F21/F20)*1000 -> 55.519079 | G22: =(G21/G20)*1000 -> 52.468277 | H22: =(H21/H20)*1000 -> 52.35375 | I22: =(I21/I20)*1000 -> 52.542371 | J22: =(J21/J20)*1000 -> 53.187433 | ... T22: =(T21/T20)*1000 -> 51.338656
B23: Precio (S/. x kg) | C23: 3.305678 | D23: 3.3422812 | E23: 3.3510876 | F23: 3.3920961 | G23: 3.4214913 | H23: 3.4321061 | I23: 3.4669191 | J23: 3.4954268 | K23: 3.8031874 | L23: 4.1160683 | M23: 4.2507882 | N23: 5.0540967 | O23: 5.2362093 | P23: 5.9095403 | Q23: 6.0691638 | R23: 6.4175362 | S23: 6.7727417 | T23: 6.96375
A25: Vacuno | B25: Población (unidades) | C25: 4980291 | D25: 5035612 | E25: 5163700 | F25: 5193414 | G25: 5184822 | H25: 5249783.1 | I25: 5241101.5 | J25: 5420865 | K25: 5442988.7 | L25: 5459435 | M25: 5520199.7 | N25: 5589173.1 | O25: 5660984 | P25: 5555988 | Q25: 5577958.8 | R25: 5553469.5 | S25: 5525454.3 | T25: 5535569
B26: Saca (unidades) | C26: 875746 | D26: 920031 | E26: 951383.1 | F26: 986401.51 | G26: 1020294 | H26: 1074578 | I26: 1127320.8 | J26: 1138577.9 | K26: 1151905.9 | L26: 1168496.7 | M26: 1218722.5 | N26: 1266709.7 | O26: 1319403.9 | P26: 1375094.6 | Q26: 1376390.8 | R26: 1367797.1 | S26: 1364230.4 | T26: 1330763.1
B27: Producción carne (t) | C27: 130249.25 | D27: 130269.42 | E27: 134137.4 | F27: 137270.7 | G27: 143554.15 | H27: 152497.22 | I27: 161578.26 | J27: 163234.95 | K27: 163317.89 | L27: 164703.53 | M27: 171871.63 | N27: 179084.39 | O27: 186616.87 | P27: 193087.24 | Q27: 196231.8 | R27: 196014.92 | S27: 192702.82 | T27: 188680.22
B28: Rendimiento (kg/unidad) | C28: =(C27/C26)*1000 -> 148.72948 | D28: =(D27/D26)*1000 -> 141.59243 | E28: =(E27/E26)*1000 -> 140.99199 | F28: =(F27/F26)*1000 -> 139.1631 | G28: =(G27/G26)*1000 -> 140.69881 | H28: =(H27/H26)*1000 -> 141.91358 | I28: =(I27/I26)*1000 -> 143.32944 | J28: =(J27/J26)*1000 -> 143.36739 | ... T28: =(T27/T26)*1000 -> 141.78348
B29: Precio (S/. x kg) | C29: 3.3390775 | D29: 3.4125664 | E29: 3.2942235 | F29: 3.5184737 | G29: 3.3325097 | H29: 3.3633941 | I29: 3.3971701 | J29: 3.5046243 | K29: 3.7709002 | L29: 4.0826893 | M29: 4.0971722 | N29: 4.2457162 | O29: 4.6922639 | P29: 4.8381645 | Q29: 5.2315176 | R29: 5.4142252 | S29: 5.4510834 | T29: 5.5319915
A31: Caprino | B31: Población (unidades) | C31: 2034914 | D31: 2017808 | E31: 1983128 | F31: 1983302 | G31: 1971863 | H31: 1952956.2 | I31: 1936854.9 | J31: 1925912 | K31: 1904124 | L31: 1928677.6 | M31: 1968305.5 | N31: 1946117 | O31: 1949502 | P31: 1928630.9 | Q31: 1905153.3 | R31: 1882042.4 | S31: 1864712.8 | T31: 1814359
B32: Saca (unidades) | C32: 451247 | D32: 468861 | E32: 476569.07 | F32: 523992.55 | G32: 524448.18 | H32: 527096.3 | I32: 518662.97 | J32: 506927 | K32: 496705.92 | L32: 505880.15 | M32: 499447.5 | N32: 489915.18 | O32: 496625.69 | P32: 505261.55 | Q32: 489955.69 | R32: 464017.77 | S32: 458811.95 | T32: 444799.26
B33: Producción carne (t) | C33: 6267.655 | D33: 5912.009 | E33: 5793.3729 | F33: 6293.5236 | G33: 6475.6422 | H33: 6617.9682 | I33: 6771.968 | J33: 6685.5586 | K33: 6419.3579 | L33: 6153.1452 | M33: 6131.0522 | N33: 6150.0225 | O33: 6246.7435 | P33: 6439.1138 | Q33: 6167.3048 | R33: 5900.8247 | S33: 5827.0338 | T33: 5547.0975
B34: Rendimiento (kg/unidad) | C34: =(C33/C32)*1000 -> 13.889633 | D34: =(D33/D32)*1000 -> 12.6093 | E34: =(E33/E32)*1000 -> 12.156418 | F34: =(F33/F32)*1000 -> 12.010712 | G34: =(G33/G32)*1000 -> 12.347535 | H34: =(H33/H32)*1000 -> 12.55552 | I34: =(I33/I32)*1000 -> 13.056587 | J34: =(J33/J32)*1000 -> 13.188405 | ... T34: =(T33/T32)*1000 -> 12.471013
B35: Precio (S/. x kg) | C35: 3.3315645 | D35: 3.2776518 | E35: 3.3131776 | F35: 3.2156136 | G35: 3.2673527 | H35: 3.0527814 | I35: 3.0056297 | J35: 3.1702418 | K35: 3.4120634 | L35: 3.6114162 | M35: 3.3793338 | N35: 3.5334883 | O35: 3.6803789 | P35: 3.9319271 | Q35: 4.0373212 | R35: 4.2799914 | S35: 4.6632557 | T35: 4.7398272
A37: Alpaca | B37: Población (unidades) | C37: 3078524 | D37: 3190373 | E37: 3335721 | F37: 3422557 | G37: 3429019 | H37: 3594514.8 | I37: 3625627 | J37: 3687340 | K37: 3780806.1 | L37: 4105581.8 | M37: 4177498.6 | N37: 4322258.4 | O37: 3927361 | P37: 4005315 | Q37: 4315792.5 | R37: 4318457.1 | S37: 4319227.8 | T37: 4330710
B38: Saca (unidades) | C38: 269643 | D38: 288318 | E38: 313415 | F38: 304890 | G38: 312092 | H38: 321478 | I38: 330071.5 | J38: 355174 | K38: 365555 | L38: 387980 | M38: 410085 | N38: 424100.05 | O38: 455558 | P38: 463354 | Q38: 481847 | R38: 446198.97 | S38: 474135 | T38: 479063
B39: Producción carne (t) | C39: 7306.77 | D39: 7712.855 | E39: 8277.0321 | F39: 8203.7176 | G39: 8322.5566 | H39: 8671.2269 | I39: 8792.6575 | J39: 9366.456 | K39: 9527.2181 | L39: 10188.547 | M39: 10760.821 | N39: 11318.373 | O39: 11999.257 | P39: 12169.054 | Q39: 12594.164 | R39: 11917.399 | S39: 12444.51 | T39: 12748.884
B40: Rendimiento (kg/unidad) | C40: =(C39/C38)*1000 -> 27.097941 | D40: =(D39/D38)*1000 -> 26.751209 | E40: =(E39/E38)*1000 -> 26.409177 | F40: =(F39/F38)*1000 -> 26.907139 | G40: =(G39/G38)*1000 -> 26.666998 | H40: =(H39/H38)*1000 -> 26.973003 | I40: =(I39/I38)*1000 -> 26.638645 | J40: =(J39/J38)*1000 -> 26.371457 | ... T40: =(T39/T38)*1000 -> 26.612124
B41: Precio (S/. x kg) | C41: 2.4034135 | D41: 2.5716504 | E41: 2.4840721 | F41: 2.530806 | G41: 2.6582433 | H41: 2.6149934 | I41: 2.5076534 | J41: 2.4956294 | K41: 2.9148449 | L41: 3.1337591 | M41: 3.4254103 | N41: 3.6541767 | O41: 4.0305761 | P41: 4.4273199 | Q41: 4.7714252 | R41: 4.6321369 | S41: 4.8140747 | T41: 4.9143385
A43: Llama | B43: Población (unidades) | C43: 1183908 | D43: 1179088 | E43: 1207275 | F43: 1230543 | G43: 1236984 | H43: 1269979 | I43: 1256101 | J43: 1274425 | K43: 1262782.2 | L43: 1237593 | M43: 1245169.2 | N43: 1226612 | O43: 1194404 | P43: 1234089 | Q43: 1211917.2 | R43: 1194708 | S43: 1105017.5 | T43: 1106201
B44: Saca (unidades) | C44: 91890 | D44: 95157 | E44: 97389 | F44: 101826 | G44: 109330 | H44: 112106 | I44: 113801 | J44: 118399 | K44: 119237 | L44: 127316 | M44: 123384 | N44: 128346 | O44: 130530 | P44: 125729 | Q44: 123360 | R44: 119806 | S44: 119195.31 | T44: 120748
B45: Producción carne (t) | C45: 3193.64 | D45: 3232.26 | E45: 3242.2636 | F45: 3496.2053 | G45: 3699.0344 | H45: 3862.8935 | I45: 3839.1 | J45: 4053.0061 | K45: 3971.4739 | L45: 4175.4554 | M45: 4075.1121 | N45: 4234.6905 | O45: 4350.1082 | P45: 4178.7037 | Q45: 4170.0467 | R45: 3980.0156 | S45: 3976.7823 | T45: 4008.8486
B46: Rendimiento (kg/unidad) | C46: =(C45/C44)*1000 -> 34.755033 | D46: =(D45/D44)*1000 -> 33.967653 | E46: =(E45/E44)*1000 -> 33.291887 | F46: =(F45/F44)*1000 -> 34.335094 | G46: =(G45/G44)*1000 -> 33.833663 | H46: =(H45/H44)*1000 -> 34.457509 | I46: =(I45/I44)*1000 -> 33.735204 | J46: =(J45/J44)*1000 -> 34.23176 | ... T46: =(T45/T44)*1000 -> 33.200124
B47: Precio (S/. x kg) | C47: 1.9254907 | D47: 2.176594 | E47: 2.3888563 | F47: 2.404597 | G47: 2.4543537 | H47: 2.4866738 | I47: 2.3899286 | J47: 2.3057938 | K47: 2.7041353 | L47: 2.8765651 | M47: 3.0247426 | N47: 3.3952692 | O47: 3.6145209 | P47: 3.8743497 | Q47: 4.2451014 | R47: 4.0899611 | S47: 4.3180239 | T47: 4.2514853
A49: Huevo | B49: Gallinas (unidades) | C49: 11899785 | D49: 12705402 | E49: 12651366 | F49: 13059118 | G49: 13362491 | H49: 13654721 | I49: 15842743 | J49: 16572273 | K49: 17048710 | L49: 17206413 | M49: 18156674 | N49: 19950695 | O49: 19846405 | P49: 21805630 | Q49: 22353253 | R49: 23883311 | S49: 24752078 | T49: 25559765
A50: Gallina | B50: Producción (t) | C50: 178685.6 | D50: 188391.17 | E50: 190914.81 | F50: 197839.01 | G50: 202356.52 | H50: 207086.03 | I50: 245451.07 | J50: 257621.12 | K50: 266540.52 | L50: 268706.94 | M50: 285101.64 | N50: 317654.41 | O50: 314023.91 | P50: 349790.78 | Q50: 358629.94 | R50: 386254.64 | S50: 400979.6 | T50: 415336.49
...

Sheet C -6
A2: C. 6 PERÚ: POBLACIÓN, SACA, PRODUCCIÓN, RENDIMIENTO Y PRECIOS RECIBIDOS POR EL PRODUCTOR,
A3: SEGÚN PRINCIPALES ESPECIES Y PRODUCTOS PECUARIOS, 2017P.
A5: Especie/ Producto | B5: Variable | C5: ANUAL | D5: Ene | E5: Feb | F5: Mar | G5: Abr | H5: May | I5: Jun | J5: Jul | K5: Ago | L5: Set | M5: Oct | N5: Nov | O5: Dic
A7: Ave | B7: Población | C7: 1.566377e+08
B8: Saca (unidades) | C8: =SUM(D8:O8) -> 7.0923295e+08 | D8: 58872047 | E8: 53666132 | F8: 58753072 | G8: 56127884 | H8: 57657420 | I8: 58647510 | J8: 62191077 | K8: 61989535 | L8: 59951959 | M8: 61255285 | N8: 58709005 | O8: 61412026
B9: Producción carne (t) | C9: =SUM(D9:O9) -> 1569280.1 | D9: 130327.09 | E9: 116051.85 | F9: 122369.14 | G9: 125228.11 | H9: 122838.16 | I9: 127477.74 | J9: 141940.39 | K9: 139782.72 | L9: 136754.46 | M9: 136370.21 | N9: 132364.07 | O9: 137776.13
B10: Rendimiento (kg/unidad) | C10: =(C9/C8)*1000 -> 2.2126441 | D10: =D9/D8*1000 -> 2.2137346 | E10: =E9/E8*1000 -> 2.1624784 | F10: =F9/F8*1000 -> 2.08277 | G10: =G9/G8*1000 -> 2.2311212 | H10: =H9/H8*1000 -> 2.130483 | I10: =I9/I8*1000 -> 2.1736259 | J10: =J9/J8*1000 -> 2.2823273 | K10: =K9/K8*1000 -> 2.2549406 | ... O10: =O9/O8*1000 -> 2.2434716
B11: Precio (S/. kg)1/ | C11: 4.8378666 | D11: 4.7755039 | E11: 4.7804654 | F11: 4.8321221 | G11: 4.820011 | H11: 4.8036073 | I11: 4.8248217 | J11: 4.8261245 | K11: 4.8501431 | L11: 4.8785483 | M11: 4.8506303 | N11: 4.8718005 | O11: 4.9231817
A13: Ovino | B13: Población | C13: 11338424
B14: Saca (unidades) | C14: =SUM(D14:O14) -> 2699041.6 | D14: 194010.14 | E14: 205440.45 | F14: 212969.53 | G14: 241307.57 | H14: 251694.61 | I14: 251067.59 | J14: 254406.87 | K14: 241231.79 | L14: 222990.67 | M14: 207911.27 | N14: 204200.07 | O14: 211811
B15: Producción carne (t) | C15: =SUM(D15:O15) -> 33448.792 | D15: 2353.4567 | E15: 2513.8674 | F15: 2638.5038 | G15: 3043.518 | H15: 3177.3601 | I15: 3144.7926 | J15: 3184.0548 | K15: 2961.4004 | L15: 2819.0868 | M15: 2538.8593 | N15: 2487.087 | O15: 2586.805
B16: Rendimiento (kg/unidad) | C16: =(C15/C14)*1000 -> 12.392841 | D16: =D15/D14*1000 -> 12.130586 | E16: =E15/E14*1000 -> 12.236477 | F16: =F15/F14*1000 -> 12.389114 | G16: =G15/G14*1000 -> 12.612609 | H16: =H15/H14*1000 -> 12.62387 | I16: =I15/I14*1000 -> 12.525681 | J16: =J15/J14*1000 -> 12.515601 | K16: =K15/K14*1000 -> 12.276161 | ... O16: =O15/O14*1000 -> 12.212798
B17: Precio (S/. kg)1/ | C17: 5.595888 | D17: 5.6613325 | E17: 5.6765488 | F17: 5.71777 | G17: 5.7109238 | H17: 5.7151464 | I17: 5.5091694 | J17: 5.4749557 | K17: 5.5287885 | L17: 5.5253174 | M17: 5.5048068 | N17: 5.4925947 | O17: 5.6485183
A19: Porcino | B19: Población | C19: 3187254
B20: Saca (unidades) | C20: =SUM(D20:O20) -> 3072555.8 | D20: 243902.2 | E20: 240067.65 | F20: 247258.55 | G20: 252028.43 | H20: 260171.86 | I20: 258102.51 | J20: 273496.05 | K20: 259211.74 | L20: 252002.43 | M20: 250090.02 | N20: 248358.49 | O20: 287865.86
B21: Producción carne (t) | C21: =SUM(D21:O21) -> 157740.89 | D21: 12652.517 | E21: 12271.043 | F21: 12651.95 | G21: 12879.992 | H21: 13336.126 | I21: 13256.582 | J21: 14132.6 | K21: 13257.596 | L21: 12901.375 | M21: 12805.044 | N21: 12660.92 | O21: 14935.14
B22: Rendimiento (kg/unidad) | C22: =(C21/C20)*1000 -> 51.338656 | D22: =D21/D20*1000 -> 51.87537 | E22: =E21/E20*1000 -> 51.114936 | F22: =F21/F20*1000 -> 51.168908 | G22: =G21/G20*1000 -> 51.105312 | H22: =H21/H20*1000 -> 51.258912 | I22: =I21/I20*1000 -> 51.361694 | J22: =J21/J20*1000 -> 51.673873 | K22: =K21/K20*1000 -> 51.145818 | ... O22: =O21/O20*1000 -> 51.88229
B23: Precio (S/. kg)1/ | C23: 6.967564 | D23: 6.8940905 | E23: 6.8068748 | F23: 6.8800104 | G23: 6.9139756 | H23: 7.0623846 | I23: 6.9178101 | J23: 6.9817207 | K23: 7.0223425 | L23: 6.987179 | M23: 7.0343975 | N23: 6.9098178 | O23: 7.1543964
A25: Vacuno | B25: Población | C25: 5535569
B26: Saca (unidades) | C26: =SUM(D26:O26) -> 1330763.1 | D26: 101326.71 | E26: 103395.99 | F26: 108642.44 | G26: 116585.32 | H26: 118444.44 | I26: 115668.57 | J26: 118008.19 | K26: 114142.45 | L26: 109149.95 | M26: 106539 | N26: 106252.94 | O26: 112607.08
B27: Producción carne (t) | C27: =SUM(D27:O27) -> 188680.22 | D27: 14419.351 | E27: 14690.408 | F27: 15371.431 | G27: 16572.879 | H27: 17020.947 | I27: 16625.222 | J27: 16796.884 | K27: 16045.332 | L27: 15322.948 | M27: 15005.442 | N27: 14895.507 | O27: 15913.875
B28: Rendimiento (kg/unidad) | C28: =(C27/C26)*1000 -> 141.78348 | D28: =D27/D26*1000 -> 142.30552 | E28: =E27/E26*1000 -> 142.07909 | F28: =F27/F26*1000 -> 141.48643 | G28: =G27/G26*1000 -> 142.15236 | H28: =H27/H26*1000 -> 143.70406 | I28: =I27/I26*1000 -> 143.73155 | J28: =J27/J26*1000 -> 142.33659 | K28: =K27/K26*1000 -> 140.57288 | ... O28: =O27/O26*1000 -> 141.32215
B29: Precio (S/. kg)1/ | C29: 5.5319245 | D29: 5.5475455 | E29: 5.5578437 | F29: 5.5796274 | G29: 5.5922305 | H29: 5.5798771 | I29: 5.4661524 | J29: 5.498531 | K29: 5.5076821 | L29: 5.5020442 | M29: 5.5109984 | N29: 5.5141379 | O29: 5.5272277
A31: Caprino | B31: Población | C31: 1885990
B32: Saca (unidades) | C32: =SUM(D32:O32) -> 444799.26 | D32: 34357.129 | E32: 35244.306 | F32: 33522.798 | G32: 35899.291 | H32: 38826.783 | I32: 39177.26 | J32: 39728.767 | K32: 38468.275 | L32: 37402.654 | M32: 36735 | N32: 36530 | O32: 38907
B33: Producción carne (t) | C33: =SUM(D33:O33) -> 5547.0975 | D33: 430.05728 | E33: 424.58485 | F33: 414.07835 | G33: 448.96574 | H33: 475.96517 | I33: 475.38385 | J33: 496.3798 | K33: 489.29941 | L33: 475.12019 | M33: 503.31964 | N33: 436.10077 | O33: 477.84249
B34: Rendimiento (kg/unidad) | C34: =(C33/C32)*1000 -> 12.471013 | D34: =D33/D32*1000 -> 12.517265 | E34: =E33/E32*1000 -> 12.046906 | F34: =F33/F32*1000 -> 12.352142 | G34: =G33/G32*1000 -> 12.506256 | H34: =H33/H32*1000 -> 12.258682 | I34: =I33/I32*1000 -> 12.134178 | J34: =J33/J32*1000 -> 12.494216 | K34: =K33/K32*1000 -> 12.719557 | ... O34: =O33/O32*1000 -> 12.281659
B35: Precio (S/. kg)1/ | C35: 4.7411779 | D35: 4.6869494 | E35: 4.7381075 | F35: 4.7105545 | G35: 4.7558179 | H35: 4.7593452 | I35: 4.7659947 | J35: 4.7685371 | K35: 4.7776329 | L35: 4.7303703 | M35: 4.807967 | N35: 4.7196257 | O35: 4.6570242
A37: Alpaca | B37: Población | C37: 4330710
B38: Saca (unidades) | C38: =SUM(D38:O38) -> 479063 | D38: 34327 | E38: 37327 | F38: 40917 | G38: 49129 | H38: 46726 | I38: 46896 | J38: 46273 | K38: 41934 | L38: 36717 | M38: 34904 | N38: 32844 | O38: 31069
B39: Producción carne (t) | C39: =SUM(D39:O39) -> 12748.884 | D39: 880.07213 | E39: 989.16847 | F39: 1092.3799 | G39: 1326.5954 | H39: 1261.7389 | I39: 1264.4702 | J39: 1240.8573 | K39: 1120.4726 | L39: 973.41241 | M39: 922.10936 | N39: 862.60914 | O39: 814.99795
B40: Rendimiento (kg/unidad) | C40: =(C39/C38)*1000 -> 26.612124 | D40: =D39/D38*1000 -> 25.637898 | E40: =E39/E38*1000 -> 26.50008 | F40: =F39/F38*1000 -> 26.697459 | G40: =G39/G38*1000 -> 27.002287 | H40: =H39/H38*1000 -> 27.00293 | I40: =I39/I38*1000 -> 26.963285 | J40: =J39/J38*1000 -> 26.816012 | K40: =K39/K38*1000 -> 26.719908 | ... O40: =O39/O38*1000 -> 26.231869
B41: Precio (S/. kg)1/ | C41: 4.9215836 | D41: 4.8521257 | E41: 4.9150339 | F41: 4.9250596 | G41: 5.0082894 | H41: 4.9524051 | I41: 4.9494555 | J41: 4.963313 | K41: 4.9265866 | L41: 4.8816971 | M41: 4.8551886 | N41: 4.9012043 | O41: 4.8417025
A43: Llama | B43: Población | C43: 1106201
B44: Saca (unidades) | C44: =SUM(D44:O44) -> 120765 | D44: 8531 | E44: 9230 | F44: 9826 | G44: 11524 | H44: 11412 | I44: 11831 | J44: 11140 | K44: 10491 | L44: 9684 | M44: 8785 | N44: 8748 | O44: 9563
B45: Producción carne (t) | C45: =SUM(D45:O45) -> 4008.8486 | D45: 281.2529 | E45: 309.17065 | F45: 326.05546 | G45: 392.81079 | H45: 385.96921 | I45: 397.02864 | J45: 364.92154 | K45: 340.89843 | L45: 314.46536 | M45: 291.22507 | N45: 287.23549 | O45: 317.81504
B46: Rendimiento (kg/unidad) | C46: =(C45/C44)*1000 -> 33.19545 | D46: =D45/D44*1000 -> 32.968339 | E46: =E45/E44*1000 -> 33.496278 | F46: =F45/F44*1000 -> 33.182929 | G46: =G45/G44*1000 -> 34.086323 | H46: =H45/H44*1000 -> 33.821347 | I46: =I45/I44*1000 -> 33.558333 | J46: =J45/J44*1000 -> 32.757769 | K46: =K45/K44*1000 -> 32.494369 | ... O46: =O45/O44*1000 -> 33.233822
B47: Precio (S/. kg)1/ | C47: 4.2540549 | D47: 4.2701159 | E47: 4.2726112 | F47: 4.2782449 | G47: 4.3119107 | H47: 4.3339401 | I47: 4.2846988 | J47: 4.1692662 | K47: 4.1680491 | L47: 4.1868443 | M47: 4.186044 | N47: 4.185929 | O47: 4.3701697
A49: Huevo | B49: Gallinas en producción3/ | C49: =AVERAGE(D49:O49) -> 25559765 | D49: 25410815 | E49: 25468568 | F49: 25744535 | G49: 25538765 | H49: 25542275 | I49: 25558564 | J49: 25411769 | K49: 25426575 | L49: 25517110 | M49: 25646002 | N49: 25667608 | O49: 25784590
A50: Gallina | B50: Producción huevo (t) | C50: =SUM(D50:O50) -> 415336.49 | D50: 34513.37 | E50: 34585.257 | F50: 34774.231 | G50: 34581.329 | H50: 34510.133 | I50: 34490.312 | J50: 34487.699 | K50: 34374.816 | L50: 34414.115 | M50: 34726.144 | N50: 34886.884 | O50: 34992.201
...

Sheet C 7
A2: C. 7 PERÚ: PRODUCCIÓN PECUARIA POR ESPECIE SEGÚN REGIÓN, 2017P.
A3: (Unidades)
A5: Región | B5: Ave | C5: Ovino | D5: Porcino | E5: Vacuno | F5: Caprino | G5: Alpaca | H5: Llama
A6: NACIONAL | B6: =(B8+B9+B10+B11+B12+B16+B17+B18+B19+B20+B21+B22+B23+B24+B25+B26+B27+B28+B31+B32+B33+B34+B35+B36) -> 7.0923295e+08 | C6: =(C8+C9+C10+C11+C12+C16+C17+C18+C19+C20+C21+C22+C23+C24+C25+C26+C27+C28+C31+C32+C33+C34+C35+C36) -> 2699041.6 | D6: =(D8+D9+D10+D11+D12+D16+D17+D18+D19+D20+D21+D22+D23+D24+D25+D26+D27+D28+D31+D32+D33+D34+D35+D36) -> 3072555.8 | E6: =(E8+E9+E10+E11+E12+E16+E17+E18+E19+E20+E21+E22+E23+E24+E25+E26+E27+E28+E31+E32+E33+E34+E35+E36) -> 1331223.1 | F6: =(F8+F9+F10+F11+F12+F16+F17+F18+F19+F20+F21+F22+F23+F24+F25+F26+F27+F28+F31+F32+F33+F34+F35+F36) -> 444799.26 | G6: =(G8+G9+G10+G11+G12+G16+G17+G18+G19+G20+G21+G22+G23+G24+G25+G26+G27+G28+G31+G32+G33+G34+G35+G36) -> 479063 | H6: =(H8+H9+H10+H11+H12+H16+H17+H18+H19+H20+H21+H22+H23+H24+H25+H26+H27+H28+H31+H32+H33+H34+H35+H36) -> 120748
A8: Tumbes | B8: =[3]AVE!T10 -> 71935.695 | C8: =+[3]OVINO!T10 -> 3096 | D8: =+[3]PORCINO!T10 -> 7991 | E8: 5673 | F8: =+[3]CAPRINO!T10 -> 32867 | G8: =+[3]ALPACA!T10 -> 0 | H8: =+[3]LLAMA!T10 -> 0
A9: Piura | B9: =[3]AVE!T11 -> 13281847 | C9: =+[3]OVINO!T11 -> 115852.64 | D9: =+[3]PORCINO!T11 -> 110733.79 | E9: 45661.078 | F9: =+[3]CAPRINO!T11 -> 94622.264 | G9: =+[3]ALPACA!T11 -> 0 | H9: =+[3]LLAMA!T11 -> 0
A10: Lambayeque | B10: =[3]AVE!T12 -> 10413791 | C10: =+[3]OVINO!T12 -> 28880 | D10: =+[3]PORCINO!T12 -> 29483 | E10: 22198 | F10: =+[3]CAPRINO!T12 -> 30600 | G10: =+[3]ALPACA!T12 -> 0 | H10: =+[3]LLAMA!T12 -> 0
A11: La Libertad | B11: =[3]AVE!T13 -> 1.2337786e+08 | C11: =+[3]OVINO!T13 -> 184002 | D11: =+[3]PORCINO!T13 -> 298028 | E11: 54880 | F11: =+[3]CAPRINO!T13 -> 37209 | G11: =+[3]ALPACA!T13 -> 1174 | H11: =+[3]LLAMA!T13 -> 0
A12: Cajamarca | B12: =[3]AVE!T14 -> 1833960.6 | C12: =+[3]OVINO!T14 -> 102957 | D12: =+[3]PORCINO!T14 -> 147970 | E12: 210048 | F12: =+[3]CAPRINO!T14 -> 28609 | G12: =+[3]ALPACA!T14 -> 0 | H12: =+[3]LLAMA!T14 -> 0
A13: Cajamarca | B13: =[3]AVE!T15 -> 1008678.3 | C13: =+[3]OVINO!T15 -> 76306 | D13: =+[3]PORCINO!T15 -> 62722 | E13: 119143 | F13: =+[3]CAPRINO!T15 -> 16975 | G13: =+[3]ALPACA!T15 -> 0 | H13: =+[3]LLAMA!T15 -> 0
A14: Chota | B14: =[3]AVE!T16 -> 403471.33 | C14: =+[3]OVINO!T16 -> 19897 | D14: =+[3]PORCINO!T16 -> 49315 | E14: 60316 | F14: =+[3]CAPRINO!T16 -> 1057 | G14: =+[3]ALPACA!T16 -> 0 | H14: =+[3]LLAMA!T16 -> 0
A15: Jaén | B15: =[3]AVE!T17 -> 421810.93 | C15: =+[3]OVINO!T17 -> 6754 | D15: =+[3]PORCINO!T17 -> 35933 | E15: 30589 | F15: =+[3]CAPRINO!T17 -> 10577 | G15: =+[3]ALPACA!T17 -> 0 | H15: =+[3]LLAMA!T17 -> 0
A16: Amazonas | B16: 1736237.4 | C16: =+[3]OVINO!T18 -> 3305 | D16: =+[3]PORCINO!T18 -> 33563 | E16: 59675 | F16: =+[3]CAPRINO!T18 -> 4507 | G16: =+[3]ALPACA!T18 -> 0 | H16: =+[3]LLAMA!T18 -> 0
A17: Ancash | B17: =[3]AVE!T19 -> 17683179 | C17: =+[3]OVINO!T19 -> 132418.92 | D17: =+[3]PORCINO!T19 -> 42272 | E17: 70685 | F17: =+[3]CAPRINO!T19 -> 20432 | G17: =+[3]ALPACA!T19 -> 348 | H17: =+[3]LLAMA!T19 -> 0
A18: Lima | B18: =[3]AVE!T20 -> 3.775188e+08 | C18: =+[3]OVINO!T20 -> 80867 | D18: =+[3]PORCINO!T20 -> 1132149 | E18: 116208 | F18: =+[3]CAPRINO!T20 -> 48379 | G18: =+[3]ALPACA!T20 -> 2939 | H18: =+[3]LLAMA!T20 -> 1597
A19: Ica | B19: =[3]AVE!T21 -> 34888755 | C19: =+[3]OVINO!T21 -> 5024 | D19: =+[3]PORCINO!T21 -> 93401 | E19: 12350 | F19: =+[3]CAPRINO!T21 -> 14913 | G19: =+[3]ALPACA!T21 -> 0 | H19: =+[3]LLAMA!T21 -> 0
A20: Huánuco | B20: =[3]AVE!T22 -> 637988.01 | C20: =+[3]OVINO!T22 -> 163418 | D20: =+[3]PORCINO!T22 -> 207816 | E20: 120539 | F20: =+[3]CAPRINO!T22 -> 26502 | G20: =+[3]ALPACA!T22 -> 978 | H20: =+[3]LLAMA!T22 -> 45
A21: Pasco | B21: =[3]AVE!T23 -> 205633.28 | C21: =+[3]OVINO!T23 -> 99700 | D21: =+[3]PORCINO!T23 -> 34316 | E21: 21814 | F21: =+[3]CAPRINO!T23 -> 1189 | G21: =+[3]ALPACA!T23 -> 13273 | H21: =+[3]LLAMA!T23 -> 3896
A22: Junín | B22: =[3]AVE!T24 -> 5570881.6 | C22: =+[3]OVINO!T24 -> 304545 | D22: =+[3]PORCINO!T24 -> 106651 | E22: 77250 | F22: =+[3]CAPRINO!T24 -> 4659 | G22: =+[3]ALPACA!T24 -> 14982 | H22: =+[3]LLAMA!T24 -> 9563
A23: Huancavelica | B23: =[3]AVE!T25 -> 505939.05 | C23: =+[3]OVINO!T25 -> 126716 | D23: =+[3]PORCINO!T25 -> 42772 | E23: 33790 | F23: =+[3]CAPRINO!T25 -> 28698 | G23: =+[3]ALPACA!T25 -> 30246 | H23: =+[3]LLAMA!T25 -> 11023
A24: Arequipa | B24: =[3]AVE!T26 -> 69740819 | C24: =+[3]OVINO!T26 -> 136584 | D24: =+[3]PORCINO!T26 -> 202875 | E24: 34053 | F24: =+[3]CAPRINO!T26 -> 15642 | G24: =+[3]ALPACA!T26 -> 47101 | H24: =+[3]LLAMA!T26 -> 11994
A25: Moquegua | B25: =[3]AVE!T27 -> 86126.851 | C25: =+[3]OVINO!T27 -> 3991 | D25: =+[3]PORCINO!T27 -> 21597 | E25: 4227 | F25: =+[3]CAPRINO!T27 -> 861 | G25: =+[3]ALPACA!T27 -> 4653 | H25: =+[3]LLAMA!T27 -> 1788
A26: Tacna | B26: =[3]AVE!T28 -> 9438792.5 | C26: =+[3]OVINO!T28 -> 7851 | D26: =+[3]PORCINO!T28 -> 66586 | E26: 5042 | F26: =+[3]CAPRINO!T28 -> 5022 | G26: =+[3]ALPACA!T28 -> 6322 | H26: =+[3]LLAMA!T28 -> 4418
A27: Ayacucho | B27: =[3]AVE!T29 -> 549179.57 | C27: =+[3]OVINO!T29 -> 154484 | D27: =+[3]PORCINO!T29 -> 52959 | E27: 88827 | F27: =+[3]CAPRINO!T29 -> 28342 | G27: =+[3]ALPACA!T29 -> 42540 | H27: =+[3]LLAMA!T29 -> 8586
A28: Apurímac | B28: =[3]AVE!T30 -> 406961.94 | C28: =+[3]OVINO!T30 -> 83655 | D28: =+[3]PORCINO!T30 -> 70374 | E28: 42914 | F28: =+[3]CAPRINO!T30 -> 18043 | G28: =+[3]ALPACA!T30 -> 22936 | H28: =+[3]LLAMA!T30 -> 9871
... A36: Madre de Dios | B36: =[3]AVE!T38 -> 3865818.4 | C36: =+[3]OVINO!T38 -> 2349 | D36: =+[3]PORCINO!T38 -> 13055 | E36: 14409 | F36: =+[3]CAPRINO!T38 -> 0 | G36: =+[3]ALPACA!T38 -> 0 | H36: =+[3]LLAMA!T38 -> 0
A37: P Preliminar.
A38: Fuente:Direcciones Regionales de Agricultura.
A39: Elaboración: MInisterio de Agricultura y Riego-DGESEP-DEA.

Sheet C 8
A2: C. 8 PERÚ: PRODUCCIÓN DE CARNE POR ESPECIE SEGÚN REGIÓN, 2017P.
A3: (Toneladas)
A5: Región | B5: Ave | C5: Ovino | D5: Porcino | E5: Vacuno | F5: Caprino | G5: Alpaca | H5: Llama
A6: NACIONAL | B6: =(B8+B9+B10+B11+B12+B16+B17+B18+B19+B20+B21+B22+B23+B24+B25+B26+B27+B28+B31+B32+B33+B34+B35+B36) -> 1569280.1 | C6: =(C8+C9+C10+C11+C12+C16+C17+C18+C19+C20+C21+C22+C23+C24+C25+C26+C27+C28+C31+C32+C33+C34+C35+C36) -> 33448.792 | D6: =(D8+D9+D10+D11+D12+D16+D17+D18+D19+D20+D21+D22+D23+D24+D25+D26+D27+D28+D31+D32+D33+D34+D35+D36) -> 157740.89 | E6: =(E8+E9+E10+E11+E12+E16+E17+E18+E19+E20+E21+E22+E23+E24+E25+E26+E27+E28+E31+E32+E33+E34+E35+E36) -> 188680.22 | F6: =(F8+F9+F10+F11+F12+F16+F17+F18+F19+F20+F21+F22+F23+F24+F25+F26+F27+F28+F31+F32+F33+F34+F35+F36) -> 5547.0975 | G6: =(G8+G9+G10+G11+G12+G16+G17+G18+G19+G20+G21+G22+G23+G24+G25+G26+G27+G28+G31+G32+G33+G34+G35+G36) -> 12748.884 | H6: =(H8+H9+H10+H11+H12+H16+H17+H18+H19+H20+H21+H22+H23+H24+H25+H26+H27+H28+H31+H32+H33+H34+H35+H36) -> 4008.8486
A8: Tumbes | B8: =+[3]AVE!T50 -> 163.70602 | C8: =+[3]OVINO!T50 -> 36.9308 | D8: =+[3]PORCINO!T50 -> 398.3565 | E8: =+[3]VACUNO!T50 -> 880.46808 | F8: =+[3]CAPRINO!T50 -> 378.4136 | G8: =+[3]ALPACA!T50 -> 0 | H8: =+[3]LLAMA!T50 -> 0
A9: Piura | B9: =+[3]AVE!T51 -> 28902.433 | C9: =+[3]OVINO!T51 -> 1359.7008 | D9: =+[3]PORCINO!T51 -> 4739.3321 | E9: =+[3]VACUNO!T51 -> 7680.1689 | F9: =+[3]CAPRINO!T51 -> 1376.5339 | G9: =+[3]ALPACA!T51 -> 0 | H9: =+[3]LLAMA!T51 -> 0
A10: Lambayeque | B10: =+[3]AVE!T52 -> 22689.221 | C10: =+[3]OVINO!T52 -> 539.00879 | D10: =+[3]PORCINO!T52 -> 1665.243 | E10: =+[3]VACUNO!T52 -> 3077.7476 | F10: =+[3]CAPRINO!T52 -> 455.53059 | G10: =+[3]ALPACA!T52 -> 0 | H10: =+[3]LLAMA!T52 -> 0
A11: La Libertad | B11: =+[3]AVE!T53 -> 270846.86 | C11: =+[3]OVINO!T53 -> 2413.3136 | D11: =+[3]PORCINO!T53 -> 16876.298 | E11: =+[3]VACUNO!T53 -> 7660.4258 | F11: =+[3]CAPRINO!T53 -> 506.56438 | G11: =+[3]ALPACA!T53 -> 36.813845 | H11: =+[3]LLAMA!T53 -> 0
A12: Cajamarca | B12: =+[3]AVE!T54 -> 3616.9015 | C12: =+[3]OVINO!T54 -> 1219.3389 | D12: =+[3]PORCINO!T54 -> 6393.4849 | E12: =+[3]VACUNO!T54 -> 26793.983 | F12: =+[3]CAPRINO!T54 -> 233.79402 | G12: =+[3]ALPACA!T54 -> 0 | H12: =+[3]LLAMA!T54 -> 0
A13: Cajamarca | B13: =+[3]AVE!T55 -> 2441.5335 | C13: =+[3]OVINO!T55 -> 894.03844 | D13: =+[3]PORCINO!T55 -> 2316.7117 | E13: =+[3]VACUNO!T55 -> 13938.926 | F13: =+[3]CAPRINO!T55 -> 114.97218 | G13: =+[3]ALPACA!T55 -> 0 | H13: =+[3]LLAMA!T55 -> 0
A14: Chota | B14: =+[3]AVE!T56 -> 574.62437 | C14: =+[3]OVINO!T56 -> 254.844 | D14: =+[3]PORCINO!T56 -> 2293.1865 | E14: =+[3]VACUNO!T56 -> 8232.1129 | F14: =+[3]CAPRINO!T56 -> 13.2468 | G14: =+[3]ALPACA!T56 -> 0 | H14: =+[3]LLAMA!T56 -> 0
A15: Jaén | B15: =+[3]AVE!T57 -> 600.74366 | C15: =+[3]OVINO!T57 -> 70.45644 | D15: =+[3]PORCINO!T57 -> 1783.5867 | E15: =+[3]VACUNO!T57 -> 4622.9442 | F15: =+[3]CAPRINO!T57 -> 105.57504 | G15: =+[3]ALPACA!T57 -> 0 | H15: =+[3]LLAMA!T57 -> 0
A16: Amazonas | B16: =+[3]AVE!T58 -> 3696.9187 | C16: =+[3]OVINO!T58 -> 50.5768 | D16: =+[3]PORCINO!T58 -> 1712.1916 | E16: =+[3]VACUNO!T58 -> 8885.0826 | F16: =+[3]CAPRINO!T58 -> 56.8592 | G16: =+[3]ALPACA!T58 -> 0 | H16: =+[3]LLAMA!T58 -> 0
A17: Ancash | B17: =+[3]AVE!T59 -> 39416.052 | C17: =+[3]OVINO!T59 -> 1375.9864 | D17: =+[3]PORCINO!T59 -> 1374.8967 | E17: =+[3]VACUNO!T59 -> 9018.7473 | F17: =+[3]CAPRINO!T59 -> 213.5368 | G17: =+[3]ALPACA!T59 -> 9.9782866 | H17: =+[3]LLAMA!T59 -> 0
A18: Lima | B18: =+[3]AVE!T60 -> 848197.85 | C18: =+[3]OVINO!T60 -> 976.16657 | D18: =+[3]PORCINO!T60 -> 71500.074 | E18: =+[3]VACUNO!T60 -> 21841.727 | F18: =+[3]CAPRINO!T60 -> 602.63478 | G18: =+[3]ALPACA!T60 -> 79.858572 | H18: =+[3]LLAMA!T60 -> 50.109622
A19: Ica | B19: =+[3]AVE!T61 -> 72365.199 | C19: =+[3]OVINO!T61 -> 61.184412 | D19: =+[3]PORCINO!T61 -> 3934.9574 | E19: =+[3]VACUNO!T61 -> 2006.4705 | F19: =+[3]CAPRINO!T61 -> 211.30357 | G19: =+[3]ALPACA!T61 -> 0 | H19: =+[3]LLAMA!T61 -> 0
... A36: Madre de Dios | B36: =+[3]AVE!T78 -> 8393.4579 | C36: =+[3]OVINO!T78 -> 45.673 | D36: =+[3]PORCINO!T78 -> 836.93296 | E36: =+[3]VACUNO!T78 -> 2389.3683 | F36: =+[3]CAPRINO!T78 -> 0 | G36: =+[3]ALPACA!T78 -> 0 | H36: =+[3]LLAMA!T78 -> 0
A37: P Preliminar.
A38: Fuente:Direcciones Regionales de Agricultura.
A39: Elaboración: MInisterio de Agricultura y Riego-DGESEP-DEA.

Sheet C 9
A2: C. 9 PERÚ: RENDIMIENTO DE CARNE POR ESPECIE SEGÚN REGIÓN, 2017P.
A3: (Kg/unidad)
A5: Región | B5: Ave | C5: Ovino | D5: Porcino | E5: Vacuno | F5: Caprino | G5: Alpaca | H5: Llama
A6: NACIONAL | B6: =('C 8'!B6/'C 7'!B6)*1000 -> 2.2126441 | C6: =('C 8'!C6/'C 7'!C6)*1000 -> 12.392841 | D6: =('C 8'!D6/'C 7'!D6)*1000 -> 51.338656 | E6: =('C 8'!E6/'C 7'!E6)*1000 -> 141.73449 | F6: =('C 8'!F6/'C 7'!F6)*1000 -> 12.471013 | G6: =('C 8'!G6/'C 7'!G6)*1000 -> 26.612124 | H6: =('C 8'!H6/'C 7'!H6)*1000 -> 33.200124
A8: Tumbes | B8: =('C 8'!B8/'C 7'!B8)*1000 -> 2.2757273 | C8: =('C 8'!C8/'C 7'!C8)*1000 -> 11.928553 | D8: =('C 8'!D8/'C 7'!D8)*1000 -> 49.850644 | E8: =('C 8'!E8/'C 7'!E8)*1000 -> 155.20326 | F8: =('C 8'!F8/'C 7'!F8)*1000 -> 11.513482 | G8: 0 | H8: 0 | I8: -
A9: Piura | B9: =('C 8'!B9/'C 7'!B9)*1000 -> 2.1760854 | C9: =('C 8'!C9/'C 7'!C9)*1000 -> 11.736468 | D9: =('C 8'!D9/'C 7'!D9)*1000 -> 42.799332 | E9: =('C 8'!E9/'C 7'!E9)*1000 -> 168.19947 | F9: =('C 8'!F9/'C 7'!F9)*1000 -> 14.547675 | G9: 0 | H9: 0
A10: Lambayeque | B10: =('C 8'!B10/'C 7'!B10)*1000 -> 2.1787666 | C10: =('C 8'!C10/'C 7'!C10)*1000 -> 18.663739 | D10: =('C 8'!D10/'C 7'!D10)*1000 -> 56.481463 | E10: =('C 8'!E10/'C 7'!E10)*1000 -> 138.64977 | F10: =('C 8'!F10/'C 7'!F10)*1000 -> 14.88662 | G10: 0 | H10: 0
A11: La Libertad | B11: =('C 8'!B11/'C 7'!B11)*1000 -> 2.1952631 | C11: =('C 8'!C11/'C 7'!C11)*1000 -> 13.115692 | D11: =('C 8'!D11/'C 7'!D11)*1000 -> 56.626553 | E11: =('C 8'!E11/'C 7'!E11)*1000 -> 139.58502 | F11: =('C 8'!F11/'C 7'!F11)*1000 -> 13.614028 | G11: =('C 8'!G11/'C 7'!G11)*1000 -> 31.357619 | H11: 0
A12: Cajamarca | B12: =('C 8'!B12/'C 7'!B12)*1000 -> 1.9721806 | C12: =('C 8'!C12/'C 7'!C12)*1000 -> 11.843186 | D12: =('C 8'!D12/'C 7'!D12)*1000 -> 43.207981 | E12: =('C 8'!E12/'C 7'!E12)*1000 -> 127.56124 | F12: =('C 8'!F12/'C 7'!F12)*1000 -> 8.1720444 | G12: 0 | H12: 0
A13: Cajamarca | B13: =('C 8'!B13/'C 7'!B13)*1000 -> 2.4205274 | C13: =('C 8'!C13/'C 7'!C13)*1000 -> 11.716489 | D13: =('C 8'!D13/'C 7'!D13)*1000 -> 36.93619 | E13: =('C 8'!E13/'C 7'!E13)*1000 -> 116.99325 | F13: =('C 8'!F13/'C 7'!F13)*1000 -> 6.7730297 | G13: 0 | H13: 0
A14: Chota | B14: =('C 8'!B14/'C 7'!B14)*1000 -> 1.4242013 | C14: =('C 8'!C14/'C 7'!C14)*1000 -> 12.808162 | D14: =('C 8'!D14/'C 7'!D14)*1000 -> 46.500791 | E14: =('C 8'!E14/'C 7'!E14)*1000 -> 136.48307 | F14: =('C 8'!F14/'C 7'!F14)*1000 -> 12.53245 | G14: 0 | H14: 0
A15: Jaén | B15: =('C 8'!B15/'C 7'!B15)*1000 -> 1.4242013 | C15: =('C 8'!C15/'C 7'!C15)*1000 -> 10.431809 | D15: =('C 8'!D15/'C 7'!D15)*1000 -> 49.636454 | E15: =('C 8'!E15/'C 7'!E15)*1000 -> 151.13094 | F15: =('C 8'!F15/'C 7'!F15)*1000 -> 9.9815676 | G15: 0 | H15: 0
A16: Amazonas | B16: =('C 8'!B16/'C 7'!B16)*1000 -> 2.1292703 | C16: =('C 8'!C16/'C 7'!C16)*1000 -> 15.303116 | D16: =('C 8'!D16/'C 7'!D16)*1000 -> 51.01426 | E16: =('C 8'!E16/'C 7'!E16)*1000 -> 148.8912 | F16: =('C 8'!F16/'C 7'!F16)*1000 -> 12.615753 | G16: 0 | H16: 0
A17: Ancash | B17: =('C 8'!B17/'C 7'!B17)*1000 -> 2.2290139 | C17: =('C 8'!C17/'C 7'!C17)*1000 -> 10.391161 | D17: =('C 8'!D17/'C 7'!D17)*1000 -> 32.524997 | E17: =('C 8'!E17/'C 7'!E17)*1000 -> 127.59068 | F17: =('C 8'!F17/'C 7'!F17)*1000 -> 10.451096 | G17: =('C 8'!G17/'C 7'!G17)*1000 -> 28.673237 | H17: 0
A18: Lima | B18: =('C 8'!B18/'C 7'!B18)*1000 -> 2.2467698 | C18: =('C 8'!C18/'C 7'!C18)*1000 -> 12.07126 | D18: =('C 8'!D18/'C 7'!D18)*1000 -> 63.154297 | E18: =('C 8'!E18/'C 7'!E18)*1000 -> 187.95373 | F18: =('C 8'!F18/'C 7'!F18)*1000 -> 12.456537 | G18: =('C 8'!G18/'C 7'!G18)*1000 -> 27.172022 | H18: =('C 8'!H18/'C 7'!H18)*1000 -> 31.377346
A19: Ica | B19: =('C 8'!B19/'C 7'!B19)*1000 -> 2.0741697 | C19: =('C 8'!C19/'C 7'!C19)*1000 -> 12.178426 | D19: =('C 8'!D19/'C 7'!D19)*1000 -> 42.129714 | E19: =('C 8'!E19/'C 7'!E19)*1000 -> 162.46724 | F19: =('C 8'!F19/'C 7'!F19)*1000 -> 14.169085 | G19: 0 | H19: 0
A20: Huánuco | B20: =('C 8'!B20/'C 7'!B20)*1000 -> 1.9013827 | C20: =('C 8'!C20/'C 7'!C20)*1000 -> 10.717004 | D20: =('C 8'!D20/'C 7'!D20)*1000 -> 32.645037 | E20: =('C 8'!E20/'C 7'!E20)*1000 -> 153.43452 | F20: =('C 8'!F20/'C 7'!F20)*1000 -> 9.1170463 | G20: =('C 8'!G20/'C 7'!G20)*1000 -> 26.440951 | H20: =('C 8'!H20/'C 7'!H20)*1000 -> 27.5
A21: Pasco | B21: =('C 8'!B21/'C 7'!B21)*1000 -> 1.9753233 | C21: =('C 8'!C21/'C 7'!C21)*1000 -> 13.855818 | D21: =('C 8'!D21/'C 7'!D21)*1000 -> 36.861391 | E21: =('C 8'!E21/'C 7'!E21)*1000 -> 156.19844 | F21: =('C 8'!F21/'C 7'!F21)*1000 -> 11.393299 | G21: =('C 8'!G21/'C 7'!G21)*1000 -> 24.207515 | H21: =('C 8'!H21/'C 7'!H21)*1000 -> 29.581138
A22: Junín | B22: =('C 8'!B22/'C 7'!B22)*1000 -> 2.1636072 | C22: =('C 8'!C22/'C 7'!C22)*1000 -> 10.836544 | D22: =('C 8'!D22/'C 7'!D22)*1000 -> 41.696128 | E22: =('C 8'!E22/'C 7'!E22)*1000 -> 123.11498 | F22: =('C 8'!F22/'C 7'!F22)*1000 -> 10.246577 | G22: =('C 8'!G22/'C 7'!G22)*1000 -> 21.446155 | H22: =('C 8'!H22/'C 7'!H22)*1000 -> 28.519535
A23: Huancavelica | B23: =('C 8'!B23/'C 7'!B23)*1000 -> 1.8737064 | C23: =('C 8'!C23/'C 7'!C23)*1000 -> 12.635346 | D23: =('C 8'!D23/'C 7'!D23)*1000 -> 34.751816 | E23: =('C 8'!E23/'C 7'!E23)*1000 -> 114.95975 | F23: =('C 8'!F23/'C 7'!F23)*1000 -> 12.86591 | G23: =('C 8'!G23/'C 7'!G23)*1000 -> 25.88079 | H23: =('C 8'!H23/'C 7'!H23)*1000 -> 34.09978
A24: Arequipa | B24: =('C 8'!B24/'C 7'!B24)*1000 -> 2.199662 | C24: =('C 8'!C24/'C 7'!C24)*1000 -> 14.82021 | D24: =('C 8'!D24/'C 7'!D24)*1000 -> 56.006822 | E24: =('C 8'!E24/'C 7'!E24)*1000 -> 161.16272 | F24: =('C 8'!F24/'C 7'!F24)*1000 -> 11.403235 | G24: =('C 8'!G24/'C 7'!G24)*1000 -> 25.245167 | H24: =('C 8'!H24/'C 7'!H24)*1000 -> 31.722711
A25: Moquegua | B25: =('C 8'!B25/'C 7'!B25)*1000 -> 1.9793178 | C25: =('C 8'!C25/'C 7'!C25)*1000 -> 21.161253 | D25: =('C 8'!D25/'C 7'!D25)*1000 -> 40.970864 | E25: =('C 8'!E25/'C 7'!E25)*1000 -> 233.21011 | F25: =('C 8'!F25/'C 7'!F25)*1000 -> 15.545645 | G25: =('C 8'!G25/'C 7'!G25)*1000 -> 31.12824 | H25: =('C 8'!H25/'C 7'!H25)*1000 -> 43.210515
A26: Tacna | B26: =('C 8'!B26/'C 7'!B26)*1000 -> 2.1862064 | C26: =('C 8'!C26/'C 7'!C26)*1000 -> 23.201274 | D26: =('C 8'!D26/'C 7'!D26)*1000 -> 39.355615 | E26: =('C 8'!E26/'C 7'!E26)*1000 -> 192.28673 | F26: =('C 8'!F26/'C 7'!F26)*1000 -> 14.316129 | G26: =('C 8'!G26/'C 7'!G26)*1000 -> 28.861982 | H26: =('C 8'!H26/'C 7'!H26)*1000 -> 29.226573
A27: Ayacucho | B27: =('C 8'!B27/'C 7'!B27)*1000 -> 1.9279083 | C27: =('C 8'!C27/'C 7'!C27)*1000 -> 11.906393 | D27: =('C 8'!D27/'C 7'!D27)*1000 -> 44.029468 | E27: =('C 8'!E27/'C 7'!E27)*1000 -> 128.54409 | F27: =('C 8'!F27/'C 7'!F27)*1000 -> 11.861478 | G27: =('C 8'!G27/'C 7'!G27)*1000 -> 26.602665 | H27: =('C 8'!H27/'C 7'!H27)*1000 -> 30.32521
A28: Apurímac | B28: =('C 8'!B28/'C 7'!B28)*1000 -> 1.8767903 | C28: =('C 8'!C28/'C 7'!C28)*1000 -> 11.475981 | D28: =('C 8'!D28/'C 7'!D28)*1000 -> 40.83636 | E28: =('C 8'!E28/'C 7'!E28)*1000 -> 109.49154 | F28: =('C 8'!F28/'C 7'!F28)*1000 -> 10.778695 | G28: =('C 8'!G28/'C 7'!G28)*1000 -> 24.812544 | H28: =('C 8'!H28/'C 7'!H28)*1000 -> 29.521781
A29: Abancay | B29: =('C 8'!B29/'C 7'!B29)*1000 -> 1.8955676 | C29: =('C 8'!C29/'C 7'!C29)*1000 -> 12.267828 | D29: =('C 8'!D29/'C 7'!D29)*1000 -> 36.588973 | E29: =('C 8'!E29/'C 7'!E29)*1000 -> 111.48969 | F29: =('C 8'!F29/'C 7'!F29)*1000 -> 11.440618 | G29: =('C 8'!G29/'C 7'!G29)*1000 -> 25.073974 | H29: =('C 8'!H29/'C 7'!H29)*1000 -> 31.40422
A30: Andahuaylas | B30: =('C 8'!B30/'C 7'!B30)*1000 -> 1.8486244 | C30: =('C 8'!C30/'C 7'!C30)*1000 -> 10.706623 | D30: =('C 8'!D30/'C 7'!D30)*1000 -> 43.2072 | E30: =('C 8'!E30/'C 7'!E30)*1000 -> 107.30683 | F30: =('C 8'!F30/'C 7'!F30)*1000 -> 10.498066 | G30: =('C 8'!G30/'C 7'!G30)*1000 -> 23.833816 | H30: =('C 8'!H30/'C 7'!H30)*1000 -> 27.715207
A31: Cusco | B31: =('C 8'!B31/'C 7'!B31)*1000 -> 2.0603567 | C31: =('C 8'!C31/'C 7'!C31)*1000 -> 11.242658 | D31: =('C 8'!D31/'C 7'!D31)*1000 -> 40.279876 | E31: =('C 8'!E31/'C 7'!E31)*1000 -> 143.64941 | F31: =('C 8'!F31/'C 7'!F31)*1000 -> 12.289629 | G31: =('C 8'!G31/'C 7'!G31)*1000 -> 27.02208 | H31: =('C 8'!H31/'C 7'!H31)*1000 -> 29.254759
A32: Puno | B32: =('C 8'!B32/'C 7'!B32)*1000 -> 1.876637 | C32: =('C 8'!C32/'C 7'!C32)*1000 -> 13.451975 | D32: =('C 8'!D32/'C 7'!D32)*1000 -> 33.098457 | E32: =('C 8'!E32/'C 7'!E32)*1000 -> 143.32853 | F32: 0 | G32: =('C 8'!G32/'C 7'!G32)*1000 -> 27.383048 | H32: =('C 8'!H32/'C 7'!H32)*1000 -> 38.234064
A33: San Martín | B33: =('C 8'!B33/'C 7'!B33)*1000 -> 2.1646012 | C33: =('C 8'!C33/'C 7'!C33)*1000 -> 10.991614 | D33: =('C 8'!D33/'C 7'!D33)*1000 -> 44.146884 | E33: =('C 8'!E33/'C 7'!E33)*1000 -> 108.31166 | F33: 0 | G33: 0 | H33: 0
